Workbook

Sheet Cover
B3: IB PORTFOLIO · PROJECT 15 OF 20
B4: Salik
B5: Company Profile and Buyer Screen
B6: DFM: SALIK · AED millions · per-share values in AED · as of FY2025 accounts · market data 18 Sep 2026
B9: What this is | C9: A company profile and buyer screen for Salik, Dubai's toll-gate operator, on FY2025 accounts and 18 September 2026 market data: what the business is, how it has performed since the 2022 IPO, where it trades against listed toll roads, who could realistically own a stake, and what a financial sponsor and a strategic operator could each pay.
B11: How it is built | C11: • Four years of income, cash flow and balance sheet with growth, margins, cash conversion and leverage.
C12: • Trading multiples against a short, stated peer set with exclusions explained.
C13: • Twelve candidate buyers scored 1–5 on strategic fit, toll-road precedent, financial capacity, regional presence and the likelihood of Government of Dubai consent; weights are inputs and the ranking is live.
C14: • Ability to pay: a sponsor constrained by 6x leverage, a five-year exit and a 13% hurdle; a strategic constrained by a 7% cost of capital over the 45 years left on the concession.
B16: Contents | C16: Profile — the business, the case for a buyer, the constraint
C17: Financials — FY2022–FY2025 income, cash, balance sheet
C18: Trading — multiples at the market price and against peers
C19: Buyer Screen — twelve candidates, five criteria, live ranking
C20: Ability to Pay — sponsor versus strategic, price per share
C21: Checks — fourteen tests; must read MODEL OK
B23: Key outputs (live) | C23: FY2025 EBITDA (AED m) | E23: =Financials!$F$8 -> 2165
C24: EV / EBITDA at the market price | E24: =Trading!$D$10 -> 20.213857
C25: Price return since the IPO | E25: =Trading!$D$14 -> 1.685
C26: Highest-scoring candidate | E26: ='Buyer Screen'!$E$22 -> Vinci Concessions
C27: Sponsor ability to pay (AED per share) | E27: ='Ability to Pay'!$C$31 -> 4.6578897
C28: Strategic ability to pay (AED per share) | E28: ='Ability to Pay'!$C$43 -> 6.0455248
B30: Colour code | C30: Blue = hard-coded input
C31: Black = formula
C32: Green = link to another sheet
C33: Accent fill = scenario selector / key levers
B35: Sources | C35: Salik Company PJSC financial statements FY2022–FY2025 via Yahoo Finance for SALIK.AE; concession terms, gates and tariff from the 2022 IPO prospectus and RTA announcements.
C36: Share price and 52-week range: DFM close, 18 September 2026. Peer multiples: Yahoo Finance the same day.
C37: Buyer scores are the author's judgements from public precedent; criteria weights and every ability-to-pay input are stated.
C38: Nothing here is a recommendation and there is no suggestion any party is or has been in discussions.
B40: Prepared by | C40: Jainam Mehta · github.com/jainammehta1215/ib-portfolio

Sheet Financials
B1: Salik — Company Profile and Buyer Screen | G1: SALIK
B2: Four years since the IPO — income, cash and balance sheet
B4: INCOME STATEMENT (AED millions)
C5: FY2022A | D5: FY2023A | E5: FY2024A | F5: FY2025A
B6: Revenue | C6: 1892 | D6: 2109 | E6: 2292 | F6: 3097
B7: Growth | D7: =D6/C6-1 -> 0.11469345 | E7: =E6/D6-1 -> 0.086770982 | F7: =F6/E6-1 -> 0.35122164
B8: EBITDA | C8: 1443 | D8: 1420 | E8: 1627 | F8: 2165
B9: EBITDA margin | C9: =C8/C6 -> 0.76268499 | D9: =D8/D6 -> 0.67330488 | E9: =E8/E6 -> 0.70986038 | F9: =F8/F6 -> 0.69906361
B10: Depreciation and amortisation | C10: -44 | D10: -83 | E10: -91 | F10: -145
B11: Net finance cost | C11: -73 | D11: -239 | E11: -257 | F11: -313
B12: Corporate tax | C12: 0 | D12: 0 | E12: -115 | F12: -154
B13: Net profit | C13: 1326 | D13: 1098 | E13: 1165 | F13: 1553
B14: check: EBITDA − D&A − finance − tax | C14: =C8+C10+C11+C12 -> 1326 | D14: =D8+D10+D11+D12 -> 1098 | E14: =E8+E10+E11+E12 -> 1164 | F14: =F8+F10+F11+F12 -> 1553
B15: Earnings per share (AED) | C15: =C13/7500 -> 0.1768 | D15: =D13/7500 -> 0.1464 | E15: =E13/7500 -> 0.15533333 | F15: =F13/7500 -> 0.20706667
B17: CASH FLOW AND DISTRIBUTION
B18: Cash from operations | C18: 1516 | D18: 1454 | E18: 1463 | F18: 2082
B19: Capital expenditure | C19: -3 | D19: -5 | E19: -6 | F19: -3
B20: Free cash flow | C20: =C18+C19 -> 1513 | D20: =D18+D19 -> 1449 | E20: =E18+E19 -> 1457 | F20: =F18+F19 -> 2079
B21: Dividends paid | C21: -827 | D21: -1039 | E21: -1095 | F21: -1391
B22: Dividends paid / prior-year net profit | D22: =-Financials!$D$21/Financials!$C$13 -> 0.78355958 | E22: =-Financials!$E$21/Financials!$D$13 -> 0.99726776 | F22: =-Financials!$F$21/Financials!$E$13 -> 1.1939914
B23: Free cash flow / EBITDA | C23: =Financials!$C$20/Financials!$C$8 -> 1.04851 | D23: =Financials!$D$20/Financials!$D$8 -> 1.0204225 | E23: =Financials!$E$20/Financials!$E$8 -> 0.89551321 | F23: =Financials!$F$20/Financials!$F$8 -> 0.96027714
B25: BALANCE SHEET
B26: Borrowings | C26: 3986 | D26: 3997 | E26: 4000 | F26: 4001
B27: Cash | C27: 823 | D27: 266 | E27: 964 | F27: 513
B28: Net debt | C28: =C26-C27 -> 3163 | D28: =D26-D27 -> 3731 | E28: =E26-E27 -> 3036 | F28: =F26-F27 -> 3488
B29: Net debt / EBITDA | C29: =Financials!$C$28/Financials!$C$8 -> 2.1919612 | D29: =Financials!$D$28/Financials!$D$8 -> 2.6274648 | E29: =Financials!$E$28/Financials!$E$8 -> 1.8660111 | F29: =Financials!$F$28/Financials!$F$8 -> 1.6110855
B30: EBITDA / net finance cost | C30: =-Financials!$C$8/Financials!$C$11 -> 19.767123 | D30: =-Financials!$D$8/Financials!$D$11 -> 5.9414226 | E30: =-Financials!$E$8/Financials!$E$11 -> 6.3307393 | F30: =-Financials!$F$8/Financials!$F$11 -> 6.9169329
B31: Shareholders' equity | C31: 604 | D31: 663 | E31: 1088 | F31: 1219
B32: The FY2025 step-up is the tariff, not traffic: variable pricing from 31 January 2025 (AED 6 at peak, AED 4 off-peak) and two gates opened in November 2024. Capex is negligible because the RTA builds and operates the gates; Salik's cost is a concession fee inside operating expenses. Equity is small because the company was formed with AED 4bn of debt and pays out all its profit.

Sheet Profile
B1: Salik — Company Profile and Buyer Screen | F1: SALIK
B2: What Salik is, in the form a buyer's investment committee would read it
B4: THE BUSINESS
B5: What it does | C5: Operates Dubai's automated road-toll system under an exclusive 49-year concession from the Roads and Transport Authority running to 2071. Ten gates as of 2025. Tolls are collected electronically per crossing; the tariff is set by government decree.
B6: Revenue model | C6: Toll revenue per crossing (the large majority), plus fines, tag activation and ancillary services. Variable pricing was introduced on 31 January 2025: AED 6 at peak hours, AED 4 off-peak, free between 1am and 2am. Ancillary growth comes from parking payments and partnerships.
B7: Cost model | C7: Asset-light. The RTA builds, owns and maintains the gates; Salik pays a concession fee and a service fee. There is almost no capital expenditure, so EBITDA converts to cash at close to 100%.
B8: Ownership | C8: Listed on the Dubai Financial Market since 29 September 2022 at AED 2.00 per share, raising AED 3.7bn for the Government of Dubai, which retains 75.1%. Free float 24.9%.
B9: Capital structure | C9: AED 4.0bn of bank debt put in place at formation and held flat since; the company distributes all of its net profit. Leverage has fallen from 2.2x to 1.6x EBITDA on earnings growth alone.
B11: WHY A BUYER WOULD LOOK
B12: Predictability | C12: Traffic in a growing city, a tariff set by decree and a 45-year remaining term. The revenue line is closer to a regulated utility than to a typical toll road with traffic risk.
B13: Growth levers | C13: New gates (two added in 2024), tariff changes (2025), population growth, and ancillary revenue. All three of the first are policy decisions, not management decisions, which is both the attraction and the constraint.
B14: The constraint | C14: The Government of Dubai holds 75.1% and the RTA controls the gates, the tariff and the concession. Any change of control is a policy decision. The realistic transactions are a further sell-down of the government's stake, an anchor stake to a long-term investor, or a partnership; an unsolicited bid is not one of them.
B16: KEY NUMBERS, FY2025
B17: Revenue (AED m) | C17: =Financials!$F$6 -> 3097
B18: EBITDA (AED m) | C18: =Financials!$F$8 -> 2165
B19: EBITDA margin | C19: =Financials!$F$9 -> 0.69906361
B20: Net profit (AED m) | C20: =Financials!$F$13 -> 1553
B21: Free cash flow / EBITDA | C21: =Financials!$F$23 -> 0.96027714
B22: Net debt / EBITDA | C22: =Financials!$F$29 -> 1.6110855

Sheet Trading
B1: Salik — Company Profile and Buyer Screen | G1: SALIK
B2: Where Salik trades, against listed toll roads and a local concession
B4: SALIK AT THE MARKET PRICE
B5: Share price (AED, DFM close 18 Sep 2026) | D5: 5.37
B6: Shares (millions) | D6: 7500
B7: Market capitalisation | D7: =Trading!$D$5*Trading!$D$6 -> 40275
B8: Net debt, FY2025 | D8: =Financials!$F$28 -> 3488
B9: Enterprise value | D9: =Trading!$D$7+Trading!$D$8 -> 43763
B10: EV / EBITDA, FY2025 | D10: =Trading!$D$9/Financials!$F$8 -> 20.213857
B11: P / E, FY2025 | D11: =Trading!$D$7/Financials!$F$13 -> 25.933677
B12: Dividend yield on FY2025 dividends paid | D12: =-Financials!$F$21/Trading!$D$7 -> 0.034537554
B13: Free cash flow yield to enterprise value | D13: =Financials!$F$20/Trading!$D$9 -> 0.047505884
B14: Price return since the IPO at AED 2.00 | D14: =Trading!$D$5/2-1 -> 1.685
B16: LISTED COMPARABLES — trailing EV / EBITDA, 18 September 2026
B17: Company | C17: Business | D17: EV / EBITDA | E17: Included | F17: If included | G17: Note
B18: Transurban (ASX) | C18: Toll roads, Australia and North America | D18: 26.3 | E18: 1 | F18: =IF(E18=1,D18,"") -> 26.3
B19: Ferrovial (Cintra) | C19: Toll roads, Europe and North America | D19: 27.7 | E19: 0 | F19: =IF(E19=1,D19,"") | G19: Group multiple distorted by construction and airports
B20: Vinci | C20: Concessions and contracting, France | D20: 7.2 | E20: 0 | F20: =IF(E20=1,D20,"") | G20: Contracting dilutes the concession multiple
B21: IRB Infrastructure (NSE) | C21: Toll roads, India | D21: 15.5 | E21: 1 | F21: =IF(E21=1,D21,"") -> 15.5
B22: Vesta (NYSE) | C22: Industrial real estate, Mexico — yield comparator | D22: 16.9 | E22: 0 | F22: =IF(E22=1,D22,"") | G22: Not a toll road; shown for yield context only
B23: Tabreed (DFM) | C23: District cooling concessions, UAE | D23: 12.1 | E23: 1 | F23: =IF(E23=1,D23,"") -> 12.1
B24: Salik at the market price | D24: =Trading!$D$10 -> 20.213857
B25: Median of included peers | D25: =MEDIAN(F18:F23) -> 15.5
B26: Salik premium / (discount) to the peer median | D26: =Trading!$D$10/Trading!$D$25-1 -> 0.30411979
B27: Pure toll-road operators with long concessions trade at high-teens to mid-twenties EBITDA multiples because the cash flows are long, contracted and inflation-linked. Salik sits inside that range with the shortest listed history and the least traffic risk, which is why the peer set is short and the exclusions are stated.

Sheet Buyer Screen
B1: Salik — Company Profile and Buyer Screen | M1: SALIK
B2: Twelve candidates scored on five criteria — the scores are judgements and the weights are inputs
B4: CRITERIA WEIGHTS (must sum to 100%)
B5: Government consent | F5: 0.25 | G5: 0.2 | H5: 0.2 | I5: 0.15 | J5: 0.2 | K5: =SUM(F5:J5) -> 1
B7: THE SCREEN (scores 1 = weak, 5 = strong)
B8: Candidate | C8: Type | D8: Home | E8: Precedent and relevant assets | F8: Strategic fit | G8: Toll-road precedent | H8: Financial capacity | I8: Regional presence | J8: Government consent | K8: Weighted | L8: Rank | M8: Read-across
B9: Transurban | C9: Strategic | D9: Australia | E9: Owns 20+ urban toll roads; WestConnex, 407 ETR | F9: 5 | G9: 5 | H9: 3 | I9: 2 | J9: 3 | K9: =SUMPRODUCT(F9:J9,$F$5:$J$5) -> 3.75 | L9: =RANK(K9,$K$9:$K$20) -> 10 | M9: Best operator fit; balance sheet stretched; no Gulf presence
B10: Vinci Concessions | C10: Strategic | D10: France | E10: Autoroutes du Sud; Lima Expresa; airports | F10: 5 | G10: 5 | H10: 5 | I10: 3 | J10: 3 | K10: =SUMPRODUCT(F10:J10,$F$5:$J$5) -> 4.3 | L10: =RANK(K10,$K$9:$K$20) -> 1 | M10: Deepest pockets among strategics; Gulf contracting relationships via Vinci
B11: Ferrovial / Cintra | C11: Strategic | D11: Spain / NL | E11: 407 ETR, LBJ and NTE managed lanes | F11: 5 | G11: 5 | H11: 4 | I11: 2 | J11: 3 | K11: =SUMPRODUCT(F11:J11,$F$5:$J$5) -> 3.95 | L11: =RANK(K11,$K$9:$K$20) -> 8 | M11: Managed-lane expertise fits dynamic pricing; light in the region
B12: Abertis (Mundys / ACS) | C12: Strategic | D12: Spain / Italy | E12: Largest toll-road operator by km; Red de Carreteras, Sanef | F12: 5 | G12: 5 | H12: 4 | I12: 3 | J12: 3 | K12: =SUMPRODUCT(F12:J12,$F$5:$J$5) -> 4.1 | L12: =RANK(K12,$K$9:$K$20) -> 4 | M12: Largest pure toll-road owner; would want operational control the RTA will not give
B13: Globalvia | C13: Strategic | D13: Spain | E13: Mid-size toll roads and rail concessions | F13: 4 | G13: 4 | H13: 2 | I13: 2 | J13: 2 | K13: =SUMPRODUCT(F13:J13,$F$5:$J$5) -> 2.9 | L13: =RANK(K13,$K$9:$K$20) -> 12 | M13: Too small for a AED 40bn asset except as a minority partner
B14: Global Infrastructure Partners (BlackRock) | C14: Financial | D14: US | E14: Jafurah midstream (Aramco); Gatwick; ports | F14: 4 | G14: 3 | H14: 5 | I14: 4 | J14: 4 | K14: =SUMPRODUCT(F14:J14,$F$5:$J$5) -> 4 | L14: =RANK(K14,$K$9:$K$20) -> 7 | M14: Just closed Jafurah with Aramco; the template for a Gulf minority-stake deal
B15: Brookfield Infrastructure | C15: Financial | D15: Canada | E15: Toll roads in Brazil, India, Peru; large Gulf activity | F15: 4 | G15: 4 | H15: 5 | I15: 4 | J15: 4 | K15: =SUMPRODUCT(F15:J15,$F$5:$J$5) -> 4.2 | L15: =RANK(K15,$K$9:$K$20) -> 2 | M15: Owns toll roads and has a Gulf office; natural anchor investor
B16: Macquarie Asset Management | C16: Financial | D16: Australia | E16: Historic toll-road sponsor; UK, US, India roads | F16: 4 | G16: 5 | H16: 5 | I16: 3 | J16: 3 | K16: =SUMPRODUCT(F16:J16,$F$5:$J$5) -> 4.05 | L16: =RANK(K16,$K$9:$K$20) -> 6 | M16: Invented the listed toll-road fund model; strong precedent
B17: KKR Infrastructure | C17: Financial | D17: US | E17: ADNOC pipelines; Indian roads platform | F17: 4 | G17: 4 | H17: 5 | I17: 4 | J17: 4 | K17: =SUMPRODUCT(F17:J17,$F$5:$J$5) -> 4.2 | L17: =RANK(K17,$K$9:$K$20) -> 2 | M17: ADNOC pipelines precedent shows the Gulf structure works
B18: CVC / DIF Capital Partners | C18: Financial | D18: NL / Luxembourg | E18: Mid-market PPP and transport concessions | F18: 3 | G18: 4 | H18: 3 | I18: 3 | J18: 3 | K18: =SUMPRODUCT(F18:J18,$F$5:$J$5) -> 3.2 | L18: =RANK(K18,$K$9:$K$20) -> 11 | M18: Cheque size is the constraint
B19: PIF / Mubadala / ADQ | C19: Sovereign | D19: Gulf | E19: Regional infrastructure; co-investment with global sponsors | F19: 3 | G19: 2 | H19: 5 | I19: 5 | J19: 5 | K19: =SUMPRODUCT(F19:J19,$F$5:$J$5) -> 3.9 | L19: =RANK(K19,$K$9:$K$20) -> 9 | M19: Most likely co-investor in any government sell-down; no operational value-add
B20: Dubai Holding / ICD (incumbent) | C20: Sovereign | D20: Dubai | E20: Existing owner group; reorganisation rather than a sale | F20: 3 | G20: 3 | H20: 5 | I20: 5 | J20: 5 | K20: =SUMPRODUCT(F20:J20,$F$5:$J$5) -> 4.1 | L20: =RANK(K20,$K$9:$K$20) -> 4 | M20: The counterparty in every scenario; a reorganisation is more likely than a sale
B22: Highest-scoring candidate | E22: =INDEX($B$9:$B$20,MATCH(MAX('Buyer Screen'!$K$9:$K$20),'Buyer Screen'!$K$9:$K$20,0)) -> Vinci Concessions
B23: weighted score | E23: =MAX('Buyer Screen'!$K$9:$K$20) -> 4.3
B24: Financial and sovereign buyers in the top five | E24: =SUMPRODUCT((C9:C20<>"Strategic")*(L9:L20<=5)) -> 3
B25: The screen ranks who could realistically hold a stake, not who would bid for control. Vinci leads on fit and balance sheet; the sponsors that have already done minority infrastructure deals with Gulf sovereigns — Brookfield, KKR, GIP — sit immediately behind it, level with the incumbent shareholder group. The purest operators, Transurban and Ferrovial, score highest on fit and fall down the list on consent and capacity, which is the finding: the likely transaction is a minority stake to a sponsor or sovereign, with an operator as a partner rather than a buyer.

Sheet Ability to Pay
B1: Salik — Company Profile and Buyer Screen | F1: SALIK
B2: What a sponsor and a strategic could each pay per share, and why they differ
B4: COMMON OPERATING CASE
B5: FY2025 EBITDA | C5: =Financials!$F$8 -> 2165
B6: EBITDA growth, next five years | C6: 0.06 | F6: Traffic and population plus ancillary; below the 2025 step-up, which was a tariff event
B7: Corporate tax | C7: 0.09
B8: Depreciation and amortisation as % of EBITDA | C8: 0.07
B9: Capex as % of EBITDA | C9: 0.005
B10: Net debt today | C10: =Financials!$F$28 -> 3488
B11: EBITDA in year five | C11: ='Ability to Pay'!$C$5*(1+'Ability to Pay'!$C$6)^5 -> 2897.2584
B13: A. FINANCIAL SPONSOR — leverage and a return hurdle
B14: Debt at entry (x EBITDA) | C14: 6 | F14: Infrastructure lenders will go further on a concession with no traffic risk than on a corporate
B15: Cost of debt | C15: 0.06
B16: Exit EV / EBITDA in year five | C16: 18 | F16: Below today's multiple on purpose
B17: Required equity IRR | C17: 0.13 | F17: Core-plus infrastructure; lower than a buyout because the risk is lower
B18: Debt raised at entry | C18: ='Ability to Pay'!$C$5*'Ability to Pay'!$C$14 -> 12990
B19: Debt paydown, year by year (all free cash after interest and tax repays debt)
B20: Opening debt | C20: ='Ability to Pay'!$C$18 -> 12990 | D20: =C24 -> 11607.912 | E20: =D24 -> 10024.881 | F20: =E24 -> 8222.4069 | G20: =F24 -> 6180.5281
B21: EBITDA | C21: ='Ability to Pay'!$C$5*(1+'Ability to Pay'!$C$6)^1 -> 2294.9 | D21: ='Ability to Pay'!$C$5*(1+'Ability to Pay'!$C$6)^2 -> 2432.594 | E21: ='Ability to Pay'!$C$5*(1+'Ability to Pay'!$C$6)^3 -> 2578.5496 | F21: ='Ability to Pay'!$C$5*(1+'Ability to Pay'!$C$6)^4 -> 2733.2626 | G21: ='Ability to Pay'!$C$5*(1+'Ability to Pay'!$C$6)^5 -> 2897.2584
B22: Interest on opening debt | C22: =-C20*'Ability to Pay'!$C$15 -> -779.4 | D22: =-D20*'Ability to Pay'!$C$15 -> -696.4747 | E22: =-E20*'Ability to Pay'!$C$15 -> -601.49284 | F22: =-F20*'Ability to Pay'!$C$15 -> -493.34441 | G22: =-G20*'Ability to Pay'!$C$15 -> -370.83169
B23: Cash after tax and capex available to repay debt | C23: =(C21+C22-C21*'Ability to Pay'!$C$8)*(1-'Ability to Pay'!$C$7)+C21*'Ability to Pay'!$C$8-C21*'Ability to Pay'!$C$9 -> 1382.0884 | D23: =(D21+D22-D21*'Ability to Pay'!$C$8)*(1-'Ability to Pay'!$C$7)+D21*'Ability to Pay'!$C$8-D21*'Ability to Pay'!$C$9 -> 1583.0309 | E23: =(E21+E22-E21*'Ability to Pay'!$C$8)*(1-'Ability to Pay'!$C$7)+E21*'Ability to Pay'!$C$8-E21*'Ability to Pay'!$C$9 -> 1802.4738 | F23: =(F21+F22-F21*'Ability to Pay'!$C$8)*(1-'Ability to Pay'!$C$7)+F21*'Ability to Pay'!$C$8-F21*'Ability to Pay'!$C$9 -> 2041.8788 | G23: =(G21+G22-G21*'Ability to Pay'!$C$8)*(1-'Ability to Pay'!$C$7)+G21*'Ability to Pay'!$C$8-G21*'Ability to Pay'!$C$9 -> 2302.8147
B24: Closing debt | C24: =MAX(0,C20-C23) -> 11607.912 | D24: =MAX(0,D20-D23) -> 10024.881 | E24: =MAX(0,E20-E23) -> 8222.4069 | F24: =MAX(0,F20-F23) -> 6180.5281 | G24: =MAX(0,G20-G23) -> 3877.7134
B26: Exit enterprise value | C26: ='Ability to Pay'!$C$11*'Ability to Pay'!$C$16 -> 52150.651
B27: Exit equity value | C27: ='Ability to Pay'!$C$26-'Ability to Pay'!$G$24 -> 48272.937
B28: Maximum equity cheque at the hurdle: exit equity / (1 + IRR)^5 | C28: ='Ability to Pay'!$C$27/(1+'Ability to Pay'!$C$17)^5 -> 26200.616
B29: Transaction and financing fees (% of EV) | C29: 0.02
B30: Maximum enterprise value a sponsor can pay | C30: =('Ability to Pay'!$C$28+'Ability to Pay'!$C$18)/(1+'Ability to Pay'!$C$29) -> 38422.173
B31: Maximum price per share — sponsor (AED) | C31: =('Ability to Pay'!$C$30-'Ability to Pay'!$C$10)/7500 -> 4.6578897
B32: versus the market price | C32: ='Ability to Pay'!$C$31/Trading!$D$5-1 -> -0.13260899
B34: B. STRATEGIC OPERATOR — cost of capital over the remaining concession
B35: Strategic buyer's WACC for a Gulf concession | C35: 0.07
B36: Cost synergies as % of EBITDA | C36: 0.03 | F36: Little to synergise: the RTA runs the gates. Technology and procurement only
B37: Remaining concession life (years, to 2071) | C37: 45
B38: Long-run cash flow growth after year five | C38: 0.03
B39: Year-one free cash flow to the firm, with synergies | C39: ='Ability to Pay'!$C$5*(1+'Ability to Pay'!$C$6)*(1+'Ability to Pay'!$C$36)*(1-'Ability to Pay'!$C$8)*(1-'Ability to Pay'!$C$7)+'Ability to Pay'!$C$5*(1+'Ability to Pay'!$C$6)*'Ability to Pay'!$C$8-'Ability to Pay'!$C$5*(1+'Ability to Pay'!$C$6)*'Ability to Pay'!$C$9 -> 2149.6076
B40: PV of years one to five (growing annuity at g) | C40: ='Ability to Pay'!$C$39/('Ability to Pay'!$C$35-'Ability to Pay'!$C$6)*(1-((1+'Ability to Pay'!$C$6)/(1+'Ability to Pay'!$C$35))^5) -> 9858.8867
B41: PV of years six to end of concession (growing annuity at long-run g) | C41: ='Ability to Pay'!$C$39*(1+'Ability to Pay'!$C$6)^4*(1+'Ability to Pay'!$C$38)/('Ability to Pay'!$C$35-'Ability to Pay'!$C$38)*(1-((1+'Ability to Pay'!$C$38)/(1+'Ability to Pay'!$C$35))^('Ability to Pay'!$C$37-5))/(1+'Ability to Pay'!$C$35)^5 -> 38970.549
B42: Maximum enterprise value a strategic can pay | C42: ='Ability to Pay'!$C$40+'Ability to Pay'!$C$41 -> 48829.436
B43: Maximum price per share — strategic (AED) | C43: =('Ability to Pay'!$C$42-'Ability to Pay'!$C$10)/7500 -> 6.0455248
B44: versus the market price | C44: ='Ability to Pay'!$C$43/Trading!$D$5-1 -> 0.12579605
...

Sheet Checks
B1: Salik — Company Profile and Buyer Screen | E1: SALIK
B2: Every check must read TRUE
B4: INTEGRITY CHECKS
B5: Reported net profit reconciles to EBITDA less D&A, finance and tax in every year | C5: =AND(ABS(Financials!$C$13-Financials!$C$14)<2,ABS(Financials!$D$13-Financials!$D$14)<2,ABS(Financials!$E$13-Financials!$E$14)<2,ABS(Financials!$F$13-Financials!$F$14)<2) -> TRUE
B6: Capex is below 1% of EBITDA in every year | C6: =AND(-Financials!$C$19/Financials!$C$8<0.01,-Financials!$D$19/Financials!$D$8<0.01,-Financials!$E$19/Financials!$E$8<0.01,-Financials!$F$19/Financials!$F$8<0.01) -> TRUE
B7: Net debt / EBITDA has fallen since FY2022 | C7: =Financials!$F$29<Financials!$C$29 -> TRUE
B8: Market capitalisation reconciles to price times shares | C8: =ABS(Trading!$D$7-5.37*7500)<0.01 -> TRUE
B9: Share price lies within the 52-week range | C9: =AND(Trading!$D$5>=4.96-0.05,Trading!$D$5<=6.78+0.05) -> TRUE
B10: Peer median evaluates to a number | C10: =ISNUMBER(Trading!$D$25) -> TRUE
B11: Criteria weights sum to 100% | C11: =ABS('Buyer Screen'!$K$5-1)<0.0001 -> TRUE
B12: Every score lies between 1 and 5 | C12: =AND(MIN('Buyer Screen'!F9:J20)>=1,MAX('Buyer Screen'!F9:J20)<=5) -> TRUE
B13: Weighted scores lie between 1 and 5 | C13: =AND(MIN('Buyer Screen'!$K$9:$K$20)>=1,MAX('Buyer Screen'!$K$9:$K$20)<=5) -> TRUE
B14: Sponsor debt is fully serviced: closing debt never negative and below opening | C14: =AND('Ability to Pay'!$G$24>=0,'Ability to Pay'!$G$24<'Ability to Pay'!$C$18) -> TRUE
B15: Sponsor exit multiple is not above today's trading multiple | C15: ='Ability to Pay'!$C$16<=Trading!$D$10 -> TRUE
B16: Strategic WACC exceeds long-run growth | C16: ='Ability to Pay'!$C$35>'Ability to Pay'!$C$38 -> TRUE
B17: Strategic ability to pay exceeds the sponsor's (the structural result) | C17: ='Ability to Pay'!$C$43>'Ability to Pay'!$C$31 -> TRUE
B18: Government stake plus free float equals 100% | C18: =ABS(0.751+0.249-1)<0.001 -> TRUE
B20: MODEL STATUS | C20: =IF(COUNTIF(C5:C18,FALSE())=0,"MODEL OK","CHECK FAILED") -> MODEL OK
B22: The thirteenth check is a discipline check: if the sponsor's number ever exceeds the strategic's, either the leverage or the exit multiple has been pushed past what the asset supports.
