Workbook

Sheet Cover
B3: IB PORTFOLIO · PROJECT 05 OF 20
B4: Tata Consultancy Services
B5: Football Field and Valuation Summary
B6: NSE: TCS · INR billions · per-share values in INR · as of market data 12 Sep 2026 · financials FY2026 (year to 31 Mar 2026)
B9: What this is | C9: Everything Projects 2 to 4 produced about what a business like TCS is worth, put on one page, plus the DCF the football field needed and did not have. Seven methodologies, each a range rather than a point, against the 12 September 2026 share price.
B11: How it is built | C11: • A compact five-year DCF in INR: local risk-free rate, beta regressed against the NIFTY 50, terminal value by perpetuity growth and by exit multiple with each checking the other, and a live WACC-by-growth sensitivity grid.
C12: • Trading-multiple ranges carried in from Project 3 (peer 25th to 75th percentile) and precedent-transaction ranges from Project 4, each flagged for how far it can be trusted.
C13: • The beta regression Project 2 used for Apple was run for TCS and rejected: Indian shares against the S&P 500 give R-squared of 0.01. The WACC sheet records the rejected regressions rather than deleting them.
C14: • Eighteen integrity checks, including one that fails if the forecast assumes growth above anything TCS has recently achieved.
B16: Contents | C16: Football Field — the chart and the data behind it
C17: Ranges — every bar, its source and its caveat
C18: DCF — five-year forecast, terminal value both ways, sensitivity grid
C19: WACC — beta regressions accepted and rejected, cost of capital build
C20: Inputs — market data, cost of capital and forecast drivers
C21: Checks — eighteen tests; must read MODEL OK
B23: Key outputs (live) | C23: DCF value per share (INR) | E23: =DCF!K39 -> 1952.7431
C24: Current share price (INR) | E24: =Inputs!$C$5 -> 2200.8
C25: Recommended range (INR) | E25: =Ranges!C16 -> 1675.903
C26: Recommended midpoint (INR) | E26: =Ranges!E16 -> 2145.0286
C27: WACC (INR) | E27: =Inputs!$C$22 -> 0.13302523
C28: Terminal value as % of EV | E28: =DCF!K35 -> 0.69817826
B30: Colour code | C30: Blue = hard-coded input
C31: Black = formula
C32: Green = link to another sheet
C33: Accent fill = scenario selector / key levers
B35: Sources | C35: TCS annual financials FY2023-FY2026 (year to 31 March), Yahoo Finance fundamentals for TCS.NS, restating the consolidated annual report.
C36: Share price, 52-week range and share count: Yahoo Finance, 12 September 2026 — the same market date as Projects 3 and 4.
C37: Risk-free rate: India 10-year G-Sec at 7.02%, 11 September 2026.
C38: Equity risk premium: 4.5% mature-market premium (as used in Project 2) plus a 2.2% India country risk premium (Damodaran).
C39: Beta: five years of weekly returns to 12 September 2026, TCS against the NIFTY 50, 254 observations.
C40: Trading-multiple ranges from Project 3; precedent-transaction ranges from Project 4.
B42: Prepared by | C42: Jainam Mehta · github.com/jainammehta1215/ib-portfolio

Sheet Inputs
B1: Tata Consultancy Services — Football Field and Valuation Summary | F1: TATA CONSULTANCY SERVICES
B2: Market data, capital structure, cost of capital and forecast drivers
B4: MARKET DATA (12 SEPTEMBER 2026)
B5: TCS share price (INR) | C5: 2200.8 | F5: Yahoo Finance, NSE close 12 Sep 2026. Same price as Projects 3 and 4
B6: 52-week high (INR) | C6: 3350 | F6: Yahoo Finance
B7: 52-week low (INR) | C7: 1976.8 | F7: Yahoo Finance
B8: Shares outstanding (m) | C8: 3618.0875 | F8: Project 3
B9: USD per INR | C9: 0.010467 | F9: USDINR 95.54; used only to restate Project 3's US$ net cash
B10: Net cash (US$m, from Project 3) | C10: 3019.9388 | F10: Project 3 reports net debt of US$(3,020)m
B11: Net cash (INR bn) | C11: =C10*95.54/1000 -> 288.52496 | F11: Restated at the 12 Sep 2026 rate
B13: COST OF CAPITAL (INR, LOCAL CAPM)
B14: Risk-free rate: India 10-year G-Sec | C14: 0.0702 | F14: 7.02% on 11 Sep 2026. Local-currency cash flows require a local-currency risk-free rate
B15: Raw beta (TCS vs NIFTY 50, 5y weekly) | C15: 0.907 | F15: 254 weekly observations to 12 Sep 2026; R-squared 0.28. See the WACC sheet
B16: Blume-adjusted beta | C16: =0.67*C15+0.33 -> 0.93769 | F16: 0.67 x raw + 0.33, as banks apply it; pulls the estimate toward 1.0
B17: Mature-market equity risk premium | C17: 0.045 | F17: Same 4.5% used in Project 2, for consistency across the portfolio
B18: India country risk premium | C18: 0.022 | F18: Damodaran country risk premium for India (Baa3/BBB-). Verify against the current table before reuse
B19: India equity risk premium | C19: =C17+C18 -> 0.067 | F19: Mature-market premium plus country risk
B20: Cost of equity | C20: =C14+C16*C19 -> 0.13302523 | F20: CAPM in INR
B21: Debt as % of capital | C21: 0 | F21: TCS carries no meaningful borrowing and is net cash, so WACC collapses to the cost of equity
B22: WACC (INR) | C22: =C20*(1-C21) -> 0.13302523 | F22: Used to discount INR cash flows
B24: FORECAST DRIVERS
B25: Tax rate on EBIT | C25: 0.255 | F25: Between the FY2025 and FY2026 effective rates
B26: D&A as % of revenue | C26: 0.021 | F26: FY2026 actual: 2.08%
B27: Capex as % of revenue | C27: 0.016 | F27: FY2026 actual: 1.55%. An asset-light business
B28: Increase in working capital as % of incremental revenue | C28: 0.15 | F28: Receivables-driven; a growth business absorbs cash here
B29: Terminal growth (INR, nominal) | C29: 0.055 | F29: Roughly Indian long-run inflation plus modest real growth; well below nominal GDP
B30: Exit EV/EBITDA (cross-check only) | C30: 11 | F30: Used to test the perpetuity assumption, not to value the company
B31: Mid-year discounting convention | C31: 1 | F31: 1 = cash flows arrive mid-year (periods 0.5, 1.5, ...); 0 = year-end
B33: ANALYST CONSENSUS (RESEARCH-TARGET BAR)
B34: Analyst target — low (INR) | C34: 1775 | F34: Lowest of 43 published 12-month targets, 12 Sep 2026
B35: Analyst target — average (INR) | C35: 2943.65 | F35: Consensus average; the figure most often quoted back in a meeting
B36: Analyst target — high (INR) | C36: 3900 | F36: Highest published target
B37: Number of analysts covering | C37: 43 | F37: Coverage depth. A thin consensus is worth less than a broad one
B39: Everything above is a hard-coded input (blue). Every figure on every other sheet is a formula. The DCF is deliberately compact: five forecast years, one case, and a sensitivity grid — its job is to produce one honest bar on the football field, not to replace Project 2's full treatment.

Sheet WACC
B1: Tata Consultancy Services — Football Field and Valuation Summary | G1: TATA CONSULTANCY SERVICES
B2: Beta estimated where the regression is valid, and a record of the regressions that were rejected
B4: BETA ESTIMATE USED
B5: Regression | C5: Raw beta | D5: R-squared
B6: TCS vs NIFTY 50 (INR) | C6: 0.907 | D6: 0.28 | G6: Accepted: same market, same currency, same trading hours
B8: REGRESSIONS RUN AND REJECTED
B9: Regression | C9: Raw beta | D9: R-squared
B10: TCS vs S&P 500 (USD returns) | C10: 0.14 | D10: 0.01 | G10: Rejected: R-squared 0.01 — no explanatory power
B11: Infosys vs S&P 500 (USD returns) | C11: 0.24 | D11: 0.02 | G11: Rejected: R-squared 0.02
B12: HCLTech vs S&P 500 (USD returns) | C12: 0.062 | D12: 0 | G12: Rejected: R-squared 0.00
B13: Wipro vs S&P 500 (USD returns) | C13: 0.326 | D13: 0.04 | G13: Rejected: R-squared 0.04
B14: Accenture vs S&P 500 | C14: 0.975 | D14: 0.24 | G14: US-listed peer: regression behaves normally
B15: Cognizant vs S&P 500 | C15: 0.908 | D15: 0.23 | G15: US-listed peer: regression behaves normally
B16: EPAM vs S&P 500 | C16: 1.485 | D16: 0.16 | G16: US-listed peer: regression behaves normally
B18: Project 2 built Apple's beta by regressing ten peers against the S&P 500, unlevering, taking the median and relevering. The same recipe applied to TCS breaks: Indian shares regressed against the S&P 500 give betas of 0.06 to 0.33 with R-squared of 0.00 to 0.04, because the two markets trade in different hours and different currencies. A beta with no explanatory power is not a conservative beta, it is a wrong one. The regression is therefore run in the market where TCS actually trades, against the NIFTY 50, in INR — which is also why the whole DCF is built in INR.
B20: COST OF CAPITAL BUILD
B21: Risk-free rate (India 10-year G-Sec) | C21: =Inputs!$C$14 -> 0.0702
B22: Raw beta | C22: =Inputs!$C$15 -> 0.907
B23: Blume-adjusted beta | C23: =Inputs!$C$16 -> 0.93769
B24: India equity risk premium | C24: =Inputs!$C$19 -> 0.067
B25: Cost of equity | C25: =Inputs!$C$20 -> 0.13302523
B26: WACC (INR) | C26: =Inputs!$C$22 -> 0.13302523
B28: TCS is net cash, so there is no debt tranche to weight and WACC equals the cost of equity. Stating that explicitly is better than building a capital-structure table whose debt weight is zero.

Sheet DCF
B1: Tata Consultancy Services — Football Field and Valuation Summary | L1: TATA CONSULTANCY SERVICES
B2: INR billions · fiscal year to 31 March · actuals in blue, forecast driven off the Inputs sheet
B4: UNLEVERED FREE CASH FLOW
C5: FY2023A | D5: FY2024A | E5: FY2025A | F5: FY2026A | G5: FY2027E | H5: FY2028E | I5: FY2029E | J5: FY2030E | K5: FY2031E
B6: Revenue | C6: 2254.58 | D6: 2408.93 | E6: 2553.24 | F6: 2670.21 | G6: =F6*(1+G7) -> 2750.3163 | H6: =G6*(1+H7) -> 2860.329 | I6: =H6*(1+I7) -> 3003.3454 | J6: =I6*(1+J7) -> 3168.5294 | K6: =J6*(1+K7) -> 3358.6412
B7: Growth | D7: =D6/C6-1 -> 0.068460645 | E7: =E6/D6-1 -> 0.059906265 | F7: =F6/E6-1 -> 0.04581238 | G7: 0.03 | H7: 0.04 | I7: 0.05 | J7: 0.055 | K7: 0.06
B8: EBIT | C8: 543.77 | D8: 594.25 | E8: 622.93 | F8: 670.22 | G8: =G6*G9 -> 682.07844 | H8: =H6*H9 -> 709.36158 | I8: =I6*I9 -> 750.83635 | J8: =J6*J9 -> 792.13235 | K8: =K6*K9 -> 839.66029
B9: EBIT margin | C9: =C8/C6 -> 0.24118461 | D9: =D8/D6 -> 0.24668629 | E9: =E8/E6 -> 0.24397628 | F9: =F8/F6 -> 0.25099899 | G9: 0.248 | H9: 0.248 | I9: 0.25 | J9: 0.25 | K9: 0.25
B10: Less: tax on EBIT | C10: =-C8*0.257 -> -139.74889 | D10: =-D8*0.2564 -> -152.3657 | E10: =-E8*0.253 -> -157.60129 | F10: =-F8*0.246 -> -164.87412 | G10: =-G8*Inputs!$C$25 -> -173.93 | H10: =-H8*Inputs!$C$25 -> -180.8872 | I10: =-I8*Inputs!$C$25 -> -191.46327 | J10: =-J8*Inputs!$C$25 -> -201.99375 | K10: =-K8*Inputs!$C$25 -> -214.11337
B11: NOPAT | C11: =C8+C10 -> 404.02111 | D11: =D8+D10 -> 441.8843 | E11: =E8+E10 -> 465.32871 | F11: =F8+F10 -> 505.34588 | G11: =G8+G10 -> 508.14844 | H11: =H8+H10 -> 528.47438 | I11: =I8+I10 -> 559.37308 | J11: =J8+J10 -> 590.1386 | K11: =K8+K10 -> 625.54692
B12: Plus: depreciation and amortisation | C12: 50.22 | D12: 49.85 | E12: 52.42 | F12: 55.6 | G12: =G6*Inputs!$C$26 -> 57.756642 | H12: =H6*Inputs!$C$26 -> 60.066908 | I12: =I6*Inputs!$C$26 -> 63.070253 | J12: =J6*Inputs!$C$26 -> 66.539117 | K12: =K6*Inputs!$C$26 -> 70.531464
B13: Less: capital expenditure | C13: -31 | D13: -26.74 | E13: -39.37 | F13: -41.46 | G13: =-G6*Inputs!$C$27 -> -44.005061 | H13: =-H6*Inputs!$C$27 -> -45.765263 | I13: =-I6*Inputs!$C$27 -> -48.053526 | J13: =-J6*Inputs!$C$27 -> -50.69647 | K13: =-K6*Inputs!$C$27 -> -53.738259
B14: Less: increase in working capital | D14: =-(D6-C6)*Inputs!$C$28 -> -23.1525 | E14: =-(E6-D6)*Inputs!$C$28 -> -21.6465 | F14: =-(F6-E6)*Inputs!$C$28 -> -17.5455 | G14: =-(G6-F6)*Inputs!$C$28 -> -12.015945 | H14: =-(H6-G6)*Inputs!$C$28 -> -16.501898 | I14: =-(I6-H6)*Inputs!$C$28 -> -21.452467 | J14: =-(J6-I6)*Inputs!$C$28 -> -24.7776 | K14: =-(K6-J6)*Inputs!$C$28 -> -28.516765
B15: Unlevered free cash flow | C15: =C11+C12+C13+C14 -> 423.24111 | D15: =D11+D12+D13+D14 -> 441.8418 | E15: =E11+E12+E13+E14 -> 456.73221 | F15: =F11+F12+F13+F14 -> 501.94038 | G15: =G11+G12+G13+G14 -> 509.88408 | H15: =H11+H12+H13+H14 -> 526.27412 | I15: =I11+I12+I13+I14 -> 552.93734 | J15: =J11+J12+J13+J14 -> 581.20365 | K15: =K11+K12+K13+K14 -> 613.82336
B16: Memo: EBITDA | C16: 627.08 | D16: 677.6 | E16: 713.69 | F16: 722.74 | G16: =G8+G12 -> 739.83508 | H16: =H8+H12 -> 769.42849 | I16: =I8+I12 -> 813.9066 | J16: =J8+J12 -> 858.67147 | K16: =K8+K12 -> 910.19175
B18: DISCOUNTING
B19: Discount period (years) | G19: =1-Inputs!$C$31*0.5 -> 0.5 | H19: =2-Inputs!$C$31*0.5 -> 1.5 | I19: =3-Inputs!$C$31*0.5 -> 2.5 | J19: =4-Inputs!$C$31*0.5 -> 3.5 | K19: =5-Inputs!$C$31*0.5 -> 4.5
B20: Discount factor | G20: =1/(1+Inputs!$C$22)^G19 -> 0.93946414 | H20: =1/(1+Inputs!$C$22)^H19 -> 0.82916436 | I20: =1/(1+Inputs!$C$22)^I19 -> 0.73181456 | J20: =1/(1+Inputs!$C$22)^J19 -> 0.64589432 | K20: =1/(1+Inputs!$C$22)^K19 -> 0.57006173
B21: PV of free cash flow | G21: =G15*G20 -> 479.01781 | H21: =H15*H20 -> 436.36775 | I21: =I15*I20 -> 404.6476 | J21: =J15*J20 -> 375.39614 | K21: =K15*K20 -> 349.91721
B23: TERMINAL VALUE — TWO METHODS, EACH CHECKING THE OTHER
B24: Terminal value at FY2031 (perpetuity growth) | K24: =K15*(1+Inputs!$C$29)/(Inputs!$C$22-Inputs!$C$29) -> 8299.6698
B25: PV of terminal value (perpetuity growth) | K25: =K24*K20 -> 4731.3241
B26: Terminal value at FY2031 (exit multiple) | K26: =K16*Inputs!$C$30 -> 10012.109
B27: PV of terminal value (exit multiple) | K27: =K26*K20 -> 5707.5203
B28: Growth implied by the exit multiple | K28: =(Inputs!$C$22*K26-K15)/(K26+K15) -> 0.067574283 | L28: If this is far from the assumed terminal growth, one of the two assumptions is wrong
B29: Exit multiple implied by terminal growth | K29: =K24/K16 -> 9.1185948
B31: VALUATION BRIDGE (PERPETUITY-GROWTH METHOD)
B32: Sum of PV of forecast free cash flow | K32: =SUM(G21:K21) -> 2045.3465
B33: PV of terminal value | K33: =K25 -> 4731.3241
B34: Enterprise value | K34: =K32+K33 -> 6776.6706
B35: Terminal value as % of enterprise value | K35: =K33/K34 -> 0.69817826 | L35: Above roughly 80% the answer is an assumption about 2031, not a forecast
B36: Plus: net cash | K36: =Inputs!$C$11 -> 288.52496
B37: Equity value | K37: =K34+K36 -> 7065.1956
B38: Shares outstanding (m) | K38: =Inputs!$C$8 -> 3618.0875
B39: Value per share (INR) | K39: =K37*1000/K38 -> 1952.7431
B40: Current share price (INR) | K40: =Inputs!$C$5 -> 2200.8
B41: Market price vs DCF value | K41: =K40/K39-1 -> 0.12702995 | L41: Positive = the market pays more than this DCF supports
B43: SENSITIVITY: VALUE PER SHARE (INR)
B44: Terminal growth \ WACC | C44: =Inputs!$C$22+-0.01 -> 0.12302523 | D44: =Inputs!$C$22+-0.005 -> 0.12802523 | E44: =Inputs!$C$22+0 -> 0.13302523 | F44: =Inputs!$C$22+0.005 -> 0.13802523 | G44: =Inputs!$C$22+0.01 -> 0.14302523
B45: =Inputs!$C$29+-0.01 -> 0.045 | C45: =(SUMPRODUCT($G$15:$K$15,1/(1+C$44)^$G$19:$K$19)+$K$15*(1+$B45)/(C$44-$B45)*1/(1+C$44)^$K$19+Inputs!$C$11)*1000/Inputs!$C$8 -> 2004.9805 | D45: =(SUMPRODUCT($G$15:$K$15,1/(1+D$44)^$G$19:$K$19)+$K$15*(1+$B45)/(D$44-$B45)*1/(1+D$44)^$K$19+Inputs!$C$11)*1000/Inputs!$C$8 -> 1892.7136 | E45: =(SUMPRODUCT($G$15:$K$15,1/(1+E$44)^$G$19:$K$19)+$K$15*(1+$B45)/(E$44-$B45)*1/(1+E$44)^$K$19+Inputs!$C$11)*1000/Inputs!$C$8 -> 1793.198 | F45: =(SUMPRODUCT($G$15:$K$15,1/(1+F$44)^$G$19:$K$19)+$K$15*(1+$B45)/(F$44-$B45)*1/(1+F$44)^$K$19+Inputs!$C$11)*1000/Inputs!$C$8 -> 1704.3776 | G45: =(SUMPRODUCT($G$15:$K$15,1/(1+G$44)^$G$19:$K$19)+$K$15*(1+$B45)/(G$44-$B45)*1/(1+G$44)^$K$19+Inputs!$C$11)*1000/Inputs!$C$8 -> 1624.6157
...

Sheet Ranges
B1: Tata Consultancy Services — Football Field and Valuation Summary | I1: TATA CONSULTANCY SERVICES
B2: Every bar, its source, what it is worth trusting, and the weight it carries in the recommended range
B4: Methodology | C4: Low (INR) | D4: High (INR) | E4: Midpoint | F4: Width | G4: Weight | H4: Source
B5: 52-week trading range | C5: =Inputs!$C$7 -> 1976.8 | D5: =Inputs!$C$6 -> 3350 | E5: =AVERAGE(C5:D5) -> 2663.4 | F5: =D5-C5 -> 1373.2 | G5: 0 | H5: Market | I5: Where the shares have actually changed hands. Context, not a valuation, so it carries no weight.
B6: Analyst price targets (43) | C6: =Inputs!$C$34 -> 1775 | D6: =Inputs!$C$36 -> 3900 | E6: =AVERAGE(C6:D6) -> 2837.5 | F6: =D6-C6 -> 2125 | G6: 0.1 | H6: Consensus | I6: Published 12-month targets. Weighted lightly: the analysts are reading the same filings as everyone else, and targets lag the price.
B7: DCF — WACC and growth sensitivity | C7: =MIN(DCF!C45:G49) -> 1624.6157 | D7: =MAX(DCF!C45:G49) -> 2504.3007 | E7: =AVERAGE(C7:D7) -> 2064.4582 | F7: =D7-C7 -> 879.68505 | G7: 0.35 | H7: Project 5 | I7: Low and high are the corners of the sensitivity grid: WACC plus or minus 100bp against terminal growth plus or minus 100bp.
B8: Trading comps — EV/CY2027 revenue | C8: 1242.05 | D8: 1745.32 | E8: =AVERAGE(C8:D8) -> 1493.685 | F8: =D8-C8 -> 503.27 | G8: 0.15 | H8: Project 3 | I8: Peer 25th to 75th percentile, calendarised to TCS's March year. The forward multiple institutional investors quote.
B9: Trading comps — EV/LTM EBITDA | C9: 1652.2 | D9: 2478.49 | E9: =AVERAGE(C9:D9) -> 2065.345 | F9: =D9-C9 -> 826.29 | G9: 0.15 | H9: Project 3 | I9: Peer 25th to 75th percentile. No estimates involved, so no forecast risk.
B10: Trading comps — P/E (CY2027) | C10: 1874.11 | D10: 2688.94 | E10: =AVERAGE(C10:D10) -> 2281.525 | F10: =D10-C10 -> 814.83 | G10: 0.15 | H10: Project 3 | I10: Equity multiple; consistent with TCS's net-cash balance sheet, which flatters EV multiples.
B11: Precedents — EV/LTM revenue | C11: 1428.41 | D11: 2682.41 | E11: =AVERAGE(C11:D11) -> 2055.41 | F11: =D11-C11 -> 1254 | G11: 0.05 | H11: Project 4 | I11: Illustrative. Fourteen deals, none remotely TCS's size, struck when the sector traded far higher. Weighted down accordingly.
B12: Precedents — EV/LTM EBITDA | C12: 2862.26 | D12: 3532.32 | E12: =AVERAGE(C12:D12) -> 3197.29 | F12: =D12-C12 -> 670.06 | G12: 0.05 | H12: Project 4 | I12: Illustrative and the weakest bar on the page: five disclosed observations, all mid-cap, all pre-2023.
B13: Total weight | G13: =SUM(G5:G12) -> 1
B15: RECOMMENDED RANGE (WEIGHTED)
B16: Recommended value per share (INR) | C16: =SUMPRODUCT($C$5:$C$12,$G$5:$G$12)/$G$13 -> 1675.903 | D16: =SUMPRODUCT($D$5:$D$12,$G$5:$G$12)/$G$13 -> 2614.1543 | E16: =SUMPRODUCT($E$5:$E$12,$G$5:$G$12)/$G$13 -> 2145.0286 | I16: Low, high and midpoint, each weighted by the column G weights. Change a weight and this line moves: that is the conversation with the client, and it is better had in the open than hidden inside a judgement.
B18: CONCLUSION
B19: Current share price (INR) | C19: =Inputs!$C$5 -> 2200.8
B20: Low across all methodologies | C20: =MIN(C5:C12) -> 1242.05
B21: High across all methodologies | C21: =MAX(D5:D12) -> 3900
B22: Median of the methodology midpoints | C22: =MEDIAN(E5:E12) -> 2173.435
B23: Recommended midpoint (weighted) | C23: =E16 -> 2145.0286
B24: Market price vs the recommended midpoint | C24: =C19/C23-1 -> 0.026000297
B26: • The bars do not agree, and a football field that did agree would be hiding something. The useful reading is which methods cluster: the DCF and the three trading-comps bars all land between roughly 1,200 and 2,700, and the share price sits in the upper half of that cluster.
B27: • The weights are judgement and they are on the page as inputs rather than buried in a formula. Trading comps carry 45% between three multiples because they need no forecast; the DCF carries 35% because it is the only method that values TCS rather than its peer group; precedents carry 10% because of the size and cycle mismatch; analyst targets carry 10% because they recycle public information; the 52-week range carries nothing because it is context.
B28: • The two precedent bars sit above everything else. Part of that is a genuine control premium and part is the cycle — the deals were struck when IT services traded at 20-30x earnings and the sector has since de-rated to 10-15x. Project 4's notes flag this; it is repeated here because a reader looking only at this page would otherwise take the precedent bars at face value.
B29: • The DCF and the trading comps are built on completely different logic — one discounts TCS's own cash flows at an INR cost of capital, the other asks what the market pays for comparable businesses today — and they overlap heavily. That agreement is the most informative thing on the page.

Sheet Football Field
B1: Tata Consultancy Services — Football Field and Valuation Summary | J1: TATA CONSULTANCY SERVICES
B2: Implied value per share (INR) by methodology · bar = the range, not a point estimate
B4: CHART DATA (linked from Ranges)
B5: Methodology | C5: Base (invisible) | D5: Span | E5: Low | F5: High
B6: 52-week trading range | C6: =Ranges!C5 -> 1976.8 | D6: =Ranges!D5-Ranges!C5 -> 1373.2 | E6: =Ranges!C5 -> 1976.8 | F6: =Ranges!D5 -> 3350
B7: Analyst price targets (43) | C7: =Ranges!C6 -> 1775 | D7: =Ranges!D6-Ranges!C6 -> 2125 | E7: =Ranges!C6 -> 1775 | F7: =Ranges!D6 -> 3900
B8: DCF — WACC and growth sensitivity | C8: =Ranges!C7 -> 1624.6157 | D8: =Ranges!D7-Ranges!C7 -> 879.68505 | E8: =Ranges!C7 -> 1624.6157 | F8: =Ranges!D7 -> 2504.3007
B9: Trading comps — EV/CY2027 revenue | C9: =Ranges!C8 -> 1242.05 | D9: =Ranges!D8-Ranges!C8 -> 503.27 | E9: =Ranges!C8 -> 1242.05 | F9: =Ranges!D8 -> 1745.32
B10: Trading comps — EV/LTM EBITDA | C10: =Ranges!C9 -> 1652.2 | D10: =Ranges!D9-Ranges!C9 -> 826.29 | E10: =Ranges!C9 -> 1652.2 | F10: =Ranges!D9 -> 2478.49
B11: Trading comps — P/E (CY2027) | C11: =Ranges!C10 -> 1874.11 | D11: =Ranges!D10-Ranges!C10 -> 814.83 | E11: =Ranges!C10 -> 1874.11 | F11: =Ranges!D10 -> 2688.94
B12: Precedents — EV/LTM revenue | C12: =Ranges!C11 -> 1428.41 | D12: =Ranges!D11-Ranges!C11 -> 1254 | E12: =Ranges!C11 -> 1428.41 | F12: =Ranges!D11 -> 2682.41
B13: Precedents — EV/LTM EBITDA | C13: =Ranges!C12 -> 2862.26 | D13: =Ranges!D12-Ranges!C12 -> 670.06 | E13: =Ranges!C12 -> 2862.26 | F13: =Ranges!D12 -> 3532.32
B14: Recommended range (weighted) | C14: =Ranges!C16 -> 1675.903 | D14: =Ranges!D16-Ranges!C16 -> 938.25127 | E14: =Ranges!C16 -> 1675.903 | F14: =Ranges!D16 -> 2614.1543
B16: Current share price: INR 2,200.80 (12 Sep 2026)
B43: The first series is deliberately unfilled: each bar floats from its low to its high, which is what makes this a football field rather than a stacked bar chart. The final bar, in the accent colour, is the weighted recommended range. Read the overlap between bars, not any single bar.

Sheet Checks
B1: Tata Consultancy Services — Football Field and Valuation Summary | E1: TATA CONSULTANCY SERVICES
B2: Every check must read TRUE
B4: INTEGRITY CHECKS
B5: WACC exceeds terminal growth | C5: =Inputs!$C$22>Inputs!$C$29 -> TRUE
B6: Enterprise value ties to the sum of its parts | C6: =ABS(DCF!K34-(DCF!K32+DCF!K33))<0.01 -> TRUE
B7: Equity value ties to EV plus net cash | C7: =ABS(DCF!K37-(DCF!K34+DCF!K36))<0.01 -> TRUE
B8: DCF value per share is positive | C8: =DCF!K39>0 -> TRUE
B9: Terminal value is between 50% and 90% of EV | C9: =AND(DCF!K35>0.5,DCF!K35<0.9) -> TRUE
B10: The two terminal-value methods are within 35% of each other | C10: =ABS(DCF!K24/DCF!K26-1)<0.35 -> TRUE
B11: Base-case sensitivity cell reconciles to the bridge | C11: =ABS(DCF!E47-DCF!K39)<1 -> TRUE
B12: Every forecast free cash flow is positive | C12: =MIN(DCF!G15:K15)>0 -> TRUE
B13: Forecast revenue growth never exceeds the historical maximum | C13: =MAX(DCF!G7:K7)<=MAX(DCF!D7:F7) -> TRUE
B14: Every football-field bar is ordered low to high | C14: =SUMPRODUCT(--(Ranges!C5:C12>Ranges!D5:D12))=0 -> TRUE
B15: Every bar has positive width | C15: =MIN(Ranges!F5:F12)>0 -> TRUE
B16: Methodology weights sum to 100% | C16: =ABS(Ranges!G13-1)<0.0001 -> TRUE
B17: Recommended range is ordered low <= mid <= high | C17: =AND(Ranges!C16<=Ranges!E16,Ranges!E16<=Ranges!D16) -> TRUE
B18: Recommended range sits inside the overall range of methods | C18: =AND(Ranges!C16>=Ranges!C20,Ranges!D16<=Ranges!C21) -> TRUE
B19: Analyst consensus bar is ordered low <= average <= high | C19: =AND(Inputs!$C$34<=Inputs!$C$35,Inputs!$C$35<=Inputs!$C$36) -> TRUE
B20: Chart data ties to the Ranges sheet | C20: =AND(ABS(SUM('Football Field'!E6:E14)-(SUM(Ranges!C5:C12)+Ranges!C16))<0.01,ABS(SUM('Football Field'!F6:F14)-(SUM(Ranges!D5:D12)+Ranges!D16))<0.01) -> TRUE
B21: Share price and share count match Projects 3 and 4 | C21: =AND(ABS(Inputs!$C$5-2200.8)<0.01,ABS(Inputs!$C$8-3618.087518)<0.01) -> TRUE
B22: Current price sits inside the overall range | C22: =AND(Inputs!$C$5>=Ranges!C20,Inputs!$C$5<=Ranges!C21) -> TRUE
B24: MODEL STATUS | C24: =IF(COUNTIF(C5:C22,FALSE())=0,"MODEL OK","CHECK FAILED") -> MODEL OK
B26: The growth-discipline check is the unusual one: it fails if the forecast assumes TCS grows faster than it has in any of the last three years. A DCF that quietly solves for the current share price by lifting growth is the most common way this analysis goes wrong, and a check is a cheaper defence than a reviewer.
