Workbook

Sheet Cover
B3: IB PORTFOLIO · PROJECT 13 OF 20
B4: Emaar Properties
B5: Real-Estate NAV and Development Appraisal
B6: DFM: EMAAR · AED millions · per-share values in AED · as of FY2025 results · market data 18 Sep 2026
B9: What this is | C9: A net-asset-value model of Emaar Properties on the FY2025 results and 18 September 2026 market data, valuing the UAE and international development businesses on their disclosed backlog and land bank and the mall and hospitality portfolios at capitalisation yields, then measuring the discount the market applies. A residual-value development appraisal for one illustrative Dubai tower shows why land is the most volatile line in the NAV.
B11: How it is built | C11: • Development valued as the present value of the margin embedded in the sold-but-unrecognised backlog, after tax, plus the land bank at a stated value per square foot; Emaar's 80% share of the UAE business taken, and cross-checked against the listed Emaar Development price.
C12: • Malls and hospitality capitalised at stated yields; half of cash treated as customer advances held for construction.
C13: • A residual land valuation: gross development value less construction, soft costs, marketing and finance, less a target profit solved on total cost including land.
C14: • Two sensitivity grids and fifteen checks, including an external test of block A against the market.
B16: Contents | C16: Summary — NAV, discount, the appraisal
C17: NAV — four asset blocks, cash haircut, NAV per share and the discount
C18: Development Appraisal — residual land value for one tower, break-even and cushion
C19: Sensitivity — NAV against yield and margin; land value against price and cost
C20: Inputs — disclosed operating data, balance sheet, market data, valuation assumptions
C21: Checks — fifteen tests; must read MODEL OK
B23: Key outputs (live) | C23: Net asset value (AED m) | E23: =NAV!$C$30 -> 178771.22
C24: NAV per share (AED) | E24: =NAV!$C$33 -> 20.225734
C25: Share price (AED) | E25: =NAV!$C$34 -> 11.8
C26: Discount to NAV | E26: =NAV!$C$35 -> 0.41658483
C27: Residual land value per sq ft GFA (AED) | E27: ='Development Appraisal'!$C$31 -> 766.792
C28: Price cushion on the scheme | E28: ='Development Appraisal'!$C$36 -> 0.16666667
B30: Colour code | C30: Blue = hard-coded input
C31: Black = formula
C32: Green = link to another sheet
C33: Accent fill = scenario selector / key levers
B35: Sources | C35: Emaar Properties PJSC, FY2025 results announcement (12 February 2026): revenue backlog, recurring revenue and EBITDA, hospitality revenue, land bank; 9M 2025 release for the mall and hospitality split.
C36: Emaar Properties and Emaar Development FY2025 balance sheets via Yahoo Finance (EMAAR.AE, EMAARDEV.AE). Share prices: DFM close, 18 September 2026.
C37: Yields, development margins, discount rate, land values per square foot, the cash haircut and every input in the development appraisal are stated assumptions on the Inputs sheet.
C38: Nothing here is a recommendation. The valuation is an analytical exercise on public information.
B40: Prepared by | C40: Jainam Mehta · github.com/jainammehta1215/ib-portfolio

Sheet Inputs
B1: Emaar Properties — Real-Estate NAV and Development Appraisal | F1: EMAAR PROPERTIES
B2: Disclosed operating data, balance sheet, market data and valuation assumptions
B4: DISCLOSED OPERATING DATA, FY2025 (AED millions unless stated)
B5: Revenue backlog, group | C5: 155000 | F5: Sold but not yet recognised; 12 February 2026 announcement
B6: of which Emaar Development (UAE) | C6: 125200
B7: of which international and other | C7: =Inputs!$C$5-Inputs!$C$6 -> 29800
B8: Recurring revenue (malls, hospitality, leisure, commercial) | C8: 10500
B9: Recurring EBITDA | C9: 8100
B10: of which hospitality, leisure and entertainment revenue | C10: 4200
B11: assumed hospitality EBITDA margin | C11: 0.55 | F11: Emaar's hotels are owned, not leased; disclosed 9M margins run in the mid-50s
B12: Hospitality and leisure EBITDA | C12: =Inputs!$C$10*Inputs!$C$11 -> 2310
B13: Malls and commercial leasing EBITDA (recurring less hospitality) | C13: =Inputs!$C$9-Inputs!$C$12 -> 5790
B14: UAE land bank (million sq ft) | C14: 370
B15: International land bank (million sq ft) | C15: 290
B16: Emaar Development EBITDA, FY2025 | C16: 14300 | F16: 52% margin on AED 27.5bn revenue
B18: BALANCE SHEET, 31 DECEMBER 2025
B19: Cash and bank balances | C19: 52633
B20: Borrowings and sukuk | C20: 10615
B21: Equity attributable to owners | C21: 94278
B22: Non-controlling interests (memo) | C22: 13398
B23: Book value per share (AED) | C23: =Inputs!$C$21/8838.8 -> 10.66638
B25: MARKET DATA
B26: Emaar Properties share price (AED, DFM close 18 Sep 2026) | C26: 11.8
B27: Shares outstanding (millions) | C27: 8838.8
B28: Market capitalisation | C28: =Inputs!$C$26*Inputs!$C$27 -> 104297.84
B29: Price / book | C29: =Inputs!$C$26/Inputs!$C$23 -> 1.1062797
B30: Emaar Development share price (AED) | C30: 13.52
B31: Emaar Development shares (millions) | C31: 4000
B32: Emaar Development market capitalisation | C32: =Inputs!$C$30*Inputs!$C$31 -> 54080
B33: Emaar Properties' stake in Emaar Development | C33: 0.8 | F33: Approximately 80% since the 2017 listing; stated input
B35: VALUATION ASSUMPTIONS — stated inputs
B36: Development margin on backlog revenue (pre-tax) | C36: 0.42 | F36: Emaar Development reports a 52% EBITDA margin; a lower figure allows for the cost inflation typical of a late-cycle backlog
B37: International development margin | C37: 0.25
B38: Average years to recognise the backlog | C38: 3.5 | F38: Delivery schedules run three to five years from launch
B39: Discount rate for development cash flows | C39: 0.11 | F39: Above the cost of equity for the group: development is the riskiest activity in it
B40: UAE corporate tax | C40: 0.09
B41: UAE land bank value (AED per sq ft of plot) | C41: 45 | F41: Master-plan land carried at historic cost; a conservative blended figure across Dubai and the Northern Emirates
B42: International land bank value (AED per sq ft of plot) | C42: 8
B43: Capitalisation yield — malls and commercial | C43: 0.07 | F43: Prime Dubai retail; Dubai Mall is the single most valuable asset in the group
B44: Capitalisation yield — hospitality and leisure | C44: 0.085
...

Sheet NAV
B1: Emaar Properties — Real-Estate NAV and Development Appraisal | F1: EMAAR PROPERTIES
B2: Net asset value, block by block, and the discount the market applies
B4: A. UAE DEVELOPMENT — EMAAR DEVELOPMENT
B5: Pre-tax profit embedded in the backlog | C5: =Inputs!$C$6*Inputs!$C$36 -> 52584
B6: Discount factor at the mid-point of delivery | C6: =1/(1+Inputs!$C$39)^(Inputs!$C$38/2) -> 0.83307631
B7: Present value of backlog profit, after tax | C7: =NAV!$C$5*NAV!$C$6*(1-Inputs!$C$40) -> 39863.901
B8: UAE land bank | C8: =Inputs!$C$14*Inputs!$C$41 -> 16650
B9: UAE development, 100% | C9: =NAV!$C$7+NAV!$C$8 -> 56513.901
B10: Emaar Properties' share | C10: =NAV!$C$9*Inputs!$C$33 -> 45211.121
B11: cross-check: Emaar Development market value × stake | C11: =Inputs!$C$32*Inputs!$C$33 -> 43264 | F11: The listed subsidiary's price is a second opinion on block A
B12: NAV block versus the listed value | C12: =NAV!$C$10/NAV!$C$11-1 -> 0.045005571
B14: B. INTERNATIONAL DEVELOPMENT
B15: Present value of international backlog profit, after tax | C15: =Inputs!$C$7*Inputs!$C$37*NAV!$C$6*(1-Inputs!$C$40) -> 5647.8409
B16: International land bank | C16: =Inputs!$C$15*Inputs!$C$42 -> 2320
B17: International development | C17: =NAV!$C$15+NAV!$C$16 -> 7967.8409 | F17: Emaar Misr and the Indian business have their own minorities; ignored here, which overstates block B slightly
B19: C. MALLS AND COMMERCIAL LEASING
B20: EBITDA capitalised at the yield | C20: =Inputs!$C$13/Inputs!$C$43 -> 82714.286
B21: implied EV / EBITDA | C21: =NAV!$C$20/Inputs!$C$13 -> 14.285714
B23: D. HOSPITALITY, LEISURE AND ENTERTAINMENT
B24: EBITDA capitalised at the yield | C24: =Inputs!$C$12/Inputs!$C$44 -> 27176.471
B26: GROSS ASSET VALUE TO NAV
B27: Gross asset value (A + B + C + D) | C27: =NAV!$C$10+NAV!$C$17+NAV!$C$20+NAV!$C$24 -> 163069.72
B28: Add: cash not held as customer advances | C28: =Inputs!$C$19*(1-Inputs!$C$45) -> 26316.5
B29: Less: borrowings | C29: =-Inputs!$C$20 -> -10615
B30: Net asset value | C30: =NAV!$C$27+NAV!$C$28+NAV!$C$29 -> 178771.22
B32: PER SHARE AND AGAINST THE MARKET
B33: NAV per share (AED) | C33: =NAV!$C$30/Inputs!$C$27 -> 20.225734
B34: Share price (AED) | C34: =Inputs!$C$26 -> 11.8
B35: Discount of the price to NAV | C35: =1-NAV!$C$34/NAV!$C$33 -> 0.41658483
B36: Price / NAV | C36: =NAV!$C$34/NAV!$C$33 -> 0.58341517
B37: NAV / book value (the revaluation surplus the accounts do not show) | C37: =NAV!$C$30/Inputs!$C$21 -> 1.8962135
B38: Share of gross asset value in recurring-income assets (C + D) | C38: =(NAV!$C$20+NAV!$C$24)/NAV!$C$27 -> 0.67388818
B39: Market capitalisation as a share of recurring assets plus free cash alone | C39: =Inputs!$C$28/(NAV!$C$20+NAV!$C$24+NAV!$C$28+NAV!$C$29) -> 0.83044802 | F39: Below 100% means the market is paying nothing for either development business
B40: UAE developers have traded at discounts of 30–50% to bottom-up NAV through most of their listed history. The discount is the market's judgement on the cycle: a backlog sold at today's prices is only worth its margin if buyers complete, and the land bank is worth its stated value only if launches continue. The model does not predict the discount; it measures it.

Sheet Development Appraisal
B1: Emaar Properties — Real-Estate NAV and Development Appraisal | F1: EMAAR PROPERTIES
B2: Residual land value for one illustrative Dubai residential tower — AED millions
B4: THE SCHEME — stated inputs
B5: Gross floor area (thousand sq ft) | C5: 600
B6: Saleable efficiency | C6: 0.82 | F6: Net saleable area as a share of gross floor area
B7: Net saleable area (thousand sq ft) | C7: ='Development Appraisal'!$C$5*'Development Appraisal'!$C$6 -> 492
B8: Average sale price (AED per sq ft of saleable area) | C8: 2400 | F8: A prime but not trophy Dubai location, September 2026
B9: Construction cost (AED per sq ft of gross floor area) | C9: 700
B10: Professional and soft costs as % of construction | C10: 0.12
B11: Sales and marketing as % of gross development value | C11: 0.035
B12: Programme (months from land purchase to completion) | C12: 36
B13: Finance rate on development costs | C13: 0.07
B14: Average share of costs outstanding over the programme | C14: 0.5 | F14: S-curve approximation
B15: Target developer profit on total cost | C15: 0.2
B16: Share of GDV collected before completion (off-plan) | C16: 0.6 | F16: Reduces the finance charge; Dubai off-plan payment plans typically collect 40–70% during construction
B18: GROSS DEVELOPMENT VALUE
B19: Gross development value | C19: ='Development Appraisal'!$C$7*'Development Appraisal'!$C$8/1000 -> 1180.8
B21: COSTS
B22: Construction | C22: ='Development Appraisal'!$C$5*'Development Appraisal'!$C$9/1000 -> 420
B23: Professional and soft costs | C23: ='Development Appraisal'!$C$22*'Development Appraisal'!$C$10 -> 50.4
B24: Sales and marketing | C24: ='Development Appraisal'!$C$19*'Development Appraisal'!$C$11 -> 41.328
B25: Finance on costs net of off-plan receipts | C25: =MAX(0,('Development Appraisal'!$C$22+'Development Appraisal'!$C$23)-'Development Appraisal'!$C$19*'Development Appraisal'!$C$16*'Development Appraisal'!$C$14)*'Development Appraisal'!$C$13*'Development Appraisal'!$C$12/12*'Development Appraisal'!$C$14 -> 12.1968 | F25: Off-plan collections fund construction as it proceeds, which is why Dubai developers carry so little debt
B26: Total development cost before land | C26: ='Development Appraisal'!$C$22+'Development Appraisal'!$C$23+'Development Appraisal'!$C$24+'Development Appraisal'!$C$25 -> 523.9248
B28: RESIDUAL LAND VALUE
B29: Developer profit required: target % of (cost + land), solved | C29: ='Development Appraisal'!$C$19*'Development Appraisal'!$C$15/(1+'Development Appraisal'!$C$15) -> 196.8 | F29: Profit is a share of total cost including land. Since cost + land = GDV − profit, profit = k × GDV / (1 + k)
B30: Residual land value | C30: ='Development Appraisal'!$C$19-'Development Appraisal'!$C$26-'Development Appraisal'!$C$29 -> 460.0752
B31: Residual land value per sq ft of gross floor area (AED) | C31: ='Development Appraisal'!$C$30*1000/'Development Appraisal'!$C$5 -> 766.792
B32: Land as % of gross development value | C32: ='Development Appraisal'!$C$30/'Development Appraisal'!$C$19 -> 0.38963008
B33: Developer profit as % of gross development value | C33: ='Development Appraisal'!$C$29/'Development Appraisal'!$C$19 -> 0.16666667
B34: Check: profit / (total cost + land) | C34: ='Development Appraisal'!$C$29/('Development Appraisal'!$C$26+'Development Appraisal'!$C$30) -> 0.2
B35: Break-even sale price if land is bought at the residual (AED per sq ft) | C35: =('Development Appraisal'!$C$26+'Development Appraisal'!$C$30)*1000/'Development Appraisal'!$C$7 -> 2000
B36: Price cushion before the developer loses money | C36: =1-'Development Appraisal'!$C$35/'Development Appraisal'!$C$8 -> 0.16666667
B37: The residual is the most a developer can pay for the plot and still make its target return. Every assumption flows straight into it: a 10% fall in sale prices takes far more than 10% off the land value, which is why land is the most volatile asset in property and why Emaar's land bank is carried at cost.

Sheet Sensitivity
B1: Emaar Properties — Real-Estate NAV and Development Appraisal | H1: EMAAR PROPERTIES
B2: NAV per share (AED) and residual land value — every cell rebuilds the calculation
B4: NAV PER SHARE — MALL YIELD (rows) versus DEVELOPMENT MARGIN (columns)
B5: ↓ rows \ columns → | C5: 0.34 | D5: 0.38 | E5: 0.42 | F5: 0.46 | G5: 0.5
B6: 0.06 | C6: =(((Inputs!$C$6*C$5*NAV!$C$6*(1-Inputs!$C$40)+NAV!$C$8)*Inputs!$C$33)+NAV!$C$17+Inputs!$C$13/$B6+NAV!$C$24+NAV!$C$28+NAV!$C$29)/Inputs!$C$27 -> 21.098162 | D6: =(((Inputs!$C$6*D$5*NAV!$C$6*(1-Inputs!$C$40)+NAV!$C$8)*Inputs!$C$33)+NAV!$C$17+Inputs!$C$13/$B6+NAV!$C$24+NAV!$C$28+NAV!$C$29)/Inputs!$C$27 -> 21.441789 | E6: =(((Inputs!$C$6*E$5*NAV!$C$6*(1-Inputs!$C$40)+NAV!$C$8)*Inputs!$C$33)+NAV!$C$17+Inputs!$C$13/$B6+NAV!$C$24+NAV!$C$28+NAV!$C$29)/Inputs!$C$27 -> 21.785416 | F6: =(((Inputs!$C$6*F$5*NAV!$C$6*(1-Inputs!$C$40)+NAV!$C$8)*Inputs!$C$33)+NAV!$C$17+Inputs!$C$13/$B6+NAV!$C$24+NAV!$C$28+NAV!$C$29)/Inputs!$C$27 -> 22.129043 | G6: =(((Inputs!$C$6*G$5*NAV!$C$6*(1-Inputs!$C$40)+NAV!$C$8)*Inputs!$C$33)+NAV!$C$17+Inputs!$C$13/$B6+NAV!$C$24+NAV!$C$28+NAV!$C$29)/Inputs!$C$27 -> 22.47267
B7: 0.065 | C7: =(((Inputs!$C$6*C$5*NAV!$C$6*(1-Inputs!$C$40)+NAV!$C$8)*Inputs!$C$33)+NAV!$C$17+Inputs!$C$13/$B7+NAV!$C$24+NAV!$C$28+NAV!$C$29)/Inputs!$C$27 -> 20.258333 | D7: =(((Inputs!$C$6*D$5*NAV!$C$6*(1-Inputs!$C$40)+NAV!$C$8)*Inputs!$C$33)+NAV!$C$17+Inputs!$C$13/$B7+NAV!$C$24+NAV!$C$28+NAV!$C$29)/Inputs!$C$27 -> 20.60196 | E7: =(((Inputs!$C$6*E$5*NAV!$C$6*(1-Inputs!$C$40)+NAV!$C$8)*Inputs!$C$33)+NAV!$C$17+Inputs!$C$13/$B7+NAV!$C$24+NAV!$C$28+NAV!$C$29)/Inputs!$C$27 -> 20.945587 | F7: =(((Inputs!$C$6*F$5*NAV!$C$6*(1-Inputs!$C$40)+NAV!$C$8)*Inputs!$C$33)+NAV!$C$17+Inputs!$C$13/$B7+NAV!$C$24+NAV!$C$28+NAV!$C$29)/Inputs!$C$27 -> 21.289214 | G7: =(((Inputs!$C$6*G$5*NAV!$C$6*(1-Inputs!$C$40)+NAV!$C$8)*Inputs!$C$33)+NAV!$C$17+Inputs!$C$13/$B7+NAV!$C$24+NAV!$C$28+NAV!$C$29)/Inputs!$C$27 -> 21.632841
B8: 0.07 | C8: =(((Inputs!$C$6*C$5*NAV!$C$6*(1-Inputs!$C$40)+NAV!$C$8)*Inputs!$C$33)+NAV!$C$17+Inputs!$C$13/$B8+NAV!$C$24+NAV!$C$28+NAV!$C$29)/Inputs!$C$27 -> 19.53848 | D8: =(((Inputs!$C$6*D$5*NAV!$C$6*(1-Inputs!$C$40)+NAV!$C$8)*Inputs!$C$33)+NAV!$C$17+Inputs!$C$13/$B8+NAV!$C$24+NAV!$C$28+NAV!$C$29)/Inputs!$C$27 -> 19.882107 | E8: =(((Inputs!$C$6*E$5*NAV!$C$6*(1-Inputs!$C$40)+NAV!$C$8)*Inputs!$C$33)+NAV!$C$17+Inputs!$C$13/$B8+NAV!$C$24+NAV!$C$28+NAV!$C$29)/Inputs!$C$27 -> 20.225734 | F8: =(((Inputs!$C$6*F$5*NAV!$C$6*(1-Inputs!$C$40)+NAV!$C$8)*Inputs!$C$33)+NAV!$C$17+Inputs!$C$13/$B8+NAV!$C$24+NAV!$C$28+NAV!$C$29)/Inputs!$C$27 -> 20.569361 | G8: =(((Inputs!$C$6*G$5*NAV!$C$6*(1-Inputs!$C$40)+NAV!$C$8)*Inputs!$C$33)+NAV!$C$17+Inputs!$C$13/$B8+NAV!$C$24+NAV!$C$28+NAV!$C$29)/Inputs!$C$27 -> 20.912988
B9: 0.075 | C9: =(((Inputs!$C$6*C$5*NAV!$C$6*(1-Inputs!$C$40)+NAV!$C$8)*Inputs!$C$33)+NAV!$C$17+Inputs!$C$13/$B9+NAV!$C$24+NAV!$C$28+NAV!$C$29)/Inputs!$C$27 -> 18.914608 | D9: =(((Inputs!$C$6*D$5*NAV!$C$6*(1-Inputs!$C$40)+NAV!$C$8)*Inputs!$C$33)+NAV!$C$17+Inputs!$C$13/$B9+NAV!$C$24+NAV!$C$28+NAV!$C$29)/Inputs!$C$27 -> 19.258234 | E9: =(((Inputs!$C$6*E$5*NAV!$C$6*(1-Inputs!$C$40)+NAV!$C$8)*Inputs!$C$33)+NAV!$C$17+Inputs!$C$13/$B9+NAV!$C$24+NAV!$C$28+NAV!$C$29)/Inputs!$C$27 -> 19.601861 | F9: =(((Inputs!$C$6*F$5*NAV!$C$6*(1-Inputs!$C$40)+NAV!$C$8)*Inputs!$C$33)+NAV!$C$17+Inputs!$C$13/$B9+NAV!$C$24+NAV!$C$28+NAV!$C$29)/Inputs!$C$27 -> 19.945488 | G9: =(((Inputs!$C$6*G$5*NAV!$C$6*(1-Inputs!$C$40)+NAV!$C$8)*Inputs!$C$33)+NAV!$C$17+Inputs!$C$13/$B9+NAV!$C$24+NAV!$C$28+NAV!$C$29)/Inputs!$C$27 -> 20.289115
B10: 0.08 | C10: =(((Inputs!$C$6*C$5*NAV!$C$6*(1-Inputs!$C$40)+NAV!$C$8)*Inputs!$C$33)+NAV!$C$17+Inputs!$C$13/$B10+NAV!$C$24+NAV!$C$28+NAV!$C$29)/Inputs!$C$27 -> 18.368719 | D10: =(((Inputs!$C$6*D$5*NAV!$C$6*(1-Inputs!$C$40)+NAV!$C$8)*Inputs!$C$33)+NAV!$C$17+Inputs!$C$13/$B10+NAV!$C$24+NAV!$C$28+NAV!$C$29)/Inputs!$C$27 -> 18.712346 | E10: =(((Inputs!$C$6*E$5*NAV!$C$6*(1-Inputs!$C$40)+NAV!$C$8)*Inputs!$C$33)+NAV!$C$17+Inputs!$C$13/$B10+NAV!$C$24+NAV!$C$28+NAV!$C$29)/Inputs!$C$27 -> 19.055973 | F10: =(((Inputs!$C$6*F$5*NAV!$C$6*(1-Inputs!$C$40)+NAV!$C$8)*Inputs!$C$33)+NAV!$C$17+Inputs!$C$13/$B10+NAV!$C$24+NAV!$C$28+NAV!$C$29)/Inputs!$C$27 -> 19.3996 | G10: =(((Inputs!$C$6*G$5*NAV!$C$6*(1-Inputs!$C$40)+NAV!$C$8)*Inputs!$C$33)+NAV!$C$17+Inputs!$C$13/$B10+NAV!$C$24+NAV!$C$28+NAV!$C$29)/Inputs!$C$27 -> 19.743227
B12: RESIDUAL LAND VALUE PER SQ FT OF GFA (AED) — SALE PRICE (rows) versus CONSTRUCTION COST (columns)
B13: ↓ rows \ columns → | C13: 600 | D13: 650 | E13: 700 | F13: 750 | G13: 800
B14: 2000 | C14: =(('Development Appraisal'!$C$7*$B14/1000)/(1+'Development Appraisal'!$C$15)-(('Development Appraisal'!$C$5*C$13/1000)+(('Development Appraisal'!$C$5*C$13/1000)*'Development Appraisal'!$C$10)+(('Development Appraisal'!$C$7*$B14/1000)*'Development Appraisal'!$C$11)+(MAX(0,(('Development Appraisal'!$C$5*C$13/1000)+(('Development Appraisal'!$C$5*C$13/1000)*'Development Appraisal'!$C$10))-('Development Appraisal'!$C$7*$B14/1000)*'Development Appraisal'!$C$16*'Development Appraisal'!$C$14)*'Development Appraisal'!$C$13*'Development Appraisal'!$C$12/12*'Development Appraisal'!$C$14)))*1000/'Development Appraisal'!$C$5 -> 618.36667 | D14: =(('Development Appraisal'!$C$7*$B14/1000)/(1+'Development Appraisal'!$C$15)-(('Development Appraisal'!$C$5*D$13/1000)+(('Development Appraisal'!$C$5*D$13/1000)*'Development Appraisal'!$C$10)+(('Development Appraisal'!$C$7*$B14/1000)*'Development Appraisal'!$C$11)+(MAX(0,(('Development Appraisal'!$C$5*D$13/1000)+(('Development Appraisal'!$C$5*D$13/1000)*'Development Appraisal'!$C$10))-('Development Appraisal'!$C$7*$B14/1000)*'Development Appraisal'!$C$16*'Development Appraisal'!$C$14)*'Development Appraisal'!$C$13*'Development Appraisal'!$C$12/12*'Development Appraisal'!$C$14)))*1000/'Development Appraisal'!$C$5 -> 556.48667 | E14: =(('Development Appraisal'!$C$7*$B14/1000)/(1+'Development Appraisal'!$C$15)-(('Development Appraisal'!$C$5*E$13/1000)+(('Development Appraisal'!$C$5*E$13/1000)*'Development Appraisal'!$C$10)+(('Development Appraisal'!$C$7*$B14/1000)*'Development Appraisal'!$C$11)+(MAX(0,(('Development Appraisal'!$C$5*E$13/1000)+(('Development Appraisal'!$C$5*E$13/1000)*'Development Appraisal'!$C$10))-('Development Appraisal'!$C$7*$B14/1000)*'Development Appraisal'!$C$16*'Development Appraisal'!$C$14)*'Development Appraisal'!$C$13*'Development Appraisal'!$C$12/12*'Development Appraisal'!$C$14)))*1000/'Development Appraisal'!$C$5 -> 494.60667 | F14: =(('Development Appraisal'!$C$7*$B14/1000)/(1+'Development Appraisal'!$C$15)-(('Development Appraisal'!$C$5*F$13/1000)+(('Development Appraisal'!$C$5*F$13/1000)*'Development Appraisal'!$C$10)+(('Development Appraisal'!$C$7*$B14/1000)*'Development Appraisal'!$C$11)+(MAX(0,(('Development Appraisal'!$C$5*F$13/1000)+(('Development Appraisal'!$C$5*F$13/1000)*'Development Appraisal'!$C$10))-('Development Appraisal'!$C$7*$B14/1000)*'Development Appraisal'!$C$16*'Development Appraisal'!$C$14)*'Development Appraisal'!$C$13*'Development Appraisal'!$C$12/12*'Development Appraisal'!$C$14)))*1000/'Development Appraisal'!$C$5 -> 432.72667 | G14: =(('Development Appraisal'!$C$7*$B14/1000)/(1+'Development Appraisal'!$C$15)-(('Development Appraisal'!$C$5*G$13/1000)+(('Development Appraisal'!$C$5*G$13/1000)*'Development Appraisal'!$C$10)+(('Development Appraisal'!$C$7*$B14/1000)*'Development Appraisal'!$C$11)+(MAX(0,(('Development Appraisal'!$C$5*G$13/1000)+(('Development Appraisal'!$C$5*G$13/1000)*'Development Appraisal'!$C$10))-('Development Appraisal'!$C$7*$B14/1000)*'Development Appraisal'!$C$16*'Development Appraisal'!$C$14)*'Development Appraisal'!$C$13*'Development Appraisal'!$C$12/12*'Development Appraisal'!$C$14)))*1000/'Development Appraisal'!$C$5 -> 370.84667
B15: 2200 | C15: =(('Development Appraisal'!$C$7*$B15/1000)/(1+'Development Appraisal'!$C$15)-(('Development Appraisal'!$C$5*C$13/1000)+(('Development Appraisal'!$C$5*C$13/1000)*'Development Appraisal'!$C$10)+(('Development Appraisal'!$C$7*$B15/1000)*'Development Appraisal'!$C$11)+(MAX(0,(('Development Appraisal'!$C$5*C$13/1000)+(('Development Appraisal'!$C$5*C$13/1000)*'Development Appraisal'!$C$10))-('Development Appraisal'!$C$7*$B15/1000)*'Development Appraisal'!$C$16*'Development Appraisal'!$C$14)*'Development Appraisal'!$C$13*'Development Appraisal'!$C$12/12*'Development Appraisal'!$C$14)))*1000/'Development Appraisal'!$C$5 -> 754.45933 | D15: =(('Development Appraisal'!$C$7*$B15/1000)/(1+'Development Appraisal'!$C$15)-(('Development Appraisal'!$C$5*D$13/1000)+(('Development Appraisal'!$C$5*D$13/1000)*'Development Appraisal'!$C$10)+(('Development Appraisal'!$C$7*$B15/1000)*'Development Appraisal'!$C$11)+(MAX(0,(('Development Appraisal'!$C$5*D$13/1000)+(('Development Appraisal'!$C$5*D$13/1000)*'Development Appraisal'!$C$10))-('Development Appraisal'!$C$7*$B15/1000)*'Development Appraisal'!$C$16*'Development Appraisal'!$C$14)*'Development Appraisal'!$C$13*'Development Appraisal'!$C$12/12*'Development Appraisal'!$C$14)))*1000/'Development Appraisal'!$C$5 -> 692.57933 | E15: =(('Development Appraisal'!$C$7*$B15/1000)/(1+'Development Appraisal'!$C$15)-(('Development Appraisal'!$C$5*E$13/1000)+(('Development Appraisal'!$C$5*E$13/1000)*'Development Appraisal'!$C$10)+(('Development Appraisal'!$C$7*$B15/1000)*'Development Appraisal'!$C$11)+(MAX(0,(('Development Appraisal'!$C$5*E$13/1000)+(('Development Appraisal'!$C$5*E$13/1000)*'Development Appraisal'!$C$10))-('Development Appraisal'!$C$7*$B15/1000)*'Development Appraisal'!$C$16*'Development Appraisal'!$C$14)*'Development Appraisal'!$C$13*'Development Appraisal'!$C$12/12*'Development Appraisal'!$C$14)))*1000/'Development Appraisal'!$C$5 -> 630.69933 | F15: =(('Development Appraisal'!$C$7*$B15/1000)/(1+'Development Appraisal'!$C$15)-(('Development Appraisal'!$C$5*F$13/1000)+(('Development Appraisal'!$C$5*F$13/1000)*'Development Appraisal'!$C$10)+(('Development Appraisal'!$C$7*$B15/1000)*'Development Appraisal'!$C$11)+(MAX(0,(('Development Appraisal'!$C$5*F$13/1000)+(('Development Appraisal'!$C$5*F$13/1000)*'Development Appraisal'!$C$10))-('Development Appraisal'!$C$7*$B15/1000)*'Development Appraisal'!$C$16*'Development Appraisal'!$C$14)*'Development Appraisal'!$C$13*'Development Appraisal'!$C$12/12*'Development Appraisal'!$C$14)))*1000/'Development Appraisal'!$C$5 -> 568.81933 | G15: =(('Development Appraisal'!$C$7*$B15/1000)/(1+'Development Appraisal'!$C$15)-(('Development Appraisal'!$C$5*G$13/1000)+(('Development Appraisal'!$C$5*G$13/1000)*'Development Appraisal'!$C$10)+(('Development Appraisal'!$C$7*$B15/1000)*'Development Appraisal'!$C$11)+(MAX(0,(('Development Appraisal'!$C$5*G$13/1000)+(('Development Appraisal'!$C$5*G$13/1000)*'Development Appraisal'!$C$10))-('Development Appraisal'!$C$7*$B15/1000)*'Development Appraisal'!$C$16*'Development Appraisal'!$C$14)*'Development Appraisal'!$C$13*'Development Appraisal'!$C$12/12*'Development Appraisal'!$C$14)))*1000/'Development Appraisal'!$C$5 -> 506.93933
B16: 2400 | C16: =(('Development Appraisal'!$C$7*$B16/1000)/(1+'Development Appraisal'!$C$15)-(('Development Appraisal'!$C$5*C$13/1000)+(('Development Appraisal'!$C$5*C$13/1000)*'Development Appraisal'!$C$10)+(('Development Appraisal'!$C$7*$B16/1000)*'Development Appraisal'!$C$11)+(MAX(0,(('Development Appraisal'!$C$5*C$13/1000)+(('Development Appraisal'!$C$5*C$13/1000)*'Development Appraisal'!$C$10))-('Development Appraisal'!$C$7*$B16/1000)*'Development Appraisal'!$C$16*'Development Appraisal'!$C$14)*'Development Appraisal'!$C$13*'Development Appraisal'!$C$12/12*'Development Appraisal'!$C$14)))*1000/'Development Appraisal'!$C$5 -> 890.552 | D16: =(('Development Appraisal'!$C$7*$B16/1000)/(1+'Development Appraisal'!$C$15)-(('Development Appraisal'!$C$5*D$13/1000)+(('Development Appraisal'!$C$5*D$13/1000)*'Development Appraisal'!$C$10)+(('Development Appraisal'!$C$7*$B16/1000)*'Development Appraisal'!$C$11)+(MAX(0,(('Development Appraisal'!$C$5*D$13/1000)+(('Development Appraisal'!$C$5*D$13/1000)*'Development Appraisal'!$C$10))-('Development Appraisal'!$C$7*$B16/1000)*'Development Appraisal'!$C$16*'Development Appraisal'!$C$14)*'Development Appraisal'!$C$13*'Development Appraisal'!$C$12/12*'Development Appraisal'!$C$14)))*1000/'Development Appraisal'!$C$5 -> 828.672 | E16: =(('Development Appraisal'!$C$7*$B16/1000)/(1+'Development Appraisal'!$C$15)-(('Development Appraisal'!$C$5*E$13/1000)+(('Development Appraisal'!$C$5*E$13/1000)*'Development Appraisal'!$C$10)+(('Development Appraisal'!$C$7*$B16/1000)*'Development Appraisal'!$C$11)+(MAX(0,(('Development Appraisal'!$C$5*E$13/1000)+(('Development Appraisal'!$C$5*E$13/1000)*'Development Appraisal'!$C$10))-('Development Appraisal'!$C$7*$B16/1000)*'Development Appraisal'!$C$16*'Development Appraisal'!$C$14)*'Development Appraisal'!$C$13*'Development Appraisal'!$C$12/12*'Development Appraisal'!$C$14)))*1000/'Development Appraisal'!$C$5 -> 766.792 | F16: =(('Development Appraisal'!$C$7*$B16/1000)/(1+'Development Appraisal'!$C$15)-(('Development Appraisal'!$C$5*F$13/1000)+(('Development Appraisal'!$C$5*F$13/1000)*'Development Appraisal'!$C$10)+(('Development Appraisal'!$C$7*$B16/1000)*'Development Appraisal'!$C$11)+(MAX(0,(('Development Appraisal'!$C$5*F$13/1000)+(('Development Appraisal'!$C$5*F$13/1000)*'Development Appraisal'!$C$10))-('Development Appraisal'!$C$7*$B16/1000)*'Development Appraisal'!$C$16*'Development Appraisal'!$C$14)*'Development Appraisal'!$C$13*'Development Appraisal'!$C$12/12*'Development Appraisal'!$C$14)))*1000/'Development Appraisal'!$C$5 -> 704.912 | G16: =(('Development Appraisal'!$C$7*$B16/1000)/(1+'Development Appraisal'!$C$15)-(('Development Appraisal'!$C$5*G$13/1000)+(('Development Appraisal'!$C$5*G$13/1000)*'Development Appraisal'!$C$10)+(('Development Appraisal'!$C$7*$B16/1000)*'Development Appraisal'!$C$11)+(MAX(0,(('Development Appraisal'!$C$5*G$13/1000)+(('Development Appraisal'!$C$5*G$13/1000)*'Development Appraisal'!$C$10))-('Development Appraisal'!$C$7*$B16/1000)*'Development Appraisal'!$C$16*'Development Appraisal'!$C$14)*'Development Appraisal'!$C$13*'Development Appraisal'!$C$12/12*'Development Appraisal'!$C$14)))*1000/'Development Appraisal'!$C$5 -> 643.032
B17: 2600 | C17: =(('Development Appraisal'!$C$7*$B17/1000)/(1+'Development Appraisal'!$C$15)-(('Development Appraisal'!$C$5*C$13/1000)+(('Development Appraisal'!$C$5*C$13/1000)*'Development Appraisal'!$C$10)+(('Development Appraisal'!$C$7*$B17/1000)*'Development Appraisal'!$C$11)+(MAX(0,(('Development Appraisal'!$C$5*C$13/1000)+(('Development Appraisal'!$C$5*C$13/1000)*'Development Appraisal'!$C$10))-('Development Appraisal'!$C$7*$B17/1000)*'Development Appraisal'!$C$16*'Development Appraisal'!$C$14)*'Development Appraisal'!$C$13*'Development Appraisal'!$C$12/12*'Development Appraisal'!$C$14)))*1000/'Development Appraisal'!$C$5 -> 1026.6447 | D17: =(('Development Appraisal'!$C$7*$B17/1000)/(1+'Development Appraisal'!$C$15)-(('Development Appraisal'!$C$5*D$13/1000)+(('Development Appraisal'!$C$5*D$13/1000)*'Development Appraisal'!$C$10)+(('Development Appraisal'!$C$7*$B17/1000)*'Development Appraisal'!$C$11)+(MAX(0,(('Development Appraisal'!$C$5*D$13/1000)+(('Development Appraisal'!$C$5*D$13/1000)*'Development Appraisal'!$C$10))-('Development Appraisal'!$C$7*$B17/1000)*'Development Appraisal'!$C$16*'Development Appraisal'!$C$14)*'Development Appraisal'!$C$13*'Development Appraisal'!$C$12/12*'Development Appraisal'!$C$14)))*1000/'Development Appraisal'!$C$5 -> 964.76467 | E17: =(('Development Appraisal'!$C$7*$B17/1000)/(1+'Development Appraisal'!$C$15)-(('Development Appraisal'!$C$5*E$13/1000)+(('Development Appraisal'!$C$5*E$13/1000)*'Development Appraisal'!$C$10)+(('Development Appraisal'!$C$7*$B17/1000)*'Development Appraisal'!$C$11)+(MAX(0,(('Development Appraisal'!$C$5*E$13/1000)+(('Development Appraisal'!$C$5*E$13/1000)*'Development Appraisal'!$C$10))-('Development Appraisal'!$C$7*$B17/1000)*'Development Appraisal'!$C$16*'Development Appraisal'!$C$14)*'Development Appraisal'!$C$13*'Development Appraisal'!$C$12/12*'Development Appraisal'!$C$14)))*1000/'Development Appraisal'!$C$5 -> 902.88467 | F17: =(('Development Appraisal'!$C$7*$B17/1000)/(1+'Development Appraisal'!$C$15)-(('Development Appraisal'!$C$5*F$13/1000)+(('Development Appraisal'!$C$5*F$13/1000)*'Development Appraisal'!$C$10)+(('Development Appraisal'!$C$7*$B17/1000)*'Development Appraisal'!$C$11)+(MAX(0,(('Development Appraisal'!$C$5*F$13/1000)+(('Development Appraisal'!$C$5*F$13/1000)*'Development Appraisal'!$C$10))-('Development Appraisal'!$C$7*$B17/1000)*'Development Appraisal'!$C$16*'Development Appraisal'!$C$14)*'Development Appraisal'!$C$13*'Development Appraisal'!$C$12/12*'Development Appraisal'!$C$14)))*1000/'Development Appraisal'!$C$5 -> 841.00467 | G17: =(('Development Appraisal'!$C$7*$B17/1000)/(1+'Development Appraisal'!$C$15)-(('Development Appraisal'!$C$5*G$13/1000)+(('Development Appraisal'!$C$5*G$13/1000)*'Development Appraisal'!$C$10)+(('Development Appraisal'!$C$7*$B17/1000)*'Development Appraisal'!$C$11)+(MAX(0,(('Development Appraisal'!$C$5*G$13/1000)+(('Development Appraisal'!$C$5*G$13/1000)*'Development Appraisal'!$C$10))-('Development Appraisal'!$C$7*$B17/1000)*'Development Appraisal'!$C$16*'Development Appraisal'!$C$14)*'Development Appraisal'!$C$13*'Development Appraisal'!$C$12/12*'Development Appraisal'!$C$14)))*1000/'Development Appraisal'!$C$5 -> 779.12467
B18: 2800 | C18: =(('Development Appraisal'!$C$7*$B18/1000)/(1+'Development Appraisal'!$C$15)-(('Development Appraisal'!$C$5*C$13/1000)+(('Development Appraisal'!$C$5*C$13/1000)*'Development Appraisal'!$C$10)+(('Development Appraisal'!$C$7*$B18/1000)*'Development Appraisal'!$C$11)+(MAX(0,(('Development Appraisal'!$C$5*C$13/1000)+(('Development Appraisal'!$C$5*C$13/1000)*'Development Appraisal'!$C$10))-('Development Appraisal'!$C$7*$B18/1000)*'Development Appraisal'!$C$16*'Development Appraisal'!$C$14)*'Development Appraisal'!$C$13*'Development Appraisal'!$C$12/12*'Development Appraisal'!$C$14)))*1000/'Development Appraisal'!$C$5 -> 1160.9733 | D18: =(('Development Appraisal'!$C$7*$B18/1000)/(1+'Development Appraisal'!$C$15)-(('Development Appraisal'!$C$5*D$13/1000)+(('Development Appraisal'!$C$5*D$13/1000)*'Development Appraisal'!$C$10)+(('Development Appraisal'!$C$7*$B18/1000)*'Development Appraisal'!$C$11)+(MAX(0,(('Development Appraisal'!$C$5*D$13/1000)+(('Development Appraisal'!$C$5*D$13/1000)*'Development Appraisal'!$C$10))-('Development Appraisal'!$C$7*$B18/1000)*'Development Appraisal'!$C$16*'Development Appraisal'!$C$14)*'Development Appraisal'!$C$13*'Development Appraisal'!$C$12/12*'Development Appraisal'!$C$14)))*1000/'Development Appraisal'!$C$5 -> 1100.8573 | E18: =(('Development Appraisal'!$C$7*$B18/1000)/(1+'Development Appraisal'!$C$15)-(('Development Appraisal'!$C$5*E$13/1000)+(('Development Appraisal'!$C$5*E$13/1000)*'Development Appraisal'!$C$10)+(('Development Appraisal'!$C$7*$B18/1000)*'Development Appraisal'!$C$11)+(MAX(0,(('Development Appraisal'!$C$5*E$13/1000)+(('Development Appraisal'!$C$5*E$13/1000)*'Development Appraisal'!$C$10))-('Development Appraisal'!$C$7*$B18/1000)*'Development Appraisal'!$C$16*'Development Appraisal'!$C$14)*'Development Appraisal'!$C$13*'Development Appraisal'!$C$12/12*'Development Appraisal'!$C$14)))*1000/'Development Appraisal'!$C$5 -> 1038.9773 | F18: =(('Development Appraisal'!$C$7*$B18/1000)/(1+'Development Appraisal'!$C$15)-(('Development Appraisal'!$C$5*F$13/1000)+(('Development Appraisal'!$C$5*F$13/1000)*'Development Appraisal'!$C$10)+(('Development Appraisal'!$C$7*$B18/1000)*'Development Appraisal'!$C$11)+(MAX(0,(('Development Appraisal'!$C$5*F$13/1000)+(('Development Appraisal'!$C$5*F$13/1000)*'Development Appraisal'!$C$10))-('Development Appraisal'!$C$7*$B18/1000)*'Development Appraisal'!$C$16*'Development Appraisal'!$C$14)*'Development Appraisal'!$C$13*'Development Appraisal'!$C$12/12*'Development Appraisal'!$C$14)))*1000/'Development Appraisal'!$C$5 -> 977.09733 | G18: =(('Development Appraisal'!$C$7*$B18/1000)/(1+'Development Appraisal'!$C$15)-(('Development Appraisal'!$C$5*G$13/1000)+(('Development Appraisal'!$C$5*G$13/1000)*'Development Appraisal'!$C$10)+(('Development Appraisal'!$C$7*$B18/1000)*'Development Appraisal'!$C$11)+(MAX(0,(('Development Appraisal'!$C$5*G$13/1000)+(('Development Appraisal'!$C$5*G$13/1000)*'Development Appraisal'!$C$10))-('Development Appraisal'!$C$7*$B18/1000)*'Development Appraisal'!$C$16*'Development Appraisal'!$C$14)*'Development Appraisal'!$C$13*'Development Appraisal'!$C$12/12*'Development Appraisal'!$C$14)))*1000/'Development Appraisal'!$C$5 -> 915.21733

Sheet Summary
B1: Emaar Properties — Real-Estate NAV and Development Appraisal | F1: EMAAR PROPERTIES
B2: Emaar on one page
B4: NET ASSET VALUE (AED millions)
B5: A. UAE development, Emaar's share | C5: =NAV!$C$10 -> 45211.121
B6: B. International development | C6: =NAV!$C$17 -> 7967.8409
B7: C. Malls and commercial leasing | C7: =NAV!$C$20 -> 82714.286
B8: D. Hospitality, leisure and entertainment | C8: =NAV!$C$24 -> 27176.471
B9: Gross asset value | C9: =NAV!$C$27 -> 163069.72
B10: Free cash less borrowings | C10: =NAV!$C$28+NAV!$C$29 -> 15701.5
B11: Net asset value | C11: =NAV!$C$30 -> 178771.22
B13: AGAINST THE MARKET
B14: NAV per share (AED) | C14: =NAV!$C$33 -> 20.225734
B15: Share price (AED) | C15: =NAV!$C$34 -> 11.8
B16: Discount to NAV | C16: =NAV!$C$35 -> 0.41658483
B17: Price / book | C17: =Inputs!$C$29 -> 1.1062797
B18: Market cap as % of recurring assets plus free cash | C18: =NAV!$C$39 -> 0.83044802
B20: THE DEVELOPMENT APPRAISAL
B21: Gross development value of the illustrative tower | C21: ='Development Appraisal'!$C$19 -> 1180.8
B22: Residual land value | C22: ='Development Appraisal'!$C$30 -> 460.0752
B23: per sq ft of gross floor area (AED) | C23: ='Development Appraisal'!$C$31 -> 766.792
B24: Price cushion before the scheme loses money | C24: ='Development Appraisal'!$C$36 -> 0.16666667
B26: • Emaar trades at a wide discount to a bottom-up NAV, as UAE developers have for most of their listed history. The market capitalisation covers the recurring assets and the free cash and little more; the price ascribes almost no value to a backlog of AED 155bn and 660 million square feet of land.
B27: • The two halves of the group deserve different multiples and get them. Dubai Mall and the leasing portfolio are capitalised at a 7% yield, roughly 14x EBITDA; the development backlog is discounted at 11% over three and a half years and taxed. The recurring assets are about half of gross value.
B28: • Half the cash is treated as belonging to buyers, not shareholders. Off-plan collections sit in escrow to fund construction; counting them as free cash is the most common way a developer NAV is overstated.
B29: • The development appraisal shows why the discount exists. Land is a residual: at the base case it is close to two-fifths of GDV, and a 10% fall in sale prices removes about a fifth of the land value, twice the gearing. The market applies that gearing to the whole land bank.

Sheet Checks
B1: Emaar Properties — Real-Estate NAV and Development Appraisal | E1: EMAAR PROPERTIES
B2: Every check must read TRUE
B4: INTEGRITY CHECKS
B5: Backlog split sums to the group figure | C5: =ABS(Inputs!$C$6+Inputs!$C$7-Inputs!$C$5)<0.01 -> TRUE
B6: Mall EBITDA plus hospitality EBITDA equals disclosed recurring EBITDA | C6: =ABS(Inputs!$C$13+Inputs!$C$12-Inputs!$C$9)<0.01 -> TRUE
B7: Recurring EBITDA margin is plausible (60–85%) | C7: =AND(Inputs!$C$9/Inputs!$C$8>0.6,Inputs!$C$9/Inputs!$C$8<0.85) -> TRUE
B8: Development margin assumed is below Emaar Development's reported EBITDA margin | C8: =Inputs!$C$36<0.52 -> TRUE
B9: Discount factor lies between 0 and 1 | C9: =AND(NAV!$C$6>0,NAV!$C$6<1) -> TRUE
B10: Gross asset value equals the sum of the four blocks | C10: =ABS(NAV!$C$27-(NAV!$C$10+NAV!$C$17+NAV!$C$20+NAV!$C$24))<0.01 -> TRUE
B11: NAV per share reconciles to NAV over shares | C11: =ABS(NAV!$C$33-NAV!$C$30/Inputs!$C$27)<0.001 -> TRUE
B12: Block A is within 40% of the listed Emaar Development value | C12: =ABS(NAV!$C$12)<0.4 -> TRUE
B13: Base NAV sensitivity cell reconciles to the NAV sheet | C13: =ABS(Sensitivity!E8-NAV!$C$33)<0.01 -> TRUE
B14: Base appraisal sensitivity cell reconciles to the residual land value | C14: =ABS(Sensitivity!E16-'Development Appraisal'!$C$31)<0.5 -> TRUE
B15: Developer profit equals the target share of total cost including land | C15: =ABS('Development Appraisal'!$C$34-'Development Appraisal'!$C$15)<0.0001 -> TRUE
B16: Residual land value is positive | C16: ='Development Appraisal'!$C$30>0 -> TRUE
B17: GDV exceeds total cost plus land plus profit by less than a rounding error | C17: =ABS('Development Appraisal'!$C$19-('Development Appraisal'!$C$26+'Development Appraisal'!$C$30+'Development Appraisal'!$C$29))<0.01 -> TRUE
B18: Market capitalisation reconciles to price times shares | C18: =ABS(Inputs!$C$28-Inputs!$C$26*Inputs!$C$27)<0.01 -> TRUE
B19: Share price lies within the 52-week range | C19: =AND(Inputs!$C$26>=10.15-0.1,Inputs!$C$26<=17.25+0.1) -> TRUE
B21: MODEL STATUS | C21: =IF(COUNTIF(C5:C19,FALSE())=0,"MODEL OK","CHECK FAILED") -> MODEL OK
B23: The eighth check compares the model's own value for the UAE development block with what the Dubai market pays for the listed subsidiary that owns it. It is the only external test a NAV can be given, and it is deliberately loose.
