Workbook

Sheet Cover
B3: IB PORTFOLIO · PROJECT 18 OF 20
B4: Dubai World and Nakheel
B5: Restructuring: Liquidity, Recoveries and Debt-for-Equity
B6: Restructuring 2010–11 · US$ billions unless stated · as of terms of May–Sep 2010 and Nakheel 2011
B9: What this is | C9: The 2010–11 restructuring of Dubai World and Nakheel rebuilt as a restructuring model from the announced terms: the liquidity mismatch that forced the November 2009 standstill, whether the eight-year plan could be met from asset sales, the present-value recovery of each creditor class under the extended low-coupon terms, and the Government of Dubai's US$8.9bn debt-for-equity conversion.
B11: How it is built | C11: • Liquidity: the December 2009 maturity against available cash; net realisable assets after stated haircuts against the two bank tranches at maturity, with and without the DP World stake; cash interest saved by the coupon cut.
C12: • Recoveries: each tranche valued as a bullet with its cash coupon, PIK accretion and guarantee cover at a stated 2010 discount rate; Nakheel's 40% cash / 60% sukuk trade settlement and extended bank debt on the same basis; a ranked waterfall.
C13: • Debt-for-equity: the equity value implied by assets less the present value of bank claims, the government's recovery, its break-even asset value, and the counterfactual in which the banks had taken equity.
C14: • A sensitivity of bank recovery to the discount rate and to guarantee cover.
B16: Contents | C16: Summary — liquidity, recoveries, debt-for-equity
C17: Liquidity — the 2009 maturity; asset cover over the plan
C18: Recoveries — PV by tranche and class; the waterfall
C19: Debt-for-Equity — the government's conversion and break-even
C20: Sensitivity — discount rate against guarantee cover
C21: Inputs — announced terms and stated assumptions
C22: Checks — fourteen tests; must read MODEL OK
B24: Key outputs (live) | C24: Shortfall on the Dec 2009 sukuk (US$ bn) | E24: =Liquidity!$C$7 -> 3.02
C25: Asset cover with / without DP World | E25: =TEXT(Liquidity!$C$19,"0.00")&"x / "&TEXT(Liquidity!$C$23,"0.00")&"x" -> 0.93x / 0.47x
C26: Bank recovery, present value | E26: =Recoveries!$C$12 -> 0.71415578
C27: Value transferred from banks (US$ bn) | E27: =Recoveries!$C$16 -> 2.6787812
C28: Nakheel trade creditor recovery | E28: =Recoveries!$C$21 -> 0.97782462
C29: Government recovery on conversion, PV | E29: ='Debt-for-Equity'!$C$15 -> 0.48215245
B31: Colour code | C31: Blue = hard-coded input
C32: Black = formula
C33: Green = link to another sheet
C34: Accent fill = scenario selector / key levers
B36: Sources | C36: Dubai World and Government of Dubai announcements of 20 May 2010 (terms proposed) and 10 September 2010 (creditor approval); Nakheel announcements of 2010–2011 including the August 2011 sukuk; Abu Dhabi support of 14 December 2009.
C37: Tranche amounts, tenors, coupons and PIK options, the government conversion and Nakheel's cash/sukuk split are as publicly reported. Discount rates, asset values, haircuts and the guarantee share are stated inputs.
C38: The model is a reconstruction for learning from public information; it is not a statement about any creditor's actual position or accounting.
B40: Prepared by | C40: Jainam Mehta · github.com/jainammehta1215/ib-portfolio

Sheet Inputs
B1: Dubai World and Nakheel — Restructuring: Liquidity, Recoveries and Debt-for-Equity | F1: DUBAI WORLD
B2: The announced terms, and the stated assumptions needed to value them
B4: DUBAI WORLD — CLAIMS AT THE STANDSTILL (US$ bn)
B5: Bank and financial creditors (about 70 lenders) | C5: 14.4
B6: Government of Dubai claims (existing loans and the Dubai Financial Support Fund advances) | C6: 8.9
B7: Other claims included in the restructuring perimeter | C7: 1.6 | F7: Total perimeter reported as about US$24.9bn
B8: Total restructured | C8: =Inputs!$C$5+Inputs!$C$6+Inputs!$C$7 -> 24.9
B10: BANK TERMS AGREED (September 2010)
B11: Tranche A: amount | C11: 4.4
B12: Tranche A: tenor (years, bullet) | C12: 5
B13: Tranche A: cash coupon | C13: 0.01
B14: Tranche B: amount | C14: 10
B15: Tranche B: tenor (years, bullet) | C15: 8
B16: Tranche B: cash coupon | C16: 0.01
B17: Tranche B: payment-in-kind margin (option chosen by most US$ lenders) | C17: 0.015 | F17: Lenders chose between 1.5% PIK with a government shortfall guarantee, 2.5% with partial cover, and 3.5% with none
B18: Share of Tranche B covered by the government shortfall guarantee (stated) | C18: 0.6
B19: Original contractual coupon on the bank debt (stated: pre-crisis LIBOR plus margin, all-in) | C19: 0.055
B21: GOVERNMENT OF DUBAI
B22: Claims converted to equity in Dubai World | C22: =Inputs!$C$6 -> 8.9
B23: New money committed: working capital facility | C23: 0.5
B24: New money committed: interest support over the term | C24: 1
B26: NAKHEEL (separated from Dubai World; its own plan, 2011)
B27: Trade creditor claims | C27: 2.7 | F27: About AED 10bn of contractor and supplier claims
B28: paid in cash | C28: 0.4
B29: paid in a 5-year sukuk | C29: 0.6
B30: sukuk profit rate | C30: 0.1 | F30: AED 4.8bn sukuk issued August 2011 at 10%
B31: Nakheel bank debt extended | C31: 1.6
B32: extension (years) | C32: 5
B33: coupon after extension (stated) | C33: 0.04
B34: Government support injected into Nakheel (equity and converted debt) | C34: 8
B36: VALUATION ASSUMPTIONS — stated
B37: Discount rate for a Dubai government-related credit in 2010 (yield on comparable paper) | C37: 0.08 | F37: Dubai sovereign five-year paper yielded 6–7% in 2010; corporate GREs traded wider
B38: Spread by which the guaranteed portion is discounted below the corporate rate | C38: 0.015
B39: Discount rate for the government-guaranteed portion | C39: =Inputs!$C$37-Inputs!$C$38 -> 0.065
B40: Discount rate for the Nakheel sukuk (traded near par to a small discount after issue) | C40: 0.11
B42: ASSET REALISATION PLAN (US$ bn, as described in the plan)
B43: Stake in DP World (about 80%, at 2010 market value) | C43: 8.5
B44: Istithmar World portfolio (Barneys, hotels, financial stakes) | C44: 3
B45: Drydocks World and Dubai Maritime City | C45: 1.5
B46: Economic Zones World (Jafza) | C46: 4
...

Sheet Liquidity
B1: Dubai World and Nakheel — Restructuring: Liquidity, Recoveries and Debt-for-Equity | F1: DUBAI WORLD
B2: Why the standstill happened, and whether the eight-year plan could be met from assets
B4: THE PROBLEM IN NOVEMBER 2009
B5: Nakheel sukuk maturing 14 December 2009 (US$ bn) | C5: 3.52
B6: Group cash available to meet it without support (stated) | C6: 0.5
B7: Shortfall on a single maturity | C7: =Liquidity!$C$5-Liquidity!$C$6 -> 3.02
B8: Abu Dhabi support that paid it (14 December 2009, US$ bn) | C8: 10 | F8: Of which US$4.1bn to Nakheel's sukuk and the rest to the standstill period
B9: Further group maturities falling in 2010–2011 before the plan (stated) | C9: 6
B10: Cash plus Abu Dhabi support divided by maturities to end-2011 | C10: =(Liquidity!$C$6+Liquidity!$C$8)/(Liquidity!$C$5+Liquidity!$C$9) -> 1.1029412
B11: A liquidity crisis is a mismatch of dates, not a shortage of assets. Dubai World's assets were worth more than its debt on most estimates; it simply could not turn a port operator and a property portfolio into US$3.5bn in three weeks. The standstill bought time; Abu Dhabi's US$10bn bought the first maturity.
B13: CAN THE EIGHT-YEAR PLAN BE MET FROM ASSET SALES?
B14: Gross asset value in the plan | C14: =Inputs!$C$43+Inputs!$C$44+Inputs!$C$45+Inputs!$C$46+Inputs!$C$47 -> 19
B15: Net realisable after haircuts | C15: =Inputs!$C$43*(1-Inputs!$C$49)+(Inputs!$C$44+Inputs!$C$45+Inputs!$C$46+Inputs!$C$47)*(1-Inputs!$C$48) -> 14.575
B16: Tranche A due in year five | C16: =Inputs!$C$11 -> 4.4
B17: Tranche B due in year eight, including accrued PIK | C17: =Inputs!$C$14*(1+Inputs!$C$17)^Inputs!$C$15 -> 11.264926
B18: Total bank principal to repay over the plan | C18: =Liquidity!$C$16+Liquidity!$C$17 -> 15.664926
B19: Net realisable assets / bank principal | C19: =Liquidity!$C$15/Liquidity!$C$18 -> 0.93042253
B20: Annual cash interest under the new terms (both tranches at 1%) | C20: =(Inputs!$C$11+Inputs!$C$14)*0.01 -> 0.144
B21: compared with cash interest at the original all-in coupon | C21: =(Inputs!$C$11+Inputs!$C$14)*Inputs!$C$19 -> 0.792
B22: Annual cash interest saved by the coupon cut | C22: =Liquidity!$C$21-Liquidity!$C$20 -> 0.648
B23: Asset cover without selling DP World (the crown jewel the plan hoped to keep) | C23: =(Liquidity!$C$15-Inputs!$C$43*(1-Inputs!$C$49))/Liquidity!$C$18 -> 0.46920107
B24: On forced-sale 2010 values the plan did not quite cover the debt even with DP World, and covered less than half without it. That is the case for the eight-year tenor: the plan relied on asset values recovering, and on DP World growing into the debt, rather than on sales into the trough. The 1% coupon — US$0.65bn a year of cash interest saved — is what made waiting affordable.

Sheet Recoveries
B1: Dubai World and Nakheel — Restructuring: Liquidity, Recoveries and Debt-for-Equity | F1: DUBAI WORLD
B2: What each class received, in present value — the nominal number was 100 cents; the economic one was not
B4: DUBAI WORLD BANK CREDITORS
B5: Tranche A: PV at the discount rate (US$ bn) | C5: =Inputs!$C$11*(Inputs!$C$13*(1-(1+Inputs!$C$37)^-Inputs!$C$12)/Inputs!$C$37+(1+0)^Inputs!$C$12/(1+Inputs!$C$37)^Inputs!$C$12) -> 3.1702453
B6: recovery, cents on the dollar | C6: =Recoveries!$C$5/Inputs!$C$11 -> 0.7205103
B7: Tranche B, guaranteed portion: PV at the guaranteed rate | C7: =Inputs!$C$14*Inputs!$C$18*(Inputs!$C$16*(1-(1+Inputs!$C$39)^-Inputs!$C$15)/Inputs!$C$39+(1+Inputs!$C$17)^Inputs!$C$15/(1+Inputs!$C$39)^Inputs!$C$15) -> 4.4492968
B8: Tranche B, unguaranteed portion: PV at the corporate rate | C8: =Inputs!$C$14*(1-Inputs!$C$18)*(Inputs!$C$16*(1-(1+Inputs!$C$37)^-Inputs!$C$15)/Inputs!$C$37+(1+Inputs!$C$17)^Inputs!$C$15/(1+Inputs!$C$37)^Inputs!$C$15) -> 2.6643011
B9: Tranche B: PV | C9: =Recoveries!$C$7+Recoveries!$C$8 -> 7.1135979
B10: recovery, cents on the dollar | C10: =Recoveries!$C$9/Inputs!$C$14 -> 0.71135979
B11: Bank creditors: total PV | C11: =Recoveries!$C$5+Recoveries!$C$9 -> 10.283843
B12: Bank creditors: blended recovery | C12: =Recoveries!$C$11/Inputs!$C$5 -> 0.71415578
B13: economic haircut (1 − recovery) | C13: =1-Recoveries!$C$12 -> 0.28584422
B14: For comparison: PV of the original debt at its original coupon over five years at the same discount rate | C14: =Inputs!$C$5*(Inputs!$C$19*(1-(1+Inputs!$C$37)^-5)/Inputs!$C$37+(1+0)^5/(1+Inputs!$C$37)^5) -> 12.962624
B15: as cents on the dollar (what the loans were worth even before the restructuring, at 2010 yields) | C15: =Recoveries!$C$14/Inputs!$C$5 -> 0.90018225
B16: Value transferred from banks to the company by the new terms (US$ bn) | C16: =Recoveries!$C$14-Recoveries!$C$11 -> 2.6787812
B18: NAKHEEL CREDITORS
B19: Trade creditors: cash element | C19: =Inputs!$C$27*Inputs!$C$28 -> 1.08
B20: Trade creditors: PV of the sukuk element | C20: =Inputs!$C$27*Inputs!$C$29*(Inputs!$C$30*(1-(1+Inputs!$C$40)^-5)/Inputs!$C$40+(1+0)^5/(1+Inputs!$C$40)^5) -> 1.5601265
B21: Trade creditors: recovery | C21: =(Recoveries!$C$19+Recoveries!$C$20)/Inputs!$C$27 -> 0.97782462
B22: Nakheel banks: PV of the extended loan | C22: =Inputs!$C$31*(Inputs!$C$33*(1-(1+Inputs!$C$37)^-Inputs!$C$32)/Inputs!$C$37+(1+0)^Inputs!$C$32/(1+Inputs!$C$37)^Inputs!$C$32) -> 1.3444666
B23: Nakheel banks: recovery | C23: =Recoveries!$C$22/Inputs!$C$31 -> 0.8402916
B25: THE WATERFALL, IN ONE TABLE
B26: Class (ranked by recovery) | C26: Claim | D26: PV received | E26: Recovery
B27: Nakheel trade creditors (40% cash, 60% 10% sukuk) | C27: =Inputs!$C$27 -> 2.7 | D27: =Recoveries!$C$19+Recoveries!$C$20 -> 2.6401265 | E27: =D27/C27 -> 0.97782462
B28: Nakheel banks (5-year extension) | C28: =Inputs!$C$31 -> 1.6 | D28: =Recoveries!$C$22 -> 1.3444666 | E28: =D28/C28 -> 0.8402916
B29: Dubai World Tranche A (5 years, 1%) | C29: =Inputs!$C$11 -> 4.4 | D29: =Recoveries!$C$5 -> 3.1702453 | E29: =D29/C29 -> 0.7205103
B30: Dubai World Tranche B (8 years, 1% + PIK, part-guaranteed) | C30: =Inputs!$C$14 -> 10 | D30: =Recoveries!$C$9 -> 7.1135979 | E30: =D30/C30 -> 0.71135979
B31: Government of Dubai (converted to equity) | C31: =Inputs!$C$6 -> 8.9 | D31: =0 -> 0 | E31: =D31/C31 -> 0
B32: Nobody took a nominal haircut except the government, which took all of it by converting to equity. The banks' 'full recovery' was worth roughly 70 cents on the dollar in present value: five to eight years at 1% when the market required 8%. Trade creditors, who could stop building, did best. That ordering — operational leverage over legal seniority — is the lesson of most Gulf restructurings of the period.

Sheet Debt-for-Equity
B1: Dubai World and Nakheel — Restructuring: Liquidity, Recoveries and Debt-for-Equity | F1: DUBAI WORLD
B2: The government's conversion: what it gave up, what it received, and why the banks would not do it
B4: THE CONVERSION
B5: Government claims converted to Dubai World equity (US$ bn) | C5: =Inputs!$C$22 -> 8.9
B6: New money committed alongside | C6: =Inputs!$C$23+Inputs!$C$24 -> 1.5
B7: Total government exposure to the plan | C7: ='Debt-for-Equity'!$C$5+'Debt-for-Equity'!$C$6 -> 10.4
B9: WHAT THE EQUITY WAS WORTH
B10: Enterprise value of the restructured group: net realisable assets (Liquidity sheet) | C10: =Liquidity!$C$15 -> 14.575
B11: Less: bank debt at present value (the market value of the claims ranking ahead) | C11: =-Recoveries!$C$11 -> -10.283843
B12: memo: bank debt at face | C12: =-Inputs!$C$5 -> -14.4
B13: Implied equity value on a present-value basis | C13: ='Debt-for-Equity'!$C$10+'Debt-for-Equity'!$C$11 -> 4.2911568
B14: Implied equity value if the debt is taken at face | C14: ='Debt-for-Equity'!$C$10+'Debt-for-Equity'!$C$12 -> 0.175
B15: Government recovery on the converted claims: equity value / claims converted (PV basis) | C15: =MAX(0,'Debt-for-Equity'!$C$13)/'Debt-for-Equity'!$C$5 -> 0.48215245
B16: on a face-value basis | C16: =MAX(0,'Debt-for-Equity'!$C$14)/'Debt-for-Equity'!$C$5 -> 0.019662921
B17: Asset value at which the government's equity is worth its converted claims (US$ bn) | C17: =Recoveries!$C$11+'Debt-for-Equity'!$C$5 -> 19.183843 | F17: With DP World's later performance the group cleared this level; in 2010 it was a bet
B19: WHY THE BANKS TOOK PAPER AND THE GOVERNMENT TOOK EQUITY
B20: If the banks had converted 30% of their claims to equity instead: equity claim they would hold (US$ bn) | C20: =Inputs!$C$5*0.3 -> 4.32
B21: PV of the remaining 70% on the new terms plus a pro-rata share of the PV equity | C21: =Recoveries!$C$11*0.7+'Debt-for-Equity'!$C$20/('Debt-for-Equity'!$C$20+'Debt-for-Equity'!$C$5)*MAX(0,'Debt-for-Equity'!$C$10-Recoveries!$C$11*0.7) -> 9.6091031
B22: recovery under that alternative | C22: ='Debt-for-Equity'!$C$21/Inputs!$C$5 -> 0.66729883
B23: versus the recovery they accepted | C23: ='Debt-for-Equity'!$C$22-Recoveries!$C$12 -> -0.046856951
B24: The government converted because it was the only creditor whose objective was not recovery: it needed the group to survive and its name to be honoured. The banks took paper because paper with a 1% coupon and a sovereign shortfall guarantee could stay on the books at close to par, while equity in a Dubai holding company in 2010 could not. Regulatory accounting, not valuation, chose the instruments.

Sheet Sensitivity
B1: Dubai World and Nakheel — Restructuring: Liquidity, Recoveries and Debt-for-Equity | H1: DUBAI WORLD
B2: Bank recovery under different discount rates and Tranche B guarantee cover
B4: BLENDED BANK RECOVERY: DISCOUNT RATE (rows) versus GUARANTEED SHARE OF TRANCHE B (columns)
B5: ↓ discount rate \ guaranteed share → | C5: 0 | D5: 0.3 | E5: 0.6 | F5: 0.8 | G5: 1
B6: 0.06 | C6: =(Inputs!$C$11*(Inputs!$C$13*(1-(1+$B6)^-Inputs!$C$12)/$B6+1/(1+$B6)^Inputs!$C$12)+Inputs!$C$14*C$5*(Inputs!$C$16*(1-(1+($B6-Inputs!$C$38))^-Inputs!$C$15)/($B6-Inputs!$C$38)+(1+Inputs!$C$17)^Inputs!$C$15/(1+($B6-Inputs!$C$38))^Inputs!$C$15)+Inputs!$C$14*(1-C$5)*(Inputs!$C$16*(1-(1+$B6)^-Inputs!$C$15)/$B6+(1+Inputs!$C$17)^Inputs!$C$15/(1+$B6)^Inputs!$C$15))/Inputs!$C$5 -> 0.77513981 | D6: =(Inputs!$C$11*(Inputs!$C$13*(1-(1+$B6)^-Inputs!$C$12)/$B6+1/(1+$B6)^Inputs!$C$12)+Inputs!$C$14*D$5*(Inputs!$C$16*(1-(1+($B6-Inputs!$C$38))^-Inputs!$C$15)/($B6-Inputs!$C$38)+(1+Inputs!$C$17)^Inputs!$C$15/(1+($B6-Inputs!$C$38))^Inputs!$C$15)+Inputs!$C$14*(1-D$5)*(Inputs!$C$16*(1-(1+$B6)^-Inputs!$C$15)/$B6+(1+Inputs!$C$17)^Inputs!$C$15/(1+$B6)^Inputs!$C$15))/Inputs!$C$5 -> 0.79372697 | E6: =(Inputs!$C$11*(Inputs!$C$13*(1-(1+$B6)^-Inputs!$C$12)/$B6+1/(1+$B6)^Inputs!$C$12)+Inputs!$C$14*E$5*(Inputs!$C$16*(1-(1+($B6-Inputs!$C$38))^-Inputs!$C$15)/($B6-Inputs!$C$38)+(1+Inputs!$C$17)^Inputs!$C$15/(1+($B6-Inputs!$C$38))^Inputs!$C$15)+Inputs!$C$14*(1-E$5)*(Inputs!$C$16*(1-(1+$B6)^-Inputs!$C$15)/$B6+(1+Inputs!$C$17)^Inputs!$C$15/(1+$B6)^Inputs!$C$15))/Inputs!$C$5 -> 0.81231413 | F6: =(Inputs!$C$11*(Inputs!$C$13*(1-(1+$B6)^-Inputs!$C$12)/$B6+1/(1+$B6)^Inputs!$C$12)+Inputs!$C$14*F$5*(Inputs!$C$16*(1-(1+($B6-Inputs!$C$38))^-Inputs!$C$15)/($B6-Inputs!$C$38)+(1+Inputs!$C$17)^Inputs!$C$15/(1+($B6-Inputs!$C$38))^Inputs!$C$15)+Inputs!$C$14*(1-F$5)*(Inputs!$C$16*(1-(1+$B6)^-Inputs!$C$15)/$B6+(1+Inputs!$C$17)^Inputs!$C$15/(1+$B6)^Inputs!$C$15))/Inputs!$C$5 -> 0.82470557 | G6: =(Inputs!$C$11*(Inputs!$C$13*(1-(1+$B6)^-Inputs!$C$12)/$B6+1/(1+$B6)^Inputs!$C$12)+Inputs!$C$14*G$5*(Inputs!$C$16*(1-(1+($B6-Inputs!$C$38))^-Inputs!$C$15)/($B6-Inputs!$C$38)+(1+Inputs!$C$17)^Inputs!$C$15/(1+($B6-Inputs!$C$38))^Inputs!$C$15)+Inputs!$C$14*(1-G$5)*(Inputs!$C$16*(1-(1+$B6)^-Inputs!$C$15)/$B6+(1+Inputs!$C$17)^Inputs!$C$15/(1+$B6)^Inputs!$C$15))/Inputs!$C$5 -> 0.83709701
B7: 0.07 | C7: =(Inputs!$C$11*(Inputs!$C$13*(1-(1+$B7)^-Inputs!$C$12)/$B7+1/(1+$B7)^Inputs!$C$12)+Inputs!$C$14*C$5*(Inputs!$C$16*(1-(1+($B7-Inputs!$C$38))^-Inputs!$C$15)/($B7-Inputs!$C$38)+(1+Inputs!$C$17)^Inputs!$C$15/(1+($B7-Inputs!$C$38))^Inputs!$C$15)+Inputs!$C$14*(1-C$5)*(Inputs!$C$16*(1-(1+$B7)^-Inputs!$C$15)/$B7+(1+Inputs!$C$17)^Inputs!$C$15/(1+$B7)^Inputs!$C$15))/Inputs!$C$5 -> 0.7271505 | D7: =(Inputs!$C$11*(Inputs!$C$13*(1-(1+$B7)^-Inputs!$C$12)/$B7+1/(1+$B7)^Inputs!$C$12)+Inputs!$C$14*D$5*(Inputs!$C$16*(1-(1+($B7-Inputs!$C$38))^-Inputs!$C$15)/($B7-Inputs!$C$38)+(1+Inputs!$C$17)^Inputs!$C$15/(1+($B7-Inputs!$C$38))^Inputs!$C$15)+Inputs!$C$14*(1-D$5)*(Inputs!$C$16*(1-(1+$B7)^-Inputs!$C$15)/$B7+(1+Inputs!$C$17)^Inputs!$C$15/(1+$B7)^Inputs!$C$15))/Inputs!$C$5 -> 0.74423904 | E7: =(Inputs!$C$11*(Inputs!$C$13*(1-(1+$B7)^-Inputs!$C$12)/$B7+1/(1+$B7)^Inputs!$C$12)+Inputs!$C$14*E$5*(Inputs!$C$16*(1-(1+($B7-Inputs!$C$38))^-Inputs!$C$15)/($B7-Inputs!$C$38)+(1+Inputs!$C$17)^Inputs!$C$15/(1+($B7-Inputs!$C$38))^Inputs!$C$15)+Inputs!$C$14*(1-E$5)*(Inputs!$C$16*(1-(1+$B7)^-Inputs!$C$15)/$B7+(1+Inputs!$C$17)^Inputs!$C$15/(1+$B7)^Inputs!$C$15))/Inputs!$C$5 -> 0.76132759 | F7: =(Inputs!$C$11*(Inputs!$C$13*(1-(1+$B7)^-Inputs!$C$12)/$B7+1/(1+$B7)^Inputs!$C$12)+Inputs!$C$14*F$5*(Inputs!$C$16*(1-(1+($B7-Inputs!$C$38))^-Inputs!$C$15)/($B7-Inputs!$C$38)+(1+Inputs!$C$17)^Inputs!$C$15/(1+($B7-Inputs!$C$38))^Inputs!$C$15)+Inputs!$C$14*(1-F$5)*(Inputs!$C$16*(1-(1+$B7)^-Inputs!$C$15)/$B7+(1+Inputs!$C$17)^Inputs!$C$15/(1+$B7)^Inputs!$C$15))/Inputs!$C$5 -> 0.77271996 | G7: =(Inputs!$C$11*(Inputs!$C$13*(1-(1+$B7)^-Inputs!$C$12)/$B7+1/(1+$B7)^Inputs!$C$12)+Inputs!$C$14*G$5*(Inputs!$C$16*(1-(1+($B7-Inputs!$C$38))^-Inputs!$C$15)/($B7-Inputs!$C$38)+(1+Inputs!$C$17)^Inputs!$C$15/(1+($B7-Inputs!$C$38))^Inputs!$C$15)+Inputs!$C$14*(1-G$5)*(Inputs!$C$16*(1-(1+$B7)^-Inputs!$C$15)/$B7+(1+Inputs!$C$17)^Inputs!$C$15/(1+$B7)^Inputs!$C$15))/Inputs!$C$5 -> 0.78411232
B8: 0.08 | C8: =(Inputs!$C$11*(Inputs!$C$13*(1-(1+$B8)^-Inputs!$C$12)/$B8+1/(1+$B8)^Inputs!$C$12)+Inputs!$C$14*C$5*(Inputs!$C$16*(1-(1+($B8-Inputs!$C$38))^-Inputs!$C$15)/($B8-Inputs!$C$38)+(1+Inputs!$C$17)^Inputs!$C$15/(1+($B8-Inputs!$C$38))^Inputs!$C$15)+Inputs!$C$14*(1-C$5)*(Inputs!$C$16*(1-(1+$B8)^-Inputs!$C$15)/$B8+(1+Inputs!$C$17)^Inputs!$C$15/(1+$B8)^Inputs!$C$15))/Inputs!$C$5 -> 0.6827082 | D8: =(Inputs!$C$11*(Inputs!$C$13*(1-(1+$B8)^-Inputs!$C$12)/$B8+1/(1+$B8)^Inputs!$C$12)+Inputs!$C$14*D$5*(Inputs!$C$16*(1-(1+($B8-Inputs!$C$38))^-Inputs!$C$15)/($B8-Inputs!$C$38)+(1+Inputs!$C$17)^Inputs!$C$15/(1+($B8-Inputs!$C$38))^Inputs!$C$15)+Inputs!$C$14*(1-D$5)*(Inputs!$C$16*(1-(1+$B8)^-Inputs!$C$15)/$B8+(1+Inputs!$C$17)^Inputs!$C$15/(1+$B8)^Inputs!$C$15))/Inputs!$C$5 -> 0.69843199 | E8: =(Inputs!$C$11*(Inputs!$C$13*(1-(1+$B8)^-Inputs!$C$12)/$B8+1/(1+$B8)^Inputs!$C$12)+Inputs!$C$14*E$5*(Inputs!$C$16*(1-(1+($B8-Inputs!$C$38))^-Inputs!$C$15)/($B8-Inputs!$C$38)+(1+Inputs!$C$17)^Inputs!$C$15/(1+($B8-Inputs!$C$38))^Inputs!$C$15)+Inputs!$C$14*(1-E$5)*(Inputs!$C$16*(1-(1+$B8)^-Inputs!$C$15)/$B8+(1+Inputs!$C$17)^Inputs!$C$15/(1+$B8)^Inputs!$C$15))/Inputs!$C$5 -> 0.71415578 | F8: =(Inputs!$C$11*(Inputs!$C$13*(1-(1+$B8)^-Inputs!$C$12)/$B8+1/(1+$B8)^Inputs!$C$12)+Inputs!$C$14*F$5*(Inputs!$C$16*(1-(1+($B8-Inputs!$C$38))^-Inputs!$C$15)/($B8-Inputs!$C$38)+(1+Inputs!$C$17)^Inputs!$C$15/(1+($B8-Inputs!$C$38))^Inputs!$C$15)+Inputs!$C$14*(1-F$5)*(Inputs!$C$16*(1-(1+$B8)^-Inputs!$C$15)/$B8+(1+Inputs!$C$17)^Inputs!$C$15/(1+$B8)^Inputs!$C$15))/Inputs!$C$5 -> 0.7246383 | G8: =(Inputs!$C$11*(Inputs!$C$13*(1-(1+$B8)^-Inputs!$C$12)/$B8+1/(1+$B8)^Inputs!$C$12)+Inputs!$C$14*G$5*(Inputs!$C$16*(1-(1+($B8-Inputs!$C$38))^-Inputs!$C$15)/($B8-Inputs!$C$38)+(1+Inputs!$C$17)^Inputs!$C$15/(1+($B8-Inputs!$C$38))^Inputs!$C$15)+Inputs!$C$14*(1-G$5)*(Inputs!$C$16*(1-(1+$B8)^-Inputs!$C$15)/$B8+(1+Inputs!$C$17)^Inputs!$C$15/(1+$B8)^Inputs!$C$15))/Inputs!$C$5 -> 0.73512083
B9: 0.09 | C9: =(Inputs!$C$11*(Inputs!$C$13*(1-(1+$B9)^-Inputs!$C$12)/$B9+1/(1+$B9)^Inputs!$C$12)+Inputs!$C$14*C$5*(Inputs!$C$16*(1-(1+($B9-Inputs!$C$38))^-Inputs!$C$15)/($B9-Inputs!$C$38)+(1+Inputs!$C$17)^Inputs!$C$15/(1+($B9-Inputs!$C$38))^Inputs!$C$15)+Inputs!$C$14*(1-C$5)*(Inputs!$C$16*(1-(1+$B9)^-Inputs!$C$15)/$B9+(1+Inputs!$C$17)^Inputs!$C$15/(1+$B9)^Inputs!$C$15))/Inputs!$C$5 -> 0.64151466 | D9: =(Inputs!$C$11*(Inputs!$C$13*(1-(1+$B9)^-Inputs!$C$12)/$B9+1/(1+$B9)^Inputs!$C$12)+Inputs!$C$14*D$5*(Inputs!$C$16*(1-(1+($B9-Inputs!$C$38))^-Inputs!$C$15)/($B9-Inputs!$C$38)+(1+Inputs!$C$17)^Inputs!$C$15/(1+($B9-Inputs!$C$38))^Inputs!$C$15)+Inputs!$C$14*(1-D$5)*(Inputs!$C$16*(1-(1+$B9)^-Inputs!$C$15)/$B9+(1+Inputs!$C$17)^Inputs!$C$15/(1+$B9)^Inputs!$C$15))/Inputs!$C$5 -> 0.65599447 | E9: =(Inputs!$C$11*(Inputs!$C$13*(1-(1+$B9)^-Inputs!$C$12)/$B9+1/(1+$B9)^Inputs!$C$12)+Inputs!$C$14*E$5*(Inputs!$C$16*(1-(1+($B9-Inputs!$C$38))^-Inputs!$C$15)/($B9-Inputs!$C$38)+(1+Inputs!$C$17)^Inputs!$C$15/(1+($B9-Inputs!$C$38))^Inputs!$C$15)+Inputs!$C$14*(1-E$5)*(Inputs!$C$16*(1-(1+$B9)^-Inputs!$C$15)/$B9+(1+Inputs!$C$17)^Inputs!$C$15/(1+$B9)^Inputs!$C$15))/Inputs!$C$5 -> 0.67047429 | F9: =(Inputs!$C$11*(Inputs!$C$13*(1-(1+$B9)^-Inputs!$C$12)/$B9+1/(1+$B9)^Inputs!$C$12)+Inputs!$C$14*F$5*(Inputs!$C$16*(1-(1+($B9-Inputs!$C$38))^-Inputs!$C$15)/($B9-Inputs!$C$38)+(1+Inputs!$C$17)^Inputs!$C$15/(1+($B9-Inputs!$C$38))^Inputs!$C$15)+Inputs!$C$14*(1-F$5)*(Inputs!$C$16*(1-(1+$B9)^-Inputs!$C$15)/$B9+(1+Inputs!$C$17)^Inputs!$C$15/(1+$B9)^Inputs!$C$15))/Inputs!$C$5 -> 0.6801275 | G9: =(Inputs!$C$11*(Inputs!$C$13*(1-(1+$B9)^-Inputs!$C$12)/$B9+1/(1+$B9)^Inputs!$C$12)+Inputs!$C$14*G$5*(Inputs!$C$16*(1-(1+($B9-Inputs!$C$38))^-Inputs!$C$15)/($B9-Inputs!$C$38)+(1+Inputs!$C$17)^Inputs!$C$15/(1+($B9-Inputs!$C$38))^Inputs!$C$15)+Inputs!$C$14*(1-G$5)*(Inputs!$C$16*(1-(1+$B9)^-Inputs!$C$15)/$B9+(1+Inputs!$C$17)^Inputs!$C$15/(1+$B9)^Inputs!$C$15))/Inputs!$C$5 -> 0.68978071
B10: 0.1 | C10: =(Inputs!$C$11*(Inputs!$C$13*(1-(1+$B10)^-Inputs!$C$12)/$B10+1/(1+$B10)^Inputs!$C$12)+Inputs!$C$14*C$5*(Inputs!$C$16*(1-(1+($B10-Inputs!$C$38))^-Inputs!$C$15)/($B10-Inputs!$C$38)+(1+Inputs!$C$17)^Inputs!$C$15/(1+($B10-Inputs!$C$38))^Inputs!$C$15)+Inputs!$C$14*(1-C$5)*(Inputs!$C$16*(1-(1+$B10)^-Inputs!$C$15)/$B10+(1+Inputs!$C$17)^Inputs!$C$15/(1+$B10)^Inputs!$C$15))/Inputs!$C$5 -> 0.60329945 | D10: =(Inputs!$C$11*(Inputs!$C$13*(1-(1+$B10)^-Inputs!$C$12)/$B10+1/(1+$B10)^Inputs!$C$12)+Inputs!$C$14*D$5*(Inputs!$C$16*(1-(1+($B10-Inputs!$C$38))^-Inputs!$C$15)/($B10-Inputs!$C$38)+(1+Inputs!$C$17)^Inputs!$C$15/(1+($B10-Inputs!$C$38))^Inputs!$C$15)+Inputs!$C$14*(1-D$5)*(Inputs!$C$16*(1-(1+$B10)^-Inputs!$C$15)/$B10+(1+Inputs!$C$17)^Inputs!$C$15/(1+$B10)^Inputs!$C$15))/Inputs!$C$5 -> 0.6166444 | E10: =(Inputs!$C$11*(Inputs!$C$13*(1-(1+$B10)^-Inputs!$C$12)/$B10+1/(1+$B10)^Inputs!$C$12)+Inputs!$C$14*E$5*(Inputs!$C$16*(1-(1+($B10-Inputs!$C$38))^-Inputs!$C$15)/($B10-Inputs!$C$38)+(1+Inputs!$C$17)^Inputs!$C$15/(1+($B10-Inputs!$C$38))^Inputs!$C$15)+Inputs!$C$14*(1-E$5)*(Inputs!$C$16*(1-(1+$B10)^-Inputs!$C$15)/$B10+(1+Inputs!$C$17)^Inputs!$C$15/(1+$B10)^Inputs!$C$15))/Inputs!$C$5 -> 0.62998934 | F10: =(Inputs!$C$11*(Inputs!$C$13*(1-(1+$B10)^-Inputs!$C$12)/$B10+1/(1+$B10)^Inputs!$C$12)+Inputs!$C$14*F$5*(Inputs!$C$16*(1-(1+($B10-Inputs!$C$38))^-Inputs!$C$15)/($B10-Inputs!$C$38)+(1+Inputs!$C$17)^Inputs!$C$15/(1+($B10-Inputs!$C$38))^Inputs!$C$15)+Inputs!$C$14*(1-F$5)*(Inputs!$C$16*(1-(1+$B10)^-Inputs!$C$15)/$B10+(1+Inputs!$C$17)^Inputs!$C$15/(1+$B10)^Inputs!$C$15))/Inputs!$C$5 -> 0.63888597 | G10: =(Inputs!$C$11*(Inputs!$C$13*(1-(1+$B10)^-Inputs!$C$12)/$B10+1/(1+$B10)^Inputs!$C$12)+Inputs!$C$14*G$5*(Inputs!$C$16*(1-(1+($B10-Inputs!$C$38))^-Inputs!$C$15)/($B10-Inputs!$C$38)+(1+Inputs!$C$17)^Inputs!$C$15/(1+($B10-Inputs!$C$38))^Inputs!$C$15)+Inputs!$C$14*(1-G$5)*(Inputs!$C$16*(1-(1+$B10)^-Inputs!$C$15)/$B10+(1+Inputs!$C$17)^Inputs!$C$15/(1+$B10)^Inputs!$C$15))/Inputs!$C$5 -> 0.6477826
B12: At 2010 yields the banks' recovery sat between 65 and 75 cents whatever the guarantee cover; only a discount rate near the 1% coupon itself — which is what a bank's accounting effectively assumed — takes it back to par. The grid is the whole argument between the economists and the accountants.

Sheet Summary
B1: Dubai World and Nakheel — Restructuring: Liquidity, Recoveries and Debt-for-Equity | F1: DUBAI WORLD
B2: The restructuring in numbers
B4: LIQUIDITY
B5: Shortfall on the December 2009 Nakheel sukuk (US$ bn) | C5: =Liquidity!$C$7 -> 3.02
B6: Net realisable assets / bank principal over the plan | C6: =Liquidity!$C$19 -> 0.93042253
B7: without DP World | C7: =Liquidity!$C$23 -> 0.46920107
B8: Annual cash interest saved by the coupon cut (US$ bn) | C8: =Liquidity!$C$22 -> 0.648
B10: RECOVERIES, PRESENT VALUE
B11: Tranche A (5 years, 1%) | C11: =Recoveries!$C$6 -> 0.7205103
B12: Tranche B (8 years, 1% + PIK, 60% guaranteed) | C12: =Recoveries!$C$10 -> 0.71135979
B13: Bank creditors, blended | C13: =Recoveries!$C$12 -> 0.71415578
B14: Value transferred from banks to the company (US$ bn) | C14: =Recoveries!$C$16 -> 2.6787812
B15: Nakheel trade creditors | C15: =Recoveries!$C$21 -> 0.97782462
B16: Nakheel banks | C16: =Recoveries!$C$23 -> 0.8402916
B18: DEBT-FOR-EQUITY
B19: Government claims converted (US$ bn) | C19: ='Debt-for-Equity'!$C$5 -> 8.9
B20: Implied equity value, PV basis (US$ bn) | C20: ='Debt-for-Equity'!$C$13 -> 4.2911568
B21: Government recovery on conversion, PV basis | C21: ='Debt-for-Equity'!$C$15 -> 0.48215245
B22: Asset value at which the conversion breaks even (US$ bn) | C22: ='Debt-for-Equity'!$C$17 -> 19.183843
B24: • The crisis was a maturity, not a balance sheet: US$3.5bn due in three weeks against US$0.5bn of cash, in a group whose assets covered its debt. Every term that followed — five and eight-year bullets, 1% coupons, an asset-sale programme — was designed to buy time for DP World to grow into the debt rather than be sold into the trough. On 2010 forced-sale values the assets covered about 93% of the bank principal; the plan was a bet on recovery, and the tenor was the size of the bet.
B25: • Nobody took a nominal haircut except the government. The banks' '100 cents' was worth about 70 in present value at 2010 yields; the coupon cut alone transferred several billion dollars from lenders to the company. Regulatory accounting let the banks carry the paper near par, which is why they accepted it and why they would not take equity.
B26: • Trade creditors did best. Nakheel's contractors received 40% in cash and 60% in a 10% sukuk that traded near par: a recovery above the banks' despite ranking below them, because they could stop the projects. Operational leverage beat legal seniority.
B27: • The government's conversion was the only true risk capital in the plan. On 2010 asset values its equity was worth a fraction of the US$8.9bn converted; it broke even only if the assets reached the bank debt's present value plus its own claim. DP World's subsequent performance is why the bet paid, not the terms.

Sheet Checks
B1: Dubai World and Nakheel — Restructuring: Liquidity, Recoveries and Debt-for-Equity | E1: DUBAI WORLD
B2: Every check must read TRUE
B4: INTEGRITY CHECKS
B5: Restructured perimeter reconciles to the reported US$24.9bn within US$0.1bn | C5: =ABS(Inputs!$C$8-24.9)<0.1 -> TRUE
B6: Tranche A plus Tranche B equal the bank claims | C6: =ABS(Inputs!$C$11+Inputs!$C$14-Inputs!$C$5)<0.001 -> TRUE
B7: Tranche A PV reproduces a hand calculation (1% five-year bullet at 8%) | C7: =ABS(Recoveries!$C$5/Inputs!$C$11-(0.01*(1-1.08^-5)/0.08+1.08^-5))<0.0001 -> TRUE
B8: Tranche B recovery is below Tranche A recovery (longer, riskier) | C8: =Recoveries!$C$10<Recoveries!$C$6 -> TRUE
B9: Blended bank recovery lies between 55 and 85 cents | C9: =AND(Recoveries!$C$12>0.55,Recoveries!$C$12<0.85) -> TRUE
B10: Value transfer equals PV of old terms less PV of new terms | C10: =ABS(Recoveries!$C$16-(Recoveries!$C$14-Recoveries!$C$11))<0.0001 -> TRUE
B11: Nakheel trade recovery exceeds the banks' (operational leverage) | C11: =Recoveries!$C$21>Recoveries!$C$12 -> TRUE
B12: Nakheel cash and sukuk shares sum to 100% | C12: =ABS(Inputs!$C$28+Inputs!$C$29-1)<0.0001 -> TRUE
B13: Waterfall table recoveries are all between 0% and 100% | C13: =AND(MIN(Recoveries!E27:E31)>=0,MAX(Recoveries!E27:E31)<=1) -> TRUE
B14: Asset cover on forced-sale 2010 values is close to one times with DP World (0.85–1.15x) and well below without it (<0.7x) | C14: =AND(Liquidity!$C$19>0.85,Liquidity!$C$19<1.15,Liquidity!$C$23<0.7) -> TRUE
B15: Government break-even exceeds net realisable assets on 2010 values (it was a bet) | C15: ='Debt-for-Equity'!$C$17>Liquidity!$C$15 -> TRUE
B16: Base sensitivity cell reconciles to the Recoveries sheet | C16: =ABS(Sensitivity!E8-Recoveries!$C$12)<0.0001 -> TRUE
B17: Recovery falls as the discount rate rises in every column of the grid | C17: =AND(Sensitivity!C10<Sensitivity!C6,Sensitivity!D10<Sensitivity!D6,Sensitivity!E10<Sensitivity!E6,Sensitivity!F10<Sensitivity!F6,Sensitivity!G10<Sensitivity!G6) -> TRUE
B18: Recovery rises with guarantee cover in every row of the grid | C18: =AND(Sensitivity!G6>=Sensitivity!C6,Sensitivity!G7>=Sensitivity!C7,Sensitivity!G8>=Sensitivity!C8,Sensitivity!G9>=Sensitivity!C9,Sensitivity!G10>=Sensitivity!C10) -> TRUE
B20: MODEL STATUS | C20: =IF(COUNTIF(C5:C18,FALSE())=0,"MODEL OK","CHECK FAILED") -> MODEL OK
B22: The third check reproduces a tranche present value by hand. The rest test the relationships the case is built to show: recovery falls with tenor and rises with guarantee cover, trade creditors beat banks, and the plan needed DP World.
