Workbook

Sheet Cover
B3: IB PORTFOLIO · PROJECT 10 OF 20
B4: Reliance Industries
B5: Sum-of-the-Parts Valuation
B6: NSE: RELIANCE · ₹ crore · per-share values in ₹ · as of FY2026 audited segment results · market data 18 Sep 2026
B9: What this is | C9: A sum-of-the-parts valuation of Reliance Industries on the audited FY2026 segment results and 18 September 2026 market data. Each of the five reported segments is valued on its own peer group, RIL's economic share is taken, consolidated net debt and a holding-company discount are deducted, and the bridge is then run backwards to show the multiple the market is paying for Jio Platforms ahead of its listing.
B11: How it is built | C11: • Segment EBITDA from the audited Ind AS 108 segment note; ownership stakes in Jio Platforms and Reliance Retail Ventures from the annual report.
C12: • Peer multiples read from public market data with each exclusion stated and reasoned; the selected multiple is shown against the peer median so the judgement is visible.
C13: • Net debt on the same adjusted basis as Project 8, so the two workbooks agree to the rupee.
C14: • A market-implied solve for the Jio and Retail multiples, two sensitivity grids and a low–high range.
B16: Contents | C16: Summary — the parts, the bridge, the per-share value and the market-implied Jio multiple
C17: SOTP — segment EVs, RIL share, net debt, discount, per-share
C18: Peers — peer multiples by segment with medians and exclusions
C19: Market-Implied — the Jio and Retail multiples the share price implies
C20: Sensitivity — Jio versus Retail multiple, Jio versus discount, low–high range
C21: Inputs — segment EBITDA, stakes, selected multiples, group items, market data
C22: Checks — sixteen tests; must read MODEL OK
B24: Key outputs (live) | C24: Gross asset value (₹ crore) | E24: =SOTP!$G$11 -> 1848611
C25: SOTP value per share (₹) | E25: =SOTP!$G$22 -> 1064.6124
C26: Share price (₹) | E26: =SOTP!$G$23 -> 1244.6
C27: Upside / (downside) | E27: =SOTP!$G$24 -> -0.14461482
C28: Market-implied Jio EV / EBITDA | E28: ='Market-Implied'!$C$11 -> 17.273598
C29: Market-implied Jio EV (US$ bn) | E29: ='Market-Implied'!$C$14 -> 158.37924
B31: Colour code | C31: Blue = hard-coded input
C32: Black = formula
C33: Green = link to another sheet
C34: Accent fill = scenario selector / key levers
B36: Sources | C36: Reliance Industries Limited, audited consolidated segment information for the year ended 31 March 2026 (media release, 24 April 2026).
C37: Ownership stakes in Jio Platforms (67.03%) and Reliance Retail Ventures (85.06%): Reliance Industries annual report.
C38: Peer EV / EBITDA multiples: Yahoo Finance, 18 September 2026, as listed on the Peers sheet.
C39: Share price: NSE close, 18 September 2026. Holding-company discount is a stated input.
C40: Nothing here is a recommendation. The valuation is an analytical exercise on public information.
B42: Prepared by | C42: Jainam Mehta · github.com/jainammehta1215/ib-portfolio

Sheet Inputs
B1: Reliance Industries — Sum-of-the-Parts Valuation | I1: RELIANCE INDUSTRIES
B2: Segment EBITDA, ownership, selected multiples and group-level items
B4: SEGMENT EBITDA AND OWNERSHIP (₹ crore, FY2026 audited segment information)
B5: Segment | C5: FY2025A | D5: FY2026A | E5: Growth | F5: RIL stake | G5: Multiple | H5: Low | I5: High
B6: Digital Services (Jio Platforms) | C6: 65001 | D6: 76560 | E6: =D6/C6-1 -> 0.17782803 | F6: 0.6703 | G6: 12 | H6: 10 | I6: 14
B7: Retail (Reliance Retail Ventures) | C7: 25094 | D7: 27034 | E7: =D7/C7-1 -> 0.077309317 | F7: 0.8506 | G7: 25 | H7: 20 | I7: 30
B8: Oil to Chemicals | C8: 54988 | D8: 60546 | E8: =D8/C8-1 -> 0.1010766 | F8: 1 | G8: 7.5 | H8: 6.5 | I8: 8.5
B9: Oil and Gas (E&P) | C9: 21188 | D9: 19050 | E9: =D9/C9-1 -> -0.10090617 | F9: 1 | G9: 5 | H9: 4 | I9: 6
B10: Others (media, consumer brands, new energy) | C10: 8526 | D10: 10857 | E10: =D10/C10-1 -> 0.27339901 | F10: 1 | G10: 10 | H10: 8 | I10: 12
B11: Total segment EBITDA | C11: =SUM(C6:C10) -> 174797 | D11: =SUM(D6:D10) -> 194047
B12: RIL stake in Jio Platforms is 67.03% after the 2020 investments by Meta, Google, Vista, KKR, PIF and others; in Reliance Retail Ventures it is 85.06% after the 2020 and 2023 rounds. Stakes are stated inputs from the annual report. Multiples are selected on the Peers sheet.
B14: GROUP-LEVEL ITEMS (₹ crore)
B15: Consolidated EBITDA, as reported | C15: 207911 | I15: Exceeds the segment total by unallocated interest income and the one-off disposal gain; segments are valued, the rest is not
B16: Outstanding debt (company definition) | C16: 374421
B17: Cash and cash equivalents (company definition) | C17: 249704
B18: Lease liabilities | C18: 23579
B19: Deferred spectrum liabilities | C19: 99552 | I19: Sits in Jio economically; deducted at group level here, see the SOTP note
B20: Adjusted net debt (consistent with Project 8) | C20: =Inputs!$C$16-Inputs!$C$17+Inputs!$C$18+Inputs!$C$19 -> 247848
B21: Non-controlling interests at book (memo, not deducted) | C21: 181836 | I21: Minorities are handled through the stake percentages, so deducting book NCI as well would double count
B22: Holding-company discount | C22: 0.1 | I22: Indian conglomerates typically trade at 10–25% below the sum of their parts; 10% reflects that Jio and Retail are consolidated, not associates
B24: MARKET DATA
B25: Share price (₹, NSE close 18 Sep 2026) | C25: 1244.6
B26: Shares outstanding (crore) | C26: 1353.25
B27: Market capitalisation | C27: =Inputs!$C$25*Inputs!$C$26 -> 1684254.9
B28: Diluted EPS, FY2026 (₹) | C28: 59.69
B29: 52-week low (₹) | C29: 1235.3
B30: 52-week high (₹) | C30: 1611.8

Sheet Peers
B1: Reliance Industries — Sum-of-the-Parts Valuation | G1: RELIANCE INDUSTRIES
B2: Trailing EV / EBITDA by segment peer group, 18 September 2026, with exclusions stated
B4: DIGITAL SERVICES (JIO PLATFORMS)
B5: Ticker | C5: Company | D5: EV / EBITDA | E5: Included | F5: If included | G5: Note
B6: BHARTIARTL.NS | C6: Bharti Airtel | D6: 11.6 | E6: 1 | F6: =IF(E6=1,D6,"") -> 11.6 | G6: Direct Indian peer, the anchor
B7: SCMN.SW | C7: Swisscom | D7: 11.8 | E7: 1 | F7: =IF(E7=1,D7,"") -> 11.8
B8: T | C8: AT&T | D8: 7.6 | E8: 1 | F8: =IF(E8=1,D8,"") -> 7.6
B9: VZ | C9: Verizon | D9: 7.7 | E9: 1 | F9: =IF(E9=1,D9,"") -> 7.7
B10: IDEA.NS | C10: Vodafone Idea | D10: 27.9 | E10: 0 | F10: =IF(E10=1,D10,"") | G10: Distressed balance sheet; multiple is not a valuation signal
B11: Z74.SI | C11: Singtel | D11: 23.4 | E11: 0 | F11: =IF(E11=1,D11,"") | G11: EBITDA excludes large associate earnings; multiple overstated
B12: Median of included peers | D12: =MEDIAN($F$6:$F$11) -> 9.65
B13: Mean of included peers | D13: =AVERAGE($F$6:$F$11) -> 9.675
B14: Selected multiple for the segment | D14: =Inputs!$G$6 -> 12
B15: Selected versus median | D15: =Peers!$D$14/Peers!$D$12-1 -> 0.24352332
B17: RETAIL (RELIANCE RETAIL VENTURES)
B18: Ticker | C18: Company | D18: EV / EBITDA | E18: Included | F18: If included | G18: Note
B19: DMART.NS | C19: Avenue Supermarts | D19: 44.9 | E19: 1 | F19: =IF(E19=1,D19,"") -> 44.9 | G19: Indian grocery leader
B20: TRENT.NS | C20: Trent | D20: 50.7 | E20: 1 | F20: =IF(E20=1,D20,"") -> 50.7 | G20: Indian fashion retail
B21: WMT | C21: Walmart | D21: 20.8 | E21: 1 | F21: =IF(E21=1,D21,"") -> 20.8
B22: COST | C22: Costco | D22: 27.9 | E22: 1 | F22: =IF(E22=1,D22,"") -> 27.9
B23: TGT | C23: Target | D23: 10.1 | E23: 1 | F23: =IF(E23=1,D23,"") -> 10.1
B24: Median of included peers | D24: =MEDIAN($F$19:$F$23) -> 27.9
B25: Mean of included peers | D25: =AVERAGE($F$19:$F$23) -> 30.88
B26: Selected multiple for the segment | D26: =Inputs!$G$7 -> 25
B27: Selected versus median | D27: =Peers!$D$26/Peers!$D$24-1 -> -0.10394265
B29: OIL TO CHEMICALS
B30: Ticker | C30: Company | D30: EV / EBITDA | E30: Included | F30: If included | G30: Note
B31: BPCL.NS | C31: Bharat Petroleum | D31: 5.6 | E31: 1 | F31: =IF(E31=1,D31,"") -> 5.6 | G31: Indian refiner-marketer
B32: IOC.NS | C32: Indian Oil | D32: 4.6 | E32: 1 | F32: =IF(E32=1,D32,"") -> 4.6
B33: VLO | C33: Valero | D33: 9.4 | E33: 1 | F33: =IF(E33=1,D33,"") -> 9.4
B34: MPC | C34: Marathon Petroleum | D34: 9.9 | E34: 1 | F34: =IF(E34=1,D34,"") -> 9.9
B35: LYB | C35: LyondellBasell | D35: 9.1 | E35: 1 | F35: =IF(E35=1,D35,"") -> 9.1 | G35: Petrochemicals
B36: DOW | C36: Dow | D36: 9.6 | E36: 1 | F36: =IF(E36=1,D36,"") -> 9.6 | G36: Petrochemicals
B37: HINDPETRO.NS | C37: Hindustan Petroleum | D37: 13.4 | E37: 0 | F37: =IF(E37=1,D37,"") | G37: Trailing EBITDA depressed by LPG under-recoveries; multiple not meaningful
B38: Median of included peers | D38: =MEDIAN($F$31:$F$37) -> 9.25
B39: Mean of included peers | D39: =AVERAGE($F$31:$F$37) -> 8.0333333
B40: Selected multiple for the segment | D40: =Inputs!$G$8 -> 7.5
B41: Selected versus median | D41: =Peers!$D$40/Peers!$D$38-1 -> -0.18918919
B43: OIL AND GAS (E&P)
B44: Ticker | C44: Company | D44: EV / EBITDA | E44: Included | F44: If included | G44: Note
...

Sheet SOTP
B1: Reliance Industries — Sum-of-the-Parts Valuation | I1: RELIANCE INDUSTRIES
B2: Segment enterprise values, RIL's share, net debt, discount and value per share
B4: SEGMENT VALUES (₹ crore)
B5: Segment | C5: EBITDA FY26 | D5: Multiple | E5: Segment EV | F5: RIL stake | G5: RIL share of EV | H5: % of gross | I5: Per share (₹)
B6: Digital Services (Jio Platforms) | C6: =Inputs!$D$6 -> 76560 | D6: =Inputs!$G$6 -> 12 | E6: =C6*D6 -> 918720 | F6: =Inputs!$F$6 -> 0.6703 | G6: =E6*F6 -> 615818.02 | H6: =G6/SOTP!$G$11 -> 0.33312471 | I6: =G6/Inputs!$C$26 -> 455.06596
B7: Retail (Reliance Retail Ventures) | C7: =Inputs!$D$7 -> 27034 | D7: =Inputs!$G$7 -> 25 | E7: =C7*D7 -> 675850 | F7: =Inputs!$F$7 -> 0.8506 | G7: =E7*F7 -> 574878.01 | H7: =G7/SOTP!$G$11 -> 0.31097835 | I7: =G7/Inputs!$C$26 -> 424.81287
B8: Oil to Chemicals | C8: =Inputs!$D$8 -> 60546 | D8: =Inputs!$G$8 -> 7.5 | E8: =C8*D8 -> 454095 | F8: =Inputs!$F$8 -> 1 | G8: =E8*F8 -> 454095 | H8: =G8/SOTP!$G$11 -> 0.24564118 | I8: =G8/Inputs!$C$26 -> 335.55884
B9: Oil and Gas (E&P) | C9: =Inputs!$D$9 -> 19050 | D9: =Inputs!$G$9 -> 5 | E9: =C9*D9 -> 95250 | F9: =Inputs!$F$9 -> 1 | G9: =E9*F9 -> 95250 | H9: =G9/SOTP!$G$11 -> 0.051525171 | I9: =G9/Inputs!$C$26 -> 70.386108
B10: Others (media, consumer brands, new energy) | C10: =Inputs!$D$10 -> 10857 | D10: =Inputs!$G$10 -> 10 | E10: =C10*D10 -> 108570 | F10: =Inputs!$F$10 -> 1 | G10: =E10*F10 -> 108570 | H10: =G10/SOTP!$G$11 -> 0.058730581 | I10: =G10/Inputs!$C$26 -> 80.229078
B11: Gross asset value (RIL share) | G11: =SUM(G6:G10) -> 1848611 | I11: =SOTP!$G$11/Inputs!$C$26 -> 1366.0529
B13: FROM GROSS ASSET VALUE TO EQUITY VALUE
B14: Less: adjusted net debt | G14: =-Inputs!$C$20 -> -247848
B15: Net asset value before discount | G15: =SOTP!$G$11+SOTP!$G$14 -> 1600763
B16: Less: holding-company discount | G16: =-SOTP!$G$15*Inputs!$C$22 -> -160076.3
B17: Equity value | G17: =SOTP!$G$15+SOTP!$G$16 -> 1440686.7
B19: PER SHARE
B20: Gross asset value per share (₹) | G20: =SOTP!$G$11/Inputs!$C$26 -> 1366.0529
B21: NAV per share before discount (₹) | G21: =SOTP!$G$15/Inputs!$C$26 -> 1182.9027
B22: SOTP value per share (₹) | G22: =SOTP!$G$17/Inputs!$C$26 -> 1064.6124
B23: Share price (₹) | G23: =Inputs!$C$25 -> 1244.6
B24: Upside / (downside) to the SOTP value | G24: =SOTP!$G$22/SOTP!$G$23-1 -> -0.14461482
B25: Implied group EV / segment EBITDA at the SOTP value | G25: =(SOTP!$G$17+Inputs!$C$20)/Inputs!$D$11 -> 8.7016791
B26: Market EV / segment EBITDA today | G26: =(Inputs!$C$27+Inputs!$C$20)/Inputs!$D$11 -> 9.9568813
B27: Implied P/E at the SOTP value | G27: =SOTP!$G$22/Inputs!$C$28 -> 17.835691
B29: Net debt is deducted at group level in full although roughly a third of the spectrum liabilities belong economically to Jio's minority shareholders. The alternative — deducting Jio's own net debt inside the segment before applying the stake — needs Jio's balance sheet, which the results release does not give. The simplification understates value by roughly ₹25 per share and is left in because it errs the right way.

Sheet Market-Implied
B1: Reliance Industries — Sum-of-the-Parts Valuation | F1: RELIANCE INDUSTRIES
B2: Run backwards: what is the market paying for Jio Platforms today?
B4: SOLVE FOR THE JIO MULTIPLE THE SHARE PRICE IMPLIES
B5: Market capitalisation | C5: =Inputs!$C$27 -> 1684254.9
B6: Equity value before discount the market implies (market cap / (1 − discount)) | C6: ='Market-Implied'!$C$5/(1-Inputs!$C$22) -> 1871394.4
B7: Gross asset value the market implies | C7: ='Market-Implied'!$C$6+Inputs!$C$20 -> 2119242.4
B8: Less: RIL's share of the other four segments at base multiples | C8: =-(SOTP!$G$7+SOTP!$G$8+SOTP!$G$9+SOTP!$G$10) -> -1232793
B9: RIL's share of Jio Platforms EV the market implies | C9: ='Market-Implied'!$C$7+'Market-Implied'!$C$8 -> 886449.38
B10: Jio Platforms EV at 100% | C10: ='Market-Implied'!$C$9/Inputs!$F$6 -> 1322466.6
B11: Market-implied Jio EV / EBITDA | C11: ='Market-Implied'!$C$10/Inputs!$D$6 -> 17.273598
B12: Premium to the telecom peer median | C12: ='Market-Implied'!$C$11/Peers!$D$12-1 -> 0.7900101
B13: Premium to Bharti Airtel's multiple | C13: ='Market-Implied'!$C$11/Peers!$D$6-1 -> 0.48910323 | F13: Bharti is the direct listed comparable and the anchor a Jio IPO will be priced against
B14: Market-implied Jio Platforms EV in US$ billion at ₹83.5 | C14: ='Market-Implied'!$C$10/8350 -> 158.37924
B16: THE SAME SOLVE FOR RETAIL
B17: RIL's share of Retail EV the market implies (Jio at base) | C17: ='Market-Implied'!$C$7-(SOTP!$G$6+SOTP!$G$8+SOTP!$G$9+SOTP!$G$10) -> 845509.37
B18: Retail EV at 100% | C18: ='Market-Implied'!$C$17/Inputs!$F$7 -> 994015.25
B19: Market-implied Retail EV / EBITDA | C19: ='Market-Implied'!$C$18/Inputs!$D$7 -> 36.769078
B20: Market-implied Retail EV in US$ billion | C20: ='Market-Implied'!$C$18/8350 -> 119.04374 | F20: The 2023 private round valued Reliance Retail Ventures at roughly US$100 billion
B22: Only one segment can be solved for at a time; each solve holds the other four at their base multiples. The Jio solve is the useful one because Jio is about to be priced by a public market, and the gap between this number and the eventual listing multiple is the size of the re-rating the sell-side is arguing about.

Sheet Sensitivity
B1: Reliance Industries — Sum-of-the-Parts Valuation | H1: RELIANCE INDUSTRIES
B2: SOTP value per share (₹) — every cell rebuilds the full bridge
B4: JIO MULTIPLE (rows) versus RETAIL MULTIPLE (columns), discount at base
B5: ↓ rows \ columns → | C5: 20 | D5: 22.5 | E5: 25 | F5: 27.5 | G5: 30
B6: 10 | C6: =((Inputs!$D$6*$B6*Inputs!$F$6+Inputs!$D$7*C$5*Inputs!$F$7+Inputs!$D$8*Inputs!$G$8*Inputs!$F$8+Inputs!$D$9*Inputs!$G$9*Inputs!$F$9+Inputs!$D$10*Inputs!$G$10*Inputs!$F$10)-Inputs!$C$20)*(1-Inputs!$C$22)/Inputs!$C$26 -> 919.88618 | D6: =((Inputs!$D$6*$B6*Inputs!$F$6+Inputs!$D$7*D$5*Inputs!$F$7+Inputs!$D$8*Inputs!$G$8*Inputs!$F$8+Inputs!$D$9*Inputs!$G$9*Inputs!$F$9+Inputs!$D$10*Inputs!$G$10*Inputs!$F$10)-Inputs!$C$20)*(1-Inputs!$C$22)/Inputs!$C$26 -> 958.11934 | E6: =((Inputs!$D$6*$B6*Inputs!$F$6+Inputs!$D$7*E$5*Inputs!$F$7+Inputs!$D$8*Inputs!$G$8*Inputs!$F$8+Inputs!$D$9*Inputs!$G$9*Inputs!$F$9+Inputs!$D$10*Inputs!$G$10*Inputs!$F$10)-Inputs!$C$20)*(1-Inputs!$C$22)/Inputs!$C$26 -> 996.3525 | F6: =((Inputs!$D$6*$B6*Inputs!$F$6+Inputs!$D$7*F$5*Inputs!$F$7+Inputs!$D$8*Inputs!$G$8*Inputs!$F$8+Inputs!$D$9*Inputs!$G$9*Inputs!$F$9+Inputs!$D$10*Inputs!$G$10*Inputs!$F$10)-Inputs!$C$20)*(1-Inputs!$C$22)/Inputs!$C$26 -> 1034.5857 | G6: =((Inputs!$D$6*$B6*Inputs!$F$6+Inputs!$D$7*G$5*Inputs!$F$7+Inputs!$D$8*Inputs!$G$8*Inputs!$F$8+Inputs!$D$9*Inputs!$G$9*Inputs!$F$9+Inputs!$D$10*Inputs!$G$10*Inputs!$F$10)-Inputs!$C$20)*(1-Inputs!$C$22)/Inputs!$C$26 -> 1072.8188
B7: 11 | C7: =((Inputs!$D$6*$B7*Inputs!$F$6+Inputs!$D$7*C$5*Inputs!$F$7+Inputs!$D$8*Inputs!$G$8*Inputs!$F$8+Inputs!$D$9*Inputs!$G$9*Inputs!$F$9+Inputs!$D$10*Inputs!$G$10*Inputs!$F$10)-Inputs!$C$20)*(1-Inputs!$C$22)/Inputs!$C$26 -> 954.01613 | D7: =((Inputs!$D$6*$B7*Inputs!$F$6+Inputs!$D$7*D$5*Inputs!$F$7+Inputs!$D$8*Inputs!$G$8*Inputs!$F$8+Inputs!$D$9*Inputs!$G$9*Inputs!$F$9+Inputs!$D$10*Inputs!$G$10*Inputs!$F$10)-Inputs!$C$20)*(1-Inputs!$C$22)/Inputs!$C$26 -> 992.24929 | E7: =((Inputs!$D$6*$B7*Inputs!$F$6+Inputs!$D$7*E$5*Inputs!$F$7+Inputs!$D$8*Inputs!$G$8*Inputs!$F$8+Inputs!$D$9*Inputs!$G$9*Inputs!$F$9+Inputs!$D$10*Inputs!$G$10*Inputs!$F$10)-Inputs!$C$20)*(1-Inputs!$C$22)/Inputs!$C$26 -> 1030.4824 | F7: =((Inputs!$D$6*$B7*Inputs!$F$6+Inputs!$D$7*F$5*Inputs!$F$7+Inputs!$D$8*Inputs!$G$8*Inputs!$F$8+Inputs!$D$9*Inputs!$G$9*Inputs!$F$9+Inputs!$D$10*Inputs!$G$10*Inputs!$F$10)-Inputs!$C$20)*(1-Inputs!$C$22)/Inputs!$C$26 -> 1068.7156 | G7: =((Inputs!$D$6*$B7*Inputs!$F$6+Inputs!$D$7*G$5*Inputs!$F$7+Inputs!$D$8*Inputs!$G$8*Inputs!$F$8+Inputs!$D$9*Inputs!$G$9*Inputs!$F$9+Inputs!$D$10*Inputs!$G$10*Inputs!$F$10)-Inputs!$C$20)*(1-Inputs!$C$22)/Inputs!$C$26 -> 1106.9488
B8: 12 | C8: =((Inputs!$D$6*$B8*Inputs!$F$6+Inputs!$D$7*C$5*Inputs!$F$7+Inputs!$D$8*Inputs!$G$8*Inputs!$F$8+Inputs!$D$9*Inputs!$G$9*Inputs!$F$9+Inputs!$D$10*Inputs!$G$10*Inputs!$F$10)-Inputs!$C$20)*(1-Inputs!$C$22)/Inputs!$C$26 -> 988.14608 | D8: =((Inputs!$D$6*$B8*Inputs!$F$6+Inputs!$D$7*D$5*Inputs!$F$7+Inputs!$D$8*Inputs!$G$8*Inputs!$F$8+Inputs!$D$9*Inputs!$G$9*Inputs!$F$9+Inputs!$D$10*Inputs!$G$10*Inputs!$F$10)-Inputs!$C$20)*(1-Inputs!$C$22)/Inputs!$C$26 -> 1026.3792 | E8: =((Inputs!$D$6*$B8*Inputs!$F$6+Inputs!$D$7*E$5*Inputs!$F$7+Inputs!$D$8*Inputs!$G$8*Inputs!$F$8+Inputs!$D$9*Inputs!$G$9*Inputs!$F$9+Inputs!$D$10*Inputs!$G$10*Inputs!$F$10)-Inputs!$C$20)*(1-Inputs!$C$22)/Inputs!$C$26 -> 1064.6124 | F8: =((Inputs!$D$6*$B8*Inputs!$F$6+Inputs!$D$7*F$5*Inputs!$F$7+Inputs!$D$8*Inputs!$G$8*Inputs!$F$8+Inputs!$D$9*Inputs!$G$9*Inputs!$F$9+Inputs!$D$10*Inputs!$G$10*Inputs!$F$10)-Inputs!$C$20)*(1-Inputs!$C$22)/Inputs!$C$26 -> 1102.8456 | G8: =((Inputs!$D$6*$B8*Inputs!$F$6+Inputs!$D$7*G$5*Inputs!$F$7+Inputs!$D$8*Inputs!$G$8*Inputs!$F$8+Inputs!$D$9*Inputs!$G$9*Inputs!$F$9+Inputs!$D$10*Inputs!$G$10*Inputs!$F$10)-Inputs!$C$20)*(1-Inputs!$C$22)/Inputs!$C$26 -> 1141.0787
B9: 13 | C9: =((Inputs!$D$6*$B9*Inputs!$F$6+Inputs!$D$7*C$5*Inputs!$F$7+Inputs!$D$8*Inputs!$G$8*Inputs!$F$8+Inputs!$D$9*Inputs!$G$9*Inputs!$F$9+Inputs!$D$10*Inputs!$G$10*Inputs!$F$10)-Inputs!$C$20)*(1-Inputs!$C$22)/Inputs!$C$26 -> 1022.276 | D9: =((Inputs!$D$6*$B9*Inputs!$F$6+Inputs!$D$7*D$5*Inputs!$F$7+Inputs!$D$8*Inputs!$G$8*Inputs!$F$8+Inputs!$D$9*Inputs!$G$9*Inputs!$F$9+Inputs!$D$10*Inputs!$G$10*Inputs!$F$10)-Inputs!$C$20)*(1-Inputs!$C$22)/Inputs!$C$26 -> 1060.5092 | E9: =((Inputs!$D$6*$B9*Inputs!$F$6+Inputs!$D$7*E$5*Inputs!$F$7+Inputs!$D$8*Inputs!$G$8*Inputs!$F$8+Inputs!$D$9*Inputs!$G$9*Inputs!$F$9+Inputs!$D$10*Inputs!$G$10*Inputs!$F$10)-Inputs!$C$20)*(1-Inputs!$C$22)/Inputs!$C$26 -> 1098.7423 | F9: =((Inputs!$D$6*$B9*Inputs!$F$6+Inputs!$D$7*F$5*Inputs!$F$7+Inputs!$D$8*Inputs!$G$8*Inputs!$F$8+Inputs!$D$9*Inputs!$G$9*Inputs!$F$9+Inputs!$D$10*Inputs!$G$10*Inputs!$F$10)-Inputs!$C$20)*(1-Inputs!$C$22)/Inputs!$C$26 -> 1136.9755 | G9: =((Inputs!$D$6*$B9*Inputs!$F$6+Inputs!$D$7*G$5*Inputs!$F$7+Inputs!$D$8*Inputs!$G$8*Inputs!$F$8+Inputs!$D$9*Inputs!$G$9*Inputs!$F$9+Inputs!$D$10*Inputs!$G$10*Inputs!$F$10)-Inputs!$C$20)*(1-Inputs!$C$22)/Inputs!$C$26 -> 1175.2087
B10: 14 | C10: =((Inputs!$D$6*$B10*Inputs!$F$6+Inputs!$D$7*C$5*Inputs!$F$7+Inputs!$D$8*Inputs!$G$8*Inputs!$F$8+Inputs!$D$9*Inputs!$G$9*Inputs!$F$9+Inputs!$D$10*Inputs!$G$10*Inputs!$F$10)-Inputs!$C$20)*(1-Inputs!$C$22)/Inputs!$C$26 -> 1056.406 | D10: =((Inputs!$D$6*$B10*Inputs!$F$6+Inputs!$D$7*D$5*Inputs!$F$7+Inputs!$D$8*Inputs!$G$8*Inputs!$F$8+Inputs!$D$9*Inputs!$G$9*Inputs!$F$9+Inputs!$D$10*Inputs!$G$10*Inputs!$F$10)-Inputs!$C$20)*(1-Inputs!$C$22)/Inputs!$C$26 -> 1094.6391 | E10: =((Inputs!$D$6*$B10*Inputs!$F$6+Inputs!$D$7*E$5*Inputs!$F$7+Inputs!$D$8*Inputs!$G$8*Inputs!$F$8+Inputs!$D$9*Inputs!$G$9*Inputs!$F$9+Inputs!$D$10*Inputs!$G$10*Inputs!$F$10)-Inputs!$C$20)*(1-Inputs!$C$22)/Inputs!$C$26 -> 1132.8723 | F10: =((Inputs!$D$6*$B10*Inputs!$F$6+Inputs!$D$7*F$5*Inputs!$F$7+Inputs!$D$8*Inputs!$G$8*Inputs!$F$8+Inputs!$D$9*Inputs!$G$9*Inputs!$F$9+Inputs!$D$10*Inputs!$G$10*Inputs!$F$10)-Inputs!$C$20)*(1-Inputs!$C$22)/Inputs!$C$26 -> 1171.1054 | G10: =((Inputs!$D$6*$B10*Inputs!$F$6+Inputs!$D$7*G$5*Inputs!$F$7+Inputs!$D$8*Inputs!$G$8*Inputs!$F$8+Inputs!$D$9*Inputs!$G$9*Inputs!$F$9+Inputs!$D$10*Inputs!$G$10*Inputs!$F$10)-Inputs!$C$20)*(1-Inputs!$C$22)/Inputs!$C$26 -> 1209.3386
B12: JIO MULTIPLE (rows) versus HOLDING-COMPANY DISCOUNT (columns), Retail at base
B13: ↓ rows \ columns → | C13: 0 | D13: 0.05 | E13: 0.1 | F13: 0.15 | G13: 0.2
B14: 10 | C14: =((Inputs!$D$6*$B14*Inputs!$F$6+Inputs!$D$7*Inputs!$G$7*Inputs!$F$7+Inputs!$D$8*Inputs!$G$8*Inputs!$F$8+Inputs!$D$9*Inputs!$G$9*Inputs!$F$9+Inputs!$D$10*Inputs!$G$10*Inputs!$F$10)-Inputs!$C$20)*(1-C$13)/Inputs!$C$26 -> 1107.0583 | D14: =((Inputs!$D$6*$B14*Inputs!$F$6+Inputs!$D$7*Inputs!$G$7*Inputs!$F$7+Inputs!$D$8*Inputs!$G$8*Inputs!$F$8+Inputs!$D$9*Inputs!$G$9*Inputs!$F$9+Inputs!$D$10*Inputs!$G$10*Inputs!$F$10)-Inputs!$C$20)*(1-D$13)/Inputs!$C$26 -> 1051.7054 | E14: =((Inputs!$D$6*$B14*Inputs!$F$6+Inputs!$D$7*Inputs!$G$7*Inputs!$F$7+Inputs!$D$8*Inputs!$G$8*Inputs!$F$8+Inputs!$D$9*Inputs!$G$9*Inputs!$F$9+Inputs!$D$10*Inputs!$G$10*Inputs!$F$10)-Inputs!$C$20)*(1-E$13)/Inputs!$C$26 -> 996.3525 | F14: =((Inputs!$D$6*$B14*Inputs!$F$6+Inputs!$D$7*Inputs!$G$7*Inputs!$F$7+Inputs!$D$8*Inputs!$G$8*Inputs!$F$8+Inputs!$D$9*Inputs!$G$9*Inputs!$F$9+Inputs!$D$10*Inputs!$G$10*Inputs!$F$10)-Inputs!$C$20)*(1-F$13)/Inputs!$C$26 -> 940.99958 | G14: =((Inputs!$D$6*$B14*Inputs!$F$6+Inputs!$D$7*Inputs!$G$7*Inputs!$F$7+Inputs!$D$8*Inputs!$G$8*Inputs!$F$8+Inputs!$D$9*Inputs!$G$9*Inputs!$F$9+Inputs!$D$10*Inputs!$G$10*Inputs!$F$10)-Inputs!$C$20)*(1-G$13)/Inputs!$C$26 -> 885.64667
B15: 11 | C15: =((Inputs!$D$6*$B15*Inputs!$F$6+Inputs!$D$7*Inputs!$G$7*Inputs!$F$7+Inputs!$D$8*Inputs!$G$8*Inputs!$F$8+Inputs!$D$9*Inputs!$G$9*Inputs!$F$9+Inputs!$D$10*Inputs!$G$10*Inputs!$F$10)-Inputs!$C$20)*(1-C$13)/Inputs!$C$26 -> 1144.9805 | D15: =((Inputs!$D$6*$B15*Inputs!$F$6+Inputs!$D$7*Inputs!$G$7*Inputs!$F$7+Inputs!$D$8*Inputs!$G$8*Inputs!$F$8+Inputs!$D$9*Inputs!$G$9*Inputs!$F$9+Inputs!$D$10*Inputs!$G$10*Inputs!$F$10)-Inputs!$C$20)*(1-D$13)/Inputs!$C$26 -> 1087.7315 | E15: =((Inputs!$D$6*$B15*Inputs!$F$6+Inputs!$D$7*Inputs!$G$7*Inputs!$F$7+Inputs!$D$8*Inputs!$G$8*Inputs!$F$8+Inputs!$D$9*Inputs!$G$9*Inputs!$F$9+Inputs!$D$10*Inputs!$G$10*Inputs!$F$10)-Inputs!$C$20)*(1-E$13)/Inputs!$C$26 -> 1030.4824 | F15: =((Inputs!$D$6*$B15*Inputs!$F$6+Inputs!$D$7*Inputs!$G$7*Inputs!$F$7+Inputs!$D$8*Inputs!$G$8*Inputs!$F$8+Inputs!$D$9*Inputs!$G$9*Inputs!$F$9+Inputs!$D$10*Inputs!$G$10*Inputs!$F$10)-Inputs!$C$20)*(1-F$13)/Inputs!$C$26 -> 973.23342 | G15: =((Inputs!$D$6*$B15*Inputs!$F$6+Inputs!$D$7*Inputs!$G$7*Inputs!$F$7+Inputs!$D$8*Inputs!$G$8*Inputs!$F$8+Inputs!$D$9*Inputs!$G$9*Inputs!$F$9+Inputs!$D$10*Inputs!$G$10*Inputs!$F$10)-Inputs!$C$20)*(1-G$13)/Inputs!$C$26 -> 915.9844
B16: 12 | C16: =((Inputs!$D$6*$B16*Inputs!$F$6+Inputs!$D$7*Inputs!$G$7*Inputs!$F$7+Inputs!$D$8*Inputs!$G$8*Inputs!$F$8+Inputs!$D$9*Inputs!$G$9*Inputs!$F$9+Inputs!$D$10*Inputs!$G$10*Inputs!$F$10)-Inputs!$C$20)*(1-C$13)/Inputs!$C$26 -> 1182.9027 | D16: =((Inputs!$D$6*$B16*Inputs!$F$6+Inputs!$D$7*Inputs!$G$7*Inputs!$F$7+Inputs!$D$8*Inputs!$G$8*Inputs!$F$8+Inputs!$D$9*Inputs!$G$9*Inputs!$F$9+Inputs!$D$10*Inputs!$G$10*Inputs!$F$10)-Inputs!$C$20)*(1-D$13)/Inputs!$C$26 -> 1123.7575 | E16: =((Inputs!$D$6*$B16*Inputs!$F$6+Inputs!$D$7*Inputs!$G$7*Inputs!$F$7+Inputs!$D$8*Inputs!$G$8*Inputs!$F$8+Inputs!$D$9*Inputs!$G$9*Inputs!$F$9+Inputs!$D$10*Inputs!$G$10*Inputs!$F$10)-Inputs!$C$20)*(1-E$13)/Inputs!$C$26 -> 1064.6124 | F16: =((Inputs!$D$6*$B16*Inputs!$F$6+Inputs!$D$7*Inputs!$G$7*Inputs!$F$7+Inputs!$D$8*Inputs!$G$8*Inputs!$F$8+Inputs!$D$9*Inputs!$G$9*Inputs!$F$9+Inputs!$D$10*Inputs!$G$10*Inputs!$F$10)-Inputs!$C$20)*(1-F$13)/Inputs!$C$26 -> 1005.4673 | G16: =((Inputs!$D$6*$B16*Inputs!$F$6+Inputs!$D$7*Inputs!$G$7*Inputs!$F$7+Inputs!$D$8*Inputs!$G$8*Inputs!$F$8+Inputs!$D$9*Inputs!$G$9*Inputs!$F$9+Inputs!$D$10*Inputs!$G$10*Inputs!$F$10)-Inputs!$C$20)*(1-G$13)/Inputs!$C$26 -> 946.32213
B17: 13 | C17: =((Inputs!$D$6*$B17*Inputs!$F$6+Inputs!$D$7*Inputs!$G$7*Inputs!$F$7+Inputs!$D$8*Inputs!$G$8*Inputs!$F$8+Inputs!$D$9*Inputs!$G$9*Inputs!$F$9+Inputs!$D$10*Inputs!$G$10*Inputs!$F$10)-Inputs!$C$20)*(1-C$13)/Inputs!$C$26 -> 1220.8248 | D17: =((Inputs!$D$6*$B17*Inputs!$F$6+Inputs!$D$7*Inputs!$G$7*Inputs!$F$7+Inputs!$D$8*Inputs!$G$8*Inputs!$F$8+Inputs!$D$9*Inputs!$G$9*Inputs!$F$9+Inputs!$D$10*Inputs!$G$10*Inputs!$F$10)-Inputs!$C$20)*(1-D$13)/Inputs!$C$26 -> 1159.7836 | E17: =((Inputs!$D$6*$B17*Inputs!$F$6+Inputs!$D$7*Inputs!$G$7*Inputs!$F$7+Inputs!$D$8*Inputs!$G$8*Inputs!$F$8+Inputs!$D$9*Inputs!$G$9*Inputs!$F$9+Inputs!$D$10*Inputs!$G$10*Inputs!$F$10)-Inputs!$C$20)*(1-E$13)/Inputs!$C$26 -> 1098.7423 | F17: =((Inputs!$D$6*$B17*Inputs!$F$6+Inputs!$D$7*Inputs!$G$7*Inputs!$F$7+Inputs!$D$8*Inputs!$G$8*Inputs!$F$8+Inputs!$D$9*Inputs!$G$9*Inputs!$F$9+Inputs!$D$10*Inputs!$G$10*Inputs!$F$10)-Inputs!$C$20)*(1-F$13)/Inputs!$C$26 -> 1037.7011 | G17: =((Inputs!$D$6*$B17*Inputs!$F$6+Inputs!$D$7*Inputs!$G$7*Inputs!$F$7+Inputs!$D$8*Inputs!$G$8*Inputs!$F$8+Inputs!$D$9*Inputs!$G$9*Inputs!$F$9+Inputs!$D$10*Inputs!$G$10*Inputs!$F$10)-Inputs!$C$20)*(1-G$13)/Inputs!$C$26 -> 976.65986
B18: 14 | C18: =((Inputs!$D$6*$B18*Inputs!$F$6+Inputs!$D$7*Inputs!$G$7*Inputs!$F$7+Inputs!$D$8*Inputs!$G$8*Inputs!$F$8+Inputs!$D$9*Inputs!$G$9*Inputs!$F$9+Inputs!$D$10*Inputs!$G$10*Inputs!$F$10)-Inputs!$C$20)*(1-C$13)/Inputs!$C$26 -> 1258.747 | D18: =((Inputs!$D$6*$B18*Inputs!$F$6+Inputs!$D$7*Inputs!$G$7*Inputs!$F$7+Inputs!$D$8*Inputs!$G$8*Inputs!$F$8+Inputs!$D$9*Inputs!$G$9*Inputs!$F$9+Inputs!$D$10*Inputs!$G$10*Inputs!$F$10)-Inputs!$C$20)*(1-D$13)/Inputs!$C$26 -> 1195.8096 | E18: =((Inputs!$D$6*$B18*Inputs!$F$6+Inputs!$D$7*Inputs!$G$7*Inputs!$F$7+Inputs!$D$8*Inputs!$G$8*Inputs!$F$8+Inputs!$D$9*Inputs!$G$9*Inputs!$F$9+Inputs!$D$10*Inputs!$G$10*Inputs!$F$10)-Inputs!$C$20)*(1-E$13)/Inputs!$C$26 -> 1132.8723 | F18: =((Inputs!$D$6*$B18*Inputs!$F$6+Inputs!$D$7*Inputs!$G$7*Inputs!$F$7+Inputs!$D$8*Inputs!$G$8*Inputs!$F$8+Inputs!$D$9*Inputs!$G$9*Inputs!$F$9+Inputs!$D$10*Inputs!$G$10*Inputs!$F$10)-Inputs!$C$20)*(1-F$13)/Inputs!$C$26 -> 1069.9349 | G18: =((Inputs!$D$6*$B18*Inputs!$F$6+Inputs!$D$7*Inputs!$G$7*Inputs!$F$7+Inputs!$D$8*Inputs!$G$8*Inputs!$F$8+Inputs!$D$9*Inputs!$G$9*Inputs!$F$9+Inputs!$D$10*Inputs!$G$10*Inputs!$F$10)-Inputs!$C$20)*(1-G$13)/Inputs!$C$26 -> 1006.9976
B20: LOW / BASE / HIGH ON EVERY SEGMENT AT ONCE
B21: All segments at the low multiple (₹ per share) | C21: =((Inputs!$D$6*Inputs!$H$6*Inputs!$F$6+Inputs!$D$7*Inputs!$H$7*Inputs!$F$7+Inputs!$D$8*Inputs!$H$8*Inputs!$F$8+Inputs!$D$9*Inputs!$H$9*Inputs!$F$9+Inputs!$D$10*Inputs!$H$10*Inputs!$F$10)-Inputs!$C$20)*(1-Inputs!$C$22)/Inputs!$C$26 -> 852.50839
B22: All segments at the high multiple (₹ per share) | C22: =((Inputs!$D$6*Inputs!$I$6*Inputs!$F$6+Inputs!$D$7*Inputs!$I$7*Inputs!$F$7+Inputs!$D$8*Inputs!$I$8*Inputs!$F$8+Inputs!$D$9*Inputs!$I$9*Inputs!$F$9+Inputs!$D$10*Inputs!$I$10*Inputs!$F$10)-Inputs!$C$20)*(1-Inputs!$C$22)/Inputs!$C$26 -> 1276.7164
B23: All segments at the base multiple (₹ per share) | C23: =SOTP!$G$22 -> 1064.6124

Sheet Summary
B1: Reliance Industries — Sum-of-the-Parts Valuation | F1: RELIANCE INDUSTRIES
B2: The sum of the parts on one page
B4: THE PARTS
B5: Digital Services (Jio Platforms) — RIL share (₹ crore) | C5: =SOTP!$G$6 -> 615818.02
B6: Retail (Reliance Retail Ventures) — RIL share (₹ crore) | C6: =SOTP!$G$7 -> 574878.01
B7: Oil to Chemicals — RIL share (₹ crore) | C7: =SOTP!$G$8 -> 454095
B8: Oil and Gas (E&P) — RIL share (₹ crore) | C8: =SOTP!$G$9 -> 95250
B9: Others (media, consumer brands, new energy) — RIL share (₹ crore) | C9: =SOTP!$G$10 -> 108570
B10: Gross asset value (₹ crore) | C10: =SOTP!$G$11 -> 1848611
B11: Less: adjusted net debt | C11: =SOTP!$G$14 -> -247848
B12: Less: holding-company discount | C12: =SOTP!$G$16 -> -160076.3
B13: Equity value (₹ crore) | C13: =SOTP!$G$17 -> 1440686.7
B15: PER SHARE
B16: SOTP value per share (₹) | C16: =SOTP!$G$22 -> 1064.6124
B17: Range, all segments low to high (₹) | C17: =TEXT(Sensitivity!$C$21,"#,##0")&" – "&TEXT(Sensitivity!$C$22,"#,##0") -> 853 – 1,277
B18: Share price (₹) | C18: =SOTP!$G$23 -> 1244.6
B19: Upside / (downside) | C19: =SOTP!$G$24 -> -0.14461482
B21: WHAT THE MARKET IS PAYING FOR JIO
B22: Market-implied Jio EV / EBITDA | C22: ='Market-Implied'!$C$11 -> 17.273598
B23: Market-implied Jio EV (US$ billion) | C23: ='Market-Implied'!$C$14 -> 158.37924
B24: Selected Jio multiple in the SOTP | C24: =Inputs!$G$6 -> 12
B25: Premium to Bharti Airtel implied by the price | C25: ='Market-Implied'!$C$13 -> 0.48910323
B27: • Jio and Retail together are roughly two-thirds of gross asset value; the energy businesses that generate over 40% of EBITDA are worth well under a third of it. That is the whole investment case for the group's last decade in one line.
B28: • At peer multiples the SOTP sits below the share price, not above it. Run backwards, the price is consistent with Jio Platforms at roughly 17x EBITDA — a premium of about half to Bharti Airtel — or, equivalently, with Retail near 40x. The market has already priced a Jio listing at a premium; the IPO is the event that tests whether it is right.
B29: • The holding-company discount is the single largest judgement after the Jio multiple. Each five points is worth about ₹90 per share, which is the second sensitivity grid.
B30: • The energy segments are valued on peer multiples rather than through the cycle. O2C EBITDA in FY2026 was helped by strong middle-distillate cracks; a mid-cycle number would take ₹30–40 per share off the total.

Sheet Checks
B1: Reliance Industries — Sum-of-the-Parts Valuation | E1: RELIANCE INDUSTRIES
B2: Every check must read TRUE
B4: INTEGRITY CHECKS
B5: Segment EBITDA total ties to the published ₹194,047 crore | C5: =ABS(Inputs!$D$11-194047)<1 -> TRUE
B6: FY2025 segment total ties to the published ₹174,797 crore | C6: =ABS(Inputs!$C$11-174797)<1 -> TRUE
B7: Segment EBITDA is below reported consolidated EBITDA (unallocated items excluded) | C7: =Inputs!$D$11<Inputs!$C$15 -> TRUE
B8: Adjusted net debt matches Project 8 | C8: =ABS(Inputs!$C$20-247848)<1 -> TRUE
B9: Every stake is between 50% and 100% | C9: =AND(Inputs!$F$6>0.5,Inputs!$F$6<=1,Inputs!$F$7>0.5,Inputs!$F$7<=1,Inputs!$F$8>0.5,Inputs!$F$8<=1,Inputs!$F$9>0.5,Inputs!$F$9<=1,Inputs!$F$10>0.5,Inputs!$F$10<=1) -> TRUE
B10: Every base multiple lies within its low–high range | C10: =AND(Inputs!$G$6>=Inputs!$H$6,Inputs!$G$6<=Inputs!$I$6,Inputs!$G$7>=Inputs!$H$7,Inputs!$G$7<=Inputs!$I$7,Inputs!$G$8>=Inputs!$H$8,Inputs!$G$8<=Inputs!$I$8,Inputs!$G$9>=Inputs!$H$9,Inputs!$G$9<=Inputs!$I$9,Inputs!$G$10>=Inputs!$H$10,Inputs!$G$10<=Inputs!$I$10) -> TRUE
B11: Segment shares of gross value sum to 100% | C11: =ABS(SUM(SOTP!H6:H10)-1)<0.0001 -> TRUE
B12: Equity value equals NAV less discount | C12: =ABS(SOTP!$G$17-SOTP!$G$15*(1-Inputs!$C$22))<0.01 -> TRUE
B13: Per-share value reconciles to equity value over shares | C13: =ABS(SOTP!$G$22-SOTP!$G$17/Inputs!$C$26)<0.01 -> TRUE
B14: Base sensitivity cell reconciles to the SOTP sheet | C14: =ABS(Sensitivity!E8-SOTP!$G$22)<0.5 -> TRUE
B15: Low case is below base and base is below high | C15: =AND(Sensitivity!$C$21<SOTP!$G$22,SOTP!$G$22<Sensitivity!$C$22) -> TRUE
B16: Market-implied Jio multiple reproduces the share price when substituted | C16: =ABS((Inputs!$D$6*'Market-Implied'!$C$11*Inputs!$F$6+(SOTP!$G$7+SOTP!$G$8+SOTP!$G$9+SOTP!$G$10)-Inputs!$C$20)*(1-Inputs!$C$22)/Inputs!$C$26-Inputs!$C$25)<0.5 -> TRUE
B17: Every peer median evaluates to a number | C17: =AND(ISNUMBER(Peers!$D$12),ISNUMBER(Peers!$D$24),ISNUMBER(Peers!$D$38),ISNUMBER(Peers!$D$51),ISNUMBER(Peers!$D$62)) -> TRUE
B18: Every selected multiple lies within 50% of its peer median | C18: =AND(ABS(Peers!$D$15)<=0.5,ABS(Peers!$D$27)<=0.5,ABS(Peers!$D$41)<=0.5,ABS(Peers!$D$54)<=0.5,ABS(Peers!$D$65)<=0.5) -> TRUE
B19: The Bharti Airtel reference cell on the Peers sheet is Bharti | C19: =Peers!$B$6="BHARTIARTL.NS" -> TRUE
B20: Share price lies within the 52-week range | C20: =AND(Inputs!$C$25>=Inputs!$C$29-1,Inputs!$C$25<=Inputs!$C$30+1) -> TRUE
B22: MODEL STATUS | C22: =IF(COUNTIF(C5:C20,FALSE())=0,"MODEL OK","CHECK FAILED") -> MODEL OK
B24: The twelfth check is the important one: it substitutes the market-implied Jio multiple back into the full bridge and demands the share price come out, which proves the reverse solve is the exact inverse of the forward model.
