Workbook

Sheet Cover
B3: IB PORTFOLIO · PROJECT 12 OF 20
B4: Saudi Aramco
B5: Energy NAV and Price-Deck Sensitivity
B6: Tadawul: 2222 · US$ billions · per-share values in SAR · as of FY2025 annual report · market data 18 Sep 2026
B9: What this is | C9: A reserves-based net asset value of Saudi Aramco on the FY2025 annual report and 18 September 2026 market data, built under the Kingdom's fiscal terms — the sliding crude royalty and the 50% upstream income tax — with the whole company run across a Brent price deck to find the oil price the share price implies and the price at which the base dividend stops being covered.
B11: How it is built | C11: • A per-boe netback: blended realisation, the published royalty schedule applied to crude, cash costs, sustaining capex and tax; multiplied by annual production and capitalised over the 52-year reserve life as an annuity.
C12: • Downstream at a multiple of adjusted EBIT plus depreciation; corporate costs capitalised; net debt and minorities deducted.
C13: • A price deck from US$50 to US$110 with group free cash flow and dividend cover at each level, and closed-form solves for the dividend break-even and the price-implied Brent, each verified by substitution.
C14: • A calibration check that rebuilds reported FY2025 free cash flow from the netback, and two sensitivity grids.
B16: Contents | C16: Summary — netback, NAV, dividend
C17: Fiscal Terms — royalty schedule, tax rates, government take per marginal dollar
C18: NAV — netback per boe, upstream annuity, downstream, value per share
C19: Price Deck — the company across Brent; dividend cover; break-evens; price-implied Brent
C20: Sensitivity — Brent against discount rate and against sustaining capex
C21: Inputs — FY2025 figures, reserves, balance sheet, market data, assumptions
C22: Checks — fifteen tests; must read MODEL OK
B24: Key outputs (live) | C24: After-tax netback per boe at US$70 (US$) | E24: =NAV!$C$11 -> 20.205426
C25: NAV per share (SAR) | E25: =NAV!$C$31 -> 18.058241
C26: Share price (SAR) | E26: =NAV!$C$32 -> 25.56
C27: Brent the price implies at 8% (US$/bbl) | E27: ='Price Deck'!$C$22 -> 118.40225
C28: Base dividend cover at US$70 | E28: ='Price Deck'!$E$11 -> 1.03144
C29: Discount rate the price implies at US$70 | E29: ='Price Deck'!$C$23 -> 0.056881591
B31: Colour code | C31: Blue = hard-coded input
C32: Black = formula
C33: Green = link to another sheet
C34: Accent fill = scenario selector / key levers
B36: Sources | C36: Saudi Aramco Annual Report 2025 and fourth-quarter and full-year 2025 results (year to 31 December 2025): production, reserves, realised price, segment adjusted EBIT, capital expenditure, free cash flow and dividends.
C37: Balance sheet and income statement in SAR via Yahoo Finance for 2222.SR; converted at the 3.75 peg. Share price: Tadawul close, 18 September 2026.
C38: Royalty schedule and tax rates as published by the Kingdom in 2020. Costs, gas realisation, discount rate, downstream multiple and corporate costs are stated inputs.
C39: Nothing here is a recommendation. The valuation is an analytical exercise on public information.
B41: Prepared by | C41: Jainam Mehta · github.com/jainammehta1215/ib-portfolio

Sheet Inputs
B1: Saudi Aramco — Energy NAV and Price-Deck Sensitivity | F1: SAUDI ARAMCO
B2: Reported FY2025 figures, reserves and production, market data and stated assumptions
B4: REPORTED FY2025
B5: SAR per US$ (peg) | C5: 3.75
B6: Revenue (US$ bn) | C6: =1671.2/Inputs!$C$5 -> 445.65333
B7: Net income (US$ bn) | C7: =348/Inputs!$C$5 -> 92.8
B8: Upstream adjusted EBIT (US$ bn) | C8: 195.5
B9: Downstream adjusted EBIT (US$ bn) | C9: 10 | F9: Up more than four times on record refining throughput and SABIC synergies
B10: Capital expenditure (US$ bn) | C10: 52.2 | F10: 2026 guidance US$50–55bn; 65–70% upstream
B11: Free cash flow (US$ bn) | C11: 85.4
B12: Dividends paid (US$ bn) | C12: 85
B13: Annualised base dividend after the Q4 2025 increase (US$ bn) | C13: 87.5 | F13: Q4 2025 base dividend of US$21.9bn, times four; the performance-linked dividend is on top and discretionary
B14: Average realised crude price (US$/bbl) | C14: 69.2
B16: RESERVES AND PRODUCTION
B17: Proved reserves (billion boe) | C17: 247.2
B18: Total hydrocarbon production (mmboed) | C18: 12.9
B19: of which liquids (mmbpd) | C19: 10.7
B20: of which gas and NGL (mmboed) | C20: =Inputs!$C$18-Inputs!$C$19 -> 2.2
B21: Annual production (billion boe) | C21: =Inputs!$C$18*365/1000 -> 4.7085
B22: Reserve life at current production (years) | C22: =Inputs!$C$17/Inputs!$C$21 -> 52.500796
B24: BALANCE SHEET, 31 DECEMBER 2025 (US$ bn)
B25: Borrowings | C25: =363.6/Inputs!$C$5 -> 96.96
B26: Cash and cash equivalents | C26: =243.1/Inputs!$C$5 -> 64.826667
B27: Net debt | C27: =Inputs!$C$25-Inputs!$C$26 -> 32.133333
B28: Non-controlling interests at book | C28: =229.7/Inputs!$C$5 -> 61.253333 | F28: SABIC minorities, the pipeline lease vehicles and Jafurah midstream
B29: Equity attributable to shareholders | C29: =1492/Inputs!$C$5 -> 397.86667
B31: MARKET DATA
B32: Share price (SAR, Tadawul close 18 Sep 2026) | C32: 25.56
B33: Shares outstanding (billions) | C33: 241.9074
B34: Market capitalisation (US$ bn) | C34: =Inputs!$C$32*Inputs!$C$33/Inputs!$C$5 -> 1648.8408
B35: Enterprise value (US$ bn) | C35: =Inputs!$C$34+Inputs!$C$27+Inputs!$C$28 -> 1742.2275
B36: Base dividend yield at the price | C36: =Inputs!$C$13/Inputs!$C$34 -> 0.053067584
B38: VALUATION ASSUMPTIONS — stated inputs
B39: Base-case Brent (US$/bbl, flat) | C39: 70 | F39: Close to the FY2025 realisation; a flat deck, not a forecast
B40: Realised liquids price relative to Brent (US$/bbl) | C40: 0
B41: Gas and NGL realisation (US$/boe) | C41: 15 | F41: Domestic gas is regulated at roughly US$1.75/mmBtu; NGL exports lift the blend
B42: Lifting and other cash costs (US$/boe) | C42: 4 | F42: Aramco discloses upstream lifting cost near US$3/boe; the rest is SG&A and exploration
B43: Sustaining upstream capital expenditure (US$/boe) | C43: 7.5 | F43: Two-thirds of the US$52bn programme over 4.7bn boe
B44: Discount rate | C44: 0.08 | F44: Nominal, against a flat nominal price deck; conservative by construction
B45: Downstream depreciation (US$ bn) | C45: 10 | F45: Roughly two-fifths of group D&A
...

Sheet Fiscal Terms
B1: Saudi Aramco — Energy NAV and Price-Deck Sensitivity | F1: SAUDI ARAMCO
B2: The state's take: a sliding royalty on crude and a 50% upstream income tax
B4: ROYALTY SCHEDULE ON CRUDE (marginal rates, published 2020)
B5: Rate on the price up to the first threshold | C5: 0.15
B6: First threshold (US$/bbl) | C6: 70
B7: Rate between the first and second thresholds | C7: 0.45
B8: Second threshold (US$/bbl) | C8: 100
B9: Rate above the second threshold | C9: 0.8
B10: Upstream income tax rate | C10: 0.5
B11: Downstream income tax rate | C11: 0.2 | F11: Reduced from 50% to 20% for domestic downstream in 2020 to encourage integration
B13: ROYALTY PER BARREL AT THE BASE-CASE PRICE
B14: Liquids price (US$/bbl) | C14: =Inputs!$C$39+Inputs!$C$40 -> 70
B15: Royalty per barrel (US$) | C15: =MIN('Fiscal Terms'!$C$14,'Fiscal Terms'!$C$6)*'Fiscal Terms'!$C$5+MAX(0,MIN('Fiscal Terms'!$C$14,'Fiscal Terms'!$C$8)-'Fiscal Terms'!$C$6)*'Fiscal Terms'!$C$7+MAX(0,'Fiscal Terms'!$C$14-'Fiscal Terms'!$C$8)*'Fiscal Terms'!$C$9 -> 10.5
B16: Effective royalty rate | C16: ='Fiscal Terms'!$C$15/'Fiscal Terms'!$C$14 -> 0.15
B17: Government take on an incremental dollar above US$100 | C17: ='Fiscal Terms'!$C$9+(1-'Fiscal Terms'!$C$9)*'Fiscal Terms'!$C$10 -> 0.9 | F17: Ninety cents of every dollar above US$100 goes to the state. Aramco's equity has very little exposure to a spike
B18: Government take on an incremental dollar between US$70 and US$100 | C18: ='Fiscal Terms'!$C$7+(1-'Fiscal Terms'!$C$7)*'Fiscal Terms'!$C$10 -> 0.725
B19: Government take on an incremental dollar below US$70 | C19: ='Fiscal Terms'!$C$5+(1-'Fiscal Terms'!$C$5)*'Fiscal Terms'!$C$10 -> 0.575
B20: The schedule is what makes Aramco's cash flow so much less sensitive to oil than an international major's. Below US$70 the company keeps 42.5 cents of a marginal dollar; between US$70 and US$100 it keeps 27.5 cents; above US$100 it keeps ten. The price-deck grid on the Price Deck sheet is the direct consequence.

Sheet NAV
B1: Saudi Aramco — Energy NAV and Price-Deck Sensitivity | F1: SAUDI ARAMCO
B2: Per-barrel netback, upstream annuity, downstream multiple, and value per share
B4: UPSTREAM NETBACK PER BARREL OF OIL EQUIVALENT (US$)
B5: Blended realisation: liquids at the Brent-linked price, gas at its realisation | C5: =(Inputs!$C$19*'Fiscal Terms'!$C$14+Inputs!$C$20*Inputs!$C$41)/Inputs!$C$18 -> 60.620155
B6: Less: royalty (crude only, spread over all boe) | C6: =-'Fiscal Terms'!$C$15*Inputs!$C$19/Inputs!$C$18 -> -8.7093023
B7: Less: cash operating costs | C7: =-Inputs!$C$42 -> -4
B8: Less: sustaining capital expenditure | C8: =-Inputs!$C$43 -> -7.5
B9: Pre-tax cash netback | C9: =SUM(C5:C8) -> 40.410853
B10: Less: income tax at 50% | C10: =-NAV!$C$9*'Fiscal Terms'!$C$10 -> -20.205426
B11: After-tax cash netback per boe | C11: =NAV!$C$9+NAV!$C$10 -> 20.205426
B12: Share of the blended realisation Aramco keeps | C12: =NAV!$C$11/NAV!$C$5 -> 0.33331202
B14: UPSTREAM VALUE
B15: Upstream free cash flow per year (US$ bn) | C15: =NAV!$C$11*Inputs!$C$21 -> 95.13725
B16: Annuity factor over the reserve life at the discount rate | C16: =(1-(1+Inputs!$C$44)^-Inputs!$C$22)/Inputs!$C$44 -> 12.280145 | F16: Flat production, flat price. A 52-year annuity at 8% is worth 98% of a perpetuity; the tail barely matters
B17: Upstream value (US$ bn) | C17: =NAV!$C$15*NAV!$C$16 -> 1168.2992
B18: implied value per boe of proved reserves (US$) | C18: =NAV!$C$17/Inputs!$C$17 -> 4.7261296 | F18: International majors are typically valued at US$8–15 per boe of proved reserves; the state's take explains the difference
B19: calibration: model upstream FCF less corporate costs versus reported group FCF | C19: =(NAV!$C$15-Inputs!$C$47+(Inputs!$C$9+Inputs!$C$45)*(1-'Fiscal Terms'!$C$11)-(Inputs!$C$10-Inputs!$C$43*Inputs!$C$21))/Inputs!$C$11-1 -> 0.056803279 | F19: The model rebuilds group free cash flow from first principles; it should land within 20% of the reported US$85bn at the FY2025 price
B21: DOWNSTREAM AND OTHER
B22: Downstream EBITDA (adjusted EBIT + depreciation, US$ bn) | C22: =Inputs!$C$9+Inputs!$C$45 -> 20
B23: Downstream value at the multiple (US$ bn) | C23: =NAV!$C$22*Inputs!$C$46 -> 140
B24: Less: corporate costs and net interest capitalised at the discount rate | C24: =-Inputs!$C$47/Inputs!$C$44 -> -50
B26: NET ASSET VALUE
B27: Gross asset value (US$ bn) | C27: =NAV!$C$17+NAV!$C$23+NAV!$C$24 -> 1258.2992
B28: Less: net debt | C28: =-Inputs!$C$27 -> -32.133333
B29: Less: non-controlling interests at book | C29: =-Inputs!$C$28 -> -61.253333
B30: Net asset value (US$ bn) | C30: =NAV!$C$27+NAV!$C$28+NAV!$C$29 -> 1164.9126
B31: NAV per share (SAR) | C31: =NAV!$C$30*Inputs!$C$5/Inputs!$C$33 -> 18.058241
B32: Share price (SAR) | C32: =Inputs!$C$32 -> 25.56
B33: Upside / (downside) | C33: =NAV!$C$31/NAV!$C$32-1 -> -0.29349605
B34: Brent the share price implies (US$/bbl, from the Price Deck sheet) | C34: ='Price Deck'!$C$22 -> 118.40225
B35: Upstream as % of gross asset value | C35: =NAV!$C$17/NAV!$C$27 -> 0.92847488

Sheet Price Deck
B1: Saudi Aramco — Energy NAV and Price-Deck Sensitivity | I1: SAUDI ARAMCO
B2: The whole company across Brent from US$50 to US$110 — and the dividend break-even
B4: PER BARREL AND PER YEAR AT EACH PRICE
B5: Brent (US$/bbl) | C5: $50 | D5: $60 | E5: $70 | F5: $80 | G5: $90 | H5: $100 | I5: $110
B6: Brent | C6: 50 | D6: 60 | E6: 70 | F6: 80 | G6: 90 | H6: 100 | I6: 110
B7: Royalty per crude barrel (US$) | C7: =MIN(C6+Inputs!$C$40,'Fiscal Terms'!$C$6)*'Fiscal Terms'!$C$5+MAX(0,MIN(C6+Inputs!$C$40,'Fiscal Terms'!$C$8)-'Fiscal Terms'!$C$6)*'Fiscal Terms'!$C$7+MAX(0,C6+Inputs!$C$40-'Fiscal Terms'!$C$8)*'Fiscal Terms'!$C$9 -> 7.5 | D7: =MIN(D6+Inputs!$C$40,'Fiscal Terms'!$C$6)*'Fiscal Terms'!$C$5+MAX(0,MIN(D6+Inputs!$C$40,'Fiscal Terms'!$C$8)-'Fiscal Terms'!$C$6)*'Fiscal Terms'!$C$7+MAX(0,D6+Inputs!$C$40-'Fiscal Terms'!$C$8)*'Fiscal Terms'!$C$9 -> 9 | E7: =MIN(E6+Inputs!$C$40,'Fiscal Terms'!$C$6)*'Fiscal Terms'!$C$5+MAX(0,MIN(E6+Inputs!$C$40,'Fiscal Terms'!$C$8)-'Fiscal Terms'!$C$6)*'Fiscal Terms'!$C$7+MAX(0,E6+Inputs!$C$40-'Fiscal Terms'!$C$8)*'Fiscal Terms'!$C$9 -> 10.5 | F7: =MIN(F6+Inputs!$C$40,'Fiscal Terms'!$C$6)*'Fiscal Terms'!$C$5+MAX(0,MIN(F6+Inputs!$C$40,'Fiscal Terms'!$C$8)-'Fiscal Terms'!$C$6)*'Fiscal Terms'!$C$7+MAX(0,F6+Inputs!$C$40-'Fiscal Terms'!$C$8)*'Fiscal Terms'!$C$9 -> 15 | G7: =MIN(G6+Inputs!$C$40,'Fiscal Terms'!$C$6)*'Fiscal Terms'!$C$5+MAX(0,MIN(G6+Inputs!$C$40,'Fiscal Terms'!$C$8)-'Fiscal Terms'!$C$6)*'Fiscal Terms'!$C$7+MAX(0,G6+Inputs!$C$40-'Fiscal Terms'!$C$8)*'Fiscal Terms'!$C$9 -> 19.5 | H7: =MIN(H6+Inputs!$C$40,'Fiscal Terms'!$C$6)*'Fiscal Terms'!$C$5+MAX(0,MIN(H6+Inputs!$C$40,'Fiscal Terms'!$C$8)-'Fiscal Terms'!$C$6)*'Fiscal Terms'!$C$7+MAX(0,H6+Inputs!$C$40-'Fiscal Terms'!$C$8)*'Fiscal Terms'!$C$9 -> 24 | I7: =MIN(I6+Inputs!$C$40,'Fiscal Terms'!$C$6)*'Fiscal Terms'!$C$5+MAX(0,MIN(I6+Inputs!$C$40,'Fiscal Terms'!$C$8)-'Fiscal Terms'!$C$6)*'Fiscal Terms'!$C$7+MAX(0,I6+Inputs!$C$40-'Fiscal Terms'!$C$8)*'Fiscal Terms'!$C$9 -> 32
B8: After-tax netback per boe (US$) | C8: =((Inputs!$C$19*(C6+Inputs!$C$40)+Inputs!$C$20*Inputs!$C$41)/Inputs!$C$18-C7*Inputs!$C$19/Inputs!$C$18-Inputs!$C$42-Inputs!$C$43)*(1-'Fiscal Terms'!$C$10) -> 13.155039 | D8: =((Inputs!$C$19*(D6+Inputs!$C$40)+Inputs!$C$20*Inputs!$C$41)/Inputs!$C$18-D7*Inputs!$C$19/Inputs!$C$18-Inputs!$C$42-Inputs!$C$43)*(1-'Fiscal Terms'!$C$10) -> 16.680233 | E8: =((Inputs!$C$19*(E6+Inputs!$C$40)+Inputs!$C$20*Inputs!$C$41)/Inputs!$C$18-E7*Inputs!$C$19/Inputs!$C$18-Inputs!$C$42-Inputs!$C$43)*(1-'Fiscal Terms'!$C$10) -> 20.205426 | F8: =((Inputs!$C$19*(F6+Inputs!$C$40)+Inputs!$C$20*Inputs!$C$41)/Inputs!$C$18-F7*Inputs!$C$19/Inputs!$C$18-Inputs!$C$42-Inputs!$C$43)*(1-'Fiscal Terms'!$C$10) -> 22.486434 | G8: =((Inputs!$C$19*(G6+Inputs!$C$40)+Inputs!$C$20*Inputs!$C$41)/Inputs!$C$18-G7*Inputs!$C$19/Inputs!$C$18-Inputs!$C$42-Inputs!$C$43)*(1-'Fiscal Terms'!$C$10) -> 24.767442 | H8: =((Inputs!$C$19*(H6+Inputs!$C$40)+Inputs!$C$20*Inputs!$C$41)/Inputs!$C$18-H7*Inputs!$C$19/Inputs!$C$18-Inputs!$C$42-Inputs!$C$43)*(1-'Fiscal Terms'!$C$10) -> 27.04845 | I8: =((Inputs!$C$19*(I6+Inputs!$C$40)+Inputs!$C$20*Inputs!$C$41)/Inputs!$C$18-I7*Inputs!$C$19/Inputs!$C$18-Inputs!$C$42-Inputs!$C$43)*(1-'Fiscal Terms'!$C$10) -> 27.877907
B9: Upstream free cash flow (US$ bn) | C9: =C8*Inputs!$C$21 -> 61.9405 | D9: =D8*Inputs!$C$21 -> 78.538875 | E9: =E8*Inputs!$C$21 -> 95.13725 | F9: =F8*Inputs!$C$21 -> 105.87738 | G9: =G8*Inputs!$C$21 -> 116.6175 | H9: =H8*Inputs!$C$21 -> 127.35762 | I9: =I8*Inputs!$C$21 -> 131.26313
B10: Group free cash flow: upstream + downstream after tax and capex − corporate (US$ bn) | C10: =C9+(Inputs!$C$9+Inputs!$C$45)*(1-'Fiscal Terms'!$C$11)-(Inputs!$C$10-Inputs!$C$43*Inputs!$C$21)-Inputs!$C$47 -> 57.05425 | D10: =D9+(Inputs!$C$9+Inputs!$C$45)*(1-'Fiscal Terms'!$C$11)-(Inputs!$C$10-Inputs!$C$43*Inputs!$C$21)-Inputs!$C$47 -> 73.652625 | E10: =E9+(Inputs!$C$9+Inputs!$C$45)*(1-'Fiscal Terms'!$C$11)-(Inputs!$C$10-Inputs!$C$43*Inputs!$C$21)-Inputs!$C$47 -> 90.251 | F10: =F9+(Inputs!$C$9+Inputs!$C$45)*(1-'Fiscal Terms'!$C$11)-(Inputs!$C$10-Inputs!$C$43*Inputs!$C$21)-Inputs!$C$47 -> 100.99112 | G10: =G9+(Inputs!$C$9+Inputs!$C$45)*(1-'Fiscal Terms'!$C$11)-(Inputs!$C$10-Inputs!$C$43*Inputs!$C$21)-Inputs!$C$47 -> 111.73125 | H10: =H9+(Inputs!$C$9+Inputs!$C$45)*(1-'Fiscal Terms'!$C$11)-(Inputs!$C$10-Inputs!$C$43*Inputs!$C$21)-Inputs!$C$47 -> 122.47137 | I10: =I9+(Inputs!$C$9+Inputs!$C$45)*(1-'Fiscal Terms'!$C$11)-(Inputs!$C$10-Inputs!$C$43*Inputs!$C$21)-Inputs!$C$47 -> 126.37687
B11: Base dividend cover: group FCF / base dividend | C11: =C10/Inputs!$C$13 -> 0.65204857 | D11: =D10/Inputs!$C$13 -> 0.84174429 | E11: =E10/Inputs!$C$13 -> 1.03144 | F11: =F10/Inputs!$C$13 -> 1.1541843 | G11: =G10/Inputs!$C$13 -> 1.2769286 | H11: =H10/Inputs!$C$13 -> 1.3996729 | I11: =I10/Inputs!$C$13 -> 1.4443071
B12: Surplus / (shortfall) after the base dividend (US$ bn) | C12: =C10-Inputs!$C$13 -> -30.44575 | D12: =D10-Inputs!$C$13 -> -13.847375 | E12: =E10-Inputs!$C$13 -> 2.751 | F12: =F10-Inputs!$C$13 -> 13.491125 | G12: =G10-Inputs!$C$13 -> 24.23125 | H12: =H10-Inputs!$C$13 -> 34.971375 | I12: =I10-Inputs!$C$13 -> 38.876875
B14: VALUE AT EACH PRICE
B15: NAV (US$ bn) | C15: =C9*NAV!$C$16+NAV!$C$23+NAV!$C$24-Inputs!$C$27-Inputs!$C$28 -> 757.25166 | D15: =D9*NAV!$C$16+NAV!$C$23+NAV!$C$24-Inputs!$C$27-Inputs!$C$28 -> 961.08211 | E15: =E9*NAV!$C$16+NAV!$C$23+NAV!$C$24-Inputs!$C$27-Inputs!$C$28 -> 1164.9126 | F15: =F9*NAV!$C$16+NAV!$C$23+NAV!$C$24-Inputs!$C$27-Inputs!$C$28 -> 1296.8029 | G15: =G9*NAV!$C$16+NAV!$C$23+NAV!$C$24-Inputs!$C$27-Inputs!$C$28 -> 1428.6931 | H15: =H9*NAV!$C$16+NAV!$C$23+NAV!$C$24-Inputs!$C$27-Inputs!$C$28 -> 1560.5834 | I15: =I9*NAV!$C$16+NAV!$C$23+NAV!$C$24-Inputs!$C$27-Inputs!$C$28 -> 1608.5435
B16: NAV per share (SAR) | C16: =C15*Inputs!$C$5/Inputs!$C$33 -> 11.738763 | D16: =D15*Inputs!$C$5/Inputs!$C$33 -> 14.898502 | E16: =E15*Inputs!$C$5/Inputs!$C$33 -> 18.058241 | F16: =F15*Inputs!$C$5/Inputs!$C$33 -> 20.102778 | G16: =G15*Inputs!$C$5/Inputs!$C$33 -> 22.147315 | H16: =H15*Inputs!$C$5/Inputs!$C$33 -> 24.191852 | I16: =I15*Inputs!$C$5/Inputs!$C$33 -> 24.93532
B17: Versus the share price | C17: =C16/Inputs!$C$32-1 -> -0.54073696 | D17: =D16/Inputs!$C$32-1 -> -0.4171165 | E17: =E16/Inputs!$C$32-1 -> -0.29349605 | F17: =F16/Inputs!$C$32-1 -> -0.21350635 | G17: =G16/Inputs!$C$32-1 -> -0.13351664 | H17: =H16/Inputs!$C$32-1 -> -0.053526935 | I17: =I16/Inputs!$C$32-1 -> -0.024439769
B19: BREAK-EVENS (closed form)
B20: Brent at which group FCF exactly covers the base dividend (US$/bbl) | C20: =(Inputs!$C$13-((Inputs!$C$20*Inputs!$C$41/Inputs!$C$18-Inputs!$C$42-Inputs!$C$43+Inputs!$C$19/Inputs!$C$18*Inputs!$C$40*(1-'Fiscal Terms'!$C$5))*(1-'Fiscal Terms'!$C$10)*Inputs!$C$21+(Inputs!$C$9+Inputs!$C$45)*(1-'Fiscal Terms'!$C$11)-(Inputs!$C$10-Inputs!$C$43*Inputs!$C$21)-Inputs!$C$47))/(Inputs!$C$19/Inputs!$C$18*(1-'Fiscal Terms'!$C$5)*(1-'Fiscal Terms'!$C$10)*Inputs!$C$21) -> 68.342609 | I20: Valid while the answer is below the first royalty threshold, which the check confirms
B21: Brent at which group FCF is zero (US$/bbl) | C21: =-((Inputs!$C$20*Inputs!$C$41/Inputs!$C$18-Inputs!$C$42-Inputs!$C$43+Inputs!$C$19/Inputs!$C$18*Inputs!$C$40*(1-'Fiscal Terms'!$C$5))*(1-'Fiscal Terms'!$C$10)*Inputs!$C$21+(Inputs!$C$9+Inputs!$C$45)*(1-'Fiscal Terms'!$C$11)-(Inputs!$C$10-Inputs!$C$43*Inputs!$C$21)-Inputs!$C$47)/(Inputs!$C$19/Inputs!$C$18*(1-'Fiscal Terms'!$C$5)*(1-'Fiscal Terms'!$C$10)*Inputs!$C$21) -> 15.626605
B22: Brent the share price implies on this NAV (US$/bbl) | C22: =IF(((Inputs!$C$34+Inputs!$C$27+Inputs!$C$28-NAV!$C$23-NAV!$C$24)/NAV!$C$16)<=(((Inputs!$C$19*('Fiscal Terms'!$C$6+Inputs!$C$40)+Inputs!$C$20*Inputs!$C$41)/Inputs!$C$18-(MIN('Fiscal Terms'!$C$6+Inputs!$C$40,'Fiscal Terms'!$C$6)*'Fiscal Terms'!$C$5+MAX(0,MIN('Fiscal Terms'!$C$6+Inputs!$C$40,'Fiscal Terms'!$C$8)-'Fiscal Terms'!$C$6)*'Fiscal Terms'!$C$7+MAX(0,'Fiscal Terms'!$C$6+Inputs!$C$40-'Fiscal Terms'!$C$8)*'Fiscal Terms'!$C$9)*Inputs!$C$19/Inputs!$C$18-Inputs!$C$42-Inputs!$C$43)*(1-'Fiscal Terms'!$C$10)*Inputs!$C$21),('Fiscal Terms'!$C$6-((((Inputs!$C$19*('Fiscal Terms'!$C$6+Inputs!$C$40)+Inputs!$C$20*Inputs!$C$41)/Inputs!$C$18-(MIN('Fiscal Terms'!$C$6+Inputs!$C$40,'Fiscal Terms'!$C$6)*'Fiscal Terms'!$C$5+MAX(0,MIN('Fiscal Terms'!$C$6+Inputs!$C$40,'Fiscal Terms'!$C$8)-'Fiscal Terms'!$C$6)*'Fiscal Terms'!$C$7+MAX(0,'Fiscal Terms'!$C$6+Inputs!$C$40-'Fiscal Terms'!$C$8)*'Fiscal Terms'!$C$9)*Inputs!$C$19/Inputs!$C$18-Inputs!$C$42-Inputs!$C$43)*(1-'Fiscal Terms'!$C$10)*Inputs!$C$21)-((Inputs!$C$34+Inputs!$C$27+Inputs!$C$28-NAV!$C$23-NAV!$C$24)/NAV!$C$16))/(Inputs!$C$19/Inputs!$C$18*(1-'Fiscal Terms'!$C$5)*(1-'Fiscal Terms'!$C$10)*Inputs!$C$21)),IF(((Inputs!$C$34+Inputs!$C$27+Inputs!$C$28-NAV!$C$23-NAV!$C$24)/NAV!$C$16)<=(((Inputs!$C$19*('Fiscal Terms'!$C$8+Inputs!$C$40)+Inputs!$C$20*Inputs!$C$41)/Inputs!$C$18-(MIN('Fiscal Terms'!$C$8+Inputs!$C$40,'Fiscal Terms'!$C$6)*'Fiscal Terms'!$C$5+MAX(0,MIN('Fiscal Terms'!$C$8+Inputs!$C$40,'Fiscal Terms'!$C$8)-'Fiscal Terms'!$C$6)*'Fiscal Terms'!$C$7+MAX(0,'Fiscal Terms'!$C$8+Inputs!$C$40-'Fiscal Terms'!$C$8)*'Fiscal Terms'!$C$9)*Inputs!$C$19/Inputs!$C$18-Inputs!$C$42-Inputs!$C$43)*(1-'Fiscal Terms'!$C$10)*Inputs!$C$21),('Fiscal Terms'!$C$6+(((Inputs!$C$34+Inputs!$C$27+Inputs!$C$28-NAV!$C$23-NAV!$C$24)/NAV!$C$16)-(((Inputs!$C$19*('Fiscal Terms'!$C$6+Inputs!$C$40)+Inputs!$C$20*Inputs!$C$41)/Inputs!$C$18-(MIN('Fiscal Terms'!$C$6+Inputs!$C$40,'Fiscal Terms'!$C$6)*'Fiscal Terms'!$C$5+MAX(0,MIN('Fiscal Terms'!$C$6+Inputs!$C$40,'Fiscal Terms'!$C$8)-'Fiscal Terms'!$C$6)*'Fiscal Terms'!$C$7+MAX(0,'Fiscal Terms'!$C$6+Inputs!$C$40-'Fiscal Terms'!$C$8)*'Fiscal Terms'!$C$9)*Inputs!$C$19/Inputs!$C$18-Inputs!$C$42-Inputs!$C$43)*(1-'Fiscal Terms'!$C$10)*Inputs!$C$21))/(Inputs!$C$19/Inputs!$C$18*(1-'Fiscal Terms'!$C$7)*(1-'Fiscal Terms'!$C$10)*Inputs!$C$21)),('Fiscal Terms'!$C$8+(((Inputs!$C$34+Inputs!$C$27+Inputs!$C$28-NAV!$C$23-NAV!$C$24)/NAV!$C$16)-(((Inputs!$C$19*('Fiscal Terms'!$C$8+Inputs!$C$40)+Inputs!$C$20*Inputs!$C$41)/Inputs!$C$18-(MIN('Fiscal Terms'!$C$8+Inputs!$C$40,'Fiscal Terms'!$C$6)*'Fiscal Terms'!$C$5+MAX(0,MIN('Fiscal Terms'!$C$8+Inputs!$C$40,'Fiscal Terms'!$C$8)-'Fiscal Terms'!$C$6)*'Fiscal Terms'!$C$7+MAX(0,'Fiscal Terms'!$C$8+Inputs!$C$40-'Fiscal Terms'!$C$8)*'Fiscal Terms'!$C$9)*Inputs!$C$19/Inputs!$C$18-Inputs!$C$42-Inputs!$C$43)*(1-'Fiscal Terms'!$C$10)*Inputs!$C$21))/(Inputs!$C$19/Inputs!$C$18*(1-'Fiscal Terms'!$C$9)*(1-'Fiscal Terms'!$C$10)*Inputs!$C$21)))) -> 118.40225 | I22: Solved on whichever royalty leg the answer falls, and verified by substitution on the Checks sheet
B23: Discount rate the share price implies at US$70 Brent (perpetuity approximation) | C23: =(NAV!$C$15-Inputs!$C$47)/(Inputs!$C$34+Inputs!$C$27+Inputs!$C$28-NAV!$C$23) -> 0.056881591 | I23: Upstream FCF less corporate costs over the enterprise value net of downstream. The 52-year annuity differs from a perpetuity by under 2%
B24: Group free cash flow rises by about US$2.4bn for each dollar of Brent below US$70 and by roughly US$1.5bn per dollar between US$70 and US$100. The base dividend alone absorbs the bulk of free cash flow at a US$70 deck, which is why the performance-linked dividend was cut to almost nothing in 2025 and why the balance sheet, not the oil price, funded part of the 2024 payout.

Sheet Sensitivity
B1: Saudi Aramco — Energy NAV and Price-Deck Sensitivity | H1: SAUDI ARAMCO
B2: NAV per share (SAR) — each cell rebuilds the netback and the annuity
B4: BRENT (rows) versus DISCOUNT RATE (columns)
B5: ↓ rows \ columns → | C5: 0.07 | D5: 0.075 | E5: 0.08 | F5: 0.085 | G5: 0.09
B6: 55 | C6: =((((Inputs!$C$19*($B6+Inputs!$C$40)+Inputs!$C$20*Inputs!$C$41)/Inputs!$C$18-(MIN($B6+Inputs!$C$40,'Fiscal Terms'!$C$6)*'Fiscal Terms'!$C$5+MAX(0,MIN($B6+Inputs!$C$40,'Fiscal Terms'!$C$8)-'Fiscal Terms'!$C$6)*'Fiscal Terms'!$C$7+MAX(0,$B6+Inputs!$C$40-'Fiscal Terms'!$C$8)*'Fiscal Terms'!$C$9)*Inputs!$C$19/Inputs!$C$18-Inputs!$C$42-Inputs!$C$43)*(1-'Fiscal Terms'!$C$10))*Inputs!$C$21*((1-(1+C$5)^-Inputs!$C$22)/C$5)+NAV!$C$23+NAV!$C$24-Inputs!$C$27-Inputs!$C$28)*Inputs!$C$5/Inputs!$C$33 -> 15.056524 | D6: =((((Inputs!$C$19*($B6+Inputs!$C$40)+Inputs!$C$20*Inputs!$C$41)/Inputs!$C$18-(MIN($B6+Inputs!$C$40,'Fiscal Terms'!$C$6)*'Fiscal Terms'!$C$5+MAX(0,MIN($B6+Inputs!$C$40,'Fiscal Terms'!$C$8)-'Fiscal Terms'!$C$6)*'Fiscal Terms'!$C$7+MAX(0,$B6+Inputs!$C$40-'Fiscal Terms'!$C$8)*'Fiscal Terms'!$C$9)*Inputs!$C$19/Inputs!$C$18-Inputs!$C$42-Inputs!$C$43)*(1-'Fiscal Terms'!$C$10))*Inputs!$C$21*((1-(1+D$5)^-Inputs!$C$22)/D$5)+NAV!$C$23+NAV!$C$24-Inputs!$C$27-Inputs!$C$28)*Inputs!$C$5/Inputs!$C$33 -> 14.139601 | E6: =((((Inputs!$C$19*($B6+Inputs!$C$40)+Inputs!$C$20*Inputs!$C$41)/Inputs!$C$18-(MIN($B6+Inputs!$C$40,'Fiscal Terms'!$C$6)*'Fiscal Terms'!$C$5+MAX(0,MIN($B6+Inputs!$C$40,'Fiscal Terms'!$C$8)-'Fiscal Terms'!$C$6)*'Fiscal Terms'!$C$7+MAX(0,$B6+Inputs!$C$40-'Fiscal Terms'!$C$8)*'Fiscal Terms'!$C$9)*Inputs!$C$19/Inputs!$C$18-Inputs!$C$42-Inputs!$C$43)*(1-'Fiscal Terms'!$C$10))*Inputs!$C$21*((1-(1+E$5)^-Inputs!$C$22)/E$5)+NAV!$C$23+NAV!$C$24-Inputs!$C$27-Inputs!$C$28)*Inputs!$C$5/Inputs!$C$33 -> 13.318633 | F6: =((((Inputs!$C$19*($B6+Inputs!$C$40)+Inputs!$C$20*Inputs!$C$41)/Inputs!$C$18-(MIN($B6+Inputs!$C$40,'Fiscal Terms'!$C$6)*'Fiscal Terms'!$C$5+MAX(0,MIN($B6+Inputs!$C$40,'Fiscal Terms'!$C$8)-'Fiscal Terms'!$C$6)*'Fiscal Terms'!$C$7+MAX(0,$B6+Inputs!$C$40-'Fiscal Terms'!$C$8)*'Fiscal Terms'!$C$9)*Inputs!$C$19/Inputs!$C$18-Inputs!$C$42-Inputs!$C$43)*(1-'Fiscal Terms'!$C$10))*Inputs!$C$21*((1-(1+F$5)^-Inputs!$C$22)/F$5)+NAV!$C$23+NAV!$C$24-Inputs!$C$27-Inputs!$C$28)*Inputs!$C$5/Inputs!$C$33 -> 12.580612 | G6: =((((Inputs!$C$19*($B6+Inputs!$C$40)+Inputs!$C$20*Inputs!$C$41)/Inputs!$C$18-(MIN($B6+Inputs!$C$40,'Fiscal Terms'!$C$6)*'Fiscal Terms'!$C$5+MAX(0,MIN($B6+Inputs!$C$40,'Fiscal Terms'!$C$8)-'Fiscal Terms'!$C$6)*'Fiscal Terms'!$C$7+MAX(0,$B6+Inputs!$C$40-'Fiscal Terms'!$C$8)*'Fiscal Terms'!$C$9)*Inputs!$C$19/Inputs!$C$18-Inputs!$C$42-Inputs!$C$43)*(1-'Fiscal Terms'!$C$10))*Inputs!$C$21*((1-(1+G$5)^-Inputs!$C$22)/G$5)+NAV!$C$23+NAV!$C$24-Inputs!$C$27-Inputs!$C$28)*Inputs!$C$5/Inputs!$C$33 -> 11.91458
B7: 62.5 | C7: =((((Inputs!$C$19*($B7+Inputs!$C$40)+Inputs!$C$20*Inputs!$C$41)/Inputs!$C$18-(MIN($B7+Inputs!$C$40,'Fiscal Terms'!$C$6)*'Fiscal Terms'!$C$5+MAX(0,MIN($B7+Inputs!$C$40,'Fiscal Terms'!$C$8)-'Fiscal Terms'!$C$6)*'Fiscal Terms'!$C$7+MAX(0,$B7+Inputs!$C$40-'Fiscal Terms'!$C$8)*'Fiscal Terms'!$C$9)*Inputs!$C$19/Inputs!$C$18-Inputs!$C$42-Inputs!$C$43)*(1-'Fiscal Terms'!$C$10))*Inputs!$C$21*((1-(1+C$5)^-Inputs!$C$22)/C$5)+NAV!$C$23+NAV!$C$24-Inputs!$C$27-Inputs!$C$28)*Inputs!$C$5/Inputs!$C$33 -> 17.734339 | D7: =((((Inputs!$C$19*($B7+Inputs!$C$40)+Inputs!$C$20*Inputs!$C$41)/Inputs!$C$18-(MIN($B7+Inputs!$C$40,'Fiscal Terms'!$C$6)*'Fiscal Terms'!$C$5+MAX(0,MIN($B7+Inputs!$C$40,'Fiscal Terms'!$C$8)-'Fiscal Terms'!$C$6)*'Fiscal Terms'!$C$7+MAX(0,$B7+Inputs!$C$40-'Fiscal Terms'!$C$8)*'Fiscal Terms'!$C$9)*Inputs!$C$19/Inputs!$C$18-Inputs!$C$42-Inputs!$C$43)*(1-'Fiscal Terms'!$C$10))*Inputs!$C$21*((1-(1+D$5)^-Inputs!$C$22)/D$5)+NAV!$C$23+NAV!$C$24-Inputs!$C$27-Inputs!$C$28)*Inputs!$C$5/Inputs!$C$33 -> 16.654907 | E7: =((((Inputs!$C$19*($B7+Inputs!$C$40)+Inputs!$C$20*Inputs!$C$41)/Inputs!$C$18-(MIN($B7+Inputs!$C$40,'Fiscal Terms'!$C$6)*'Fiscal Terms'!$C$5+MAX(0,MIN($B7+Inputs!$C$40,'Fiscal Terms'!$C$8)-'Fiscal Terms'!$C$6)*'Fiscal Terms'!$C$7+MAX(0,$B7+Inputs!$C$40-'Fiscal Terms'!$C$8)*'Fiscal Terms'!$C$9)*Inputs!$C$19/Inputs!$C$18-Inputs!$C$42-Inputs!$C$43)*(1-'Fiscal Terms'!$C$10))*Inputs!$C$21*((1-(1+E$5)^-Inputs!$C$22)/E$5)+NAV!$C$23+NAV!$C$24-Inputs!$C$27-Inputs!$C$28)*Inputs!$C$5/Inputs!$C$33 -> 15.688437 | F7: =((((Inputs!$C$19*($B7+Inputs!$C$40)+Inputs!$C$20*Inputs!$C$41)/Inputs!$C$18-(MIN($B7+Inputs!$C$40,'Fiscal Terms'!$C$6)*'Fiscal Terms'!$C$5+MAX(0,MIN($B7+Inputs!$C$40,'Fiscal Terms'!$C$8)-'Fiscal Terms'!$C$6)*'Fiscal Terms'!$C$7+MAX(0,$B7+Inputs!$C$40-'Fiscal Terms'!$C$8)*'Fiscal Terms'!$C$9)*Inputs!$C$19/Inputs!$C$18-Inputs!$C$42-Inputs!$C$43)*(1-'Fiscal Terms'!$C$10))*Inputs!$C$21*((1-(1+F$5)^-Inputs!$C$22)/F$5)+NAV!$C$23+NAV!$C$24-Inputs!$C$27-Inputs!$C$28)*Inputs!$C$5/Inputs!$C$33 -> 14.819614 | G7: =((((Inputs!$C$19*($B7+Inputs!$C$40)+Inputs!$C$20*Inputs!$C$41)/Inputs!$C$18-(MIN($B7+Inputs!$C$40,'Fiscal Terms'!$C$6)*'Fiscal Terms'!$C$5+MAX(0,MIN($B7+Inputs!$C$40,'Fiscal Terms'!$C$8)-'Fiscal Terms'!$C$6)*'Fiscal Terms'!$C$7+MAX(0,$B7+Inputs!$C$40-'Fiscal Terms'!$C$8)*'Fiscal Terms'!$C$9)*Inputs!$C$19/Inputs!$C$18-Inputs!$C$42-Inputs!$C$43)*(1-'Fiscal Terms'!$C$10))*Inputs!$C$21*((1-(1+G$5)^-Inputs!$C$22)/G$5)+NAV!$C$23+NAV!$C$24-Inputs!$C$27-Inputs!$C$28)*Inputs!$C$5/Inputs!$C$33 -> 14.03554
B8: 70 | C8: =((((Inputs!$C$19*($B8+Inputs!$C$40)+Inputs!$C$20*Inputs!$C$41)/Inputs!$C$18-(MIN($B8+Inputs!$C$40,'Fiscal Terms'!$C$6)*'Fiscal Terms'!$C$5+MAX(0,MIN($B8+Inputs!$C$40,'Fiscal Terms'!$C$8)-'Fiscal Terms'!$C$6)*'Fiscal Terms'!$C$7+MAX(0,$B8+Inputs!$C$40-'Fiscal Terms'!$C$8)*'Fiscal Terms'!$C$9)*Inputs!$C$19/Inputs!$C$18-Inputs!$C$42-Inputs!$C$43)*(1-'Fiscal Terms'!$C$10))*Inputs!$C$21*((1-(1+C$5)^-Inputs!$C$22)/C$5)+NAV!$C$23+NAV!$C$24-Inputs!$C$27-Inputs!$C$28)*Inputs!$C$5/Inputs!$C$33 -> 20.412154 | D8: =((((Inputs!$C$19*($B8+Inputs!$C$40)+Inputs!$C$20*Inputs!$C$41)/Inputs!$C$18-(MIN($B8+Inputs!$C$40,'Fiscal Terms'!$C$6)*'Fiscal Terms'!$C$5+MAX(0,MIN($B8+Inputs!$C$40,'Fiscal Terms'!$C$8)-'Fiscal Terms'!$C$6)*'Fiscal Terms'!$C$7+MAX(0,$B8+Inputs!$C$40-'Fiscal Terms'!$C$8)*'Fiscal Terms'!$C$9)*Inputs!$C$19/Inputs!$C$18-Inputs!$C$42-Inputs!$C$43)*(1-'Fiscal Terms'!$C$10))*Inputs!$C$21*((1-(1+D$5)^-Inputs!$C$22)/D$5)+NAV!$C$23+NAV!$C$24-Inputs!$C$27-Inputs!$C$28)*Inputs!$C$5/Inputs!$C$33 -> 19.170214 | E8: =((((Inputs!$C$19*($B8+Inputs!$C$40)+Inputs!$C$20*Inputs!$C$41)/Inputs!$C$18-(MIN($B8+Inputs!$C$40,'Fiscal Terms'!$C$6)*'Fiscal Terms'!$C$5+MAX(0,MIN($B8+Inputs!$C$40,'Fiscal Terms'!$C$8)-'Fiscal Terms'!$C$6)*'Fiscal Terms'!$C$7+MAX(0,$B8+Inputs!$C$40-'Fiscal Terms'!$C$8)*'Fiscal Terms'!$C$9)*Inputs!$C$19/Inputs!$C$18-Inputs!$C$42-Inputs!$C$43)*(1-'Fiscal Terms'!$C$10))*Inputs!$C$21*((1-(1+E$5)^-Inputs!$C$22)/E$5)+NAV!$C$23+NAV!$C$24-Inputs!$C$27-Inputs!$C$28)*Inputs!$C$5/Inputs!$C$33 -> 18.058241 | F8: =((((Inputs!$C$19*($B8+Inputs!$C$40)+Inputs!$C$20*Inputs!$C$41)/Inputs!$C$18-(MIN($B8+Inputs!$C$40,'Fiscal Terms'!$C$6)*'Fiscal Terms'!$C$5+MAX(0,MIN($B8+Inputs!$C$40,'Fiscal Terms'!$C$8)-'Fiscal Terms'!$C$6)*'Fiscal Terms'!$C$7+MAX(0,$B8+Inputs!$C$40-'Fiscal Terms'!$C$8)*'Fiscal Terms'!$C$9)*Inputs!$C$19/Inputs!$C$18-Inputs!$C$42-Inputs!$C$43)*(1-'Fiscal Terms'!$C$10))*Inputs!$C$21*((1-(1+F$5)^-Inputs!$C$22)/F$5)+NAV!$C$23+NAV!$C$24-Inputs!$C$27-Inputs!$C$28)*Inputs!$C$5/Inputs!$C$33 -> 17.058617 | G8: =((((Inputs!$C$19*($B8+Inputs!$C$40)+Inputs!$C$20*Inputs!$C$41)/Inputs!$C$18-(MIN($B8+Inputs!$C$40,'Fiscal Terms'!$C$6)*'Fiscal Terms'!$C$5+MAX(0,MIN($B8+Inputs!$C$40,'Fiscal Terms'!$C$8)-'Fiscal Terms'!$C$6)*'Fiscal Terms'!$C$7+MAX(0,$B8+Inputs!$C$40-'Fiscal Terms'!$C$8)*'Fiscal Terms'!$C$9)*Inputs!$C$19/Inputs!$C$18-Inputs!$C$42-Inputs!$C$43)*(1-'Fiscal Terms'!$C$10))*Inputs!$C$21*((1-(1+G$5)^-Inputs!$C$22)/G$5)+NAV!$C$23+NAV!$C$24-Inputs!$C$27-Inputs!$C$28)*Inputs!$C$5/Inputs!$C$33 -> 16.1565
B9: 77.5 | C9: =((((Inputs!$C$19*($B9+Inputs!$C$40)+Inputs!$C$20*Inputs!$C$41)/Inputs!$C$18-(MIN($B9+Inputs!$C$40,'Fiscal Terms'!$C$6)*'Fiscal Terms'!$C$5+MAX(0,MIN($B9+Inputs!$C$40,'Fiscal Terms'!$C$8)-'Fiscal Terms'!$C$6)*'Fiscal Terms'!$C$7+MAX(0,$B9+Inputs!$C$40-'Fiscal Terms'!$C$8)*'Fiscal Terms'!$C$9)*Inputs!$C$19/Inputs!$C$18-Inputs!$C$42-Inputs!$C$43)*(1-'Fiscal Terms'!$C$10))*Inputs!$C$21*((1-(1+C$5)^-Inputs!$C$22)/C$5)+NAV!$C$23+NAV!$C$24-Inputs!$C$27-Inputs!$C$28)*Inputs!$C$5/Inputs!$C$33 -> 22.144859 | D9: =((((Inputs!$C$19*($B9+Inputs!$C$40)+Inputs!$C$20*Inputs!$C$41)/Inputs!$C$18-(MIN($B9+Inputs!$C$40,'Fiscal Terms'!$C$6)*'Fiscal Terms'!$C$5+MAX(0,MIN($B9+Inputs!$C$40,'Fiscal Terms'!$C$8)-'Fiscal Terms'!$C$6)*'Fiscal Terms'!$C$7+MAX(0,$B9+Inputs!$C$40-'Fiscal Terms'!$C$8)*'Fiscal Terms'!$C$9)*Inputs!$C$19/Inputs!$C$18-Inputs!$C$42-Inputs!$C$43)*(1-'Fiscal Terms'!$C$10))*Inputs!$C$21*((1-(1+D$5)^-Inputs!$C$22)/D$5)+NAV!$C$23+NAV!$C$24-Inputs!$C$27-Inputs!$C$28)*Inputs!$C$5/Inputs!$C$33 -> 20.797765 | E9: =((((Inputs!$C$19*($B9+Inputs!$C$40)+Inputs!$C$20*Inputs!$C$41)/Inputs!$C$18-(MIN($B9+Inputs!$C$40,'Fiscal Terms'!$C$6)*'Fiscal Terms'!$C$5+MAX(0,MIN($B9+Inputs!$C$40,'Fiscal Terms'!$C$8)-'Fiscal Terms'!$C$6)*'Fiscal Terms'!$C$7+MAX(0,$B9+Inputs!$C$40-'Fiscal Terms'!$C$8)*'Fiscal Terms'!$C$9)*Inputs!$C$19/Inputs!$C$18-Inputs!$C$42-Inputs!$C$43)*(1-'Fiscal Terms'!$C$10))*Inputs!$C$21*((1-(1+E$5)^-Inputs!$C$22)/E$5)+NAV!$C$23+NAV!$C$24-Inputs!$C$27-Inputs!$C$28)*Inputs!$C$5/Inputs!$C$33 -> 19.591644 | F9: =((((Inputs!$C$19*($B9+Inputs!$C$40)+Inputs!$C$20*Inputs!$C$41)/Inputs!$C$18-(MIN($B9+Inputs!$C$40,'Fiscal Terms'!$C$6)*'Fiscal Terms'!$C$5+MAX(0,MIN($B9+Inputs!$C$40,'Fiscal Terms'!$C$8)-'Fiscal Terms'!$C$6)*'Fiscal Terms'!$C$7+MAX(0,$B9+Inputs!$C$40-'Fiscal Terms'!$C$8)*'Fiscal Terms'!$C$9)*Inputs!$C$19/Inputs!$C$18-Inputs!$C$42-Inputs!$C$43)*(1-'Fiscal Terms'!$C$10))*Inputs!$C$21*((1-(1+F$5)^-Inputs!$C$22)/F$5)+NAV!$C$23+NAV!$C$24-Inputs!$C$27-Inputs!$C$28)*Inputs!$C$5/Inputs!$C$33 -> 18.507383 | G9: =((((Inputs!$C$19*($B9+Inputs!$C$40)+Inputs!$C$20*Inputs!$C$41)/Inputs!$C$18-(MIN($B9+Inputs!$C$40,'Fiscal Terms'!$C$6)*'Fiscal Terms'!$C$5+MAX(0,MIN($B9+Inputs!$C$40,'Fiscal Terms'!$C$8)-'Fiscal Terms'!$C$6)*'Fiscal Terms'!$C$7+MAX(0,$B9+Inputs!$C$40-'Fiscal Terms'!$C$8)*'Fiscal Terms'!$C$9)*Inputs!$C$19/Inputs!$C$18-Inputs!$C$42-Inputs!$C$43)*(1-'Fiscal Terms'!$C$10))*Inputs!$C$21*((1-(1+G$5)^-Inputs!$C$22)/G$5)+NAV!$C$23+NAV!$C$24-Inputs!$C$27-Inputs!$C$28)*Inputs!$C$5/Inputs!$C$33 -> 17.528885
B10: 85 | C10: =((((Inputs!$C$19*($B10+Inputs!$C$40)+Inputs!$C$20*Inputs!$C$41)/Inputs!$C$18-(MIN($B10+Inputs!$C$40,'Fiscal Terms'!$C$6)*'Fiscal Terms'!$C$5+MAX(0,MIN($B10+Inputs!$C$40,'Fiscal Terms'!$C$8)-'Fiscal Terms'!$C$6)*'Fiscal Terms'!$C$7+MAX(0,$B10+Inputs!$C$40-'Fiscal Terms'!$C$8)*'Fiscal Terms'!$C$9)*Inputs!$C$19/Inputs!$C$18-Inputs!$C$42-Inputs!$C$43)*(1-'Fiscal Terms'!$C$10))*Inputs!$C$21*((1-(1+C$5)^-Inputs!$C$22)/C$5)+NAV!$C$23+NAV!$C$24-Inputs!$C$27-Inputs!$C$28)*Inputs!$C$5/Inputs!$C$33 -> 23.877563 | D10: =((((Inputs!$C$19*($B10+Inputs!$C$40)+Inputs!$C$20*Inputs!$C$41)/Inputs!$C$18-(MIN($B10+Inputs!$C$40,'Fiscal Terms'!$C$6)*'Fiscal Terms'!$C$5+MAX(0,MIN($B10+Inputs!$C$40,'Fiscal Terms'!$C$8)-'Fiscal Terms'!$C$6)*'Fiscal Terms'!$C$7+MAX(0,$B10+Inputs!$C$40-'Fiscal Terms'!$C$8)*'Fiscal Terms'!$C$9)*Inputs!$C$19/Inputs!$C$18-Inputs!$C$42-Inputs!$C$43)*(1-'Fiscal Terms'!$C$10))*Inputs!$C$21*((1-(1+D$5)^-Inputs!$C$22)/D$5)+NAV!$C$23+NAV!$C$24-Inputs!$C$27-Inputs!$C$28)*Inputs!$C$5/Inputs!$C$33 -> 22.425317 | E10: =((((Inputs!$C$19*($B10+Inputs!$C$40)+Inputs!$C$20*Inputs!$C$41)/Inputs!$C$18-(MIN($B10+Inputs!$C$40,'Fiscal Terms'!$C$6)*'Fiscal Terms'!$C$5+MAX(0,MIN($B10+Inputs!$C$40,'Fiscal Terms'!$C$8)-'Fiscal Terms'!$C$6)*'Fiscal Terms'!$C$7+MAX(0,$B10+Inputs!$C$40-'Fiscal Terms'!$C$8)*'Fiscal Terms'!$C$9)*Inputs!$C$19/Inputs!$C$18-Inputs!$C$42-Inputs!$C$43)*(1-'Fiscal Terms'!$C$10))*Inputs!$C$21*((1-(1+E$5)^-Inputs!$C$22)/E$5)+NAV!$C$23+NAV!$C$24-Inputs!$C$27-Inputs!$C$28)*Inputs!$C$5/Inputs!$C$33 -> 21.125046 | F10: =((((Inputs!$C$19*($B10+Inputs!$C$40)+Inputs!$C$20*Inputs!$C$41)/Inputs!$C$18-(MIN($B10+Inputs!$C$40,'Fiscal Terms'!$C$6)*'Fiscal Terms'!$C$5+MAX(0,MIN($B10+Inputs!$C$40,'Fiscal Terms'!$C$8)-'Fiscal Terms'!$C$6)*'Fiscal Terms'!$C$7+MAX(0,$B10+Inputs!$C$40-'Fiscal Terms'!$C$8)*'Fiscal Terms'!$C$9)*Inputs!$C$19/Inputs!$C$18-Inputs!$C$42-Inputs!$C$43)*(1-'Fiscal Terms'!$C$10))*Inputs!$C$21*((1-(1+F$5)^-Inputs!$C$22)/F$5)+NAV!$C$23+NAV!$C$24-Inputs!$C$27-Inputs!$C$28)*Inputs!$C$5/Inputs!$C$33 -> 19.956149 | G10: =((((Inputs!$C$19*($B10+Inputs!$C$40)+Inputs!$C$20*Inputs!$C$41)/Inputs!$C$18-(MIN($B10+Inputs!$C$40,'Fiscal Terms'!$C$6)*'Fiscal Terms'!$C$5+MAX(0,MIN($B10+Inputs!$C$40,'Fiscal Terms'!$C$8)-'Fiscal Terms'!$C$6)*'Fiscal Terms'!$C$7+MAX(0,$B10+Inputs!$C$40-'Fiscal Terms'!$C$8)*'Fiscal Terms'!$C$9)*Inputs!$C$19/Inputs!$C$18-Inputs!$C$42-Inputs!$C$43)*(1-'Fiscal Terms'!$C$10))*Inputs!$C$21*((1-(1+G$5)^-Inputs!$C$22)/G$5)+NAV!$C$23+NAV!$C$24-Inputs!$C$27-Inputs!$C$28)*Inputs!$C$5/Inputs!$C$33 -> 18.901271
B12: BRENT (rows) versus SUSTAINING CAPEX PER BOE (columns)
B13: ↓ rows \ columns → | C13: 5.5 | D13: 6.5 | E13: 7.5 | F13: 8.5 | G13: 9.5
B14: 55 | C14: =((((Inputs!$C$19*($B14+Inputs!$C$40)+Inputs!$C$20*Inputs!$C$41)/Inputs!$C$18-(MIN($B14+Inputs!$C$40,'Fiscal Terms'!$C$6)*'Fiscal Terms'!$C$5+MAX(0,MIN($B14+Inputs!$C$40,'Fiscal Terms'!$C$8)-'Fiscal Terms'!$C$6)*'Fiscal Terms'!$C$7+MAX(0,$B14+Inputs!$C$40-'Fiscal Terms'!$C$8)*'Fiscal Terms'!$C$9)*Inputs!$C$19/Inputs!$C$18-Inputs!$C$42-C$13)*(1-'Fiscal Terms'!$C$10))*Inputs!$C$21*((1-(1+Inputs!$C$44)^-Inputs!$C$22)/Inputs!$C$44)+NAV!$C$23+NAV!$C$24-Inputs!$C$27-Inputs!$C$28)*Inputs!$C$5/Inputs!$C$33 -> 14.214963 | D14: =((((Inputs!$C$19*($B14+Inputs!$C$40)+Inputs!$C$20*Inputs!$C$41)/Inputs!$C$18-(MIN($B14+Inputs!$C$40,'Fiscal Terms'!$C$6)*'Fiscal Terms'!$C$5+MAX(0,MIN($B14+Inputs!$C$40,'Fiscal Terms'!$C$8)-'Fiscal Terms'!$C$6)*'Fiscal Terms'!$C$7+MAX(0,$B14+Inputs!$C$40-'Fiscal Terms'!$C$8)*'Fiscal Terms'!$C$9)*Inputs!$C$19/Inputs!$C$18-Inputs!$C$42-D$13)*(1-'Fiscal Terms'!$C$10))*Inputs!$C$21*((1-(1+Inputs!$C$44)^-Inputs!$C$22)/Inputs!$C$44)+NAV!$C$23+NAV!$C$24-Inputs!$C$27-Inputs!$C$28)*Inputs!$C$5/Inputs!$C$33 -> 13.766798 | E14: =((((Inputs!$C$19*($B14+Inputs!$C$40)+Inputs!$C$20*Inputs!$C$41)/Inputs!$C$18-(MIN($B14+Inputs!$C$40,'Fiscal Terms'!$C$6)*'Fiscal Terms'!$C$5+MAX(0,MIN($B14+Inputs!$C$40,'Fiscal Terms'!$C$8)-'Fiscal Terms'!$C$6)*'Fiscal Terms'!$C$7+MAX(0,$B14+Inputs!$C$40-'Fiscal Terms'!$C$8)*'Fiscal Terms'!$C$9)*Inputs!$C$19/Inputs!$C$18-Inputs!$C$42-E$13)*(1-'Fiscal Terms'!$C$10))*Inputs!$C$21*((1-(1+Inputs!$C$44)^-Inputs!$C$22)/Inputs!$C$44)+NAV!$C$23+NAV!$C$24-Inputs!$C$27-Inputs!$C$28)*Inputs!$C$5/Inputs!$C$33 -> 13.318633 | F14: =((((Inputs!$C$19*($B14+Inputs!$C$40)+Inputs!$C$20*Inputs!$C$41)/Inputs!$C$18-(MIN($B14+Inputs!$C$40,'Fiscal Terms'!$C$6)*'Fiscal Terms'!$C$5+MAX(0,MIN($B14+Inputs!$C$40,'Fiscal Terms'!$C$8)-'Fiscal Terms'!$C$6)*'Fiscal Terms'!$C$7+MAX(0,$B14+Inputs!$C$40-'Fiscal Terms'!$C$8)*'Fiscal Terms'!$C$9)*Inputs!$C$19/Inputs!$C$18-Inputs!$C$42-F$13)*(1-'Fiscal Terms'!$C$10))*Inputs!$C$21*((1-(1+Inputs!$C$44)^-Inputs!$C$22)/Inputs!$C$44)+NAV!$C$23+NAV!$C$24-Inputs!$C$27-Inputs!$C$28)*Inputs!$C$5/Inputs!$C$33 -> 12.870467 | G14: =((((Inputs!$C$19*($B14+Inputs!$C$40)+Inputs!$C$20*Inputs!$C$41)/Inputs!$C$18-(MIN($B14+Inputs!$C$40,'Fiscal Terms'!$C$6)*'Fiscal Terms'!$C$5+MAX(0,MIN($B14+Inputs!$C$40,'Fiscal Terms'!$C$8)-'Fiscal Terms'!$C$6)*'Fiscal Terms'!$C$7+MAX(0,$B14+Inputs!$C$40-'Fiscal Terms'!$C$8)*'Fiscal Terms'!$C$9)*Inputs!$C$19/Inputs!$C$18-Inputs!$C$42-G$13)*(1-'Fiscal Terms'!$C$10))*Inputs!$C$21*((1-(1+Inputs!$C$44)^-Inputs!$C$22)/Inputs!$C$44)+NAV!$C$23+NAV!$C$24-Inputs!$C$27-Inputs!$C$28)*Inputs!$C$5/Inputs!$C$33 -> 12.422302
B15: 62.5 | C15: =((((Inputs!$C$19*($B15+Inputs!$C$40)+Inputs!$C$20*Inputs!$C$41)/Inputs!$C$18-(MIN($B15+Inputs!$C$40,'Fiscal Terms'!$C$6)*'Fiscal Terms'!$C$5+MAX(0,MIN($B15+Inputs!$C$40,'Fiscal Terms'!$C$8)-'Fiscal Terms'!$C$6)*'Fiscal Terms'!$C$7+MAX(0,$B15+Inputs!$C$40-'Fiscal Terms'!$C$8)*'Fiscal Terms'!$C$9)*Inputs!$C$19/Inputs!$C$18-Inputs!$C$42-C$13)*(1-'Fiscal Terms'!$C$10))*Inputs!$C$21*((1-(1+Inputs!$C$44)^-Inputs!$C$22)/Inputs!$C$44)+NAV!$C$23+NAV!$C$24-Inputs!$C$27-Inputs!$C$28)*Inputs!$C$5/Inputs!$C$33 -> 16.584767 | D15: =((((Inputs!$C$19*($B15+Inputs!$C$40)+Inputs!$C$20*Inputs!$C$41)/Inputs!$C$18-(MIN($B15+Inputs!$C$40,'Fiscal Terms'!$C$6)*'Fiscal Terms'!$C$5+MAX(0,MIN($B15+Inputs!$C$40,'Fiscal Terms'!$C$8)-'Fiscal Terms'!$C$6)*'Fiscal Terms'!$C$7+MAX(0,$B15+Inputs!$C$40-'Fiscal Terms'!$C$8)*'Fiscal Terms'!$C$9)*Inputs!$C$19/Inputs!$C$18-Inputs!$C$42-D$13)*(1-'Fiscal Terms'!$C$10))*Inputs!$C$21*((1-(1+Inputs!$C$44)^-Inputs!$C$22)/Inputs!$C$44)+NAV!$C$23+NAV!$C$24-Inputs!$C$27-Inputs!$C$28)*Inputs!$C$5/Inputs!$C$33 -> 16.136602 | E15: =((((Inputs!$C$19*($B15+Inputs!$C$40)+Inputs!$C$20*Inputs!$C$41)/Inputs!$C$18-(MIN($B15+Inputs!$C$40,'Fiscal Terms'!$C$6)*'Fiscal Terms'!$C$5+MAX(0,MIN($B15+Inputs!$C$40,'Fiscal Terms'!$C$8)-'Fiscal Terms'!$C$6)*'Fiscal Terms'!$C$7+MAX(0,$B15+Inputs!$C$40-'Fiscal Terms'!$C$8)*'Fiscal Terms'!$C$9)*Inputs!$C$19/Inputs!$C$18-Inputs!$C$42-E$13)*(1-'Fiscal Terms'!$C$10))*Inputs!$C$21*((1-(1+Inputs!$C$44)^-Inputs!$C$22)/Inputs!$C$44)+NAV!$C$23+NAV!$C$24-Inputs!$C$27-Inputs!$C$28)*Inputs!$C$5/Inputs!$C$33 -> 15.688437 | F15: =((((Inputs!$C$19*($B15+Inputs!$C$40)+Inputs!$C$20*Inputs!$C$41)/Inputs!$C$18-(MIN($B15+Inputs!$C$40,'Fiscal Terms'!$C$6)*'Fiscal Terms'!$C$5+MAX(0,MIN($B15+Inputs!$C$40,'Fiscal Terms'!$C$8)-'Fiscal Terms'!$C$6)*'Fiscal Terms'!$C$7+MAX(0,$B15+Inputs!$C$40-'Fiscal Terms'!$C$8)*'Fiscal Terms'!$C$9)*Inputs!$C$19/Inputs!$C$18-Inputs!$C$42-F$13)*(1-'Fiscal Terms'!$C$10))*Inputs!$C$21*((1-(1+Inputs!$C$44)^-Inputs!$C$22)/Inputs!$C$44)+NAV!$C$23+NAV!$C$24-Inputs!$C$27-Inputs!$C$28)*Inputs!$C$5/Inputs!$C$33 -> 15.240272 | G15: =((((Inputs!$C$19*($B15+Inputs!$C$40)+Inputs!$C$20*Inputs!$C$41)/Inputs!$C$18-(MIN($B15+Inputs!$C$40,'Fiscal Terms'!$C$6)*'Fiscal Terms'!$C$5+MAX(0,MIN($B15+Inputs!$C$40,'Fiscal Terms'!$C$8)-'Fiscal Terms'!$C$6)*'Fiscal Terms'!$C$7+MAX(0,$B15+Inputs!$C$40-'Fiscal Terms'!$C$8)*'Fiscal Terms'!$C$9)*Inputs!$C$19/Inputs!$C$18-Inputs!$C$42-G$13)*(1-'Fiscal Terms'!$C$10))*Inputs!$C$21*((1-(1+Inputs!$C$44)^-Inputs!$C$22)/Inputs!$C$44)+NAV!$C$23+NAV!$C$24-Inputs!$C$27-Inputs!$C$28)*Inputs!$C$5/Inputs!$C$33 -> 14.792106
B16: 70 | C16: =((((Inputs!$C$19*($B16+Inputs!$C$40)+Inputs!$C$20*Inputs!$C$41)/Inputs!$C$18-(MIN($B16+Inputs!$C$40,'Fiscal Terms'!$C$6)*'Fiscal Terms'!$C$5+MAX(0,MIN($B16+Inputs!$C$40,'Fiscal Terms'!$C$8)-'Fiscal Terms'!$C$6)*'Fiscal Terms'!$C$7+MAX(0,$B16+Inputs!$C$40-'Fiscal Terms'!$C$8)*'Fiscal Terms'!$C$9)*Inputs!$C$19/Inputs!$C$18-Inputs!$C$42-C$13)*(1-'Fiscal Terms'!$C$10))*Inputs!$C$21*((1-(1+Inputs!$C$44)^-Inputs!$C$22)/Inputs!$C$44)+NAV!$C$23+NAV!$C$24-Inputs!$C$27-Inputs!$C$28)*Inputs!$C$5/Inputs!$C$33 -> 18.954571 | D16: =((((Inputs!$C$19*($B16+Inputs!$C$40)+Inputs!$C$20*Inputs!$C$41)/Inputs!$C$18-(MIN($B16+Inputs!$C$40,'Fiscal Terms'!$C$6)*'Fiscal Terms'!$C$5+MAX(0,MIN($B16+Inputs!$C$40,'Fiscal Terms'!$C$8)-'Fiscal Terms'!$C$6)*'Fiscal Terms'!$C$7+MAX(0,$B16+Inputs!$C$40-'Fiscal Terms'!$C$8)*'Fiscal Terms'!$C$9)*Inputs!$C$19/Inputs!$C$18-Inputs!$C$42-D$13)*(1-'Fiscal Terms'!$C$10))*Inputs!$C$21*((1-(1+Inputs!$C$44)^-Inputs!$C$22)/Inputs!$C$44)+NAV!$C$23+NAV!$C$24-Inputs!$C$27-Inputs!$C$28)*Inputs!$C$5/Inputs!$C$33 -> 18.506406 | E16: =((((Inputs!$C$19*($B16+Inputs!$C$40)+Inputs!$C$20*Inputs!$C$41)/Inputs!$C$18-(MIN($B16+Inputs!$C$40,'Fiscal Terms'!$C$6)*'Fiscal Terms'!$C$5+MAX(0,MIN($B16+Inputs!$C$40,'Fiscal Terms'!$C$8)-'Fiscal Terms'!$C$6)*'Fiscal Terms'!$C$7+MAX(0,$B16+Inputs!$C$40-'Fiscal Terms'!$C$8)*'Fiscal Terms'!$C$9)*Inputs!$C$19/Inputs!$C$18-Inputs!$C$42-E$13)*(1-'Fiscal Terms'!$C$10))*Inputs!$C$21*((1-(1+Inputs!$C$44)^-Inputs!$C$22)/Inputs!$C$44)+NAV!$C$23+NAV!$C$24-Inputs!$C$27-Inputs!$C$28)*Inputs!$C$5/Inputs!$C$33 -> 18.058241 | F16: =((((Inputs!$C$19*($B16+Inputs!$C$40)+Inputs!$C$20*Inputs!$C$41)/Inputs!$C$18-(MIN($B16+Inputs!$C$40,'Fiscal Terms'!$C$6)*'Fiscal Terms'!$C$5+MAX(0,MIN($B16+Inputs!$C$40,'Fiscal Terms'!$C$8)-'Fiscal Terms'!$C$6)*'Fiscal Terms'!$C$7+MAX(0,$B16+Inputs!$C$40-'Fiscal Terms'!$C$8)*'Fiscal Terms'!$C$9)*Inputs!$C$19/Inputs!$C$18-Inputs!$C$42-F$13)*(1-'Fiscal Terms'!$C$10))*Inputs!$C$21*((1-(1+Inputs!$C$44)^-Inputs!$C$22)/Inputs!$C$44)+NAV!$C$23+NAV!$C$24-Inputs!$C$27-Inputs!$C$28)*Inputs!$C$5/Inputs!$C$33 -> 17.610076 | G16: =((((Inputs!$C$19*($B16+Inputs!$C$40)+Inputs!$C$20*Inputs!$C$41)/Inputs!$C$18-(MIN($B16+Inputs!$C$40,'Fiscal Terms'!$C$6)*'Fiscal Terms'!$C$5+MAX(0,MIN($B16+Inputs!$C$40,'Fiscal Terms'!$C$8)-'Fiscal Terms'!$C$6)*'Fiscal Terms'!$C$7+MAX(0,$B16+Inputs!$C$40-'Fiscal Terms'!$C$8)*'Fiscal Terms'!$C$9)*Inputs!$C$19/Inputs!$C$18-Inputs!$C$42-G$13)*(1-'Fiscal Terms'!$C$10))*Inputs!$C$21*((1-(1+Inputs!$C$44)^-Inputs!$C$22)/Inputs!$C$44)+NAV!$C$23+NAV!$C$24-Inputs!$C$27-Inputs!$C$28)*Inputs!$C$5/Inputs!$C$33 -> 17.16191
B17: 77.5 | C17: =((((Inputs!$C$19*($B17+Inputs!$C$40)+Inputs!$C$20*Inputs!$C$41)/Inputs!$C$18-(MIN($B17+Inputs!$C$40,'Fiscal Terms'!$C$6)*'Fiscal Terms'!$C$5+MAX(0,MIN($B17+Inputs!$C$40,'Fiscal Terms'!$C$8)-'Fiscal Terms'!$C$6)*'Fiscal Terms'!$C$7+MAX(0,$B17+Inputs!$C$40-'Fiscal Terms'!$C$8)*'Fiscal Terms'!$C$9)*Inputs!$C$19/Inputs!$C$18-Inputs!$C$42-C$13)*(1-'Fiscal Terms'!$C$10))*Inputs!$C$21*((1-(1+Inputs!$C$44)^-Inputs!$C$22)/Inputs!$C$44)+NAV!$C$23+NAV!$C$24-Inputs!$C$27-Inputs!$C$28)*Inputs!$C$5/Inputs!$C$33 -> 20.487974 | D17: =((((Inputs!$C$19*($B17+Inputs!$C$40)+Inputs!$C$20*Inputs!$C$41)/Inputs!$C$18-(MIN($B17+Inputs!$C$40,'Fiscal Terms'!$C$6)*'Fiscal Terms'!$C$5+MAX(0,MIN($B17+Inputs!$C$40,'Fiscal Terms'!$C$8)-'Fiscal Terms'!$C$6)*'Fiscal Terms'!$C$7+MAX(0,$B17+Inputs!$C$40-'Fiscal Terms'!$C$8)*'Fiscal Terms'!$C$9)*Inputs!$C$19/Inputs!$C$18-Inputs!$C$42-D$13)*(1-'Fiscal Terms'!$C$10))*Inputs!$C$21*((1-(1+Inputs!$C$44)^-Inputs!$C$22)/Inputs!$C$44)+NAV!$C$23+NAV!$C$24-Inputs!$C$27-Inputs!$C$28)*Inputs!$C$5/Inputs!$C$33 -> 20.039809 | E17: =((((Inputs!$C$19*($B17+Inputs!$C$40)+Inputs!$C$20*Inputs!$C$41)/Inputs!$C$18-(MIN($B17+Inputs!$C$40,'Fiscal Terms'!$C$6)*'Fiscal Terms'!$C$5+MAX(0,MIN($B17+Inputs!$C$40,'Fiscal Terms'!$C$8)-'Fiscal Terms'!$C$6)*'Fiscal Terms'!$C$7+MAX(0,$B17+Inputs!$C$40-'Fiscal Terms'!$C$8)*'Fiscal Terms'!$C$9)*Inputs!$C$19/Inputs!$C$18-Inputs!$C$42-E$13)*(1-'Fiscal Terms'!$C$10))*Inputs!$C$21*((1-(1+Inputs!$C$44)^-Inputs!$C$22)/Inputs!$C$44)+NAV!$C$23+NAV!$C$24-Inputs!$C$27-Inputs!$C$28)*Inputs!$C$5/Inputs!$C$33 -> 19.591644 | F17: =((((Inputs!$C$19*($B17+Inputs!$C$40)+Inputs!$C$20*Inputs!$C$41)/Inputs!$C$18-(MIN($B17+Inputs!$C$40,'Fiscal Terms'!$C$6)*'Fiscal Terms'!$C$5+MAX(0,MIN($B17+Inputs!$C$40,'Fiscal Terms'!$C$8)-'Fiscal Terms'!$C$6)*'Fiscal Terms'!$C$7+MAX(0,$B17+Inputs!$C$40-'Fiscal Terms'!$C$8)*'Fiscal Terms'!$C$9)*Inputs!$C$19/Inputs!$C$18-Inputs!$C$42-F$13)*(1-'Fiscal Terms'!$C$10))*Inputs!$C$21*((1-(1+Inputs!$C$44)^-Inputs!$C$22)/Inputs!$C$44)+NAV!$C$23+NAV!$C$24-Inputs!$C$27-Inputs!$C$28)*Inputs!$C$5/Inputs!$C$33 -> 19.143478 | G17: =((((Inputs!$C$19*($B17+Inputs!$C$40)+Inputs!$C$20*Inputs!$C$41)/Inputs!$C$18-(MIN($B17+Inputs!$C$40,'Fiscal Terms'!$C$6)*'Fiscal Terms'!$C$5+MAX(0,MIN($B17+Inputs!$C$40,'Fiscal Terms'!$C$8)-'Fiscal Terms'!$C$6)*'Fiscal Terms'!$C$7+MAX(0,$B17+Inputs!$C$40-'Fiscal Terms'!$C$8)*'Fiscal Terms'!$C$9)*Inputs!$C$19/Inputs!$C$18-Inputs!$C$42-G$13)*(1-'Fiscal Terms'!$C$10))*Inputs!$C$21*((1-(1+Inputs!$C$44)^-Inputs!$C$22)/Inputs!$C$44)+NAV!$C$23+NAV!$C$24-Inputs!$C$27-Inputs!$C$28)*Inputs!$C$5/Inputs!$C$33 -> 18.695313
B18: 85 | C18: =((((Inputs!$C$19*($B18+Inputs!$C$40)+Inputs!$C$20*Inputs!$C$41)/Inputs!$C$18-(MIN($B18+Inputs!$C$40,'Fiscal Terms'!$C$6)*'Fiscal Terms'!$C$5+MAX(0,MIN($B18+Inputs!$C$40,'Fiscal Terms'!$C$8)-'Fiscal Terms'!$C$6)*'Fiscal Terms'!$C$7+MAX(0,$B18+Inputs!$C$40-'Fiscal Terms'!$C$8)*'Fiscal Terms'!$C$9)*Inputs!$C$19/Inputs!$C$18-Inputs!$C$42-C$13)*(1-'Fiscal Terms'!$C$10))*Inputs!$C$21*((1-(1+Inputs!$C$44)^-Inputs!$C$22)/Inputs!$C$44)+NAV!$C$23+NAV!$C$24-Inputs!$C$27-Inputs!$C$28)*Inputs!$C$5/Inputs!$C$33 -> 22.021377 | D18: =((((Inputs!$C$19*($B18+Inputs!$C$40)+Inputs!$C$20*Inputs!$C$41)/Inputs!$C$18-(MIN($B18+Inputs!$C$40,'Fiscal Terms'!$C$6)*'Fiscal Terms'!$C$5+MAX(0,MIN($B18+Inputs!$C$40,'Fiscal Terms'!$C$8)-'Fiscal Terms'!$C$6)*'Fiscal Terms'!$C$7+MAX(0,$B18+Inputs!$C$40-'Fiscal Terms'!$C$8)*'Fiscal Terms'!$C$9)*Inputs!$C$19/Inputs!$C$18-Inputs!$C$42-D$13)*(1-'Fiscal Terms'!$C$10))*Inputs!$C$21*((1-(1+Inputs!$C$44)^-Inputs!$C$22)/Inputs!$C$44)+NAV!$C$23+NAV!$C$24-Inputs!$C$27-Inputs!$C$28)*Inputs!$C$5/Inputs!$C$33 -> 21.573212 | E18: =((((Inputs!$C$19*($B18+Inputs!$C$40)+Inputs!$C$20*Inputs!$C$41)/Inputs!$C$18-(MIN($B18+Inputs!$C$40,'Fiscal Terms'!$C$6)*'Fiscal Terms'!$C$5+MAX(0,MIN($B18+Inputs!$C$40,'Fiscal Terms'!$C$8)-'Fiscal Terms'!$C$6)*'Fiscal Terms'!$C$7+MAX(0,$B18+Inputs!$C$40-'Fiscal Terms'!$C$8)*'Fiscal Terms'!$C$9)*Inputs!$C$19/Inputs!$C$18-Inputs!$C$42-E$13)*(1-'Fiscal Terms'!$C$10))*Inputs!$C$21*((1-(1+Inputs!$C$44)^-Inputs!$C$22)/Inputs!$C$44)+NAV!$C$23+NAV!$C$24-Inputs!$C$27-Inputs!$C$28)*Inputs!$C$5/Inputs!$C$33 -> 21.125046 | F18: =((((Inputs!$C$19*($B18+Inputs!$C$40)+Inputs!$C$20*Inputs!$C$41)/Inputs!$C$18-(MIN($B18+Inputs!$C$40,'Fiscal Terms'!$C$6)*'Fiscal Terms'!$C$5+MAX(0,MIN($B18+Inputs!$C$40,'Fiscal Terms'!$C$8)-'Fiscal Terms'!$C$6)*'Fiscal Terms'!$C$7+MAX(0,$B18+Inputs!$C$40-'Fiscal Terms'!$C$8)*'Fiscal Terms'!$C$9)*Inputs!$C$19/Inputs!$C$18-Inputs!$C$42-F$13)*(1-'Fiscal Terms'!$C$10))*Inputs!$C$21*((1-(1+Inputs!$C$44)^-Inputs!$C$22)/Inputs!$C$44)+NAV!$C$23+NAV!$C$24-Inputs!$C$27-Inputs!$C$28)*Inputs!$C$5/Inputs!$C$33 -> 20.676881 | G18: =((((Inputs!$C$19*($B18+Inputs!$C$40)+Inputs!$C$20*Inputs!$C$41)/Inputs!$C$18-(MIN($B18+Inputs!$C$40,'Fiscal Terms'!$C$6)*'Fiscal Terms'!$C$5+MAX(0,MIN($B18+Inputs!$C$40,'Fiscal Terms'!$C$8)-'Fiscal Terms'!$C$6)*'Fiscal Terms'!$C$7+MAX(0,$B18+Inputs!$C$40-'Fiscal Terms'!$C$8)*'Fiscal Terms'!$C$9)*Inputs!$C$19/Inputs!$C$18-Inputs!$C$42-G$13)*(1-'Fiscal Terms'!$C$10))*Inputs!$C$21*((1-(1+Inputs!$C$44)^-Inputs!$C$22)/Inputs!$C$44)+NAV!$C$23+NAV!$C$24-Inputs!$C$27-Inputs!$C$28)*Inputs!$C$5/Inputs!$C$33 -> 20.228716

Sheet Summary
B1: Saudi Aramco — Energy NAV and Price-Deck Sensitivity | F1: SAUDI ARAMCO
B2: Aramco on one page
B4: THE NETBACK AT US$70 BRENT
B5: Blended realisation per boe (US$) | C5: =NAV!$C$5 -> 60.620155
B6: After-tax cash netback per boe (US$) | C6: =NAV!$C$11 -> 20.205426
B7: Share of the barrel Aramco keeps after royalty, costs, capex and tax | C7: =NAV!$C$12 -> 0.33331202
B8: Government take on an incremental dollar above US$100 | C8: ='Fiscal Terms'!$C$17 -> 0.9
B10: NET ASSET VALUE
B11: Upstream value (US$ bn) | C11: =NAV!$C$17 -> 1168.2992
B12: per boe of proved reserves (US$) | C12: =NAV!$C$18 -> 4.7261296
B13: Downstream value (US$ bn) | C13: =NAV!$C$23 -> 140
B14: Net asset value (US$ bn) | C14: =NAV!$C$30 -> 1164.9126
B15: NAV per share (SAR) | C15: =NAV!$C$31 -> 18.058241
B16: Share price (SAR) | C16: =NAV!$C$32 -> 25.56
B17: Upside / (downside) | C17: =NAV!$C$33 -> -0.29349605
B18: Brent the price implies at an 8% discount rate (US$/bbl) | C18: ='Price Deck'!$C$22 -> 118.40225
B19: Discount rate the price implies at US$70 Brent | C19: ='Price Deck'!$C$23 -> 0.056881591
B21: THE DIVIDEND
B22: Base dividend, annualised (US$ bn) | C22: =Inputs!$C$13 -> 87.5
B23: Base dividend yield at the price | C23: =Inputs!$C$36 -> 0.053067584
B24: Group free cash flow at US$70 (US$ bn) | C24: ='Price Deck'!$E$10 -> 90.251
B25: Base dividend cover at US$70 | C25: ='Price Deck'!$E$11 -> 1.03144
B26: Brent at which the base dividend is exactly covered (US$/bbl) | C26: ='Price Deck'!$C$20 -> 68.342609
B28: • Aramco keeps a little over a quarter of each barrel. Royalty, costs, sustaining capex and a 50% tax take the rest, and the sliding royalty means the equity captures ten cents of every dollar above US$100. The shares are a claim on volume and cost, not on the oil price.
B29: • On a flat US$70 deck at an 8% discount rate the NAV is about 30% below the share price. For the price to be right at 8%, Brent would have to sit near US$120 for ever, which nobody assumes. The alternative reading is a discount rate under 6%: the market treats Aramco as a quasi-sovereign yield instrument, and most of the float is held by the state and its funds. The premium is a discount-rate premium, not an oil bet.
B30: • Reserves are valued at a small fraction of what an international major's would fetch per barrel. That is not a discount to be closed — it is the arithmetic of who owns the barrel. Fifty-two years of reserve life adds almost nothing beyond year thirty at an 8% discount rate.
B31: • The dividend, not the NAV, is the live question. The base payout alone needs Brent in the high sixties to be covered from free cash flow after a US$52bn capex programme. Below that the balance sheet or asset sales fund the gap, as they did in 2024 and 2025.

Sheet Checks
B1: Saudi Aramco — Energy NAV and Price-Deck Sensitivity | E1: SAUDI ARAMCO
B2: Every check must read TRUE
B4: INTEGRITY CHECKS
B5: Reserve life is between 40 and 60 years | C5: =AND(Inputs!$C$22>40,Inputs!$C$22<60) -> TRUE
B6: Royalty per barrel at the base price reproduces the schedule by hand | C6: =ABS('Fiscal Terms'!$C$15-(MIN('Fiscal Terms'!$C$14,70)*0.15+MAX(0,MIN('Fiscal Terms'!$C$14,100)-70)*0.45+MAX(0,'Fiscal Terms'!$C$14-100)*0.8))<0.0001 -> TRUE
B7: Royalty is non-decreasing across the price deck | C7: =AND('Price Deck'!$D$7>='Price Deck'!$C$7,'Price Deck'!$E$7>='Price Deck'!$D$7,'Price Deck'!$F$7>='Price Deck'!$E$7,'Price Deck'!$G$7>='Price Deck'!$F$7,'Price Deck'!$H$7>='Price Deck'!$G$7,'Price Deck'!$I$7>='Price Deck'!$H$7) -> TRUE
B8: Netback is increasing across the price deck | C8: =AND('Price Deck'!$D$8>'Price Deck'!$C$8,'Price Deck'!$E$8>'Price Deck'!$D$8,'Price Deck'!$F$8>'Price Deck'!$E$8,'Price Deck'!$G$8>'Price Deck'!$F$8,'Price Deck'!$H$8>'Price Deck'!$G$8,'Price Deck'!$I$8>'Price Deck'!$H$8) -> TRUE
B9: Base-case netback ties to the US$70 deck column | C9: =ABS(NAV!$C$11-'Price Deck'!$E$8)<0.0001 -> TRUE
B10: Base-case NAV per share ties to the US$70 deck column | C10: =ABS(NAV!$C$31-'Price Deck'!$E$16)<0.001 -> TRUE
B11: Model rebuild of FY2025 group free cash flow is within 20% of the reported figure | C11: =ABS(NAV!$C$19)<0.2 -> TRUE
B12: Annuity factor is below 1 / discount rate | C12: =NAV!$C$16<1/Inputs!$C$44 -> TRUE
B13: Dividend break-even solved on the first royalty leg is below the first threshold | C13: ='Price Deck'!$C$20<'Fiscal Terms'!$C$6 -> TRUE
B14: Dividend break-even reproduces exactly when substituted (cover = 1.0x) | C14: =ABS(((Inputs!$C$19/Inputs!$C$18*(1-'Fiscal Terms'!$C$5)*(1-'Fiscal Terms'!$C$10)*Inputs!$C$21)*'Price Deck'!$C$20+((Inputs!$C$20*Inputs!$C$41/Inputs!$C$18-Inputs!$C$42-Inputs!$C$43+Inputs!$C$19/Inputs!$C$18*Inputs!$C$40*(1-'Fiscal Terms'!$C$5))*(1-'Fiscal Terms'!$C$10)*Inputs!$C$21+(Inputs!$C$9+Inputs!$C$45)*(1-'Fiscal Terms'!$C$11)-(Inputs!$C$10-Inputs!$C$43*Inputs!$C$21)-Inputs!$C$47))/Inputs!$C$13-1)<0.0001 -> TRUE
B15: Price-implied Brent reproduces the market capitalisation when substituted | C15: =ABS((((Inputs!$C$19*('Price Deck'!$C$22+Inputs!$C$40)+Inputs!$C$20*Inputs!$C$41)/Inputs!$C$18-(MIN('Price Deck'!$C$22+Inputs!$C$40,'Fiscal Terms'!$C$6)*'Fiscal Terms'!$C$5+MAX(0,MIN('Price Deck'!$C$22+Inputs!$C$40,'Fiscal Terms'!$C$8)-'Fiscal Terms'!$C$6)*'Fiscal Terms'!$C$7+MAX(0,'Price Deck'!$C$22+Inputs!$C$40-'Fiscal Terms'!$C$8)*'Fiscal Terms'!$C$9)*Inputs!$C$19/Inputs!$C$18-Inputs!$C$42-Inputs!$C$43)*(1-'Fiscal Terms'!$C$10)*Inputs!$C$21)*NAV!$C$16+NAV!$C$23+NAV!$C$24-Inputs!$C$27-Inputs!$C$28-Inputs!$C$34)<0.5 -> TRUE
B16: Price-implied discount rate is below the model discount rate when the price exceeds NAV | C16: =IF(Inputs!$C$32>NAV!$C$31,'Price Deck'!$C$23<Inputs!$C$44,TRUE()) -> TRUE
B17: Base sensitivity cell reconciles to the NAV sheet | C17: =ABS(Sensitivity!E8-NAV!$C$31)<0.001 -> TRUE
B18: Market capitalisation reconciles to price times shares over the peg | C18: =ABS(Inputs!$C$34-Inputs!$C$32*Inputs!$C$33/Inputs!$C$5)<0.01 -> TRUE
B19: Share price lies within the 52-week range | C19: =AND(Inputs!$C$32>=23.29-0.1,Inputs!$C$32<=27.96+0.1) -> TRUE
B21: MODEL STATUS | C21: =IF(COUNTIF(C5:C19,FALSE())=0,"MODEL OK","CHECK FAILED") -> MODEL OK
B23: The seventh check rebuilds Aramco's reported free cash flow from a per-barrel netback and demands it land within 20% of the audited figure. A reserves model that cannot reproduce last year's cash is a spreadsheet, not a valuation.
