Workbook

Sheet Cover
B3: IB PORTFOLIO · PROJECT 09 OF 20
B4: DEWA
B5: IPO Valuation and Pricing Rebuild (April 2022)
B6: DFM: DEWA · AED millions · per-share values in AED · as of FY2021 prospectus figures · aftermarket to 18 Sep 2026
B9: What this is | C9: A rebuild of the April 2022 DEWA initial public offering from public announcements: the valuation on FY2021 information by three methods, the pricing inside the range and the mechanics of the book and the upsizing, the discount measured on the first day of trading, and the four-year record since against what the IPO case assumed.
B11: How it is built | C11: • Valuation by dividend yield on the committed AED 6.2 billion payout, EV / EBITDA on FY2021 adjusted EBITDA, and a five-year DCF — all on information available at the time, with today's utility multiples shown for context only.
C12: • Pricing and book: market capitalisation across the range, proceeds, cornerstone share, coverage of the open book reproducing the announced 37 times, and the coverage the original 6.5% deal would have shown.
C13: • The IPO discount from unadjusted first-day prices, money left on the table against fees, and the price that would have left a 10% first-day rise.
C14: • Aftermarket: total return with dividends, EBITDA growth delivered against assumed, and the multiple then and now.
B16: Contents | C16: Summary — deal, valuation, verdict
C17: Valuation — yield, multiple and DCF against the range
C18: Pricing & Book — size, proceeds, cornerstones, coverage, discount
C19: Aftermarket — returns to an IPO investor, delivery against the case, re-rating
C20: Sensitivity — yield method and DCF grids
C21: Inputs — deal terms, FY2021 figures, assumptions, aftermarket data
C22: Checks — fourteen tests; must read MODEL OK
B24: Key outputs (live) | C24: Final price (AED) | E24: =Inputs!$C$8 -> 2.48
C25: Gross proceeds (AED m) | E25: ='Pricing & Book'!$C$13 -> 22320
C26: Open-book coverage | E26: ='Pricing & Book'!$C$21 -> 36.971831
C27: First-day rise | E27: ='Pricing & Book'!$C$27 -> 0.15725806
C28: Money left on the table (AED m) | E28: ='Pricing & Book'!$C$29 -> 3510
C29: Total return to date, with dividends | E29: =Aftermarket!$C$9 -> 0.30483871
B31: Colour code | C31: Blue = hard-coded input
C32: Black = formula
C33: Green = link to another sheet
C34: Accent fill = scenario selector / key levers
B36: Sources | C36: DEWA PJSC price-range announcement (24 March 2022), final-price announcement (6 April 2022) and IPO FAQ: deal terms, cornerstone commitments, demand, FY2021 revenue, adjusted EBITDA, net income and leverage.
C37: Aftermarket prices: Dubai Financial Market via Yahoo Finance, unadjusted. FY2022–FY2025 financials via Yahoo Finance for DEWA.AE.
C38: Target yields, peer multiples at April 2022 levels, DCF assumptions and the fee rate are stated inputs; today's peer multiples are shown for context and are not used in the valuation.
C39: Nothing here is a recommendation. The rebuild is an analytical exercise on public information.
B41: Prepared by | C41: Jainam Mehta · github.com/jainammehta1215/ib-portfolio

Sheet Inputs
B1: DEWA — IPO Valuation and Pricing Rebuild (April 2022) | F1: DEWA
B2: Deal terms, FY2021 financials, valuation assumptions and the aftermarket record
B4: DEAL TERMS AS ANNOUNCED
B5: Shares in issue (millions) | C5: 50000
B6: Price range — low (AED) | C6: 2.25 | F6: 24 March 2022
B7: Price range — high (AED) | C7: 2.48
B8: Final offer price (AED) | C8: 2.48 | F8: 6 April 2022; the top of the range
B9: Shares offered at launch (millions) | C9: 3250 | F9: 6.5% of the company
B10: Shares offered at pricing (millions) | C10: 9000 | F10: Upsized to 18%
B11: Cornerstone commitments at launch | C11: 4700
B12: Cornerstone and strategic commitments at pricing | C12: 13800
B13: Total demand excluding cornerstones | C13: 315000 | F13: AED 315 billion, per the final-price announcement
B14: Assumed gross underwriting and advisory fees, % of proceeds | C14: 0.0175 | F14: Stated assumption; large sovereign deals in the region price below the 3–5% global norm
B16: FY2021 FINANCIALS FROM THE PROSPECTUS SUMMARY
B17: Revenue | C17: 23800 | F17: Over 95% regulated or contracted
B18: Adjusted EBITDA | C18: 12100
B19: Net income | C19: 6600
B20: Net debt / EBITDA | C20: 1.5
B21: Net debt, derived | C21: =Inputs!$C$20*Inputs!$C$18 -> 18150
B22: Non-controlling interests (Empower minority, FY2022 balance sheet as proxy) | C22: 2953
B23: Committed annual dividend, first five years | C23: 6200 | F23: AED 6.2 billion a year, paid in two instalments — the centre of the equity story
B24: Committed dividend per share (AED) | C24: =Inputs!$C$23/Inputs!$C$5 -> 0.124
B26: VALUATION ASSUMPTIONS — stated inputs at April 2022 levels
B27: Target dividend yield — demanding investor | C27: 0.055 | F27: Where Gulf and European integrated utilities traded in spring 2022
B28: Target dividend yield — generous investor | C28: 0.045
B29: EV / EBITDA — low | C29: 10 | F29: Regulated networks and integrated utilities; today's peer median is on the Valuation sheet
B30: EV / EBITDA — high | C30: 12.5
B31: EBITDA growth, five years | C31: 0.045 | F31: Dubai population and demand growth; FY2021–FY2025 actual was 10.9% a year
B32: Capital expenditure per year | C32: 8000
B33: UAE corporate tax from 2023 (applied to EBIT) | C33: 0.09
B34: Depreciation as % of EBITDA | C34: 0.45
B35: Weighted average cost of capital | C35: 0.065 | F35: A dirham-pegged regulated utility with 1.5x leverage
B36: Terminal growth | C36: 0.02
B38: AFTERMARKET (AED per share, unadjusted, DFM)
B39: First-day open, 12 April 2022 | C39: 2.98
B40: First-day high | C40: 3.05
B41: First-day close | C41: 2.87
B42: Close one year after listing, 12 April 2023 | C42: 2.47
B43: Close 18 September 2026 | C43: 2.74
B44: Dividends received per share since listing (AED) | C44: 0.496 | F44: Eight semi-annual instalments of AED 0.062 under the policy
...

Sheet Valuation
B1: DEWA — IPO Valuation and Pricing Rebuild (April 2022) | F1: DEWA
B2: Three methods on FY2021 information, against the price range
B4: 1. DIVIDEND YIELD ON THE COMMITTED PAYOUT
B5: Equity value at the demanding yield | C5: =Inputs!$C$23/Inputs!$C$27 -> 112727.27
B6: Equity value at the generous yield | C6: =Inputs!$C$23/Inputs!$C$28 -> 137777.78
B7: per share, low (AED) | C7: =Valuation!$C$5/Inputs!$C$5 -> 2.2545455
B8: per share, high (AED) | C8: =Valuation!$C$6/Inputs!$C$5 -> 2.7555556
B9: Yield at the final price | C9: =Inputs!$C$24/Inputs!$C$8 -> 0.05 | F9: Exactly 5.0%: the price was set so that the committed dividend delivered a round yield
B11: 2. EV / EBITDA ON FY2021 ADJUSTED EBITDA
B12: Enterprise value, low multiple | C12: =Inputs!$C$18*Inputs!$C$29 -> 121000
B13: Enterprise value, high multiple | C13: =Inputs!$C$18*Inputs!$C$30 -> 151250
B14: Equity value, low (EV − net debt − minorities) | C14: =Valuation!$C$12-Inputs!$C$21-Inputs!$C$22 -> 99897
B15: Equity value, high | C15: =Valuation!$C$13-Inputs!$C$21-Inputs!$C$22 -> 130147
B16: per share, low (AED) | C16: =Valuation!$C$14/Inputs!$C$5 -> 1.99794
B17: per share, high (AED) | C17: =Valuation!$C$15/Inputs!$C$5 -> 2.60294
B18: EV / EBITDA at the final price | C18: =(Inputs!$C$8*Inputs!$C$5+Inputs!$C$21+Inputs!$C$22)/Inputs!$C$18 -> 11.991983
B19: P / E at the final price | C19: =Inputs!$C$8*Inputs!$C$5/Inputs!$C$19 -> 18.787879
B20: Where utilities trade today (18 Sep 2026, trailing EV / EBITDA) — context, not an input
B21: Enel | C21: 8.4
B22: Engie | C22: 9.3
B23: Saudi Electricity | C23: 7.1
B24: Duke Energy | C24: 11.3
B25: Consolidated Edison | C25: 10.8
B26: Empower (Dubai) | C26: 11.6
B27: Tabreed | C27: 12.1
B28: Iberdrola | C28: 13.9
B29: National Grid | C29: 14.6
B30: Median | C30: =MEDIAN(C21:C29) -> 11.3
B32: 3. DISCOUNTED CASH FLOW, FIVE YEARS
B33: Year | C33: FY2022E | D33: FY2023E | E33: FY2024E | F33: FY2025E | G33: FY2026E
B34: EBITDA | C34: =Inputs!$C$18*(1+Inputs!$C$31)^1 -> 12644.5 | D34: =Inputs!$C$18*(1+Inputs!$C$31)^2 -> 13213.503 | E34: =Inputs!$C$18*(1+Inputs!$C$31)^3 -> 13808.11 | F34: =Inputs!$C$18*(1+Inputs!$C$31)^4 -> 14429.475 | G34: =Inputs!$C$18*(1+Inputs!$C$31)^5 -> 15078.801
B35: Depreciation | C35: =C34*Inputs!$C$34 -> 5690.025 | D35: =D34*Inputs!$C$34 -> 5946.0761 | E35: =E34*Inputs!$C$34 -> 6213.6496 | F35: =F34*Inputs!$C$34 -> 6493.2638 | G35: =G34*Inputs!$C$34 -> 6785.4607
B36: Tax on EBIT (from 2023) | C36: =-IF(0>=1,(C34-C35)*Inputs!$C$33,0) -> 0 | D36: =-IF(1>=1,(D34-D35)*Inputs!$C$33,0) -> -654.06837 | E36: =-IF(2>=1,(E34-E35)*Inputs!$C$33,0) -> -683.50145 | F36: =-IF(3>=1,(F34-F35)*Inputs!$C$33,0) -> -714.25902 | G36: =-IF(4>=1,(G34-G35)*Inputs!$C$33,0) -> -746.40067
B37: Capital expenditure | C37: =-Inputs!$C$32 -> -8000 | D37: =-Inputs!$C$32 -> -8000 | E37: =-Inputs!$C$32 -> -8000 | F37: =-Inputs!$C$32 -> -8000 | G37: =-Inputs!$C$32 -> -8000
B38: Free cash flow to the firm | C38: =C34+C36+C37 -> 4644.5 | D38: =D34+D36+D37 -> 4559.4341 | E38: =E34+E36+E37 -> 5124.6087 | F38: =F34+F36+F37 -> 5715.2161 | G38: =G34+G36+G37 -> 6332.4008
B39: Discount factor | C39: =1/(1+Inputs!$C$35)^1 -> 0.93896714 | D39: =1/(1+Inputs!$C$35)^2 -> 0.88165928 | E39: =1/(1+Inputs!$C$35)^3 -> 0.82784909 | F39: =1/(1+Inputs!$C$35)^4 -> 0.77732309 | G39: =1/(1+Inputs!$C$35)^5 -> 0.72988084
B40: Present value | C40: =C38*C39 -> 4361.0329 | D40: =D38*D39 -> 4019.8674 | E40: =E38*E39 -> 4242.4026 | F40: =F38*F39 -> 4442.5694 | G40: =G38*G39 -> 4621.898
B42: Terminal value at end FY2026E | C42: =G38*(1+Inputs!$C$36)/(Inputs!$C$35-Inputs!$C$36) -> 143534.42
B43: Present value of terminal value | C43: =Valuation!$C$42*G39 -> 104763.02
B44: Enterprise value | C44: =SUM(C40:G40)+Valuation!$C$43 -> 126450.79
...

Sheet Pricing & Book
B1: DEWA — IPO Valuation and Pricing Rebuild (April 2022) | F1: DEWA
B2: Size, proceeds, cornerstones, coverage and the discount left on the table
B4: MARKET CAPITALISATION AT THE RANGE
B5: At the bottom of the range | C5: =Inputs!$C$6*Inputs!$C$5 -> 112500
B6: At the top of the range | C6: =Inputs!$C$7*Inputs!$C$5 -> 124000
B7: At the final price | C7: =Inputs!$C$8*Inputs!$C$5 -> 124000 | F7: AED 124 billion, the largest company on the DFM at listing
B9: SIZE AND PROCEEDS
B10: Stake offered at launch | C10: =Inputs!$C$9/Inputs!$C$5 -> 0.065
B11: Stake offered at pricing | C11: =Inputs!$C$10/Inputs!$C$5 -> 0.18
B12: Upsizing factor | C12: =Inputs!$C$10/Inputs!$C$9 -> 2.7692308
B13: Gross proceeds to the selling shareholder | C13: =Inputs!$C$8*Inputs!$C$10 -> 22320
B14: Less: fees (assumed) | C14: =-'Pricing & Book'!$C$13*Inputs!$C$14 -> -390.6
B15: Net proceeds | C15: ='Pricing & Book'!$C$13+'Pricing & Book'!$C$14 -> 21929.4
B16: Government of Dubai's stake after the IPO | C16: =1-'Pricing & Book'!$C$11 -> 0.82
B18: THE BOOK
B19: Cornerstone and strategic commitments as % of the deal | C19: =Inputs!$C$12/'Pricing & Book'!$C$13 -> 0.61827957 | F19: Over 60% of the enlarged deal was committed before the book opened
B20: Shares placed with the open book (AED) | C20: ='Pricing & Book'!$C$13-Inputs!$C$12 -> 8520
B21: Coverage of the open book: demand / open-book allocation | C21: =Inputs!$C$13/'Pricing & Book'!$C$20 -> 36.971831 | F21: Reproduces the '37 times oversubscribed' headline
B22: Coverage of the whole deal, cornerstones included | C22: =(Inputs!$C$13+Inputs!$C$12)/'Pricing & Book'!$C$13 -> 14.731183
B23: Coverage the original 6.5% deal would have shown | C23: =(Inputs!$C$13+Inputs!$C$11)/(Inputs!$C$9*Inputs!$C$8) -> 39.665012 | F23: The number that made the upsizing possible
B24: Average fill rate for open-book orders | C24: =1/'Pricing & Book'!$C$21 -> 0.027047619
B26: THE DISCOUNT
B27: First-day close versus the offer price | C27: =Inputs!$C$41/Inputs!$C$8-1 -> 0.15725806
B28: First-day open versus the offer price | C28: =Inputs!$C$39/Inputs!$C$8-1 -> 0.2016129
B29: Money left on the table: shares sold × (first-day close − offer) | C29: =Inputs!$C$10*(Inputs!$C$41-Inputs!$C$8) -> 3510
B30: as % of gross proceeds | C30: ='Pricing & Book'!$C$29/'Pricing & Book'!$C$13 -> 0.15725806
B31: as a multiple of the fees paid | C31: ='Pricing & Book'!$C$29/-'Pricing & Book'!$C$14 -> 8.9861751
B32: Offer price that would have left a 10% first-day discount (AED) | C32: =Inputs!$C$41/1.1 -> 2.6090909 | F32: Above the range top. The range, not the pricing, was the conservative decision
B33: A 15–20% first-day rise is at the upper end of what issuers accept and the lower end of what a 37-times book would predict. The range was fixed two weeks before pricing and already sat at or above fundamental value, so the only lever left was size: the seller nearly tripled the deal rather than move the price. The money left on the table is the cost of that choice, and it bought a much larger free float.

Sheet Aftermarket
B1: DEWA — IPO Valuation and Pricing Rebuild (April 2022) | F1: DEWA
B2: Four years on: what an IPO investor earned, and what the company delivered
B4: RETURNS TO AN IPO INVESTOR (AED per share)
B5: Day one | C5: ='Pricing & Book'!$C$27 -> 0.15725806
B6: One year, price only | C6: =Inputs!$C$42/Inputs!$C$8-1 -> -0.0040322581 | F6: Below the offer price after twelve months despite the yield
B7: One year, with two dividend instalments | C7: =(Inputs!$C$42+2*Inputs!$C$24/2)/Inputs!$C$8-1 -> 0.045967742
B8: To 18 September 2026, price only | C8: =Inputs!$C$43/Inputs!$C$8-1 -> 0.10483871
B9: To 18 September 2026, with dividends received | C9: =(Inputs!$C$43+Inputs!$C$44)/Inputs!$C$8-1 -> 0.30483871
B10: Years since listing | C10: 4.44
B11: Annualised total return | C11: =(1+Aftermarket!$C$9)^(1/Aftermarket!$C$10)-1 -> 0.061759886
B12: Running yield on the IPO price | C12: =Inputs!$C$24/Inputs!$C$8 -> 0.05
B14: WHAT THE COMPANY DELIVERED, FY2021 TO FY2025
B15: Revenue growth, annualised | C15: =(Inputs!$C$47/Inputs!$C$17)^(1/4)-1 -> 0.083834971
B16: EBITDA growth, annualised | C16: =(Inputs!$C$48/Inputs!$C$18)^(1/4)-1 -> 0.10870376 | F16: More than double the 4.5% assumed in the DCF
B17: Net income growth, annualised | C17: =(Inputs!$C$49/Inputs!$C$19)^(1/4)-1 -> 0.060465684
B18: Dividend cover, FY2025 (net income / committed dividend) | C18: =Inputs!$C$49/Inputs!$C$23 -> 1.3462903
B20: MULTIPLES THEN AND NOW
B21: EV / EBITDA at the IPO, FY2021 | C21: =Valuation!$C$18 -> 11.991983
B22: EV / EBITDA today on FY2025 | C22: =(Inputs!$C$43*Inputs!$C$5+Inputs!$C$50+Inputs!$C$51)/Inputs!$C$48 -> 9.5799376
B23: P / E at the IPO | C23: =Valuation!$C$19 -> 18.787879
B24: P / E today on FY2025 | C24: =Inputs!$C$43*Inputs!$C$5/Inputs!$C$49 -> 16.413083
B25: Dividend yield today | C25: =Inputs!$C$24/Inputs!$C$43 -> 0.045255474
B26: De-rating: change in EV / EBITDA multiple | C26: =Aftermarket!$C$22/Aftermarket!$C$21-1 -> -0.20113819
B27: The business grew faster than the IPO case and the shares still spent most of four years near the offer price. The gap is the multiple: DEWA was sold at twelve times EBITDA and has since de-rated toward where global utilities trade. An IPO investor's return has come almost entirely from the dividend it was promised. That is the shape of a correctly priced regulated-utility IPO — the story was the yield, and the yield was delivered.

Sheet Sensitivity
B1: DEWA — IPO Valuation and Pricing Rebuild (April 2022) | H1: DEWA
B2: Value per share (AED) — each cell rebuilds the method
B4: DIVIDEND YIELD METHOD — TARGET YIELD (rows) versus ANNUAL DIVIDEND, AED m (columns)
B5: ↓ rows \ columns → | C5: 5600 | D5: 5900 | E5: 6200 | F5: 6500 | G5: 6800
B6: 0.04 | C6: =C$5/$B6/Inputs!$C$5 -> 2.8 | D6: =D$5/$B6/Inputs!$C$5 -> 2.95 | E6: =E$5/$B6/Inputs!$C$5 -> 3.1 | F6: =F$5/$B6/Inputs!$C$5 -> 3.25 | G6: =G$5/$B6/Inputs!$C$5 -> 3.4
B7: 0.045 | C7: =C$5/$B7/Inputs!$C$5 -> 2.4888889 | D7: =D$5/$B7/Inputs!$C$5 -> 2.6222222 | E7: =E$5/$B7/Inputs!$C$5 -> 2.7555556 | F7: =F$5/$B7/Inputs!$C$5 -> 2.8888889 | G7: =G$5/$B7/Inputs!$C$5 -> 3.0222222
B8: 0.05 | C8: =C$5/$B8/Inputs!$C$5 -> 2.24 | D8: =D$5/$B8/Inputs!$C$5 -> 2.36 | E8: =E$5/$B8/Inputs!$C$5 -> 2.48 | F8: =F$5/$B8/Inputs!$C$5 -> 2.6 | G8: =G$5/$B8/Inputs!$C$5 -> 2.72
B9: 0.055 | C9: =C$5/$B9/Inputs!$C$5 -> 2.0363636 | D9: =D$5/$B9/Inputs!$C$5 -> 2.1454545 | E9: =E$5/$B9/Inputs!$C$5 -> 2.2545455 | F9: =F$5/$B9/Inputs!$C$5 -> 2.3636364 | G9: =G$5/$B9/Inputs!$C$5 -> 2.4727273
B10: 0.06 | C10: =C$5/$B10/Inputs!$C$5 -> 1.8666667 | D10: =D$5/$B10/Inputs!$C$5 -> 1.9666667 | E10: =E$5/$B10/Inputs!$C$5 -> 2.0666667 | F10: =F$5/$B10/Inputs!$C$5 -> 2.1666667 | G10: =G$5/$B10/Inputs!$C$5 -> 2.2666667
B12: DCF — WACC (rows) versus TERMINAL GROWTH (columns)
B13: ↓ rows \ columns → | C13: 0.01 | D13: 0.015 | E13: 0.02 | F13: 0.025 | G13: 0.03
B14: 0.055 | C14: =((Valuation!$C$38/(1+$B14)^1+Valuation!$D$38/(1+$B14)^2+Valuation!$E$38/(1+$B14)^3+Valuation!$F$38/(1+$B14)^4+Valuation!$G$38/(1+$B14)^5)+Valuation!$G$38*(1+C$13)/($B14-C$13)/(1+$B14)^5-Inputs!$C$21-Inputs!$C$22)/Inputs!$C$5 -> 2.1992993 | D14: =((Valuation!$C$38/(1+$B14)^1+Valuation!$D$38/(1+$B14)^2+Valuation!$E$38/(1+$B14)^3+Valuation!$F$38/(1+$B14)^4+Valuation!$G$38/(1+$B14)^5)+Valuation!$G$38*(1+D$13)/($B14-D$13)/(1+$B14)^5-Inputs!$C$21-Inputs!$C$22)/Inputs!$C$5 -> 2.4832781 | E14: =((Valuation!$C$38/(1+$B14)^1+Valuation!$D$38/(1+$B14)^2+Valuation!$E$38/(1+$B14)^3+Valuation!$F$38/(1+$B14)^4+Valuation!$G$38/(1+$B14)^5)+Valuation!$G$38*(1+E$13)/($B14-E$13)/(1+$B14)^5-Inputs!$C$21-Inputs!$C$22)/Inputs!$C$5 -> 2.8483939 | F14: =((Valuation!$C$38/(1+$B14)^1+Valuation!$D$38/(1+$B14)^2+Valuation!$E$38/(1+$B14)^3+Valuation!$F$38/(1+$B14)^4+Valuation!$G$38/(1+$B14)^5)+Valuation!$G$38*(1+F$13)/($B14-F$13)/(1+$B14)^5-Inputs!$C$21-Inputs!$C$22)/Inputs!$C$5 -> 3.3352148 | G14: =((Valuation!$C$38/(1+$B14)^1+Valuation!$D$38/(1+$B14)^2+Valuation!$E$38/(1+$B14)^3+Valuation!$F$38/(1+$B14)^4+Valuation!$G$38/(1+$B14)^5)+Valuation!$G$38*(1+G$13)/($B14-G$13)/(1+$B14)^5-Inputs!$C$21-Inputs!$C$22)/Inputs!$C$5 -> 4.0167641
B15: 0.06 | C15: =((Valuation!$C$38/(1+$B15)^1+Valuation!$D$38/(1+$B15)^2+Valuation!$E$38/(1+$B15)^3+Valuation!$F$38/(1+$B15)^4+Valuation!$G$38/(1+$B15)^5)+Valuation!$G$38*(1+C$13)/($B15-C$13)/(1+$B15)^5-Inputs!$C$21-Inputs!$C$22)/Inputs!$C$5 -> 1.9296656 | D15: =((Valuation!$C$38/(1+$B15)^1+Valuation!$D$38/(1+$B15)^2+Valuation!$E$38/(1+$B15)^3+Valuation!$F$38/(1+$B15)^4+Valuation!$G$38/(1+$B15)^5)+Valuation!$G$38*(1+D$13)/($B15-D$13)/(1+$B15)^5-Inputs!$C$21-Inputs!$C$22)/Inputs!$C$5 -> 2.1525925 | E15: =((Valuation!$C$38/(1+$B15)^1+Valuation!$D$38/(1+$B15)^2+Valuation!$E$38/(1+$B15)^3+Valuation!$F$38/(1+$B15)^4+Valuation!$G$38/(1+$B15)^5)+Valuation!$G$38*(1+E$13)/($B15-E$13)/(1+$B15)^5-Inputs!$C$21-Inputs!$C$22)/Inputs!$C$5 -> 2.4312511 | F15: =((Valuation!$C$38/(1+$B15)^1+Valuation!$D$38/(1+$B15)^2+Valuation!$E$38/(1+$B15)^3+Valuation!$F$38/(1+$B15)^4+Valuation!$G$38/(1+$B15)^5)+Valuation!$G$38*(1+F$13)/($B15-F$13)/(1+$B15)^5-Inputs!$C$21-Inputs!$C$22)/Inputs!$C$5 -> 2.7895264 | G15: =((Valuation!$C$38/(1+$B15)^1+Valuation!$D$38/(1+$B15)^2+Valuation!$E$38/(1+$B15)^3+Valuation!$F$38/(1+$B15)^4+Valuation!$G$38/(1+$B15)^5)+Valuation!$G$38*(1+G$13)/($B15-G$13)/(1+$B15)^5-Inputs!$C$21-Inputs!$C$22)/Inputs!$C$5 -> 3.2672268
B16: 0.065 | C16: =((Valuation!$C$38/(1+$B16)^1+Valuation!$D$38/(1+$B16)^2+Valuation!$E$38/(1+$B16)^3+Valuation!$F$38/(1+$B16)^4+Valuation!$G$38/(1+$B16)^5)+Valuation!$G$38*(1+C$13)/($B16-C$13)/(1+$B16)^5-Inputs!$C$21-Inputs!$C$22)/Inputs!$C$5 -> 1.7091925 | D16: =((Valuation!$C$38/(1+$B16)^1+Valuation!$D$38/(1+$B16)^2+Valuation!$E$38/(1+$B16)^3+Valuation!$F$38/(1+$B16)^4+Valuation!$G$38/(1+$B16)^5)+Valuation!$G$38*(1+D$13)/($B16-D$13)/(1+$B16)^5-Inputs!$C$21-Inputs!$C$22)/Inputs!$C$5 -> 1.888186 | E16: =((Valuation!$C$38/(1+$B16)^1+Valuation!$D$38/(1+$B16)^2+Valuation!$E$38/(1+$B16)^3+Valuation!$F$38/(1+$B16)^4+Valuation!$G$38/(1+$B16)^5)+Valuation!$G$38*(1+E$13)/($B16-E$13)/(1+$B16)^5-Inputs!$C$21-Inputs!$C$22)/Inputs!$C$5 -> 2.1069558 | F16: =((Valuation!$C$38/(1+$B16)^1+Valuation!$D$38/(1+$B16)^2+Valuation!$E$38/(1+$B16)^3+Valuation!$F$38/(1+$B16)^4+Valuation!$G$38/(1+$B16)^5)+Valuation!$G$38*(1+F$13)/($B16-F$13)/(1+$B16)^5-Inputs!$C$21-Inputs!$C$22)/Inputs!$C$5 -> 2.3804181 | G16: =((Valuation!$C$38/(1+$B16)^1+Valuation!$D$38/(1+$B16)^2+Valuation!$E$38/(1+$B16)^3+Valuation!$F$38/(1+$B16)^4+Valuation!$G$38/(1+$B16)^5)+Valuation!$G$38*(1+G$13)/($B16-G$13)/(1+$B16)^5-Inputs!$C$21-Inputs!$C$22)/Inputs!$C$5 -> 2.7320125
B17: 0.07 | C17: =((Valuation!$C$38/(1+$B17)^1+Valuation!$D$38/(1+$B17)^2+Valuation!$E$38/(1+$B17)^3+Valuation!$F$38/(1+$B17)^4+Valuation!$G$38/(1+$B17)^5)+Valuation!$G$38*(1+C$13)/($B17-C$13)/(1+$B17)^5-Inputs!$C$21-Inputs!$C$22)/Inputs!$C$5 -> 1.5255866 | D17: =((Valuation!$C$38/(1+$B17)^1+Valuation!$D$38/(1+$B17)^2+Valuation!$E$38/(1+$B17)^3+Valuation!$F$38/(1+$B17)^4+Valuation!$G$38/(1+$B17)^5)+Valuation!$G$38*(1+D$13)/($B17-D$13)/(1+$B17)^5-Inputs!$C$21-Inputs!$C$22)/Inputs!$C$5 -> 1.6719793 | E17: =((Valuation!$C$38/(1+$B17)^1+Valuation!$D$38/(1+$B17)^2+Valuation!$E$38/(1+$B17)^3+Valuation!$F$38/(1+$B17)^4+Valuation!$G$38/(1+$B17)^5)+Valuation!$G$38*(1+E$13)/($B17-E$13)/(1+$B17)^5-Inputs!$C$21-Inputs!$C$22)/Inputs!$C$5 -> 1.8476505 | F17: =((Valuation!$C$38/(1+$B17)^1+Valuation!$D$38/(1+$B17)^2+Valuation!$E$38/(1+$B17)^3+Valuation!$F$38/(1+$B17)^4+Valuation!$G$38/(1+$B17)^5)+Valuation!$G$38*(1+F$13)/($B17-F$13)/(1+$B17)^5-Inputs!$C$21-Inputs!$C$22)/Inputs!$C$5 -> 2.0623597 | G17: =((Valuation!$C$38/(1+$B17)^1+Valuation!$D$38/(1+$B17)^2+Valuation!$E$38/(1+$B17)^3+Valuation!$F$38/(1+$B17)^4+Valuation!$G$38/(1+$B17)^5)+Valuation!$G$38*(1+G$13)/($B17-G$13)/(1+$B17)^5-Inputs!$C$21-Inputs!$C$22)/Inputs!$C$5 -> 2.3307463
B18: 0.075 | C18: =((Valuation!$C$38/(1+$B18)^1+Valuation!$D$38/(1+$B18)^2+Valuation!$E$38/(1+$B18)^3+Valuation!$F$38/(1+$B18)^4+Valuation!$G$38/(1+$B18)^5)+Valuation!$G$38*(1+C$13)/($B18-C$13)/(1+$B18)^5-Inputs!$C$21-Inputs!$C$22)/Inputs!$C$5 -> 1.3703373 | D18: =((Valuation!$C$38/(1+$B18)^1+Valuation!$D$38/(1+$B18)^2+Valuation!$E$38/(1+$B18)^3+Valuation!$F$38/(1+$B18)^4+Valuation!$G$38/(1+$B18)^5)+Valuation!$G$38*(1+D$13)/($B18-D$13)/(1+$B18)^5-Inputs!$C$21-Inputs!$C$22)/Inputs!$C$5 -> 1.4919195 | E18: =((Valuation!$C$38/(1+$B18)^1+Valuation!$D$38/(1+$B18)^2+Valuation!$E$38/(1+$B18)^3+Valuation!$F$38/(1+$B18)^4+Valuation!$G$38/(1+$B18)^5)+Valuation!$G$38*(1+E$13)/($B18-E$13)/(1+$B18)^5-Inputs!$C$21-Inputs!$C$22)/Inputs!$C$5 -> 1.6356075 | F18: =((Valuation!$C$38/(1+$B18)^1+Valuation!$D$38/(1+$B18)^2+Valuation!$E$38/(1+$B18)^3+Valuation!$F$38/(1+$B18)^4+Valuation!$G$38/(1+$B18)^5)+Valuation!$G$38*(1+F$13)/($B18-F$13)/(1+$B18)^5-Inputs!$C$21-Inputs!$C$22)/Inputs!$C$5 -> 1.8080332 | G18: =((Valuation!$C$38/(1+$B18)^1+Valuation!$D$38/(1+$B18)^2+Valuation!$E$38/(1+$B18)^3+Valuation!$F$38/(1+$B18)^4+Valuation!$G$38/(1+$B18)^5)+Valuation!$G$38*(1+G$13)/($B18-G$13)/(1+$B18)^5-Inputs!$C$21-Inputs!$C$22)/Inputs!$C$5 -> 2.0187756

Sheet Summary
B1: DEWA — IPO Valuation and Pricing Rebuild (April 2022) | F1: DEWA
B2: The DEWA IPO on one page
B4: THE DEAL
B5: Price range (AED) | C5: =TEXT(Inputs!$C$6,"0.00")&" – "&TEXT(Inputs!$C$7,"0.00") -> 2.25 – 2.48
B6: Final price (AED) | C6: =Inputs!$C$8 -> 2.48
B7: Market capitalisation at listing | C7: ='Pricing & Book'!$C$7 -> 124000
B8: Stake sold: launched at / priced at | C8: =TEXT('Pricing & Book'!$C$10,"0.0%")&" / "&TEXT('Pricing & Book'!$C$11,"0.0%") -> 6.5% / 18.0%
B9: Gross proceeds | C9: ='Pricing & Book'!$C$13 -> 22320
B10: Cornerstones as % of the deal | C10: ='Pricing & Book'!$C$19 -> 0.61827957
B11: Open-book coverage | C11: ='Pricing & Book'!$C$21 -> 36.971831
B13: THE VALUATION
B14: Dividend-yield method (AED per share) | C14: =TEXT(Valuation!$C$7,"0.00")&" – "&TEXT(Valuation!$C$8,"0.00") -> 2.25 – 2.76
B15: EV / EBITDA method (AED per share) | C15: =TEXT(Valuation!$C$16,"0.00")&" – "&TEXT(Valuation!$C$17,"0.00") -> 2.00 – 2.60
B16: DCF (AED per share) | C16: =Valuation!$C$46 -> 2.1069558
B17: Final price versus the valuation midpoint | C17: =Valuation!$C$54 -> 0.076319388
B18: Yield / EV-EBITDA / P-E at the final price | C18: =TEXT(Valuation!$C$9,"0.0%")&" / "&TEXT(Valuation!$C$18,"0.0x")&" / "&TEXT(Valuation!$C$19,"0.0x") -> 5.0% / 12.0x / 18.8x
B20: THE VERDICT
B21: First-day rise | C21: ='Pricing & Book'!$C$27 -> 0.15725806
B22: Money left on the table | C22: ='Pricing & Book'!$C$29 -> 3510
B23: Total return to an IPO investor to date | C23: =Aftermarket!$C$9 -> 0.30483871
B24: annualised | C24: =Aftermarket!$C$11 -> 0.061759886
B25: EBITDA growth delivered versus assumed | C25: =TEXT(Aftermarket!$C$16,"0.0%")&" versus "&TEXT(Inputs!$C$31,"0.0%") -> 10.9% versus 4.5%
B26: Multiple then versus now | C26: =TEXT(Aftermarket!$C$21,"0.0x")&" → "&TEXT(Aftermarket!$C$22,"0.0x") -> 12.0x → 9.6x
B28: • The price was the dividend. AED 6.2 billion a year at a 5% yield is AED 124 billion, which is the top of the range to the dirham. The book-building confirmed a number that had been chosen before the book opened.
B29: • The book was three times bigger than the deal it was built for. Demand of AED 315 billion against a launch size of AED 7–8 billion let the seller nearly triple the offering to 18% and still report 37 times coverage. Most of the enlarged deal went to cornerstones who had already agreed the price.
B30: • On FY2021 fundamentals the price was full — about 8% above the midpoint of the yield, multiple and DCF methods — yet the shares still rose 16% on day one and AED 3.5 billion was left on the table, nine times the fees. A book filled at 3% cannot be satisfied by any price inside a range; the seller took size instead.
B31: • Four years on the shares are close to the offer price and the business has grown EBITDA at 11% a year. The return has been the dividend, and the multiple has de-rated toward global utilities. For a regulated monopoly sold on yield, that is the pricing working as intended.

Sheet Checks
B1: DEWA — IPO Valuation and Pricing Rebuild (April 2022) | E1: DEWA
B2: Every check must read TRUE
B4: INTEGRITY CHECKS
B5: Market cap at the final price reproduces the announced AED 124 billion | C5: =ABS('Pricing & Book'!$C$7-124000)<1 -> TRUE
B6: Gross proceeds reproduce the announced AED 22.3 billion | C6: =ABS('Pricing & Book'!$C$13-22320)<1 -> TRUE
B7: Stake sold reproduces the announced 18% | C7: =ABS('Pricing & Book'!$C$11-0.18)<0.0001 -> TRUE
B8: Open-book coverage reproduces the announced 37 times within rounding | C8: =ABS('Pricing & Book'!$C$21-37)<1 -> TRUE
B9: Yield at the final price is 5.0% | C9: =ABS(Valuation!$C$9-0.05)<0.0005 -> TRUE
B10: Final price sits at the top of the range | C10: =Inputs!$C$8=Inputs!$C$7 -> TRUE
B11: Dividend-yield value at 5% reproduces the final price | C11: =ABS(Inputs!$C$23/0.05/Inputs!$C$5-Inputs!$C$8)<0.001 -> TRUE
B12: DCF free cash flow is positive in every year | C12: =AND(Valuation!$C$38>0,Valuation!$D$38>0,Valuation!$E$38>0,Valuation!$F$38>0,Valuation!$G$38>0) -> TRUE
B13: Terminal growth is below WACC | C13: =Inputs!$C$36<Inputs!$C$35 -> TRUE
B14: Base yield sensitivity cell reproduces the final price | C14: =ABS(Sensitivity!E8-Inputs!$C$8)<0.001 -> TRUE
B15: Base DCF sensitivity cell reconciles to the Valuation sheet | C15: =ABS(Sensitivity!E16-Valuation!$C$46)<0.001 -> TRUE
B16: Money left on the table equals shares sold times the first-day gain | C16: =ABS('Pricing & Book'!$C$29-Inputs!$C$10*(Inputs!$C$41-Inputs!$C$8))<0.01 -> TRUE
B17: Net debt derived from the disclosed 1.5x lies between AED 15bn and AED 21bn | C17: =AND(Inputs!$C$21>15000,Inputs!$C$21<21000) -> TRUE
B18: Government stake after the IPO is 82% | C18: =ABS('Pricing & Book'!$C$16-0.82)<0.0001 -> TRUE
B20: MODEL STATUS | C20: =IF(COUNTIF(C5:C18,FALSE())=0,"MODEL OK","CHECK FAILED") -> MODEL OK
B22: The first five checks reproduce the headline numbers from the company's own announcements — AED 124 billion, AED 22.3 billion, 18%, 37 times, 5% — from the raw inputs, which is what makes this a rebuild rather than a retelling.
