Workbook

Sheet Cover
B3: IB PORTFOLIO · PROJECT 06 OF 20
B4: Emirates NBD / Mashreqbank
B5: Merger Model — Accretion/Dilution, Synergies and Pro Forma
B6: DFM: EMIRATESNBD · AED millions · per-share values in AED · as of FY2025 accounts · market data 12 Sep 2026
B9: What this is | C9: A hypothetical acquisition of Mashreqbank by Emirates NBD, built on both banks' FY2025 audited accounts and 12 September 2026 market prices. Neither bank is in discussions; the transaction is a modelling exercise, and the model's conclusion is that it should not be done at this price.
B11: How it is built | C11: • Purchase accounting in full: credit mark on the acquired loan book, core deposit intangible, deferred tax on both, and the goodwill that falls out of the difference.
C12: • A three-year earnings bridge with synergies phased 25 / 75 / 100 and integration costs charged in year one, plus the synergy level that would be required merely to hold earnings per share flat.
C13: • The two tests that actually decide bank deals: tangible book value per share dilution with its earnback period, and the pro forma CET1 ratio against the regulatory minimum.
C14: • Two live sensitivity grids — premium against synergies for EPS, premium against consideration mix for tangible book — with every cell rebuilding the offer and the purchase accounting from scratch.
B16: Contents | C16: Summary — the transaction and the three tests on one page
C17: Purchase Price — offer, consideration mix, allocation and goodwill
C18: Accretion — three-year pro forma earnings bridge and the break-even synergy level
C19: Capital & TBV — tangible book dilution, earnback, CET1 and return on invested capital
C20: Sensitivity — EPS and tangible book across premium, synergies and mix
C21: Inputs — standalone financials, deal terms and purchase-accounting assumptions
C22: Checks — fourteen tests; must read MODEL OK
B24: Key outputs (live) | C24: Offer price per share (AED) | E24: ='Purchase Price'!$C$5 -> 418.625
C25: Price / tangible book paid | E25: ='Purchase Price'!$C$15 -> 2.1560497
C26: EPS accretion at full synergies | E26: =Accretion!$E$18 -> -0.022651419
C27: Tangible book value dilution | E27: ='Capital & TBV'!$C$13 -> -0.16697824
C28: Pro forma CET1 ratio | E28: ='Capital & TBV'!$C$24 -> 0.12978893
C29: Return on invested capital | E29: ='Capital & TBV'!$C$29 -> 0.086308735
B31: Colour code | C31: Blue = hard-coded input
C32: Black = formula
C33: Green = link to another sheet
C34: Accent fill = scenario selector / key levers
B36: Sources | C36: Emirates NBD Bank PJSC and Mashreqbank PSC, FY2025 annual accounts (year to 31 December 2025), via the Yahoo Finance fundamentals series for EMIRATESNBD.AE and MASQ.AE.
C37: Share prices: Dubai Financial Market close, 12 September 2026.
C38: Tax rate: UAE federal corporate tax at 9%, in force since June 2023.
C39: Capital ratios and risk-weight assumptions are stated inputs on the Inputs sheet and should be replaced with each bank's Pillar 3 disclosures before any external use.
C40: The transaction is hypothetical. Nothing here is a suggestion that either bank is or has been in discussions.
B42: Prepared by | C42: Jainam Mehta · github.com/jainammehta1215/ib-portfolio

Sheet Inputs
B1: Emirates NBD / Mashreqbank — Merger Model — Accretion/Dilution, Synergies and Pro Forma | F1: EMIRATES NBD
B2: Standalone financials, deal terms, synergies and purchase-accounting assumptions
B4: STANDALONE FINANCIALS — FY2025A (AED m)
C5: Emirates NBD | D5: Mashreqbank
B6: Net income attributable to shareholders | C6: 23442 | D6: 6615
B7: Shares outstanding (m) | C7: 6311 | D7: 200.60983
B8: Total shareholders' equity | C8: 144582 | D8: 39374
B9: Goodwill | C9: 5516 | D9: 0
B10: Other intangible assets | C10: 104 | D10: 423
B11: Total assets | C11: 1164442 | D11: 334633.9
B12: Operating expenses | C12: 15035 | D12: 3871
B13: Total revenue | C13: 49177 | D13: 12594
B14: Share price (AED, 12 Sep 2026) | C14: 31.1 | D14: 334.9
B16: DERIVED STANDALONE METRICS
B17: Tangible common equity | C17: =Inputs!$C$8-Inputs!$C$9-Inputs!$C$10 -> 138962 | D17: =Inputs!$D$8-Inputs!$D$9-Inputs!$D$10 -> 38951
B18: Market capitalisation | C18: =Inputs!$C$14*Inputs!$C$7 -> 196272.1 | D18: =Inputs!$D$14*Inputs!$D$7 -> 67184.232
B19: Earnings per share (AED) | C19: =Inputs!$C$6/Inputs!$C$7 -> 3.7144668 | D19: =Inputs!$D$6/Inputs!$D$7 -> 32.974456
B20: Tangible book value per share (AED) | C20: =Inputs!$C$17/Inputs!$C$7 -> 22.019014 | D20: =Inputs!$D$17/Inputs!$D$7 -> 194.16297
B21: Price / earnings | C21: =Inputs!$C$14/Inputs!$C$19 -> 8.3726687 | D21: =Inputs!$D$14/Inputs!$D$19 -> 10.156346
B22: Price / tangible book | C22: =Inputs!$C$14/Inputs!$C$20 -> 1.4124156 | D22: =Inputs!$D$14/Inputs!$D$20 -> 1.7248397
B24: DEAL TERMS
B25: Offer premium to unaffected share price | C25: 0.25 | F25: Mid-range for a large European or Gulf bank deal. The sensitivity grid tests 10% to 40%
B26: Consideration in acquirer stock | C26: 0.7 | F26: Stock-heavy, because a cash-heavy deal of this size would breach the CET1 floor
B27: Consideration in cash | C27: =1-$C$26 -> 0.3 | F27: Funded from surplus capital and wholesale issuance
B28: Pre-tax opportunity cost of cash consideration | C28: 0.04 | F28: Yield foregone on the cash paid away; roughly the bank's marginal funding cost
B29: Marginal tax rate on synergies and adjustments | C29: 0.09 | F29: UAE federal corporate tax, in force since June 2023
B31: SYNERGIES AND INTEGRATION
B32: Run-rate cost synergies as % of target operating expenses | C32: 0.25 | F32: Branch and head-office overlap in a single emirate. Ambitious but within the range disclosed in comparable bank mergers
B33: Synergy phasing — year 1 | C33: 0.25
B34: Synergy phasing — year 2 | C34: 0.75
B35: Synergy phasing — year 3 | C35: 1
B36: One-time integration costs as a multiple of run-rate synergies | C36: 1.5 | F36: Charged in year 1. Systems migration, redundancy and rebranding
B37: Revenue synergies | C37: 0 | F37: Set to zero on purpose. Revenue synergies in bank mergers are routinely promised and rarely delivered; the notes explain the choice
B39: PURCHASE ACCOUNTING
B40: Target gross loans as % of total assets | C40: 0.55 | F40: Approximation pending the disclosed loan book
B41: Credit mark on the acquired loan book | C41: 0.0125 | F41: Fair-value write-down for expected credit losses not yet provisioned. The single largest judgement in the model
B42: Target core deposits as % of total assets | C42: 0.65
B43: Core deposit intangible as % of core deposits | C43: 0.01 | F43: Value of a cheap, sticky funding base; recognised as an identifiable intangible
B44: Core deposit intangible amortisation period (years) | C44: 8
B46: CAPITAL
...

Sheet Purchase Price
B1: Emirates NBD / Mashreqbank — Merger Model — Accretion/Dilution, Synergies and Pro Forma | F1: EMIRATES NBD
B2: Offer, consideration mix and the allocation of the price paid
B4: OFFER
B5: Offer price per Mashreqbank share (AED) | C5: =Inputs!$D$14*(1+Inputs!$C$25) -> 418.625
B6: Equity purchase price | C6: ='Purchase Price'!$C$5*Inputs!$D$7 -> 83980.29
B7: Exchange ratio (acquirer shares per target share) | C7: ='Purchase Price'!$C$5*Inputs!$C$26/Inputs!$C$14 -> 9.4224277 | F7: What a Mashreqbank holder receives in Emirates NBD stock
B8: Consideration in stock | C8: ='Purchase Price'!$C$6*Inputs!$C$26 -> 58786.203
B9: Consideration in cash | C9: ='Purchase Price'!$C$6*Inputs!$C$27 -> 25194.087
B10: New acquirer shares issued (m) | C10: ='Purchase Price'!$C$8/Inputs!$C$14 -> 1890.2316
B11: Pro forma shares outstanding (m) | C11: =Inputs!$C$7+'Purchase Price'!$C$10 -> 8201.2316
B12: Target shareholders' ownership of the combined bank | C12: ='Purchase Price'!$C$10/'Purchase Price'!$C$11 -> 0.23048143 | F12: At this mix the acquired shareholders own roughly a quarter of the group, which is a governance question as much as a financial one
B14: Price / earnings paid | C14: ='Purchase Price'!$C$6/Inputs!$D$6 -> 12.695433
B15: Price / tangible book paid | C15: ='Purchase Price'!$C$6/Inputs!$D$17 -> 2.1560497 | F15: Compare with the acquirer's own price/tangible book on the Inputs sheet. Issuing stock below the multiple being paid transfers value to the seller
B17: FAIR VALUE OF IDENTIFIABLE NET ASSETS ACQUIRED
B18: Target tangible common equity (book) | C18: =Inputs!$D$17 -> 38951
B19: Less: credit mark on the loan book | C19: =-Inputs!$D$11*Inputs!$C$40*Inputs!$C$41 -> -2300.6081
B20: Plus: core deposit intangible recognised | C20: =Inputs!$D$11*Inputs!$C$42*Inputs!$C$43 -> 2175.1204
B21: Deferred tax on fair-value adjustments | C21: =-('Purchase Price'!$C$19+'Purchase Price'!$C$20)*Inputs!$C$29 -> 11.293894
B22: Fair value of identifiable net assets | C22: ='Purchase Price'!$C$18+'Purchase Price'!$C$19+'Purchase Price'!$C$20+'Purchase Price'!$C$21 -> 38836.806
B23: Goodwill created | C23: ='Purchase Price'!$C$6-'Purchase Price'!$C$22 -> 45143.484 | F23: The part of the price with no identifiable asset behind it. It is deducted in full from regulatory capital
B24: Goodwill as % of the price paid | C24: ='Purchase Price'!$C$23/'Purchase Price'!$C$6 -> 0.53754856
B26: Annual core deposit intangible amortisation | C26: ='Purchase Price'!$C$20/Inputs!$C$44 -> 271.89004
B27: Run-rate pre-tax cost synergies | C27: =Inputs!$D$12*Inputs!$C$32 -> 967.75
B28: One-time integration costs | C28: ='Purchase Price'!$C$27*Inputs!$C$36 -> 1451.625
B30: The credit mark and the core deposit intangible largely offset each other here, so goodwill is close to the premium over tangible book. That is the honest shape of a bank deal: almost everything paid above tangible book becomes goodwill, and goodwill is worthless for regulatory capital purposes.

Sheet Accretion
B1: Emirates NBD / Mashreqbank — Merger Model — Accretion/Dilution, Synergies and Pro Forma | G1: EMIRATES NBD
B2: Pro forma earnings bridge · AED millions except per-share
B4: PRO FORMA NET INCOME
C5: Year 1 | D5: Year 2 | E5: Year 3
B6: Acquirer net income (held flat) | C6: =Inputs!$C$6 -> 23442 | D6: =Inputs!$C$6 -> 23442 | E6: =Inputs!$C$6 -> 23442
B7: Target net income (held flat) | C7: =Inputs!$D$6 -> 6615 | D7: =Inputs!$D$6 -> 6615 | E7: =Inputs!$D$6 -> 6615
B8: Plus: after-tax cost synergies | C8: ='Purchase Price'!$C$27*Inputs!$C$33*(1-Inputs!$C$29) -> 220.16313 | D8: ='Purchase Price'!$C$27*Inputs!$C$34*(1-Inputs!$C$29) -> 660.48937 | E8: ='Purchase Price'!$C$27*Inputs!$C$35*(1-Inputs!$C$29) -> 880.6525
B9: Less: core deposit intangible amortisation, after tax | C9: =-'Purchase Price'!$C$26*(1-Inputs!$C$29) -> -247.41994 | D9: =-'Purchase Price'!$C$26*(1-Inputs!$C$29) -> -247.41994 | E9: =-'Purchase Price'!$C$26*(1-Inputs!$C$29) -> -247.41994
B10: Less: opportunity cost of cash consideration, after tax | C10: =-'Purchase Price'!$C$9*Inputs!$C$28*(1-Inputs!$C$29) -> -917.06477 | D10: =-'Purchase Price'!$C$9*Inputs!$C$28*(1-Inputs!$C$29) -> -917.06477 | E10: =-'Purchase Price'!$C$9*Inputs!$C$28*(1-Inputs!$C$29) -> -917.06477
B11: Less: one-time integration costs, after tax | C11: =-'Purchase Price'!$C$28*(1-Inputs!$C$29) -> -1320.9787 | D11: =0 -> 0 | E11: =0 -> 0
B12: Pro forma net income | C12: =SUM(C6:C11) -> 27791.7 | D12: =SUM(D6:D11) -> 29553.005 | E12: =SUM(E6:E11) -> 29773.168
B14: PER SHARE
B15: Pro forma shares (m) | C15: ='Purchase Price'!$C$11 -> 8201.2316 | D15: ='Purchase Price'!$C$11 -> 8201.2316 | E15: ='Purchase Price'!$C$11 -> 8201.2316
B16: Pro forma earnings per share (AED) | C16: =Accretion!$C$12/Accretion!$C$15 -> 3.3887227 | D16: =Accretion!$D$12/Accretion!$D$15 -> 3.6034837 | E16: =Accretion!$E$12/Accretion!$E$15 -> 3.6303289
B17: Standalone acquirer earnings per share (AED) | C17: =Inputs!$C$19 -> 3.7144668 | D17: =Inputs!$C$19 -> 3.7144668 | E17: =Inputs!$C$19 -> 3.7144668
B18: Accretion / (dilution) | C18: =Accretion!$C$16/Accretion!$C$17-1 -> -0.087696062 | D18: =Accretion!$D$16/Accretion!$D$17-1 -> -0.029878602 | E18: =Accretion!$E$16/Accretion!$E$17-1 -> -0.022651419
B19: Accretion / (dilution) per share (AED) | C19: =Accretion!$C$16-Accretion!$C$17 -> -0.32574411 | D19: =Accretion!$D$16-Accretion!$D$17 -> -0.11098307 | E19: =Accretion!$E$16-Accretion!$E$17 -> -0.084137945
B21: WHAT WOULD HAVE TO BE TRUE FOR THE DEAL TO BREAK EVEN ON EPS
B22: Pro forma net income required for EPS neutrality (steady state) | C22: =Inputs!$C$19*'Purchase Price'!$C$11 -> 30463.203
B23: Shortfall at full run-rate synergies | C23: =Accretion!$C$22-Accretion!$E$12 -> 690.03477
B24: Cost synergies required, as % of target operating expenses | C24: =(Accretion!$C$22-(Accretion!$C$6+Accretion!$C$7+Accretion!$C$9+Accretion!$C$10))/(1-Inputs!$C$29)/Inputs!$D$12 -> 0.44588736 | G24: Against the 25% assumed. If this number is not achievable, the deal is not EPS-neutral at any credible synergy level
B26: Acquirer and target earnings are held flat at FY2025. A merger model that also forecasts both banks' organic growth mixes two questions together: whether the businesses grow, and whether the transaction adds value. Holding both flat isolates the transaction, which is the question the model exists to answer.

Sheet Capital & TBV
B1: Emirates NBD / Mashreqbank — Merger Model — Accretion/Dilution, Synergies and Pro Forma | F1: EMIRATES NBD
B2: Tangible book dilution, earnback, and the regulatory capital constraint
B4: TANGIBLE COMMON EQUITY BRIDGE
B5: Acquirer tangible common equity, standalone | C5: =Inputs!$C$17 -> 138962
B6: Plus: stock issued as consideration | C6: ='Purchase Price'!$C$8 -> 58786.203
B7: Less: goodwill created | C7: =-'Purchase Price'!$C$23 -> -45143.484
B8: Less: core deposit intangible created | C8: =-'Purchase Price'!$C$20 -> -2175.1204
B9: Pro forma tangible common equity | C9: ='Capital & TBV'!$C$5+'Capital & TBV'!$C$6+'Capital & TBV'!$C$7+'Capital & TBV'!$C$8 -> 150429.6 | F9: The target's tangible net assets are exactly offset by the price paid for them, so the bridge moves only by stock issued less intangibles created
B11: Acquirer tangible book value per share, standalone (AED) | C11: =Inputs!$C$20 -> 22.019014
B12: Pro forma tangible book value per share (AED) | C12: ='Capital & TBV'!$C$9/'Purchase Price'!$C$11 -> 18.342318
B13: Tangible book value per share dilution | C13: ='Capital & TBV'!$C$12/'Capital & TBV'!$C$11-1 -> -0.16697824 | F13: The number a bank's shareholders react to first. Anything beyond roughly 5% needs a short earnback to be defensible
B14: Dilution per share (AED) | C14: ='Capital & TBV'!$C$11-'Capital & TBV'!$C$12 -> 3.6766963
B15: Tangible book earnback (years) | C15: =IF(Accretion!$E$19<=0,"Never — the deal is dilutive to EPS at full synergies",'Capital & TBV'!$C$14/Accretion!$E$19) -> Never — the deal is dilutive to EPS at full synergies | F15: Dilution per share divided by steady-state accretion per share. If earnings never exceed standalone, the book value is never earned back
B17: REGULATORY CAPITAL
B18: Acquirer risk-weighted assets | C18: =Inputs!$C$11*Inputs!$C$47 -> 721954.04
B19: Target risk-weighted assets | C19: =Inputs!$D$11*Inputs!$C$48 -> 200780.34
B20: Pro forma risk-weighted assets | C20: ='Capital & TBV'!$C$18+'Capital & TBV'!$C$19 -> 922734.38
B21: Acquirer CET1 capital, standalone | C21: ='Capital & TBV'!$C$18*Inputs!$C$49 -> 108293.11
B22: Change in CET1 capital from the transaction | C22: ='Capital & TBV'!$C$6+'Capital & TBV'!$C$7+'Capital & TBV'!$C$8 -> 11467.599 | F22: Stock issued less the goodwill and intangibles created, both of which are deducted in full from CET1
B23: Pro forma CET1 capital | C23: ='Capital & TBV'!$C$21+'Capital & TBV'!$C$22 -> 119760.7
B24: Pro forma CET1 ratio | C24: ='Capital & TBV'!$C$23/'Capital & TBV'!$C$20 -> 0.12978893
B25: Change versus standalone (percentage points) | C25: =('Capital & TBV'!$C$24-Inputs!$C$49)*100 -> -2.0211073
B26: Headroom above the regulatory minimum (percentage points) | C26: =('Capital & TBV'!$C$24-Inputs!$C$50)*100 -> 1.9788927 | F26: Negative here would mean the deal cannot be done as structured at any price
B28: RETURN ON THE CAPITAL INVESTED
B29: Return on invested capital at full synergies | C29: =(Inputs!$D$6+'Purchase Price'!$C$27*(1-Inputs!$C$29)-'Purchase Price'!$C$26*(1-Inputs!$C$29))/'Purchase Price'!$C$6 -> 0.086308735
B30: Spread over the required return (percentage points) | C30: =('Capital & TBV'!$C$29-Inputs!$C$51)*100 -> -3.3691265 | F30: The cleanest single test of whether the price is justified, and the one least sensitive to the consideration mix

Sheet Sensitivity
B1: Emirates NBD / Mashreqbank — Merger Model — Accretion/Dilution, Synergies and Pro Forma | H1: EMIRATES NBD
B2: Both grids are live: every cell rebuilds the offer, the share count and the purchase accounting from scratch
B4: EPS ACCRETION / (DILUTION) AT FULL RUN-RATE SYNERGIES
B5: Cost synergies (% of target opex) \ Offer premium | C5: 0.1 | D5: 0.175 | E5: 0.25 | F5: 0.325 | G5: 0.4
B6: 0.15 | C6: =(Inputs!$C$6+Inputs!$D$6+Inputs!$D$12*$B6*(1-Inputs!$C$29)-'Purchase Price'!$C$26*(1-Inputs!$C$29)-((Inputs!$D$14*(1+C$5)*Inputs!$D$7)*Inputs!$C$27)*Inputs!$C$28*(1-Inputs!$C$29))/(Inputs!$C$7+((Inputs!$D$14*(1+C$5)*Inputs!$D$7)*Inputs!$C$26/Inputs!$C$14))/Inputs!$C$19-1 -> -0.0030284166 | D6: =(Inputs!$C$6+Inputs!$D$6+Inputs!$D$12*$B6*(1-Inputs!$C$29)-'Purchase Price'!$C$26*(1-Inputs!$C$29)-((Inputs!$D$14*(1+D$5)*Inputs!$D$7)*Inputs!$C$27)*Inputs!$C$28*(1-Inputs!$C$29))/(Inputs!$C$7+((Inputs!$D$14*(1+D$5)*Inputs!$D$7)*Inputs!$C$26/Inputs!$C$14))/Inputs!$C$19-1 -> -0.018840325 | E6: =(Inputs!$C$6+Inputs!$D$6+Inputs!$D$12*$B6*(1-Inputs!$C$29)-'Purchase Price'!$C$26*(1-Inputs!$C$29)-((Inputs!$D$14*(1+E$5)*Inputs!$D$7)*Inputs!$C$27)*Inputs!$C$28*(1-Inputs!$C$29))/(Inputs!$C$7+((Inputs!$D$14*(1+E$5)*Inputs!$D$7)*Inputs!$C$26/Inputs!$C$14))/Inputs!$C$19-1 -> -0.034214911 | F6: =(Inputs!$C$6+Inputs!$D$6+Inputs!$D$12*$B6*(1-Inputs!$C$29)-'Purchase Price'!$C$26*(1-Inputs!$C$29)-((Inputs!$D$14*(1+F$5)*Inputs!$D$7)*Inputs!$C$27)*Inputs!$C$28*(1-Inputs!$C$29))/(Inputs!$C$7+((Inputs!$D$14*(1+F$5)*Inputs!$D$7)*Inputs!$C$26/Inputs!$C$14))/Inputs!$C$19-1 -> -0.049170071 | G6: =(Inputs!$C$6+Inputs!$D$6+Inputs!$D$12*$B6*(1-Inputs!$C$29)-'Purchase Price'!$C$26*(1-Inputs!$C$29)-((Inputs!$D$14*(1+G$5)*Inputs!$D$7)*Inputs!$C$27)*Inputs!$C$28*(1-Inputs!$C$29))/(Inputs!$C$7+((Inputs!$D$14*(1+G$5)*Inputs!$D$7)*Inputs!$C$26/Inputs!$C$14))/Inputs!$C$19-1 -> -0.063722736
B7: 0.2 | C7: =(Inputs!$C$6+Inputs!$D$6+Inputs!$D$12*$B7*(1-Inputs!$C$29)-'Purchase Price'!$C$26*(1-Inputs!$C$29)-((Inputs!$D$14*(1+C$5)*Inputs!$D$7)*Inputs!$C$27)*Inputs!$C$28*(1-Inputs!$C$29))/(Inputs!$C$7+((Inputs!$D$14*(1+C$5)*Inputs!$D$7)*Inputs!$C$26/Inputs!$C$14))/Inputs!$C$19-1 -> 0.0029177882 | D7: =(Inputs!$C$6+Inputs!$D$6+Inputs!$D$12*$B7*(1-Inputs!$C$29)-'Purchase Price'!$C$26*(1-Inputs!$C$29)-((Inputs!$D$14*(1+D$5)*Inputs!$D$7)*Inputs!$C$27)*Inputs!$C$28*(1-Inputs!$C$29))/(Inputs!$C$7+((Inputs!$D$14*(1+D$5)*Inputs!$D$7)*Inputs!$C$26/Inputs!$C$14))/Inputs!$C$19-1 -> -0.012977503 | E7: =(Inputs!$C$6+Inputs!$D$6+Inputs!$D$12*$B7*(1-Inputs!$C$29)-'Purchase Price'!$C$26*(1-Inputs!$C$29)-((Inputs!$D$14*(1+E$5)*Inputs!$D$7)*Inputs!$C$27)*Inputs!$C$28*(1-Inputs!$C$29))/(Inputs!$C$7+((Inputs!$D$14*(1+E$5)*Inputs!$D$7)*Inputs!$C$26/Inputs!$C$14))/Inputs!$C$19-1 -> -0.028433165 | F7: =(Inputs!$C$6+Inputs!$D$6+Inputs!$D$12*$B7*(1-Inputs!$C$29)-'Purchase Price'!$C$26*(1-Inputs!$C$29)-((Inputs!$D$14*(1+F$5)*Inputs!$D$7)*Inputs!$C$27)*Inputs!$C$28*(1-Inputs!$C$29))/(Inputs!$C$7+((Inputs!$D$14*(1+F$5)*Inputs!$D$7)*Inputs!$C$26/Inputs!$C$14))/Inputs!$C$19-1 -> -0.043467189 | G7: =(Inputs!$C$6+Inputs!$D$6+Inputs!$D$12*$B7*(1-Inputs!$C$29)-'Purchase Price'!$C$26*(1-Inputs!$C$29)-((Inputs!$D$14*(1+G$5)*Inputs!$D$7)*Inputs!$C$27)*Inputs!$C$28*(1-Inputs!$C$29))/(Inputs!$C$7+((Inputs!$D$14*(1+G$5)*Inputs!$D$7)*Inputs!$C$26/Inputs!$C$14))/Inputs!$C$19-1 -> -0.058096597
B8: 0.25 | C8: =(Inputs!$C$6+Inputs!$D$6+Inputs!$D$12*$B8*(1-Inputs!$C$29)-'Purchase Price'!$C$26*(1-Inputs!$C$29)-((Inputs!$D$14*(1+C$5)*Inputs!$D$7)*Inputs!$C$27)*Inputs!$C$28*(1-Inputs!$C$29))/(Inputs!$C$7+((Inputs!$D$14*(1+C$5)*Inputs!$D$7)*Inputs!$C$26/Inputs!$C$14))/Inputs!$C$19-1 -> 0.008863993 | D8: =(Inputs!$C$6+Inputs!$D$6+Inputs!$D$12*$B8*(1-Inputs!$C$29)-'Purchase Price'!$C$26*(1-Inputs!$C$29)-((Inputs!$D$14*(1+D$5)*Inputs!$D$7)*Inputs!$C$27)*Inputs!$C$28*(1-Inputs!$C$29))/(Inputs!$C$7+((Inputs!$D$14*(1+D$5)*Inputs!$D$7)*Inputs!$C$26/Inputs!$C$14))/Inputs!$C$19-1 -> -0.0071146804 | E8: =(Inputs!$C$6+Inputs!$D$6+Inputs!$D$12*$B8*(1-Inputs!$C$29)-'Purchase Price'!$C$26*(1-Inputs!$C$29)-((Inputs!$D$14*(1+E$5)*Inputs!$D$7)*Inputs!$C$27)*Inputs!$C$28*(1-Inputs!$C$29))/(Inputs!$C$7+((Inputs!$D$14*(1+E$5)*Inputs!$D$7)*Inputs!$C$26/Inputs!$C$14))/Inputs!$C$19-1 -> -0.022651419 | F8: =(Inputs!$C$6+Inputs!$D$6+Inputs!$D$12*$B8*(1-Inputs!$C$29)-'Purchase Price'!$C$26*(1-Inputs!$C$29)-((Inputs!$D$14*(1+F$5)*Inputs!$D$7)*Inputs!$C$27)*Inputs!$C$28*(1-Inputs!$C$29))/(Inputs!$C$7+((Inputs!$D$14*(1+F$5)*Inputs!$D$7)*Inputs!$C$26/Inputs!$C$14))/Inputs!$C$19-1 -> -0.037764308 | G8: =(Inputs!$C$6+Inputs!$D$6+Inputs!$D$12*$B8*(1-Inputs!$C$29)-'Purchase Price'!$C$26*(1-Inputs!$C$29)-((Inputs!$D$14*(1+G$5)*Inputs!$D$7)*Inputs!$C$27)*Inputs!$C$28*(1-Inputs!$C$29))/(Inputs!$C$7+((Inputs!$D$14*(1+G$5)*Inputs!$D$7)*Inputs!$C$26/Inputs!$C$14))/Inputs!$C$19-1 -> -0.052470457
B9: 0.3 | C9: =(Inputs!$C$6+Inputs!$D$6+Inputs!$D$12*$B9*(1-Inputs!$C$29)-'Purchase Price'!$C$26*(1-Inputs!$C$29)-((Inputs!$D$14*(1+C$5)*Inputs!$D$7)*Inputs!$C$27)*Inputs!$C$28*(1-Inputs!$C$29))/(Inputs!$C$7+((Inputs!$D$14*(1+C$5)*Inputs!$D$7)*Inputs!$C$26/Inputs!$C$14))/Inputs!$C$19-1 -> 0.014810198 | D9: =(Inputs!$C$6+Inputs!$D$6+Inputs!$D$12*$B9*(1-Inputs!$C$29)-'Purchase Price'!$C$26*(1-Inputs!$C$29)-((Inputs!$D$14*(1+D$5)*Inputs!$D$7)*Inputs!$C$27)*Inputs!$C$28*(1-Inputs!$C$29))/(Inputs!$C$7+((Inputs!$D$14*(1+D$5)*Inputs!$D$7)*Inputs!$C$26/Inputs!$C$14))/Inputs!$C$19-1 -> -0.0012518581 | E9: =(Inputs!$C$6+Inputs!$D$6+Inputs!$D$12*$B9*(1-Inputs!$C$29)-'Purchase Price'!$C$26*(1-Inputs!$C$29)-((Inputs!$D$14*(1+E$5)*Inputs!$D$7)*Inputs!$C$27)*Inputs!$C$28*(1-Inputs!$C$29))/(Inputs!$C$7+((Inputs!$D$14*(1+E$5)*Inputs!$D$7)*Inputs!$C$26/Inputs!$C$14))/Inputs!$C$19-1 -> -0.016869673 | F9: =(Inputs!$C$6+Inputs!$D$6+Inputs!$D$12*$B9*(1-Inputs!$C$29)-'Purchase Price'!$C$26*(1-Inputs!$C$29)-((Inputs!$D$14*(1+F$5)*Inputs!$D$7)*Inputs!$C$27)*Inputs!$C$28*(1-Inputs!$C$29))/(Inputs!$C$7+((Inputs!$D$14*(1+F$5)*Inputs!$D$7)*Inputs!$C$26/Inputs!$C$14))/Inputs!$C$19-1 -> -0.032061426 | G9: =(Inputs!$C$6+Inputs!$D$6+Inputs!$D$12*$B9*(1-Inputs!$C$29)-'Purchase Price'!$C$26*(1-Inputs!$C$29)-((Inputs!$D$14*(1+G$5)*Inputs!$D$7)*Inputs!$C$27)*Inputs!$C$28*(1-Inputs!$C$29))/(Inputs!$C$7+((Inputs!$D$14*(1+G$5)*Inputs!$D$7)*Inputs!$C$26/Inputs!$C$14))/Inputs!$C$19-1 -> -0.046844318
B10: 0.35 | C10: =(Inputs!$C$6+Inputs!$D$6+Inputs!$D$12*$B10*(1-Inputs!$C$29)-'Purchase Price'!$C$26*(1-Inputs!$C$29)-((Inputs!$D$14*(1+C$5)*Inputs!$D$7)*Inputs!$C$27)*Inputs!$C$28*(1-Inputs!$C$29))/(Inputs!$C$7+((Inputs!$D$14*(1+C$5)*Inputs!$D$7)*Inputs!$C$26/Inputs!$C$14))/Inputs!$C$19-1 -> 0.020756403 | D10: =(Inputs!$C$6+Inputs!$D$6+Inputs!$D$12*$B10*(1-Inputs!$C$29)-'Purchase Price'!$C$26*(1-Inputs!$C$29)-((Inputs!$D$14*(1+D$5)*Inputs!$D$7)*Inputs!$C$27)*Inputs!$C$28*(1-Inputs!$C$29))/(Inputs!$C$7+((Inputs!$D$14*(1+D$5)*Inputs!$D$7)*Inputs!$C$26/Inputs!$C$14))/Inputs!$C$19-1 -> 0.0046109642 | E10: =(Inputs!$C$6+Inputs!$D$6+Inputs!$D$12*$B10*(1-Inputs!$C$29)-'Purchase Price'!$C$26*(1-Inputs!$C$29)-((Inputs!$D$14*(1+E$5)*Inputs!$D$7)*Inputs!$C$27)*Inputs!$C$28*(1-Inputs!$C$29))/(Inputs!$C$7+((Inputs!$D$14*(1+E$5)*Inputs!$D$7)*Inputs!$C$26/Inputs!$C$14))/Inputs!$C$19-1 -> -0.011087927 | F10: =(Inputs!$C$6+Inputs!$D$6+Inputs!$D$12*$B10*(1-Inputs!$C$29)-'Purchase Price'!$C$26*(1-Inputs!$C$29)-((Inputs!$D$14*(1+F$5)*Inputs!$D$7)*Inputs!$C$27)*Inputs!$C$28*(1-Inputs!$C$29))/(Inputs!$C$7+((Inputs!$D$14*(1+F$5)*Inputs!$D$7)*Inputs!$C$26/Inputs!$C$14))/Inputs!$C$19-1 -> -0.026358545 | G10: =(Inputs!$C$6+Inputs!$D$6+Inputs!$D$12*$B10*(1-Inputs!$C$29)-'Purchase Price'!$C$26*(1-Inputs!$C$29)-((Inputs!$D$14*(1+G$5)*Inputs!$D$7)*Inputs!$C$27)*Inputs!$C$28*(1-Inputs!$C$29))/(Inputs!$C$7+((Inputs!$D$14*(1+G$5)*Inputs!$D$7)*Inputs!$C$26/Inputs!$C$14))/Inputs!$C$19-1 -> -0.041218178
B12: TANGIBLE BOOK VALUE PER SHARE DILUTION
B13: Consideration in stock \ Offer premium | C13: 0.1 | D13: 0.175 | E13: 0.25 | F13: 0.325 | G13: 0.4
B14: 0.5 | C14: =(Inputs!$C$17+((Inputs!$D$14*(1+C$13)*Inputs!$D$7)*$B14)-((Inputs!$D$14*(1+C$13)*Inputs!$D$7)-'Purchase Price'!$C$22)-'Purchase Price'!$C$20)/(Inputs!$C$7+(((Inputs!$D$14*(1+C$13)*Inputs!$D$7)*$B14)/Inputs!$C$14))/Inputs!$C$20-1 -> -0.16019155 | D14: =(Inputs!$C$17+((Inputs!$D$14*(1+D$13)*Inputs!$D$7)*$B14)-((Inputs!$D$14*(1+D$13)*Inputs!$D$7)-'Purchase Price'!$C$22)-'Purchase Price'!$C$20)/(Inputs!$C$7+(((Inputs!$D$14*(1+D$13)*Inputs!$D$7)*$B14)/Inputs!$C$14))/Inputs!$C$20-1 -> -0.18426131 | E14: =(Inputs!$C$17+((Inputs!$D$14*(1+E$13)*Inputs!$D$7)*$B14)-((Inputs!$D$14*(1+E$13)*Inputs!$D$7)-'Purchase Price'!$C$22)-'Purchase Price'!$C$20)/(Inputs!$C$7+(((Inputs!$D$14*(1+E$13)*Inputs!$D$7)*$B14)/Inputs!$C$14))/Inputs!$C$20-1 -> -0.20782203 | F14: =(Inputs!$C$17+((Inputs!$D$14*(1+F$13)*Inputs!$D$7)*$B14)-((Inputs!$D$14*(1+F$13)*Inputs!$D$7)-'Purchase Price'!$C$22)-'Purchase Price'!$C$20)/(Inputs!$C$7+(((Inputs!$D$14*(1+F$13)*Inputs!$D$7)*$B14)/Inputs!$C$14))/Inputs!$C$20-1 -> -0.23088971 | G14: =(Inputs!$C$17+((Inputs!$D$14*(1+G$13)*Inputs!$D$7)*$B14)-((Inputs!$D$14*(1+G$13)*Inputs!$D$7)-'Purchase Price'!$C$22)-'Purchase Price'!$C$20)/(Inputs!$C$7+(((Inputs!$D$14*(1+G$13)*Inputs!$D$7)*$B14)/Inputs!$C$14))/Inputs!$C$20-1 -> -0.25347964
B15: 0.6 | C15: =(Inputs!$C$17+((Inputs!$D$14*(1+C$13)*Inputs!$D$7)*$B15)-((Inputs!$D$14*(1+C$13)*Inputs!$D$7)-'Purchase Price'!$C$22)-'Purchase Price'!$C$20)/(Inputs!$C$7+(((Inputs!$D$14*(1+C$13)*Inputs!$D$7)*$B15)/Inputs!$C$14))/Inputs!$C$20-1 -> -0.14260436 | D15: =(Inputs!$C$17+((Inputs!$D$14*(1+D$13)*Inputs!$D$7)*$B15)-((Inputs!$D$14*(1+D$13)*Inputs!$D$7)-'Purchase Price'!$C$22)-'Purchase Price'!$C$20)/(Inputs!$C$7+(((Inputs!$D$14*(1+D$13)*Inputs!$D$7)*$B15)/Inputs!$C$14))/Inputs!$C$20-1 -> -0.16492822 | E15: =(Inputs!$C$17+((Inputs!$D$14*(1+E$13)*Inputs!$D$7)*$B15)-((Inputs!$D$14*(1+E$13)*Inputs!$D$7)-'Purchase Price'!$C$22)-'Purchase Price'!$C$20)/(Inputs!$C$7+(((Inputs!$D$14*(1+E$13)*Inputs!$D$7)*$B15)/Inputs!$C$14))/Inputs!$C$20-1 -> -0.18670483 | F15: =(Inputs!$C$17+((Inputs!$D$14*(1+F$13)*Inputs!$D$7)*$B15)-((Inputs!$D$14*(1+F$13)*Inputs!$D$7)-'Purchase Price'!$C$22)-'Purchase Price'!$C$20)/(Inputs!$C$7+(((Inputs!$D$14*(1+F$13)*Inputs!$D$7)*$B15)/Inputs!$C$14))/Inputs!$C$20-1 -> -0.20795409 | G15: =(Inputs!$C$17+((Inputs!$D$14*(1+G$13)*Inputs!$D$7)*$B15)-((Inputs!$D$14*(1+G$13)*Inputs!$D$7)-'Purchase Price'!$C$22)-'Purchase Price'!$C$20)/(Inputs!$C$7+(((Inputs!$D$14*(1+G$13)*Inputs!$D$7)*$B15)/Inputs!$C$14))/Inputs!$C$20-1 -> -0.2286949
B16: 0.7 | C16: =(Inputs!$C$17+((Inputs!$D$14*(1+C$13)*Inputs!$D$7)*$B16)-((Inputs!$D$14*(1+C$13)*Inputs!$D$7)-'Purchase Price'!$C$22)-'Purchase Price'!$C$20)/(Inputs!$C$7+(((Inputs!$D$14*(1+C$13)*Inputs!$D$7)*$B16)/Inputs!$C$14))/Inputs!$C$20-1 -> -0.12606533 | D16: =(Inputs!$C$17+((Inputs!$D$14*(1+D$13)*Inputs!$D$7)*$B16)-((Inputs!$D$14*(1+D$13)*Inputs!$D$7)-'Purchase Price'!$C$22)-'Purchase Price'!$C$20)/(Inputs!$C$7+(((Inputs!$D$14*(1+D$13)*Inputs!$D$7)*$B16)/Inputs!$C$14))/Inputs!$C$20-1 -> -0.14680864 | E16: =(Inputs!$C$17+((Inputs!$D$14*(1+E$13)*Inputs!$D$7)*$B16)-((Inputs!$D$14*(1+E$13)*Inputs!$D$7)-'Purchase Price'!$C$22)-'Purchase Price'!$C$20)/(Inputs!$C$7+(((Inputs!$D$14*(1+E$13)*Inputs!$D$7)*$B16)/Inputs!$C$14))/Inputs!$C$20-1 -> -0.16697824 | F16: =(Inputs!$C$17+((Inputs!$D$14*(1+F$13)*Inputs!$D$7)*$B16)-((Inputs!$D$14*(1+F$13)*Inputs!$D$7)-'Purchase Price'!$C$22)-'Purchase Price'!$C$20)/(Inputs!$C$7+(((Inputs!$D$14*(1+F$13)*Inputs!$D$7)*$B16)/Inputs!$C$14))/Inputs!$C$20-1 -> -0.18659761 | G16: =(Inputs!$C$17+((Inputs!$D$14*(1+G$13)*Inputs!$D$7)*$B16)-((Inputs!$D$14*(1+G$13)*Inputs!$D$7)-'Purchase Price'!$C$22)-'Purchase Price'!$C$20)/(Inputs!$C$7+(((Inputs!$D$14*(1+G$13)*Inputs!$D$7)*$B16)/Inputs!$C$14))/Inputs!$C$20-1 -> -0.20568895
B17: 0.8 | C17: =(Inputs!$C$17+((Inputs!$D$14*(1+C$13)*Inputs!$D$7)*$B17)-((Inputs!$D$14*(1+C$13)*Inputs!$D$7)-'Purchase Price'!$C$22)-'Purchase Price'!$C$20)/(Inputs!$C$7+(((Inputs!$D$14*(1+C$13)*Inputs!$D$7)*$B17)/Inputs!$C$14))/Inputs!$C$20-1 -> -0.11048347 | D17: =(Inputs!$C$17+((Inputs!$D$14*(1+D$13)*Inputs!$D$7)*$B17)-((Inputs!$D$14*(1+D$13)*Inputs!$D$7)-'Purchase Price'!$C$22)-'Purchase Price'!$C$20)/(Inputs!$C$7+(((Inputs!$D$14*(1+D$13)*Inputs!$D$7)*$B17)/Inputs!$C$14))/Inputs!$C$20-1 -> -0.1297918 | E17: =(Inputs!$C$17+((Inputs!$D$14*(1+E$13)*Inputs!$D$7)*$B17)-((Inputs!$D$14*(1+E$13)*Inputs!$D$7)-'Purchase Price'!$C$22)-'Purchase Price'!$C$20)/(Inputs!$C$7+(((Inputs!$D$14*(1+E$13)*Inputs!$D$7)*$B17)/Inputs!$C$14))/Inputs!$C$20-1 -> -0.14850928 | F17: =(Inputs!$C$17+((Inputs!$D$14*(1+F$13)*Inputs!$D$7)*$B17)-((Inputs!$D$14*(1+F$13)*Inputs!$D$7)-'Purchase Price'!$C$22)-'Purchase Price'!$C$20)/(Inputs!$C$7+(((Inputs!$D$14*(1+F$13)*Inputs!$D$7)*$B17)/Inputs!$C$14))/Inputs!$C$20-1 -> -0.1666626 | G17: =(Inputs!$C$17+((Inputs!$D$14*(1+G$13)*Inputs!$D$7)*$B17)-((Inputs!$D$14*(1+G$13)*Inputs!$D$7)-'Purchase Price'!$C$22)-'Purchase Price'!$C$20)/(Inputs!$C$7+(((Inputs!$D$14*(1+G$13)*Inputs!$D$7)*$B17)/Inputs!$C$14))/Inputs!$C$20-1 -> -0.18427691
B18: 0.9 | C18: =(Inputs!$C$17+((Inputs!$D$14*(1+C$13)*Inputs!$D$7)*$B18)-((Inputs!$D$14*(1+C$13)*Inputs!$D$7)-'Purchase Price'!$C$22)-'Purchase Price'!$C$20)/(Inputs!$C$7+(((Inputs!$D$14*(1+C$13)*Inputs!$D$7)*$B18)/Inputs!$C$14))/Inputs!$C$20-1 -> -0.095778021 | D18: =(Inputs!$C$17+((Inputs!$D$14*(1+D$13)*Inputs!$D$7)*$B18)-((Inputs!$D$14*(1+D$13)*Inputs!$D$7)-'Purchase Price'!$C$22)-'Purchase Price'!$C$20)/(Inputs!$C$7+(((Inputs!$D$14*(1+D$13)*Inputs!$D$7)*$B18)/Inputs!$C$14))/Inputs!$C$20-1 -> -0.11378 | E18: =(Inputs!$C$17+((Inputs!$D$14*(1+E$13)*Inputs!$D$7)*$B18)-((Inputs!$D$14*(1+E$13)*Inputs!$D$7)-'Purchase Price'!$C$22)-'Purchase Price'!$C$20)/(Inputs!$C$7+(((Inputs!$D$14*(1+E$13)*Inputs!$D$7)*$B18)/Inputs!$C$14))/Inputs!$C$20-1 -> -0.13118138 | F18: =(Inputs!$C$17+((Inputs!$D$14*(1+F$13)*Inputs!$D$7)*$B18)-((Inputs!$D$14*(1+F$13)*Inputs!$D$7)-'Purchase Price'!$C$22)-'Purchase Price'!$C$20)/(Inputs!$C$7+(((Inputs!$D$14*(1+F$13)*Inputs!$D$7)*$B18)/Inputs!$C$14))/Inputs!$C$20-1 -> -0.14801173 | G18: =(Inputs!$C$17+((Inputs!$D$14*(1+G$13)*Inputs!$D$7)*$B18)-((Inputs!$D$14*(1+G$13)*Inputs!$D$7)-'Purchase Price'!$C$22)-'Purchase Price'!$C$20)/(Inputs!$C$7+(((Inputs!$D$14*(1+G$13)*Inputs!$D$7)*$B18)/Inputs!$C$14))/Inputs!$C$20-1 -> -0.16429869
B20: Shaded cells are the base case and reconcile to the Accretion and Capital sheets. Read the second grid against the first: paying more in stock protects the CET1 ratio and worsens tangible book dilution, paying more in cash does the reverse. There is no mix that makes a price above two times tangible book look cheap.

Sheet Summary
B1: Emirates NBD / Mashreqbank — Merger Model — Accretion/Dilution, Synergies and Pro Forma | F1: EMIRATES NBD
B2: The transaction on one page
B4: THE TRANSACTION
B5: Acquirer | C5: ="Emirates NBD (DFM: EMIRATESNBD)" -> Emirates NBD (DFM: EMIRATESNBD)
B6: Target | C6: ="Mashreqbank (DFM: MASQ)" -> Mashreqbank (DFM: MASQ)
B7: Offer price per share (AED) | C7: ='Purchase Price'!$C$5 -> 418.625
B8: Premium to unaffected price | C8: =Inputs!$C$25 -> 0.25
B9: Equity purchase price (AED m) | C9: ='Purchase Price'!$C$6 -> 83980.29
B10: Consideration | C10: =TEXT(Inputs!$C$26,"0%")&" stock / "&TEXT(Inputs!$C$27,"0%")&" cash" -> 70% stock / 30% cash
B11: Exchange ratio | C11: ='Purchase Price'!$C$7 -> 9.4224277
B12: Target shareholders' ownership of the combined bank | C12: ='Purchase Price'!$C$12 -> 0.23048143
B14: THE THREE TESTS
B15: 1 · Tangible book value per share dilution | C15: ='Capital & TBV'!$C$13 -> -0.16697824
B16: Earnback | C16: ='Capital & TBV'!$C$15 -> Never — the deal is dilutive to EPS at full synergies
B17: 2 · Pro forma CET1 ratio | C17: ='Capital & TBV'!$C$24 -> 0.12978893
B18: Headroom above the minimum (pp) | C18: ='Capital & TBV'!$C$26 -> 1.9788927
B19: 3 · EPS accretion at full run-rate synergies | C19: =Accretion!$E$18 -> -0.022651419
B20: Synergies required merely to break even | C20: =Accretion!$C$24 -> 0.44588736
B22: Return on invested capital | C22: ='Capital & TBV'!$C$29 -> 0.086308735
B23: Spread over the 12% required return (pp) | C23: ='Capital & TBV'!$C$30 -> -3.3691265
B25: VERDICT
B26: • Emirates NBD trades at roughly 1.4 times tangible book. Mashreqbank trades at roughly 1.7 times, and a 25% premium takes the price paid above 2.1 times. An acquirer issuing its own stock at 1.4 times to buy assets at 2.1 times transfers value to the seller on the day the deal is announced; no amount of synergy phasing undoes that.
B27: • The arithmetic is not close. The cost synergies required just to hold earnings per share flat are far above the 25% of target operating expenses assumed here, and above anything disclosed in comparable bank mergers.
B28: • The capital ratio survives, which is why the consideration is stock-heavy. A cash-heavy structure would not.
B29: • The useful output of a merger model is often the reason not to do the deal. This one says Emirates NBD would have to buy Mashreqbank close to its unaffected price, or in stock at a materially higher acquirer rating, for the transaction to make sense for its own shareholders.

Sheet Checks
B1: Emirates NBD / Mashreqbank — Merger Model — Accretion/Dilution, Synergies and Pro Forma | E1: EMIRATES NBD
B2: Every check must read TRUE
B4: INTEGRITY CHECKS
B5: Consideration percentages sum to 100% | C5: =ABS(Inputs!$C$26+Inputs!$C$27-1)<0.0001 -> TRUE
B6: Stock plus cash consideration equals the equity purchase price | C6: =ABS('Purchase Price'!$C$8+'Purchase Price'!$C$9-'Purchase Price'!$C$6)<0.01 -> TRUE
B7: Purchase price equals net assets acquired plus goodwill | C7: =ABS('Purchase Price'!$C$6-('Purchase Price'!$C$22+'Purchase Price'!$C$23))<0.01 -> TRUE
B8: Goodwill is positive (the price exceeds fair value of net assets) | C8: ='Purchase Price'!$C$23>0 -> TRUE
B9: Pro forma share count equals acquirer shares plus new shares | C9: =ABS('Purchase Price'!$C$11-(Inputs!$C$7+'Purchase Price'!$C$10))<0.001 -> TRUE
B10: Tangible equity bridge ties to stock issued less intangibles created | C10: =ABS('Capital & TBV'!$C$9-(Inputs!$C$17+'Purchase Price'!$C$8-'Purchase Price'!$C$23-'Purchase Price'!$C$20))<0.01 -> TRUE
B11: Pro forma CET1 stays above the regulatory minimum | C11: ='Capital & TBV'!$C$24>Inputs!$C$50 -> TRUE
B12: Synergy phasing is non-decreasing and ends at 100% | C12: =AND(Inputs!$C$33<=Inputs!$C$34,Inputs!$C$34<=Inputs!$C$35,Inputs!$C$35=1) -> TRUE
B13: Year 3 pro forma net income exceeds year 1 (integration costs drop out) | C13: =Accretion!$E$12>Accretion!$C$12 -> TRUE
B14: Base-case sensitivity cell reconciles to the Accretion sheet | C14: =ABS(Sensitivity!E8-Accretion!$E$18)<0.0005 -> TRUE
B15: Base-case TBV sensitivity cell reconciles to the Capital sheet | C15: =ABS(Sensitivity!E16-'Capital & TBV'!$C$13)<0.0005 -> TRUE
B16: Price paid per share exceeds the target's unaffected price | C16: ='Purchase Price'!$C$5>Inputs!$D$14 -> TRUE
B17: Standalone EPS reconciles to reported diluted EPS within 1% | C17: =AND(ABS(Inputs!$C$19/3.71-1)<0.01,ABS(Inputs!$D$19/32.98-1)<0.01) -> TRUE
B18: Tangible common equity is below total equity for both banks | C18: =AND(Inputs!$C$17<Inputs!$C$8,Inputs!$D$17<Inputs!$D$8) -> TRUE
B20: MODEL STATUS | C20: =IF(COUNTIF(C5:C18,FALSE())=0,"MODEL OK","CHECK FAILED") -> MODEL OK
B22: The EPS reconciliation check is the one that matters most: it ties the model's computed earnings per share back to the diluted EPS each bank actually reported, so a mistyped share count or net income figure fails the model rather than quietly changing the answer.
