Workbook

Sheet Cover
B2: Apple Inc. — Three-Statement Operating Model
B3: IB portfolio · Project 1 of 20 · US$ billions unless stated · fiscal years ending late September
B5: Purpose | C5: Integrated income statement, balance sheet and cash-flow forecast FY2026E–FY2030E driven from an assumptions sheet with Base / Upside / Downside cases.
B6: How to use | C6: Change the scenario in Inputs!C4 (1 = Base, 2 = Upside, 3 = Downside). Edit blue cells only. Every other cell is a formula.
B7: Colour code | C7: Blue = hard-coded input · Black = formula · Green = link to another sheet · Yellow fill = the scenario selector and key levers.
B8: Sheets | C8: Inputs → Historical → Model (IS, BS, CF and schedules) → Checks → Summary.
B9: Historicals | C9: FY2022–FY2025 from Apple's Form 10-K filings (SEC EDGAR, CIK 0000320193), pulled via Yahoo Finance and reconciled to reported totals on the Historical sheet.
B10: Simplifications | C10: Interest on opening balances (no circularity); receivables include vendor non-trade receivables; other current liabilities include accrued expenses, deferred revenue and taxes payable; long-term marketable securities modelled as a run-off input; buybacks charged to retained earnings.
B11: Source | C11: https://www.sec.gov/cgi-bin/browse-edgar?action=getcompany&CIK=0000320193&type=10-K
B12: Author | C12: Jainam Mehta · github.com/jainammehta1215/ib-portfolio

Sheet Inputs
B2: Assumptions
B4: Scenario selector (1 Base · 2 Upside · 3 Downside) | C4: 1 | D4: =CHOOSE($C$4,"Base","Upside","Downside") -> Base
B5: Interest is computed on opening balances to avoid a circular reference. In Excel you may switch to average balances after enabling File → Options → Formulas → Iterative calculation.
B7: General inputs
B8: Interest rate on debt | C8: 0.04 | I8: Blended coupon on Apple's notes; FY2025 interest expense ≈ 3.9% of average debt (10-K)
B9: Yield on cash & investments | C9: 0.04 | I9: Approximate yield on Apple's short- and long-term marketable securities
B10: Revolver interest rate | C10: 0.055 | I10: Assumed commercial-paper / revolver rate
B11: Minimum cash balance (US$bn) | C11: 25 | I11: Operating cash floor; revolver draws when forecast cash falls below this
B12: Share price at FY2025 year-end (US$) | C12: 254 | I12: Approximate closing price late September 2025; used only for buyback share count
B13: Share price growth p.a. for buyback math | C13: 0.06 | I13: Assumed; affects share count and EPS, not cash
B15: Forecast drivers by scenario (selected row feeds the Model) | C15: FY2026E | D15: FY2027E | E15: FY2028E | F15: FY2029E | G15: FY2030E | I15: Basis / source
B16: Revenue growth | I16: FY2023–25 growth: -2.8%, +2.0%, +6.4%. Base assumes mid-single-digit growth led by services.
B17: Base | C17: 0.06 | D17: 0.05 | E17: 0.05 | F17: 0.04 | G17: 0.04
B18: Upside | C18: 0.09 | D18: 0.08 | E18: 0.07 | F18: 0.06 | G18: 0.06
B19: Downside | C19: 0.02 | D19: 0.02 | E19: 0.02 | F19: 0.02 | G19: 0.02
B20: Selected | C20: =CHOOSE($C$4,C17,C18,C19) -> 0.06 | D20: =CHOOSE($C$4,D17,D18,D19) -> 0.05 | E20: =CHOOSE($C$4,E17,E18,E19) -> 0.05 | F20: =CHOOSE($C$4,F17,F18,F19) -> 0.04 | G20: =CHOOSE($C$4,G17,G18,G19) -> 0.04
B22: Gross margin | I22: FY2025 gross margin 46.9%; services mix lifts it in Base and Upside; tariffs/pricing pressure in Downside.
B23: Base | C23: 0.47 | D23: 0.472 | E23: 0.474 | F23: 0.475 | G23: 0.475
B24: Upside | C24: 0.48 | D24: 0.485 | E24: 0.49 | F24: 0.492 | G24: 0.495
B25: Downside | C25: 0.455 | D25: 0.45 | E25: 0.45 | F25: 0.45 | G25: 0.45
B26: Selected | C26: =CHOOSE($C$4,C23,C24,C25) -> 0.47 | D26: =CHOOSE($C$4,D23,D24,D25) -> 0.472 | E26: =CHOOSE($C$4,E23,E24,E25) -> 0.474 | F26: =CHOOSE($C$4,F23,F24,F25) -> 0.475 | G26: =CHOOSE($C$4,G23,G24,G25) -> 0.475
B28: R&D as % of revenue | I28: FY2025: 8.3%
B29: Base | C29: 0.083 | D29: 0.083 | E29: 0.083 | F29: 0.083 | G29: 0.083
B30: Upside | C30: 0.082 | D30: 0.082 | E30: 0.082 | F30: 0.082 | G30: 0.082
B31: Downside | C31: 0.086 | D31: 0.086 | E31: 0.086 | F31: 0.086 | G31: 0.086
B32: Selected | C32: =CHOOSE($C$4,C29,C30,C31) -> 0.083 | D32: =CHOOSE($C$4,D29,D30,D31) -> 0.083 | E32: =CHOOSE($C$4,E29,E30,E31) -> 0.083 | F32: =CHOOSE($C$4,F29,F30,F31) -> 0.083 | G32: =CHOOSE($C$4,G29,G30,G31) -> 0.083
B34: SG&A as % of revenue | I34: FY2025: 6.6%
B35: Base | C35: 0.066 | D35: 0.066 | E35: 0.066 | F35: 0.066 | G35: 0.066
B36: Upside | C36: 0.064 | D36: 0.064 | E36: 0.064 | F36: 0.064 | G36: 0.064
B37: Downside | C37: 0.068 | D37: 0.068 | E37: 0.068 | F37: 0.068 | G37: 0.068
B38: Selected | C38: =CHOOSE($C$4,C35,C36,C37) -> 0.066 | D38: =CHOOSE($C$4,D35,D36,D37) -> 0.066 | E38: =CHOOSE($C$4,E35,E36,E37) -> 0.066 | F38: =CHOOSE($C$4,F35,F36,F37) -> 0.066 | G38: =CHOOSE($C$4,G35,G36,G37) -> 0.066
B40: Effective tax rate | I40: FY2025: 15.6% (FY2024 24.1% distorted by the EU State Aid charge)
B41: Base | C41: 0.165 | D41: 0.165 | E41: 0.165 | F41: 0.165 | G41: 0.165
B42: Upside | C42: 0.16 | D42: 0.16 | E42: 0.16 | F42: 0.16 | G42: 0.16
B43: Downside | C43: 0.175 | D43: 0.175 | E43: 0.175 | F43: 0.175 | G43: 0.175
B44: Selected | C44: =CHOOSE($C$4,C41,C42,C43) -> 0.165 | D44: =CHOOSE($C$4,D41,D42,D43) -> 0.165 | E44: =CHOOSE($C$4,E41,E42,E43) -> 0.165 | F44: =CHOOSE($C$4,F41,F42,F43) -> 0.165 | G44: =CHOOSE($C$4,G41,G42,G43) -> 0.165
B46: D&A as % of revenue | I46: FY2023–25: 3.0%, 2.9%, 2.8%
B47: Base | C47: 0.028 | D47: 0.028 | E47: 0.028 | F47: 0.028 | G47: 0.028
B48: Upside | C48: 0.028 | D48: 0.028 | E48: 0.028 | F48: 0.028 | G48: 0.028
B49: Downside | C49: 0.029 | D49: 0.029 | E49: 0.029 | F49: 0.029 | G49: 0.029
...

Sheet Summary
B2: ="Key outputs — "&Inputs!$D$4&" case (US$bn)" -> Key outputs — Base case (US$bn)
B3: Toggle Inputs!C4 to compare scenarios. Green = link to Model.
C5: FY2022A | D5: FY2023A | E5: FY2024A | F5: FY2025A | G5: FY2026E | H5: FY2027E | I5: FY2028E | J5: FY2029E | K5: FY2030E
B6: Revenue | C6: =Model!C7 -> 394.328 | D6: =Model!D7 -> 383.285 | E6: =Model!E7 -> 391.035 | F6: =Model!F7 -> 416.161 | G6: =Model!G7 -> 441.13066 | H6: =Model!H7 -> 463.18719 | I6: =Model!I7 -> 486.34655 | J6: =Model!J7 -> 505.80041 | K6: =Model!K7 -> 526.03243
B7: growth | C7: =Model!C8 -> 0 | D7: =Model!D8 -> -0.028004605 | E7: =Model!E8 -> 0.020219941 | F7: =Model!F8 -> 0.064255118 | G7: =Model!G8 -> 0.06 | H7: =Model!H8 -> 0.05 | I7: =Model!I8 -> 0.05 | J7: =Model!J8 -> 0.04 | K7: =Model!K8 -> 0.04
B8: Gross margin | C8: =Model!C11 -> 0.43309631 | D8: =Model!D11 -> 0.4413113 | E8: =Model!E11 -> 0.4620635 | F8: =Model!F11 -> 0.46905164 | G8: =Model!G11 -> 0.47 | H8: =Model!H11 -> 0.472 | I8: =Model!I11 -> 0.474 | J8: =Model!J11 -> 0.475 | K8: =Model!K11 -> 0.475
B9: EBIT | C9: =Model!C14 -> 119.437 | D9: =Model!D14 -> 114.301 | E9: =Model!E14 -> 123.216 | F9: =Model!F14 -> 133.05 | G9: =Model!G14 -> 141.60294 | H9: =Model!H14 -> 149.60946 | I9: =Model!I14 -> 158.06263 | J9: =Model!J14 -> 164.89094 | K9: =Model!K14 -> 171.48657
B10: EBIT margin | C10: =Model!C15 -> 0.30288744 | D10: =Model!D15 -> 0.29821412 | E10: =Model!E15 -> 0.31510223 | F10: =Model!F15 -> 0.319708 | G10: =Model!G15 -> 0.321 | H10: =Model!H15 -> 0.323 | I10: =Model!I15 -> 0.325 | J10: =Model!J15 -> 0.326 | K10: =Model!K15 -> 0.326
B11: Net income | C11: =Model!C23 -> 99.803 | D11: =Model!D23 -> 96.995 | E11: =Model!E23 -> 93.736 | F11: =Model!F23 -> 112.01 | G11: =Model!G23 -> 119.36614 | H11: =Model!H23 -> 126.05159 | I11: =Model!I23 -> 133.10998 | J11: =Model!J23 -> 138.81162 | K11: =Model!K23 -> 144.31897
B12: Diluted EPS (US$) | C12: =Model!C30 -> 6.1131324 | D12: =Model!D30 -> 6.1338772 | E12: =Model!E30 -> 6.0835929 | F12: =Model!F30 -> 7.4648451 | G12: =Model!G30 -> 8.1663199 | H12: =Model!H30 -> 8.8672721 | I12: =Model!I30 -> 9.6364237 | J12: =Model!J30 -> 10.348436 | K12: =Model!K30 -> 11.084185
B13: Free cash flow | C13: =Model!C100 -> 111.443 | D13: =Model!D100 -> 99.584 | E13: =Model!E100 -> 108.807 | F13: =Model!F100 -> 98.767 | G13: =Model!G100 -> 131.61306 | H13: =Model!H100 -> 139.2423 | I13: =Model!I100 -> 146.9469 | J13: =Model!J100 -> 153.23652 | K13: =Model!K100 -> 159.46638
B14: Shareholder returns | C14: =Model!C101 -> 104.243 | D14: =Model!D101 -> 92.575 | E14: =Model!E101 -> 110.183 | F14: =Model!F101 -> 106.132 | G14: =Model!G101 -> 131.61306 | H14: =Model!H101 -> 139.2423 | I14: =Model!I101 -> 146.9469 | J14: =Model!J101 -> 153.23652 | K14: =Model!K101 -> 159.46638
B15: Cash & ST investments | C15: =Model!C33 -> 48.304 | D15: =Model!D33 -> 61.555 | E15: =Model!E33 -> 65.171 | F15: =Model!F33 -> 54.697 | G15: =Model!G33 -> 59.697 | H15: =Model!H33 -> 64.697 | I15: =Model!I33 -> 69.697 | J15: =Model!J33 -> 71.697 | K15: =Model!K33 -> 73.697
B16: Total debt incl. revolver | C16: =Model!C45+Model!C48+Model!C46 -> 120.069 | D16: =Model!D45+Model!D48+Model!D46 -> 111.088 | E16: =Model!E45+Model!E48+Model!E46 -> 106.629 | F16: =Model!F45+Model!F48+Model!F46 -> 98.657 | G16: =Model!G45+Model!G48+Model!G46 -> 93.657 | H16: =Model!H45+Model!H48+Model!H46 -> 88.657 | I16: =Model!I45+Model!I48+Model!I46 -> 83.657 | J16: =Model!J45+Model!J48+Model!J46 -> 80.657 | K16: =Model!K45+Model!K48+Model!K46 -> 77.657
B17: Net debt / (net cash) | C17: =Model!C99 -> -49.04 | D17: =Model!D99 -> -51.011 | E17: =Model!E99 -> -50.021 | F17: =Model!F99 -> -33.763 | G17: =Model!G99 -> -33.763 | H17: =Model!H99 -> -33.763 | I17: =Model!I99 -> -33.763 | J17: =Model!J99 -> -33.763 | K17: =Model!K99 -> -33.763
B18: Shares outstanding (bn) | C18: =Model!C27 -> 15.943 | D18: =Model!D27 -> 15.55 | E18: =Model!E27 -> 15.117 | F18: =Model!F27 -> 14.773 | G18: =Model!G27 -> 14.373327 | H18: =Model!H27 -> 13.972383 | I18: =Model!I27 -> 13.571413 | J18: =Model!J27 -> 13.1759 | K18: =Model!K27 -> 12.786731

Sheet Historical
B2: Historical financials (US$bn) — Apple 10-K, FY2022–FY2025
B3: Reconciled: every subtotal ties to the reported statements. Receivables = trade + vendor non-trade receivables. 'Other' asset and liability lines are residuals to Apple's reported subtotals (so they include accrued expenses, deferred revenue, taxes payable and lease liabilities).
C5: FY2022 | D5: FY2023 | E5: FY2024 | F5: FY2025
B6: Income statement
B7: Revenue | C7: 394.328 | D7: 383.285 | E7: 391.035 | F7: 416.161
B8: Cost of revenue | C8: 223.546 | D8: 214.137 | E8: 210.352 | F8: 220.96
B9: Gross profit | C9: =C7-C8 -> 170.782 | D9: =D7-D8 -> 169.148 | E9: =E7-E8 -> 180.683 | F9: =F7-F8 -> 195.201
B10: Research & development | C10: 26.251 | D10: 29.915 | E10: 31.37 | F10: 34.55
B11: Selling, general & administrative | C11: 25.094 | D11: 24.932 | E11: 26.097 | F11: 27.601
B12: Operating income (EBIT) | C12: =C9-C10-C11 -> 119.437 | D12: =D9-D10-D11 -> 114.301 | E12: =E9-E10-E11 -> 123.216 | F12: =F9-F10-F11 -> 133.05
B13: Other income / (expense), net incl. interest | C13: -0.334 | D13: -0.565 | E13: 0.269 | F13: -0.321
B14: Pre-tax income | C14: =C12+C13 -> 119.103 | D14: =D12+D13 -> 113.736 | E14: =E12+E13 -> 123.485 | F14: =F12+F13 -> 132.729
B15: Income tax | C15: 19.3 | D15: 16.741 | E15: 29.749 | F15: 20.719
B16: Net income | C16: =C14-C15 -> 99.803 | D16: =D14-D15 -> 96.995 | E16: =E14-E15 -> 93.736 | F16: =F14-F15 -> 112.01
B17: Net income as reported (check) | C17: 99.803 | D17: 96.995 | E17: 93.736 | F17: 112.01
B18: Diluted weighted average shares (bn) | C18: 16.326 | D18: 15.813 | E18: 15.408 | F18: 15.005
B19: Diluted EPS (US$) | C19: =C17/C18 -> 6.1131324 | D19: =D17/D18 -> 6.1338772 | E19: =E17/E18 -> 6.0835929 | F19: =F17/F18 -> 7.4648451
B21: Balance sheet
B22: Cash & short-term investments | C22: 48.304 | D22: 61.555 | E22: 65.171 | F22: 54.697
B23: Receivables (trade + vendor non-trade) | C23: 60.932 | D23: 60.985 | E23: 66.243 | F23: 72.957
B24: Inventory | C24: 4.946 | D24: 6.331 | E24: 7.286 | F24: 5.718
B25: Other current assets | C25: 21.223 | D25: 14.695 | E25: 14.287 | F25: 14.585
B26: Total current assets | C26: =SUM(C22:C25) -> 135.405 | D26: =SUM(D22:D25) -> 143.566 | E26: =SUM(E22:E25) -> 152.987 | F26: =SUM(F22:F25) -> 147.957
B27: Long-term marketable securities | C27: 120.805 | D27: 100.544 | E27: 91.479 | F27: 77.723
B28: Property, plant & equipment, net | C28: 42.117 | D28: 43.715 | E28: 45.68 | F28: 49.834
B29: Other non-current assets (incl. deferred tax) | C29: 54.428 | D29: 64.758 | E29: 74.834 | F29: 83.727
B30: Total assets | C30: =C26+C27+C28+C29 -> 352.755 | D30: =D26+D27+D28+D29 -> 352.583 | E30: =E26+E27+E28+E29 -> 364.98 | F30: =F26+F27+F28+F29 -> 359.241
B32: Accounts payable | C32: 64.115 | D32: 62.611 | E32: 68.96 | F32: 69.86
B33: Other current liabilities | C33: 68.757 | D33: 66.89 | E33: 86.553 | F33: 75.442
B34: Current debt (incl. commercial paper) | C34: 21.11 | D34: 15.807 | E34: 20.879 | F34: 20.329
B35: Total current liabilities | C35: =SUM(C32:C34) -> 153.982 | D35: =SUM(D32:D34) -> 145.308 | E35: =SUM(E32:E34) -> 176.392 | F35: =SUM(F32:F34) -> 165.631
B36: Long-term debt | C36: 98.959 | D36: 95.281 | E36: 85.75 | F36: 78.328
B37: Other non-current liabilities | C37: 49.142 | D37: 49.848 | E37: 45.888 | F37: 41.549
B38: Total liabilities | C38: =C35+C36+C37 -> 302.083 | D38: =D35+D36+D37 -> 290.437 | E38: =E35+E36+E37 -> 308.03 | F38: =F35+F36+F37 -> 285.508
B39: Common stock & APIC | C39: 64.849 | D39: 73.812 | E39: 83.276 | F39: 93.568
B40: Retained earnings / (deficit) | C40: -3.068 | D40: -0.214 | E40: -19.154 | F40: -14.264
B41: Accumulated other comprehensive loss | C41: -11.109 | D41: -11.452 | E41: -7.172 | F41: -5.571
B42: Total shareholders' equity | C42: =C39+C40+C41 -> 50.672 | D42: =D39+D40+D41 -> 62.146 | E42: =E39+E40+E41 -> 56.95 | F42: =F39+F40+F41 -> 73.733
B43: Total liabilities & equity | C43: =C38+C42 -> 352.755 | D43: =D38+D42 -> 352.583 | E43: =E38+E42 -> 364.98 | F43: =F38+F42 -> 359.241
B44: Balance check (assets − liabilities − equity) | C44: =ROUND(C30-C43,2) -> 0 | D44: =ROUND(D30-D43,2) -> 0 | E44: =ROUND(E30-E43,2) -> 0 | F44: =ROUND(F30-F43,2) -> 0
...

Sheet Model
B2: Integrated model (US$bn)
B3: ="Scenario: "&Inputs!$D$4&" · FY2022–FY2025 actual (linked), FY2026E–FY2030E forecast" -> Scenario: Base · FY2022–FY2025 actual (linked), FY2026E–FY2030E forecast
C5: FY2022A | D5: FY2023A | E5: FY2024A | F5: FY2025A | G5: FY2026E | H5: FY2027E | I5: FY2028E | J5: FY2029E | K5: FY2030E
B6: INCOME STATEMENT
B7: Revenue | C7: =Historical!C7 -> 394.328 | D7: =Historical!D7 -> 383.285 | E7: =Historical!E7 -> 391.035 | F7: =Historical!F7 -> 416.161 | G7: =F7*(1+Inputs!C$20) -> 441.13066 | H7: =G7*(1+Inputs!D$20) -> 463.18719 | I7: =H7*(1+Inputs!E$20) -> 486.34655 | J7: =I7*(1+Inputs!F$20) -> 505.80041 | K7: =J7*(1+Inputs!G$20) -> 526.03243
B8: growth % | D8: =D7/C7-1 -> -0.028004605 | E8: =E7/D7-1 -> 0.020219941 | F8: =F7/E7-1 -> 0.064255118 | G8: =G7/F7-1 -> 0.06 | H8: =H7/G7-1 -> 0.05 | I8: =I7/H7-1 -> 0.05 | J8: =J7/I7-1 -> 0.04 | K8: =K7/J7-1 -> 0.04
B9: Cost of revenue | C9: =Historical!C8 -> 223.546 | D9: =Historical!D8 -> 214.137 | E9: =Historical!E8 -> 210.352 | F9: =Historical!F8 -> 220.96 | G9: =G7*(1-Inputs!C$26) -> 233.79925 | H9: =H7*(1-Inputs!D$26) -> 244.56284 | I9: =I7*(1-Inputs!E$26) -> 255.81829 | J9: =J7*(1-Inputs!F$26) -> 265.54522 | K9: =K7*(1-Inputs!G$26) -> 276.16703
B10: Gross profit | C10: =C7-C9 -> 170.782 | D10: =D7-D9 -> 169.148 | E10: =E7-E9 -> 180.683 | F10: =F7-F9 -> 195.201 | G10: =G7-G9 -> 207.33141 | H10: =H7-H9 -> 218.62436 | I10: =I7-I9 -> 230.52827 | J10: =J7-J9 -> 240.2552 | K10: =K7-K9 -> 249.8654
B11: gross margin % | C11: =C10/C7 -> 0.43309631 | D11: =D10/D7 -> 0.4413113 | E11: =E10/E7 -> 0.4620635 | F11: =F10/F7 -> 0.46905164 | G11: =G10/G7 -> 0.47 | H11: =H10/H7 -> 0.472 | I11: =I10/I7 -> 0.474 | J11: =J10/J7 -> 0.475 | K11: =K10/K7 -> 0.475
B12: Research & development | C12: =Historical!C10 -> 26.251 | D12: =Historical!D10 -> 29.915 | E12: =Historical!E10 -> 31.37 | F12: =Historical!F10 -> 34.55 | G12: =G7*Inputs!C$32 -> 36.613845 | H12: =H7*Inputs!D$32 -> 38.444537 | I12: =I7*Inputs!E$32 -> 40.366764 | J12: =J7*Inputs!F$32 -> 41.981434 | K12: =K7*Inputs!G$32 -> 43.660692
B13: Selling, general & administrative | C13: =Historical!C11 -> 25.094 | D13: =Historical!D11 -> 24.932 | E13: =Historical!E11 -> 26.097 | F13: =Historical!F11 -> 27.601 | G13: =G7*Inputs!C$38 -> 29.114624 | H13: =H7*Inputs!D$38 -> 30.570355 | I13: =I7*Inputs!E$38 -> 32.098872 | J13: =J7*Inputs!F$38 -> 33.382827 | K13: =K7*Inputs!G$38 -> 34.71814
B14: EBIT | C14: =C10-C12-C13 -> 119.437 | D14: =D10-D12-D13 -> 114.301 | E14: =E10-E12-E13 -> 123.216 | F14: =F10-F12-F13 -> 133.05 | G14: =G10-G12-G13 -> 141.60294 | H14: =H10-H12-H13 -> 149.60946 | I14: =I10-I12-I13 -> 158.06263 | J14: =J10-J12-J13 -> 164.89094 | K14: =K10-K12-K13 -> 171.48657
B15: EBIT margin % | C15: =C14/C7 -> 0.30288744 | D15: =D14/D7 -> 0.29821412 | E15: =E14/E7 -> 0.31510223 | F15: =F14/F7 -> 0.319708 | G15: =G14/G7 -> 0.321 | H15: =H14/H7 -> 0.323 | I15: =I14/I7 -> 0.325 | J15: =J14/J7 -> 0.326 | K15: =K14/K7 -> 0.326
B16: Depreciation & amortisation (memo, in COGS/opex) | C16: =Historical!C47 -> 11.104 | D16: =Historical!D47 -> 11.519 | E16: =Historical!E47 -> 11.445 | F16: =Historical!F47 -> 11.698 | G16: =G7*Inputs!C$50 -> 12.351658 | H16: =H7*Inputs!D$50 -> 12.969241 | I16: =I7*Inputs!E$50 -> 13.617703 | J16: =J7*Inputs!F$50 -> 14.162412 | K16: =K7*Inputs!G$50 -> 14.728908
B17: EBITDA | C17: =C14+C16 -> 130.541 | D17: =D14+D16 -> 125.82 | E17: =E14+E16 -> 134.661 | F17: =F14+F16 -> 144.748 | G17: =G14+G16 -> 153.9546 | H17: =H14+H16 -> 162.5787 | I17: =I14+I16 -> 171.68033 | J17: =J14+J16 -> 179.05335 | K17: =K14+K16 -> 186.21548
B18: Interest income on cash & investments (opening balances) | G18: =(F33+F38)*Inputs!$C$9 -> 5.2968 | H18: =(G33+G38)*Inputs!$C$9 -> 5.0968 | I18: =(H33+H38)*Inputs!$C$9 -> 4.8968 | J18: =(I33+I38)*Inputs!$C$9 -> 4.6968 | K18: =(J33+J38)*Inputs!$C$9 -> 4.5768
B19: Interest expense on debt (opening balances) | G19: =-((F45+F48)*Inputs!$C$8+F46*Inputs!$C$10) -> -3.94628 | H19: =-((G45+G48)*Inputs!$C$8+G46*Inputs!$C$10) -> -3.74628 | I19: =-((H45+H48)*Inputs!$C$8+H46*Inputs!$C$10) -> -3.54628 | J19: =-((I45+I48)*Inputs!$C$8+I46*Inputs!$C$10) -> -3.34628 | K19: =-((J45+J48)*Inputs!$C$8+J46*Inputs!$C$10) -> -3.22628
B20: Other income / (expense), net | C20: =Historical!C13 -> -0.334 | D20: =Historical!D13 -> -0.565 | E20: =Historical!E13 -> 0.269 | F20: =Historical!F13 -> -0.321 | G20: =G18+G19 -> 1.35052 | H20: =H18+H19 -> 1.35052 | I20: =I18+I19 -> 1.35052 | J20: =J18+J19 -> 1.35052 | K20: =K18+K19 -> 1.35052
B21: Pre-tax income | C21: =C14+C20 -> 119.103 | D21: =D14+D20 -> 113.736 | E21: =E14+E20 -> 123.485 | F21: =F14+F20 -> 132.729 | G21: =G14+G20 -> 142.95346 | H21: =H14+H20 -> 150.95998 | I21: =I14+I20 -> 159.41315 | J21: =J14+J20 -> 166.24146 | K21: =K14+K20 -> 172.83709
B22: Income tax | C22: =Historical!C15 -> 19.3 | D22: =Historical!D15 -> 16.741 | E22: =Historical!E15 -> 29.749 | F22: =Historical!F15 -> 20.719 | G22: =G21*Inputs!C$44 -> 23.587321 | H22: =H21*Inputs!D$44 -> 24.908397 | I22: =I21*Inputs!E$44 -> 26.30317 | J22: =J21*Inputs!F$44 -> 27.42984 | K22: =K21*Inputs!G$44 -> 28.51812
B23: Net income | C23: =C21-C22 -> 99.803 | D23: =D21-D22 -> 96.995 | E23: =E21-E22 -> 93.736 | F23: =F21-F22 -> 112.01 | G23: =G21-G22 -> 119.36614 | H23: =H21-H22 -> 126.05159 | I23: =I21-I22 -> 133.10998 | J23: =J21-J22 -> 138.81162 | K23: =K21-K22 -> 144.31897
B24: net margin % | C24: =C23/C7 -> 0.25309641 | D24: =D23/D7 -> 0.25306234 | E24: =E23/E7 -> 0.23971256 | F24: =F23/F7 -> 0.26915064 | G24: =G23/G7 -> 0.27059135 | H24: =H23/H7 -> 0.27213962 | I24: =I23/I7 -> 0.27369368 | J24: =J23/J7 -> 0.2744395 | K24: =K23/K7 -> 0.27435375
B26: SHARE COUNT & EPS
B27: Shares outstanding, year-end (bn) | C27: =Historical!C57 -> 15.943 | D27: =Historical!D57 -> 15.55 | E27: =Historical!E57 -> 15.117 | F27: =Historical!F57 -> 14.773 | G27: =F27-G74/G28+G61/G28*0.6 -> 14.373327 | H27: =G27-H74/H28+H61/H28*0.6 -> 13.972383 | I27: =H27-I74/I28+I61/I28*0.6 -> 13.571413 | J27: =I27-J74/J28+J61/J28*0.6 -> 13.1759 | K27: =J27-K74/K28+K61/K28*0.6 -> 12.786731
B28: assumed share price (US$) | F28: =Inputs!$C$12 -> 254 | G28: =F28*(1+Inputs!$C$13) -> 269.24 | H28: =G28*(1+Inputs!$C$13) -> 285.3944 | I28: =H28*(1+Inputs!$C$13) -> 302.51806 | J28: =I28*(1+Inputs!$C$13) -> 320.66915 | K28: =J28*(1+Inputs!$C$13) -> 339.9093
B29: Diluted weighted average shares (bn) | C29: =Historical!C18 -> 16.326 | D29: =Historical!D18 -> 15.813 | E29: =Historical!E18 -> 15.408 | F29: =Historical!F18 -> 15.005 | G29: =AVERAGE(F27,G27)*1.003 -> 14.616883 | H29: =AVERAGE(G27,H27)*1.003 -> 14.215374 | I29: =AVERAGE(H27,I27)*1.003 -> 13.813214 | J29: =AVERAGE(I27,J27)*1.003 -> 13.413777 | K29: =AVERAGE(J27,K27)*1.003 -> 13.02026
B30: Diluted EPS (US$) | C30: =C23/C29 -> 6.1131324 | D30: =D23/D29 -> 6.1338772 | E30: =E23/E29 -> 6.0835929 | F30: =F23/F29 -> 7.4648451 | G30: =G23/G29 -> 8.1663199 | H30: =H23/H29 -> 8.8672721 | I30: =I23/I29 -> 9.6364237 | J30: =J23/J29 -> 10.348436 | K30: =K23/K29 -> 11.084185
B32: BALANCE SHEET
B33: Cash & short-term investments | C33: =Historical!C22 -> 48.304 | D33: =Historical!D22 -> 61.555 | E33: =Historical!E22 -> 65.171 | F33: =Historical!F22 -> 54.697 | G33: =G81 -> 59.697 | H33: =H81 -> 64.697 | I33: =I81 -> 69.697 | J33: =J81 -> 71.697 | K33: =K81 -> 73.697
B34: Receivables | C34: =Historical!C23 -> 60.932 | D34: =Historical!D23 -> 60.985 | E34: =Historical!E23 -> 66.243 | F34: =Historical!F23 -> 72.957 | G34: =G7*Inputs!C$68/365 -> 77.348938 | H34: =H7*Inputs!D$68/365 -> 81.216385 | I34: =I7*Inputs!E$68/365 -> 85.277204 | J34: =J7*Inputs!F$68/365 -> 88.688292 | K34: =K7*Inputs!G$68/365 -> 92.235824
B35: Inventory | C35: =Historical!C24 -> 4.946 | D35: =Historical!D24 -> 6.331 | E35: =Historical!E24 -> 7.286 | F35: =Historical!F24 -> 5.718 | G35: =G9*Inputs!C$74/365 -> 6.4054589 | H35: =H9*Inputs!D$74/365 -> 6.7003517 | I35: =I9*Inputs!E$74/365 -> 7.0087202 | J35: =J9*Inputs!F$74/365 -> 7.2752114 | K35: =K9*Inputs!G$74/365 -> 7.5662199
B36: Other current assets | C36: =Historical!C25 -> 21.223 | D36: =Historical!D25 -> 14.695 | E36: =Historical!E25 -> 14.287 | F36: =Historical!F25 -> 14.585 | G36: =G7*Inputs!C$86 -> 15.439573 | H36: =H7*Inputs!D$86 -> 16.211552 | I36: =I7*Inputs!E$86 -> 17.022129 | J36: =J7*Inputs!F$86 -> 17.703015 | K36: =K7*Inputs!G$86 -> 18.411135
B37: Total current assets | C37: =SUM(C33:C36) -> 135.405 | D37: =SUM(D33:D36) -> 143.566 | E37: =SUM(E33:E36) -> 152.987 | F37: =SUM(F33:F36) -> 147.957 | G37: =SUM(G33:G36) -> 158.89097 | H37: =SUM(H33:H36) -> 168.82529 | I37: =SUM(I33:I36) -> 179.00505 | J37: =SUM(J33:J36) -> 185.36352 | K37: =SUM(K33:K36) -> 191.91018
B38: Long-term marketable securities | C38: =Historical!C27 -> 120.805 | D38: =Historical!D27 -> 100.544 | E38: =Historical!E27 -> 91.479 | F38: =Historical!F27 -> 77.723 | G38: =F38+Inputs!C$110 -> 67.723 | H38: =G38+Inputs!D$110 -> 57.723 | I38: =H38+Inputs!E$110 -> 47.723 | J38: =I38+Inputs!F$110 -> 42.723 | K38: =J38+Inputs!G$110 -> 37.723
B39: PP&E, net | C39: =Historical!C28 -> 42.117 | D39: =Historical!D28 -> 43.715 | E39: =Historical!E28 -> 45.68 | F39: =Historical!F28 -> 49.834 | G39: =G87 -> 51.157392 | H39: =H87 -> 52.546954 | I39: =I87 -> 54.005993 | J39: =J87 -> 55.523394 | K39: =K87 -> 57.101492
B40: Other non-current assets | C40: =Historical!C29 -> 54.428 | D40: =Historical!D29 -> 64.758 | E40: =Historical!E29 -> 74.834 | F40: =Historical!F29 -> 83.727 | G40: =G7*Inputs!C$98 -> 88.226132 | H40: =H7*Inputs!D$98 -> 92.637439 | I40: =I7*Inputs!E$98 -> 97.269311 | J40: =J7*Inputs!F$98 -> 101.16008 | K40: =K7*Inputs!G$98 -> 105.20649
B41: Total assets | C41: =C37+C38+C39+C40 -> 352.755 | D41: =D37+D38+D39+D40 -> 352.583 | E41: =E37+E38+E39+E40 -> 364.98 | F41: =F37+F38+F39+F40 -> 359.241 | G41: =G37+G38+G39+G40 -> 365.99749 | H41: =H37+H38+H39+H40 -> 371.73268 | I41: =I37+I38+I39+I40 -> 378.00336 | J41: =J37+J38+J39+J40 -> 384.77 | K41: =K37+K38+K39+K40 -> 391.94116
B43: Accounts payable | C43: =Historical!C32 -> 64.115 | D43: =Historical!D32 -> 62.611 | E43: =Historical!E32 -> 68.96 | F43: =Historical!F32 -> 69.86 | G43: =G9*Inputs!C$80/365 -> 73.662777 | H43: =H9*Inputs!D$80/365 -> 77.054045 | I43: =I9*Inputs!E$80/365 -> 80.600282 | J43: =J9*Inputs!F$80/365 -> 83.664932 | K43: =K9*Inputs!G$80/365 -> 87.011529
B44: Other current liabilities | C44: =Historical!C33 -> 68.757 | D44: =Historical!D33 -> 66.89 | E44: =Historical!E33 -> 86.553 | F44: =Historical!F33 -> 75.442 | G44: =G7*Inputs!C$92 -> 79.403519 | H44: =H7*Inputs!D$92 -> 83.373695 | I44: =I7*Inputs!E$92 -> 87.542379 | J44: =J7*Inputs!F$92 -> 91.044075 | K44: =K7*Inputs!G$92 -> 94.685838
B45: Current debt (incl. commercial paper) | C45: =Historical!C34 -> 21.11 | D45: =Historical!D34 -> 15.807 | E45: =Historical!E34 -> 20.879 | F45: =Historical!F34 -> 20.329 | G45: =F45 -> 20.329 | H45: =G45 -> 20.329 | I45: =H45 -> 20.329 | J45: =I45 -> 20.329 | K45: =J45 -> 20.329
...

Sheet Checks
B2: Model integrity checks (all should read 0 / TRUE)
C4: FY2022 | D4: FY2023 | E4: FY2024 | F4: FY2025 | G4: FY2026 | H4: FY2027 | I4: FY2028 | J4: FY2029 | K4: FY2030
B5: Balance sheet balances (assets − liabilities − equity) | C5: =Model!C56 -> 0 | D5: =Model!D56 -> 0 | E5: =Model!E56 -> 0 | F5: =Model!F56 -> 0 | G5: =Model!G56 -> 0 | H5: =Model!H56 -> 0 | I5: =Model!I56 -> 0 | J5: =Model!J56 -> 0 | K5: =Model!K56 -> 0
B6: Cash-flow closing cash = balance-sheet cash | C6: =0 -> 0 | D6: =0 -> 0 | E6: =0 -> 0 | F6: =0 -> 0 | G6: =ROUND(Model!G81-Model!G33,3) -> 0 | H6: =ROUND(Model!H81-Model!H33,3) -> 0 | I6: =ROUND(Model!I81-Model!I33,3) -> 0 | J6: =ROUND(Model!J81-Model!J33,3) -> 0 | K6: =ROUND(Model!K81-Model!K33,3) -> 0
B7: PP&E schedule closing = balance-sheet PP&E | C7: =0 -> 0 | D7: =0 -> 0 | E7: =0 -> 0 | F7: =0 -> 0 | G7: =ROUND(Model!G87-Model!G39,3) -> 0 | H7: =ROUND(Model!H87-Model!H39,3) -> 0 | I7: =ROUND(Model!I87-Model!I39,3) -> 0 | J7: =ROUND(Model!J87-Model!J39,3) -> 0 | K7: =ROUND(Model!K87-Model!K39,3) -> 0
B8: Debt schedule closing = balance-sheet LT debt | C8: =0 -> 0 | D8: =0 -> 0 | E8: =0 -> 0 | F8: =0 -> 0 | G8: =ROUND(Model!G92-Model!G48,3) -> 0 | H8: =ROUND(Model!H92-Model!H48,3) -> 0 | I8: =ROUND(Model!I92-Model!I48,3) -> 0 | J8: =ROUND(Model!J92-Model!J48,3) -> 0 | K8: =ROUND(Model!K92-Model!K48,3) -> 0
B9: Cash never below minimum (TRUE) | C9: =TRUE() -> TRUE | D9: =TRUE() -> TRUE | E9: =TRUE() -> TRUE | F9: =TRUE() -> TRUE | G9: =Model!G33>=Model!G96-0.001 -> TRUE | H9: =Model!H33>=Model!H96-0.001 -> TRUE | I9: =Model!I33>=Model!I96-0.001 -> TRUE | J9: =Model!J33>=Model!J96-0.001 -> TRUE | K9: =Model!K33>=Model!K96-0.001 -> TRUE
B10: Historical net income ties to reported (0) | C10: =ROUND(Historical!C16-Historical!C17,1) -> 0 | D10: =ROUND(Historical!D16-Historical!D17,1) -> 0 | E10: =ROUND(Historical!E16-Historical!E17,1) -> 0 | F10: =ROUND(Historical!F16-Historical!F17,1) -> 0 | G10: =0 -> 0 | H10: =0 -> 0 | I10: =0 -> 0 | J10: =0 -> 0 | K10: =0 -> 0
B12: Overall | C12: =IF(AND(SUMPRODUCT(ABS(C5:K8))<0.01,COUNTIF(C9:K9,FALSE())=0,SUMPRODUCT(ABS(C10:K10))<0.2),"MODEL OK","CHECK ERRORS") -> MODEL OK
