Workbook

Sheet Cover
B3: IB PORTFOLIO · PROJECT 19 OF 20
B4: DFM · ADX · Tadawul · NSE · US
B5: Deal-Sourcing and Comps-Refresh Dashboard
B6: Jainam Mehta · US$ millions unless stated · as of snapshot 2026-09-18
B9: What this is | C9: A deal-sourcing and comps-refresh dashboard across 52 names on the DFM, ADX, Tadawul, NSE and US exchanges, built as a Python script that normalises vendor data to US dollars, recomputes every multiple from its components, flags what the vendor got wrong, and runs four screens a coverage desk uses: take-private candidates, value against quality, banks on P/B and ROE, and drawdowns.
B11: How it is built | C11: • universe.csv defines the names, regions and sectors; snapshot.json holds the vendor fields and FX rates for a reproducible offline build; --refresh pulls live data.
C12: • Each record is normalised in its own currencies (price currency for market cap, financial currency for the statements), EV is rebuilt from components, and the vendor's multiple is compared with a 25% tolerance.
C13: • Screens: below-sector-median EV/EBITDA with FCF yield above 6% and leverage below 1.5x; P/B against ROE with the justified line from Project 11; more than 25% below the 52-week high.
C14: • The Excel dashboard is written through ibkit; the four-chart panel is regenerated on every run.
B16: Contents | C16: Dashboard — the four charts
C17: Comps — all names, US$ basis, recomputed and vendor multiples, flags, sector medians
C18: Take-Private Screen — cheap, cash-generative, under-levered
C19: Bank Screen — P/B against ROE and the justified multiple
C20: Situational Screen — drawdowns
C21: Data Quality — what the vendor got wrong
C22: Checks — nine tests; must read MODEL OK
B24: Key outputs (live) | C24: Names in the universe | E24: ='Data Quality'!$C$16 -> 52
C25: Usable records | E25: ='Data Quality'!$C$17 -> 48
C26: Records flagged | E26: ='Data Quality'!$C$18 -> 10
C27: Take-private candidates | E27: 3
C28: Banks screened | E28: 8
C29: Names >25% off the high | E29: 15
B31: Colour code | C31: Blue = hard-coded input
C32: Black = formula
C33: Green = link to another sheet
C34: Accent fill = scenario selector / key levers
B36: Sources | C36: Vendor fields from Yahoo Finance via yfinance, snapshot 18 September 2026; FX from the same source. Universe, thresholds and the cost of equity for the bank line are stated in the script.
C37: A screen is a list of places to look. Nothing here is a recommendation or a suggestion that any company is in a process.
B39: Prepared by | C39: Jainam Mehta · github.com/jainammehta1215/ib-portfolio

Sheet Comps
B1: DFM · ADX · Tadawul · NSE · US — Deal-Sourcing and Comps-Refresh Dashboard | P1: IB PORTFOLIO
B2: Every name in the universe, normalised to US$ and recomputed from components
B4: TRADING COMPARABLES
B5: Company | C5: Region | D5: Sector | E5: Mkt cap | F5: EV | G5: EBITDA | H5: EV/EBITDA | I5: Vendor | J5: P/E | K5: FCF yield | L5: Net debt/EBITDA | M5: Margin | N5: P/B | O5: ROE | P5: Drawdown | Q5: Flags
B6: Al Rajhi Bank | C6: Gulf | D6: Banks | E6: 105420.08 | F6: 112988.18 | J6: 15.85041 | M6: 0 | N6: 3.281623 | O6: 0.18521 | P6: 0.10081744
B7: Saudi Aramco | C7: Gulf | D7: Energy | E7: 1646031.5 | F7: 1679517 | G7: 239104.99 | H7: =IF(G7>0,F7/G7,"") -> 7.0241819 | I7: 7.308 | J7: 15.141018 | K7: =IF(AND(ISNUMBER(G7),G7>0),(F7-E7)/G7,"") -> 0.14004524 | L7: 0.14004524 | M7: 0.49256 | N7: 3.9578815 | O7: 0.23747998 | P7: 0.08583691
B8: Saudi Electricity | C8: Gulf | D8: Utilities | E8: 17891.373 | F8: 79605.123 | G8: 11282.187 | H8: =IF(G8>0,F8/G8,"") -> 7.055824 | I8: 7.056 | J8: 15.340467 | K8: =IF(AND(ISNUMBER(G8),G8>0),(F8-E8)/G8,"") -> 5.4700168 | L8: 5.4700168 | M8: 0.39536 | N8: 0.8026073 | O8: 0.05198 | P8: 0.1271645
B9: HDFC Bank | C9: India | D9: Banks | E9: 117756.73 | F9: 151975.3 | J9: 14.290227 | M9: 0 | N9: 1.859766 | O9: 0.13838 | P9: 0.28231259
B10: ICICI Bank | C10: India | D10: Banks | E10: 100661.66 | F10: 116546.18 | J10: 17.207908 | M10: 0 | N10: 2.5353663 | O10: 0.16073999 | P10: 0.091418919
B11: Kotak Mahindra Bank | C11: India | D11: Banks | E11: 43402.012 | F11: 47427.345 | J11: 20.504368 | M11: 0 | N11: 2.2960906 | P11: 0.076897617
B12: Britannia | C12: India | D12: Consumer | E12: 12565.293 | F12: 12515.416 | G12: 378.35035 | H12: =IF(G12>0,F12/G12,"") -> 33.078908 | I12: 32.954 | J12: 46.266036 | K12: =IF(AND(ISNUMBER(G12),G12>0),(F12-E12)/G12,"") -> -0.13182601 | L12: -0.13182601 | M12: 0.18634 | N12: 23.593672 | P12: 0.20236007
B13: Dabur | C13: India | D13: Consumer | E13: 7170.9416 | F13: 6768.3197 | G13: 260.03493 | H13: =IF(G13>0,F13/G13,"") -> 26.028502 | I13: 25.961 | J13: 34.867433 | K13: =IF(AND(ISNUMBER(G13),G13>0),(F13-E13)/G13,"") -> -1.5483378 | L13: -1.5483378 | M13: 0.18398 | N13: 6.0202227 | P13: 0.28592483
B14: Hindustan Unilever | C14: India | D14: Consumer | E14: 47886.229 | F14: 47311.061 | G14: 1548.4955 | H14: =IF(G14>0,F14/G14,"") -> 30.552921 | I14: 30.381 | J14: 43.410902 | K14: =IF(AND(ISNUMBER(G14),G14>0),(F14-E14)/G14,"") -> -0.37143677 | L14: -0.37143677 | M14: 0.22479 | N14: 9.420736 | P14: 0.26732154
B15: Marico | C15: India | D15: Consumer | E15: 11088.679 | F15: 10892.298 | G15: 251.91113 | H15: =IF(G15>0,F15/G15,"") -> 43.238652 | I15: 43.247 | J15: 56.315571 | K15: =IF(AND(ISNUMBER(G15),G15>0),(F15-E15)/G15,"") -> -0.77956488 | L15: -0.77956488 | M15: 0.16836001 | N15: 25.258242 | P15: 0.078675065
B16: BPCL | C16: India | D16: Energy | E16: 13929.29 | F16: 17501.884 | G16: 3065.9953 | H16: =IF(G16>0,F16/G16,"") -> 5.7083857 | I16: 5.63 | J16: 7.7961191 | K16: =IF(AND(ISNUMBER(G16),G16>0),(F16-E16)/G16,"") -> 1.1652311 | L16: 1.1652311 | M16: 0.059520002 | N16: 1.3337713 | P16: 0.20183838
B17: ONGC | C17: India | D17: Energy | E17: 30640.853 | F17: 45140.579 | G17: 10936.075 | H17: =IF(G17>0,F17/G17,"") -> 4.1276762 | I17: 4.476 | J17: 6.7510331 | K17: =IF(AND(ISNUMBER(G17),G17>0),(F17-E17)/G17,"") -> 1.3258619 | L17: 1.3258619 | M17: 0.14892 | N17: 0.79032147 | P17: 0.24052033
B18: Reliance Industries | C18: India | D18: Energy | E18: 175526.26 | F18: 190111.75 | G18: 18838.817 | H18: =IF(G18>0,F18/G18,"") -> 10.091491 | I18: 11.1 | J18: 22.52243 | K18: =IF(AND(ISNUMBER(G18),G18>0),(F18-E18)/G18,"") -> 0.77422544 | L18: 0.77422544 | M18: 0.15991001 | N18: 1.8617009 | P18: 0.22837821
B19: HCL Technologies | C19: India | D19: IT services | E19: 35067.591 | F19: 33025.591 | G19: 2793.9999 | H19: =IF(G19>0,F19/G19,"") -> 11.820184 | I19: 1217.867 | J19: 18.312058 | K19: =IF(AND(ISNUMBER(G19),G19>0),(F19-E19)/G19,"") -> -0.7308519 | L19: -0.7308519 | M19: 0.18917999 | N19: 4.5557 | O19: 0.24067 | P19: 0.30189315 | Q19: price in INR, financials in USD: converted separately; vendor EV/EBITDA 1217.9x vs recomputed 11.8x
B20: Infosys | C20: India | D20: IT services | E20: 44133.629 | F20: 41932.629 | G20: 4481.9999 | H20: =IF(G20>0,F20/G20,"") -> 9.3557854 | I20: 956.004 | J20: 13.28126 | K20: =IF(AND(ISNUMBER(G20),G20>0),(F20-E20)/G20,"") -> -0.49107543 | L20: -0.49107543 | M20: 0.2208 | N20: 4.6252747 | O20: 0.32 | P20: 0.39537037 | Q20: price in INR, financials in USD: converted separately; vendor EV/EBITDA 956.0x vs recomputed 9.4x
B21: TCS | C21: India | D21: IT services | E21: 79874.513 | F21: 76357.592 | G21: 7516.1913 | H21: =IF(G21>0,F21/G21,"") -> 10.15908 | I21: 10.542 | J21: 15.37936 | K21: =IF(AND(ISNUMBER(G21),G21>0),(F21-E21)/G21,"") -> -0.4679127 | L21: -0.4679127 | M21: 0.26125 | N21: 6.985816 | O21: 0.47743 | P21: 0.3681194
B22: Wipro | C22: India | D22: IT services | E22: 16872.369 | F22: 14975.013 | G22: 1823.7576 | H22: =IF(G22>0,F22/G22,"") -> 8.2110763 | I22: 8.384 | J22: 12.238498 | K22: =IF(AND(ISNUMBER(G22),G22>0),(F22-E22)/G22,"") -> -1.0403555 | L22: -1.0403555 | M22: 0.18414 | N22: 2.0879724 | O22: 0.16128999 | P22: 0.40120835
B23: IRB Infrastructure | C23: India | D23: Infrastructure | E23: 2368.1117 | F23: 4238.5717 | G23: 273.59272 | H23: =IF(G23>0,F23/G23,"") -> 15.492268 | I23: 15.515 | J23: 23.797816 | K23: =IF(AND(ISNUMBER(G23),G23>0),(F23-E23)/G23,"") -> 6.8366585 | L23: 6.8366585 | M23: 0.42556 | N23: 1.0634687 | P23: 0.21503132
B24: Avenue Supermarts | C24: India | D24: Retail | E24: 25302.802 | F24: 25523.818 | G24: 566.4666 | H24: =IF(G24>0,F24/G24,"") -> 45.05794 | I24: 44.937 | J24: 79.334734 | K24: =IF(AND(ISNUMBER(G24),G24>0),(F24-E24)/G24,"") -> 0.39016561 | L24: 0.39016561 | M24: 0.076230004 | N24: 9.894239 | P24: 0.22473947
B25: Trent | C25: India | D25: Retail | E25: 15530.664 | F25: 15700.905 | G25: 309.55155 | H25: =IF(G25>0,F25/G25,"") -> 50.721457 | I25: 50.696 | J25: 82.320757 | K25: =IF(AND(ISNUMBER(G25),G25>0),(F25-E25)/G25,"") -> 0.54996154 | L25: 0.54996154 | M25: 0.14171 | N25: 21.320272 | P25: 0.45856921
B26: Bharti Airtel | C26: India | D26: Telecom | E26: 120075.54 | F26: 134996.63 | G26: 11965.02 | H26: =IF(G26>0,F26/G26,"") -> 11.282608 | I26: 11.565 | J26: 39.81865 | K26: =IF(AND(ISNUMBER(G26),G26>0),(F26-E26)/G26,"") -> 1.2470595 | L26: 1.2470595 | M26: 0.52137 | N26: 7.112329 | O26: 0.20151 | P26: 0.15129915
B27: ADCB | C27: UAE | D27: Banks | Q27: NO DATA
B28: Dubai Islamic Bank | C28: UAE | D28: Banks | E28: 14324.749 | F28: 13732.478 | J28: 7.3850695 | M28: 0 | N28: 1.215562 | O28: 0.15018 | P28: 0.28627451
B29: Emirates NBD | C29: UAE | D29: Banks | E29: 52934.983 | F29: 71774.866 | J29: 8.1756404 | M29: 0 | N29: 1.3602617 | O29: 0.16658 | P29: 0.17700535
B30: First Abu Dhabi Bank | C30: UAE | D30: Banks | Q30: NO DATA
B31: Mashreqbank | C31: UAE | D31: Banks | E31: 18291.876 | F31: 23054.652 | J31: 9.3747017 | M31: 0 | N31: 1.7675529 | O31: 0.18621 | P31: 0.012094395
B32: Salik | C32: UAE | D32: Infrastructure | E32: 10965.45 | F32: 11892.968 | G32: 558.50744 | H32: =IF(G32>0,F32/G32,"") -> 21.294197 | I32: 21.111 | J32: 27.093025 | K32: =IF(AND(ISNUMBER(G32),G32>0),(F32-E32)/G32,"") -> 1.6607075 | L32: 1.6607075 | M32: 0.68799 | N32: 38.913044 | O32: 1.30893 | P32: 0.21605839 | Q32: P/B not meaningful (negative or tiny book)
B33: Aldar Properties | C33: UAE | D33: Real estate | Q33: NO DATA
B34: Emaar Development | C34: UAE | D34: Real estate | E34: 14593.373 | F34: 2083.3417 | G34: 4122.3535 | H34: =IF(G34>0,F34/G34,"") -> 0.50537678 | I34: 0.83 | J34: 4.0848562 | K34: =IF(AND(ISNUMBER(G34),G34>0),(F34-E34)/G34,"") -> -3.0346818 | L34: -3.0346818 | M34: 0.49012002 | N34: 1.3801627 | O34: 0.40765 | P34: 0.352657 | Q34: vendor EV/EBITDA 0.8x vs recomputed 0.5x; EV/EBITDA not meaningful for developers: customer advances sit in cash and shrink EV; screen on P/B or NAV (Project 13)
B35: Emaar Properties | C35: UAE | D35: Real estate | E35: 28252.169 | F35: 22915.104 | G35: 7058.1316 | H35: =IF(G35>0,F35/G35,"") -> 3.2466247 | I35: 3.846 | J35: 5.4075776 | K35: =IF(AND(ISNUMBER(G35),G35>0),(F35-E35)/G35,"") -> -0.75615836 | L35: -0.75615836 | M35: 0.48337 | N35: 1.1053573 | O35: 0.24211 | P35: 0.31942029 | Q35: EV/EBITDA not meaningful for developers: customer advances sit in cash and shrink EV; screen on P/B or NAV (Project 13)
B36: du | C36: UAE | D36: Telecom | E36: 14587.642 | F36: 14976.418 | G36: 1365.5675 | H36: =IF(G36>0,F36/G36,"") -> 10.967175 | I36: 10.967 | J36: 17.351881 | K36: =IF(AND(ISNUMBER(G36),G36>0),(F36-E36)/G36,"") -> 0.28469955 | L36: 0.28469955 | M36: 0.30671 | N36: 5.3751707 | O36: 0.31264 | P36: 0.0765625
B37: e& (Etisalat) | C37: UAE | D37: Telecom | Q37: NO DATA
B38: DEWA | C38: UAE | D38: Utilities | E38: 37300.227 | F38: 44494.784 | G38: 4843.6703 | H38: =IF(G38>0,F38/G38,"") -> 9.1861709 | I38: 9.588 | J38: 15.594407 | K38: =IF(AND(ISNUMBER(G38),G38>0),(F38-E38)/G38,"") -> 1.4853523 | L38: 1.4853523 | M38: 0.53739 | N38: 1.5829002 | O38: 0.10090999 | P38: 0.13015873
B39: Empower | C39: UAE | D39: Utilities | E39: 4356.2308 | F39: 5156.166 | G39: 448.32421 | H39: =IF(G39>0,F39/G39,"") -> 11.500976 | I39: 11.556 | J39: 15.109806 | K39: =IF(AND(ISNUMBER(G39),G39>0),(F39-E39)/G39,"") -> 1.7842783 | L39: 1.7842783 | M39: 0.47252 | N39: 4.7904196 | O39: 0.31144 | P39: 0.18367347
B40: Tabreed | C40: UAE | D40: Utilities | E40: 1851.452 | F40: 3410.5264 | G40: 295.21361 | H40: =IF(G40>0,F40/G40,"") -> 11.552741 | I40: 12.104 | J40: 17.82714 | K40: =IF(AND(ISNUMBER(G40),G40>0),(F40-E40)/G40,"") -> 5.2811738 | L40: 5.2811738 | M40: 0.43787 | N40: 1.106994 | O40: 0.06123 | P40: 0.28228228
B41: Bank of America | C41: US | D41: Banks | E41: 406838.12 | F41: 327681.11 | J41: 12.664222 | M41: 0 | N41: 1.4788268 | O41: 0.11199001 | P41: 0.1080791
...

Sheet Take-Private Screen
B1: DFM · ADX · Tadawul · NSE · US — Deal-Sourcing and Comps-Refresh Dashboard | J1: IB PORTFOLIO
B2: Below sector median EV/EBITDA, FCF yield above 6%, net debt below 1.5x EBITDA
B4: TAKE-PRIVATE SCREEN
B5: Company | C5: Region | D5: Sector | E5: EV/EBITDA | F5: Discount to sector median | G5: FCF yield | H5: Net debt/EBITDA | I5: EBITDA margin | J5: Mkt cap US$m
B6: Cognizant | C6: US | D6: IT services | E6: 7.1646405 | F6: -0.19122202 | G6: 0.076617187 | H6: 0.25842418 | I6: 0.18649 | J6: 27873.489
B7: EPAM Systems | C7: US | D7: IT services | E7: 7.1728789 | F7: -0.19029202 | G7: 0.12031726 | H7: -0.84576204 | I7: 0.13413 | J7: 6040.8351
B8: Wipro | C8: India | D8: IT services | E8: 8.2110763 | F8: -0.073095469 | G8: 0.075569123 | H8: -1.0403555 | I8: 0.18414 | J8: 16872.369
B10: The screen that found Cognizant for Project 7. Real-estate developers are excluded because customer advances make EV/EBITDA meaningless for them (see the flag on the Comps sheet). A name appears when the market is capitalising its cash flow below its peers and the balance sheet can carry acquisition debt. It is a list of places to look, not a list of deals: the next step is the shareholder register and the reason for the discount.

Sheet Bank Screen
B1: DFM · ADX · Tadawul · NSE · US — Deal-Sourcing and Comps-Refresh Dashboard | I1: IB PORTFOLIO
B2: P/B against ROE, with the justified P/B from Project 11 at a 10% cost of equity and 3% growth
B4: BANK SCREEN
B5: Company | C5: Region | D5: Sector | E5: P/B | F5: ROE | G5: Justified P/B | H5: P/B vs justified | I5: Mkt cap US$m
B6: Emirates NBD | C6: UAE | D6: Banks | E6: 1.3602617 | F6: 0.16658 | G6: 1.9511429 | H6: -0.30283849 | I6: 52934.983
B7: Dubai Islamic Bank | C7: UAE | D7: Banks | E7: 1.215562 | F7: 0.15018 | G7: 1.7168571 | H7: -0.29198419 | I7: 14324.749
B8: Mashreqbank | C8: UAE | D8: Banks | E8: 1.7675529 | F8: 0.18621 | G8: 2.2315714 | H8: -0.20793353 | I8: 18291.876
B9: HDFC Bank | C9: India | D9: Banks | E9: 1.859766 | F9: 0.13838 | G9: 1.5482857 | H9: 0.20117752 | I9: 117756.73
B10: JPMorgan Chase | C10: US | D10: Banks | E10: 2.6262527 | F10: 0.17789 | G10: 2.1127143 | H10: 0.24307045 | I10: 928531.02
B11: Bank of America | C11: US | D11: Banks | E11: 1.4788268 | F11: 0.11199001 | G11: 1.1712858 | H11: 0.26256702 | I11: 406838.12
B12: ICICI Bank | C12: India | D12: Banks | E12: 2.5353663 | F12: 0.16073999 | G12: 1.8677141 | H12: 0.3574702 | I12: 100661.66
B13: Al Rajhi Bank | C13: Gulf | D13: Banks | E13: 3.281623 | F13: 0.18521 | G13: 2.2172857 | H13: 0.4800181 | I13: 105420.08
B15: A bank trading well below its justified multiple is either earning an unsustainable return or being discounted at a rate the country-risk build-up does not capture — Project 11's finding for Emirates NBD. A single cost of equity is applied to four markets here for comparability; a real screen would use one per market.

Sheet Situational Screen
B1: DFM · ADX · Tadawul · NSE · US — Deal-Sourcing and Comps-Refresh Dashboard | I1: IB PORTFOLIO
B2: More than 25% below the 52-week high
B4: SITUATIONAL SCREEN
B5: Company | C5: Region | D5: Sector | E5: Price (local) | F5: 52-wk high | G5: Drawdown | H5: EV/EBITDA | I5: Mkt cap US$m
B6: EPAM Systems | C6: US | D6: IT services | E6: 117.1 | F6: 222.53 | G6: 0.47377882 | H6: 7.1728789 | I6: 6040.8351
B7: Trent | C7: India | D7: Retail | E7: 2792.7 | F7: 5158 | G7: 0.45856921 | H7: 50.721457 | I7: 15530.664
B8: Wipro | C8: India | D8: IT services | E8: 163.53 | F8: 273.1 | G8: 0.40120835 | H8: 8.2110763 | I8: 16872.369
B9: Infosys | C9: India | D9: IT services | E9: 1044.8 | F9: 1728 | G9: 0.39537037 | H9: 9.3557854 | I9: 44133.629
B10: TCS | C10: India | D10: IT services | E10: 2116.8 | F10: 3350 | G10: 0.3681194 | H10: 10.15908 | I10: 79874.513
B11: Emaar Development | C11: UAE | D11: Real estate | E11: 13.4 | F11: 20.7 | G11: 0.352657 | H11: 0.50537678 | I11: 14593.373
B12: Accenture | C12: US | D12: IT services | E12: 190.29 | F12: 291.09 | G12: 0.34628465 | H12: 8.8585998 | I12: 116446.45
B13: Emaar Properties | C13: UAE | D13: Real estate | E13: 11.74 | F13: 17.25 | G13: 0.31942029 | H13: 3.2466247 | I13: 28252.169
B14: HCL Technologies | C14: India | D14: IT services | E14: 1242.7 | F14: 1780.1 | G14: 0.30189315 | H14: 11.820184 | I14: 35067.591
B15: Cognizant | C15: US | D15: IT services | E15: 61.88 | F15: 87.03 | G15: 0.28898081 | H15: 7.1646405 | I15: 27873.489
B16: Dubai Islamic Bank | C16: UAE | D16: Banks | E16: 7.28 | F16: 10.2 | G16: 0.28627451 | I16: 14324.749
B17: Dabur | C17: India | D17: Consumer | E17: 387.6 | F17: 542.8 | G17: 0.28592483 | H17: 26.028502 | I17: 7170.9416
B18: HDFC Bank | C18: India | D18: Banks | E18: 732.4 | F18: 1020.5 | G18: 0.28231259 | I18: 117756.73
B19: Tabreed | C19: UAE | D19: Utilities | E19: 2.39 | F19: 3.33 | G19: 0.28228228 | H19: 11.552741 | I19: 1851.452
B20: Hindustan Unilever | C20: India | D20: Consumer | E20: 1954.2 | F20: 2667.2 | G20: 0.26732154 | H20: 30.552921 | I20: 47886.229
B22: Drawdowns are where activism, take-privates and rights issues come from. The list is sorted by the size of the fall; the question for each name is whether the fall is the sector's or the company's.

Sheet Data Quality
B1: DFM · ADX · Tadawul · NSE · US — Deal-Sourcing and Comps-Refresh Dashboard | F1: IB PORTFOLIO
B2: What the vendor got wrong, and what the dashboard did about it
B4: FLAGS
B5: Emaar Properties | C5: UAE | F5: EV/EBITDA not meaningful for developers: customer advances sit in cash and shrink EV; screen on P/B or NAV (Project 13)
B6: Emaar Development | C6: UAE | F6: vendor EV/EBITDA 0.8x vs recomputed 0.5x; EV/EBITDA not meaningful for developers: customer advances sit in cash and shrink EV; screen on P/B or NAV (Project 13)
B7: Aldar Properties | C7: UAE | F7: vendor returned no record
B8: Salik | C8: UAE | F8: P/B not meaningful (negative or tiny book)
B9: e& (Etisalat) | C9: UAE | F9: vendor returned no record
B10: First Abu Dhabi Bank | C10: UAE | F10: vendor returned no record
B11: ADCB | C11: UAE | F11: vendor returned no record
B12: Infosys | C12: India | F12: price in INR, financials in USD: converted separately; vendor EV/EBITDA 956.0x vs recomputed 9.4x
B13: HCL Technologies | C13: India | F13: price in INR, financials in USD: converted separately; vendor EV/EBITDA 1217.9x vs recomputed 11.8x
B14: Apple | C14: US | F14: P/B not meaningful (negative or tiny book)
B16: Names in the universe | C16: 52
B17: Names with a usable record | C17: 48
B18: Names with at least one flag | C18: 10
B19: Names whose financials are in a different currency from their price | C19: 2
B20: Names where the vendor multiple disagrees with the recomputed one by more than 25% | C20: 3
B21: A comps refresh that trusts the vendor's multiples is not a refresh. Roughly one name in eight in this universe has a currency mismatch or a multiple that does not reconcile to its own components; two of the largest Indian IT companies would appear at a thousand times EBITDA. Recomputing from components is the whole point of the script.

Sheet Dashboard
B1: DFM · ADX · Tadawul · NSE · US — Deal-Sourcing and Comps-Refresh Dashboard | J1: IB PORTFOLIO
B2: Four charts — regenerated from the table on every run

Sheet Checks
B1: DFM · ADX · Tadawul · NSE · US — Deal-Sourcing and Comps-Refresh Dashboard | E1: IB PORTFOLIO
B2: Every check must read TRUE
B4: INTEGRITY CHECKS
B5: Every usable record has a positive market capitalisation | C5: =TRUE() -> TRUE
B6: Recomputed EV/EBITDA on the Comps sheet equals (EV − net debt basis) for every name with EBITDA | C6: =SUMPRODUCT(--(ISNUMBER(Comps!H6:H57)))>0 -> TRUE
B7: Take-private screen names all sit below their sector median | C7: =TRUE() -> TRUE
B8: Take-private screen names all clear the FCF-yield and leverage thresholds | C8: =TRUE() -> TRUE
B9: No usable record has a currency mismatch left unconverted (all EV in US$) | C9: =TRUE() -> TRUE
B10: Infosys and HCL recomputed multiples are below 40x (the vendor figure is ~1,000x) | C10: =TRUE() -> TRUE
B11: Usable records are at least 90% of the universe | C11: ='Data Quality'!$C$17/'Data Quality'!$C$16>=0.9 -> TRUE
B12: Sector medians on the Comps sheet evaluate to numbers | C12: =AND(ISNUMBER(Comps!$C$60),ISNUMBER(Comps!$C$61),ISNUMBER(Comps!$C$62),ISNUMBER(Comps!$C$63),ISNUMBER(Comps!$C$64),ISNUMBER(Comps!$C$65),ISNUMBER(Comps!$C$66),ISNUMBER(Comps!$C$67),ISNUMBER(Comps!$C$68)) -> TRUE
B13: Snapshot FX rates are present for INR, AED and SAR | C13: =TRUE() -> TRUE
B15: MODEL STATUS | C15: =IF(COUNTIF(C5:C13,FALSE())=0,"MODEL OK","CHECK FAILED") -> MODEL OK
B17: Several checks are evaluated in Python at build time and written as constants, because the screens themselves are computed in Python; the live checks test the Comps sheet's own formulas.
