Workbook

Sheet Cover
B3: IB PORTFOLIO · PROJECT 08 OF 20
B4: Reliance Industries
B5: Debt Capacity and Capital Structure
B6: NSE: RELIANCE · ₹ crore unless stated · as of FY2026 audited results · market data 18 Sep 2026
B9: What this is | C9: A debt-capacity and capital-structure study of Reliance Industries built on the audited FY2026 consolidated results (year to 31 March 2026) and 18 September 2026 market data. It restates the balance sheet the way a rating agency would, sizes borrowing capacity at each rating category, finds where the cost of capital bottoms out, and tests twelve-month liquidity.
B11: How it is built | C11: • Adjusted net debt adds lease liabilities and the deferred spectrum instalments to the company's own net debt; adjusted EBITDA removes the disposal gain disclosed in the results.
C12: • Debt capacity at each rating is the minimum of three constraints — leverage, cash interest cover and FFO-to-debt — against a stated threshold grid, with the binding constraint named.
C13: • An optimal-structure grid unlevers the observed beta, re-levers it at each debt weight, looks up the implied rating and cost of debt from the same grid, and reports WACC.
C14: • A twelve-month sources-and-uses test, and two live sensitivity grids that rebuild every constraint in each cell.
B16: Contents | C16: Summary — leverage as reported and restated, capacity, the WACC minimum and liquidity
C17: Credit Profile — three definitions of net debt, cover, FFO, capitalisation, implied rating
C18: Debt Capacity — capacity by constraint and rating, headroom, what it would fund
C19: Optimal Structure — WACC across leverage with rating-linked cost of debt
C20: Liquidity — twelve-month sources and uses
C21: Sensitivity — headroom and WACC grids
C22: Inputs — audited FY2026 figures, market data, rating thresholds, cost-of-capital inputs
C23: Checks — fifteen tests; must read MODEL OK
B25: Key outputs (live) | C25: Adjusted net debt / EBITDA | E25: ='Credit Profile'!$C$13 -> 1.2455487
C26: EBITDA / cash interest | E26: ='Credit Profile'!$C$16 -> 4.9770391
C27: Incremental capacity at A (₹ crore) | E27: ='Debt Capacity'!$D$14 -> 44272
C28: WACC today | E28: ='Optimal Structure'!$C$10 -> 0.12880053
C29: Minimum WACC | E29: ='Optimal Structure'!$C$25 -> 0.12837153
C30: Twelve-month sources / uses | E30: =Liquidity!$C$19 -> 1.5072397
B32: Colour code | C32: Blue = hard-coded input
C33: Black = formula
C34: Green = link to another sheet
C35: Accent fill = scenario selector / key levers
B37: Sources | C37: Reliance Industries Limited, audited consolidated financial results and media release for the quarter and year ended 31 March 2026, dated 24 April 2026 (ril.com). Segment, balance sheet and cash flow figures as published.
C38: Share price: NSE close, 18 September 2026. Ratings: S&P Global A- and Moody's Baa1 as disclosed by the company.
C39: Risk-free rate, equity risk premium, beta, rating thresholds and credit spreads are stated inputs on the Inputs sheet.
C40: Nothing here is a recommendation. The study is an analytical exercise on public information.
B42: Prepared by | C42: Jainam Mehta · github.com/jainammehta1215/ib-portfolio

Sheet Inputs
B1: Reliance Industries — Debt Capacity and Capital Structure | F1: RELIANCE INDUSTRIES
B2: Audited FY2026 figures, market data, rating framework and cost-of-capital inputs
B4: REPORTED FY2026 (₹ crore)
B5: Revenue (value of sales and services) | C5: 1175919
B6: EBITDA, as reported | C6: 207911
B7: of which: profit on sale of listed investments (one-off) | C7: 8924 | F7: Disclosed in note 5 of the results. Removed below because a lender does not lend against a disposal gain
B8: EBITDA, adjusted | C8: =Inputs!$C$6-Inputs!$C$7 -> 198987
B9: Depreciation, amortisation and depletion | C9: 57688
B10: EBIT, adjusted | C10: =Inputs!$C$8-Inputs!$C$9 -> 141299
B11: Finance costs (P&L) | C11: 27061
B12: Interest paid (cash flow statement) | C12: 39981 | F12: Higher than the P&L charge because interest on projects under construction is capitalised. Cash cover uses this figure
B13: Profit before tax | C13: 123162
B14: Tax expense | C14: 27552
B15: Effective tax rate | C15: =Inputs!$C$14/Inputs!$C$13 -> 0.22370536
B16: Net cash from operating activities | C16: 192113
B17: Capital expenditure (company definition, ex-spectrum) | C17: 144271
B18: Dividends paid to equity holders | C18: 7443
B20: BALANCE SHEET AT 31 MARCH 2026 (₹ crore)
B21: Outstanding debt (company definition) | C21: 374421
B22: Cash and cash equivalents (company definition, incl. liquid investments) | C22: 249704
B23: Lease liabilities (current and non-current) | C23: 23579
B24: Deferred payment liabilities (spectrum instalments to DoT) | C24: 99552 | F24: Interest-bearing instalments owed to the government for spectrum. Agencies treat them as debt; the company's net debt figure excludes them
B25: Equity attributable to owners | C25: 904030
B26: Non-controlling interests | C26: 181836
B27: Borrowings due within twelve months | C27: 103670
B29: MARKET DATA
B30: Share price (₹, NSE close 18 Sep 2026) | C30: 1244.6
B31: Shares outstanding (crore) | C31: 1353.25
B32: Market capitalisation | C32: =Inputs!$C$30*Inputs!$C$31 -> 1684254.9
B33: Dividend per share, FY2026 (₹) | C33: 6
B35: COST OF CAPITAL
B36: Risk-free rate (10-year Government of India, INR) | C36: 0.0655 | F36: Benchmark G-sec yield, September 2026
B37: Equity risk premium, India | C37: 0.07 | F37: Mature-market premium plus country risk, per Damodaran's country tables
B38: Observed levered beta versus NIFTY 50 | C38: 1.05 | F38: Five-year monthly. Regressed in Project 5's method; taken as an input here
B39: Marginal tax rate (tax shield on interest) | C39: 0.2517 | F39: Section 115BAA concessional rate with surcharge and cess
B41: RATING FRAMEWORK — stated inputs
B42: Thresholds are illustrative levels adapted from published agency methodologies for large diversified industrials. Real committees also weigh business risk, diversification, liquidity and sovereign ceilings; Reliance is rated A- (S&P) and Baa1 (Moody's), two notches above India's sovereign, precisely because of those qualitative factors.
B43: Rating category | C43: AA | D43: A | E43: BBB | F43: BB | G43: B
B44: Maximum net debt / EBITDA | C44: 1 | D44: 1.75 | E44: 2.75 | F44: 4 | G44: 5.5
B45: Minimum EBITDA / cash interest | C45: 12 | D45: 8 | E45: 5 | F45: 3 | G45: 2
...

Sheet Credit Profile
B1: Reliance Industries — Debt Capacity and Capital Structure | F1: RELIANCE INDUSTRIES
B2: The balance sheet as reported, and as a rating agency would restate it
B4: NET DEBT — THREE DEFINITIONS
B5: Net debt, company definition (debt less cash) | C5: =Inputs!$C$21-Inputs!$C$22 -> 124717 | F5: The 0.6x figure in the results release
B6: Add: lease liabilities | C6: =Inputs!$C$23 -> 23579
B7: Add: deferred spectrum liabilities | C7: =Inputs!$C$24 -> 99552
B8: Adjusted net debt (agency basis) | C8: ='Credit Profile'!$C$5+'Credit Profile'!$C$6+'Credit Profile'!$C$7 -> 247848
B9: Adjusted gross debt | C9: =Inputs!$C$21+Inputs!$C$23+Inputs!$C$24 -> 497552
B11: LEVERAGE AND COVER
B12: Net debt / EBITDA — company basis, reported EBITDA | C12: ='Credit Profile'!$C$5/Inputs!$C$6 -> 0.59985763
B13: Adjusted net debt / adjusted EBITDA | C13: ='Credit Profile'!$C$8/Inputs!$C$8 -> 1.2455487 | F13: Roughly double the headline. This is the number to defend to a lender
B14: Adjusted gross debt / adjusted EBITDA | C14: ='Credit Profile'!$C$9/Inputs!$C$8 -> 2.5004247
B15: EBITDA / finance costs (P&L) | C15: =Inputs!$C$8/Inputs!$C$11 -> 7.3532759
B16: EBITDA / cash interest paid | C16: =Inputs!$C$8/Inputs!$C$12 -> 4.9770391 | F16: Uses interest actually paid, including the capitalised portion
B17: EBIT / finance costs | C17: =Inputs!$C$10/Inputs!$C$11 -> 5.2214996
B19: CASH FLOW MEASURES
B20: Funds from operations (EBITDA − cash interest − cash tax) | C20: =Inputs!$C$8-Inputs!$C$12-Inputs!$C$14 -> 131454 | F20: Tax expense is used as a proxy for cash tax; the cash flow statement shows taxes paid materially lower because of deferred tax
B21: FFO / adjusted net debt | C21: ='Credit Profile'!$C$20/'Credit Profile'!$C$8 -> 0.53038152
B22: Free cash flow (CFO − capex) | C22: =Inputs!$C$16-Inputs!$C$17 -> 47842
B23: Free cash flow after dividends | C23: ='Credit Profile'!$C$22-Inputs!$C$18 -> 40399
B24: Capex / adjusted EBITDA | C24: =Inputs!$C$17/Inputs!$C$8 -> 0.72502726 | F24: Nearly three-quarters of EBITDA is reinvested. Debt capacity is only useful if capex can be paused; here it largely cannot
B25: Years to repay adjusted net debt from free cash flow after dividends | C25: =IF('Credit Profile'!$C$23>0,'Credit Profile'!$C$8/'Credit Profile'!$C$23,"n/m") -> 6.1350033
B27: CAPITALISATION
B28: Adjusted gross debt / (debt + book equity) | C28: ='Credit Profile'!$C$9/('Credit Profile'!$C$9+Inputs!$C$25+Inputs!$C$26) -> 0.31422657
B29: Adjusted net debt / (net debt + market capitalisation) | C29: ='Credit Profile'!$C$8/('Credit Profile'!$C$8+Inputs!$C$32) -> 0.12827888 | F29: Market-value leverage. This is the weight used in the WACC work
B30: Enterprise value (market cap + adjusted net debt + NCI at book) | C30: =Inputs!$C$32+'Credit Profile'!$C$8+Inputs!$C$26 -> 2113939
B31: EV / adjusted EBITDA | C31: ='Credit Profile'!$C$30/Inputs!$C$8 -> 10.623503
B33: IMPLIED RATING FROM THE GRID
B34: Implied by leverage | C34: =IF('Credit Profile'!$C$13<=Inputs!$C$44,"AA",IF('Credit Profile'!$C$13<=Inputs!$D$44,"A",IF('Credit Profile'!$C$13<=Inputs!$E$44,"BBB",IF('Credit Profile'!$C$13<=Inputs!$F$44,"BB","B")))) -> A
B35: Implied by cash interest cover | C35: =IF('Credit Profile'!$C$16>=Inputs!$C$45,"AA",IF('Credit Profile'!$C$16>=Inputs!$D$45,"A",IF('Credit Profile'!$C$16>=Inputs!$E$45,"BBB",IF('Credit Profile'!$C$16>=Inputs!$F$45,"BB","B")))) -> BB
B36: Implied by FFO / net debt | C36: =IF('Credit Profile'!$C$21>=Inputs!$C$46,"AA",IF('Credit Profile'!$C$21>=Inputs!$D$46,"A",IF('Credit Profile'!$C$21>=Inputs!$E$46,"BBB",IF('Credit Profile'!$C$21>=Inputs!$F$46,"BB","B")))) -> A
B37: Leverage and FFO both say A. Cash interest cover, measured on interest actually paid, says BB — and the gap is the interest capitalised on nearly ₹2 lakh crore of projects under construction, which the P&L never shows. The published A- / Baa1 sits between the two readings, which is what a committee does when the metrics are strong but the capex programme is heavy and the sovereign ceiling is BBB-. The grid is a screen, not a committee.

Sheet Debt Capacity
B1: Reliance Industries — Debt Capacity and Capital Structure | H1: RELIANCE INDUSTRIES
B2: Maximum adjusted net debt at each rating — the tightest of three constraints wins
B4: CAPACITY BY CONSTRAINT (₹ crore)
B5: Rating category | C5: AA | D5: A | E5: BBB | F5: BB | G5: B
B6: From leverage: EBITDA × maximum net debt / EBITDA | C6: =Inputs!$C$8*Inputs!$C$44 -> 198987 | D6: =Inputs!$C$8*Inputs!$D$44 -> 348227.25 | E6: =Inputs!$C$8*Inputs!$E$44 -> 547214.25 | F6: =Inputs!$C$8*Inputs!$F$44 -> 795948 | G6: =Inputs!$C$8*Inputs!$G$44 -> 1094428.5
B7: From cover: EBITDA / (minimum cover × cost of debt) − cash-free | C7: =Inputs!$C$8/(Inputs!$C$45*Inputs!$C$48) -> 225608.84 | D7: =Inputs!$C$8/(Inputs!$D$45*Inputs!$D$48) -> 312872.64 | E7: =Inputs!$C$8/(Inputs!$E$45*Inputs!$E$48) -> 454827.43 | F7: =Inputs!$C$8/(Inputs!$F$45*Inputs!$F$48) -> 659990.05 | G7: =Inputs!$C$8/(Inputs!$G$45*Inputs!$G$48) -> 825672.2
B8: From FFO: FFO / minimum FFO-to-debt | C8: ='Credit Profile'!$C$20/Inputs!$C$46 -> 219090 | D8: ='Credit Profile'!$C$20/Inputs!$D$46 -> 292120 | E8: ='Credit Profile'!$C$20/Inputs!$E$46 -> 438180 | F8: ='Credit Profile'!$C$20/Inputs!$F$46 -> 657270 | G8: ='Credit Profile'!$C$20/Inputs!$G$46 -> 1095450
B9: Debt capacity — binding constraint | C9: =MIN('Debt Capacity'!$C$6,'Debt Capacity'!$C$7,'Debt Capacity'!$C$8) -> 198987 | D9: =MIN('Debt Capacity'!$D$6,'Debt Capacity'!$D$7,'Debt Capacity'!$D$8) -> 292120 | E9: =MIN('Debt Capacity'!$E$6,'Debt Capacity'!$E$7,'Debt Capacity'!$E$8) -> 438180 | F9: =MIN('Debt Capacity'!$F$6,'Debt Capacity'!$F$7,'Debt Capacity'!$F$8) -> 657270 | G9: =MIN('Debt Capacity'!$G$6,'Debt Capacity'!$G$7,'Debt Capacity'!$G$8) -> 825672.2
B10: Which constraint binds | C10: =IF('Debt Capacity'!$C$9='Debt Capacity'!$C$6,"Leverage",IF('Debt Capacity'!$C$9='Debt Capacity'!$C$7,"Cover","FFO")) -> Leverage | D10: =IF('Debt Capacity'!$D$9='Debt Capacity'!$D$6,"Leverage",IF('Debt Capacity'!$D$9='Debt Capacity'!$D$7,"Cover","FFO")) -> FFO | E10: =IF('Debt Capacity'!$E$9='Debt Capacity'!$E$6,"Leverage",IF('Debt Capacity'!$E$9='Debt Capacity'!$E$7,"Cover","FFO")) -> FFO | F10: =IF('Debt Capacity'!$F$9='Debt Capacity'!$F$6,"Leverage",IF('Debt Capacity'!$F$9='Debt Capacity'!$F$7,"Cover","FFO")) -> FFO | G10: =IF('Debt Capacity'!$G$9='Debt Capacity'!$G$6,"Leverage",IF('Debt Capacity'!$G$9='Debt Capacity'!$G$7,"Cover","FFO")) -> Cover
B12: HEADROOM AGAINST TODAY'S ADJUSTED NET DEBT
B13: Adjusted net debt today | C13: ='Credit Profile'!$C$8 -> 247848 | D13: ='Credit Profile'!$C$8 -> 247848 | E13: ='Credit Profile'!$C$8 -> 247848 | F13: ='Credit Profile'!$C$8 -> 247848 | G13: ='Credit Profile'!$C$8 -> 247848
B14: Incremental borrowing capacity | C14: ='Debt Capacity'!$C$9-'Debt Capacity'!$C$13 -> -48861 | D14: ='Debt Capacity'!$D$9-'Debt Capacity'!$D$13 -> 44272 | E14: ='Debt Capacity'!$E$9-'Debt Capacity'!$E$13 -> 190332 | F14: ='Debt Capacity'!$F$9-'Debt Capacity'!$F$13 -> 409422 | G14: ='Debt Capacity'!$G$9-'Debt Capacity'!$G$13 -> 577824.2
B15: in US$ billion at ₹83.5 / US$ | C15: ='Debt Capacity'!$C$14/8350 -> -5.8516168 | D15: ='Debt Capacity'!$D$14/8350 -> 5.3020359 | E15: ='Debt Capacity'!$E$14/8350 -> 22.794251 | F15: ='Debt Capacity'!$F$14/8350 -> 49.032575 | G15: ='Debt Capacity'!$G$14/8350 -> 69.200503
B16: as % of market capitalisation | C16: ='Debt Capacity'!$C$14/Inputs!$C$32 -> -0.029010454 | D16: ='Debt Capacity'!$D$14/Inputs!$C$32 -> 0.026285807 | E16: ='Debt Capacity'!$E$14/Inputs!$C$32 -> 0.11300664 | F16: ='Debt Capacity'!$F$14/Inputs!$C$32 -> 0.2430879 | G16: ='Debt Capacity'!$G$14/Inputs!$C$32 -> 0.34307407
B17: Pro forma net debt / EBITDA if fully drawn | C17: ='Debt Capacity'!$C$9/Inputs!$C$8 -> 1 | D17: ='Debt Capacity'!$D$9/Inputs!$C$8 -> 1.4680356 | E17: ='Debt Capacity'!$E$9/Inputs!$C$8 -> 2.2020534 | F17: ='Debt Capacity'!$F$9/Inputs!$C$8 -> 3.3030801 | G17: ='Debt Capacity'!$G$9/Inputs!$C$8 -> 4.1493776
B18: Pro forma EBITDA / interest if fully drawn | C18: =Inputs!$C$8/('Debt Capacity'!$C$9*Inputs!$C$48) -> 13.605442 | D18: =Inputs!$C$8/('Debt Capacity'!$D$9*Inputs!$D$48) -> 8.568332 | E18: =Inputs!$C$8/('Debt Capacity'!$E$9*Inputs!$E$48) -> 5.1899611 | F18: =Inputs!$C$8/('Debt Capacity'!$F$9*Inputs!$F$48) -> 3.0124152 | G18: =Inputs!$C$8/('Debt Capacity'!$G$9*Inputs!$G$48) -> 2
B20: The cover constraint assumes the whole debt stack reprices to the category's cost of debt, which overstates interest for a company whose existing borrowings were raised at lower rates. That makes the capacity numbers conservative, which is the right direction for a capacity study. Capacity from FFO ignores the feedback of new interest on FFO; the effect is second-order at these leverage levels.
B22: WHAT THE HEADROOM WOULD FUND — at the A category
B23: Incremental capacity at A | C23: ='Debt Capacity'!$D$14 -> 44272
B24: Years of FY2026 capex it would fund on its own | C24: ='Debt Capacity'!$C$23/Inputs!$C$17 -> 0.30686694
B25: Years of FY2026 free cash flow it represents | C25: =IF('Credit Profile'!$C$22>0,'Debt Capacity'!$C$23/'Credit Profile'!$C$22,"n/m") -> 0.92537937
B26: Share of market cap it could retire in a levered recapitalisation | C26: ='Debt Capacity'!$C$23/Inputs!$C$32 -> 0.026285807

Sheet Optimal Structure
B1: Reliance Industries — Debt Capacity and Capital Structure | H1: RELIANCE INDUSTRIES
B2: Weighted average cost of capital across leverage — the minimum is the optimum
B4: UNLEVERED COST OF EQUITY
B5: Market-value debt / (debt + equity) today | C5: ='Credit Profile'!$C$29 -> 0.12827888
B6: Debt / equity today | C6: ='Optimal Structure'!$C$5/(1-'Optimal Structure'!$C$5) -> 0.14715587
B7: Unlevered beta (Hamada) | C7: =Inputs!$C$38/(1+(1-Inputs!$C$39)*'Optimal Structure'!$C$6) -> 0.94584647 | H7: Observed beta stripped of today's leverage, then re-levered at each candidate structure
B8: Cost of equity today | C8: =Inputs!$C$36+Inputs!$C$38*Inputs!$C$37 -> 0.139
B9: Pre-tax cost of debt today (A category) | C9: =Inputs!$D$48 -> 0.0795
B10: WACC today | C10: =(1-'Optimal Structure'!$C$5)*'Optimal Structure'!$C$8+'Optimal Structure'!$C$5*'Optimal Structure'!$C$9*(1-Inputs!$C$39) -> 0.12880053
B12: WACC ACROSS CANDIDATE STRUCTURES
B13: Debt / (debt + equity) at market value | C13: 0% | D13: 10% | E13: 20% | F13: 30% | G13: 40% | H13: 50%
B14: Debt / (debt + equity) | C14: 0 | D14: 0.1 | E14: 0.2 | F14: 0.3 | G14: 0.4 | H14: 0.5
B15: Debt / equity | C15: ='Optimal Structure'!$C$14/(1-'Optimal Structure'!$C$14) -> 0 | D15: ='Optimal Structure'!$D$14/(1-'Optimal Structure'!$D$14) -> 0.11111111 | E15: ='Optimal Structure'!$E$14/(1-'Optimal Structure'!$E$14) -> 0.25 | F15: ='Optimal Structure'!$F$14/(1-'Optimal Structure'!$F$14) -> 0.42857143 | G15: ='Optimal Structure'!$G$14/(1-'Optimal Structure'!$G$14) -> 0.66666667 | H15: ='Optimal Structure'!$H$14/(1-'Optimal Structure'!$H$14) -> 1
B16: Implied net debt (holding firm value constant) | C16: ='Optimal Structure'!$C$14*(Inputs!$C$32+'Credit Profile'!$C$8) -> 0 | D16: ='Optimal Structure'!$D$14*(Inputs!$C$32+'Credit Profile'!$C$8) -> 193210.3 | E16: ='Optimal Structure'!$E$14*(Inputs!$C$32+'Credit Profile'!$C$8) -> 386420.59 | F16: ='Optimal Structure'!$F$14*(Inputs!$C$32+'Credit Profile'!$C$8) -> 579630.89 | G16: ='Optimal Structure'!$G$14*(Inputs!$C$32+'Credit Profile'!$C$8) -> 772841.18 | H16: ='Optimal Structure'!$H$14*(Inputs!$C$32+'Credit Profile'!$C$8) -> 966051.47
B17: Implied net debt / EBITDA | C17: ='Optimal Structure'!$C$16/Inputs!$C$8 -> 0 | D17: ='Optimal Structure'!$D$16/Inputs!$C$8 -> 0.97096944 | E17: ='Optimal Structure'!$E$16/Inputs!$C$8 -> 1.9419389 | F17: ='Optimal Structure'!$F$16/Inputs!$C$8 -> 2.9129083 | G17: ='Optimal Structure'!$G$16/Inputs!$C$8 -> 3.8838777 | H17: ='Optimal Structure'!$H$16/Inputs!$C$8 -> 4.8548472
B18: Implied rating from the leverage grid | C18: =IF('Optimal Structure'!$C$17<=Inputs!$C$44,"AA",IF('Optimal Structure'!$C$17<=Inputs!$D$44,"A",IF('Optimal Structure'!$C$17<=Inputs!$E$44,"BBB",IF('Optimal Structure'!$C$17<=Inputs!$F$44,"BB","B")))) -> AA | D18: =IF('Optimal Structure'!$D$17<=Inputs!$C$44,"AA",IF('Optimal Structure'!$D$17<=Inputs!$D$44,"A",IF('Optimal Structure'!$D$17<=Inputs!$E$44,"BBB",IF('Optimal Structure'!$D$17<=Inputs!$F$44,"BB","B")))) -> AA | E18: =IF('Optimal Structure'!$E$17<=Inputs!$C$44,"AA",IF('Optimal Structure'!$E$17<=Inputs!$D$44,"A",IF('Optimal Structure'!$E$17<=Inputs!$E$44,"BBB",IF('Optimal Structure'!$E$17<=Inputs!$F$44,"BB","B")))) -> BBB | F18: =IF('Optimal Structure'!$F$17<=Inputs!$C$44,"AA",IF('Optimal Structure'!$F$17<=Inputs!$D$44,"A",IF('Optimal Structure'!$F$17<=Inputs!$E$44,"BBB",IF('Optimal Structure'!$F$17<=Inputs!$F$44,"BB","B")))) -> BB | G18: =IF('Optimal Structure'!$G$17<=Inputs!$C$44,"AA",IF('Optimal Structure'!$G$17<=Inputs!$D$44,"A",IF('Optimal Structure'!$G$17<=Inputs!$E$44,"BBB",IF('Optimal Structure'!$G$17<=Inputs!$F$44,"BB","B")))) -> BB | H18: =IF('Optimal Structure'!$H$17<=Inputs!$C$44,"AA",IF('Optimal Structure'!$H$17<=Inputs!$D$44,"A",IF('Optimal Structure'!$H$17<=Inputs!$E$44,"BBB",IF('Optimal Structure'!$H$17<=Inputs!$F$44,"BB","B")))) -> B
B19: Pre-tax cost of debt at that rating | C19: =IF('Optimal Structure'!$C$17<=Inputs!$C$44,Inputs!$C$48,IF('Optimal Structure'!$C$17<=Inputs!$D$44,Inputs!$D$48,IF('Optimal Structure'!$C$17<=Inputs!$E$44,Inputs!$E$48,IF('Optimal Structure'!$C$17<=Inputs!$F$44,Inputs!$F$48,Inputs!$G$48)))) -> 0.0735 | D19: =IF('Optimal Structure'!$D$17<=Inputs!$C$44,Inputs!$C$48,IF('Optimal Structure'!$D$17<=Inputs!$D$44,Inputs!$D$48,IF('Optimal Structure'!$D$17<=Inputs!$E$44,Inputs!$E$48,IF('Optimal Structure'!$D$17<=Inputs!$F$44,Inputs!$F$48,Inputs!$G$48)))) -> 0.0735 | E19: =IF('Optimal Structure'!$E$17<=Inputs!$C$44,Inputs!$C$48,IF('Optimal Structure'!$E$17<=Inputs!$D$44,Inputs!$D$48,IF('Optimal Structure'!$E$17<=Inputs!$E$44,Inputs!$E$48,IF('Optimal Structure'!$E$17<=Inputs!$F$44,Inputs!$F$48,Inputs!$G$48)))) -> 0.0875 | F19: =IF('Optimal Structure'!$F$17<=Inputs!$C$44,Inputs!$C$48,IF('Optimal Structure'!$F$17<=Inputs!$D$44,Inputs!$D$48,IF('Optimal Structure'!$F$17<=Inputs!$E$44,Inputs!$E$48,IF('Optimal Structure'!$F$17<=Inputs!$F$44,Inputs!$F$48,Inputs!$G$48)))) -> 0.1005 | G19: =IF('Optimal Structure'!$G$17<=Inputs!$C$44,Inputs!$C$48,IF('Optimal Structure'!$G$17<=Inputs!$D$44,Inputs!$D$48,IF('Optimal Structure'!$G$17<=Inputs!$E$44,Inputs!$E$48,IF('Optimal Structure'!$G$17<=Inputs!$F$44,Inputs!$F$48,Inputs!$G$48)))) -> 0.1005 | H19: =IF('Optimal Structure'!$H$17<=Inputs!$C$44,Inputs!$C$48,IF('Optimal Structure'!$H$17<=Inputs!$D$44,Inputs!$D$48,IF('Optimal Structure'!$H$17<=Inputs!$E$44,Inputs!$E$48,IF('Optimal Structure'!$H$17<=Inputs!$F$44,Inputs!$F$48,Inputs!$G$48)))) -> 0.1205
B20: Implied EBITDA / interest | C20: =IF('Optimal Structure'!$C$16>0,Inputs!$C$8/('Optimal Structure'!$C$16*'Optimal Structure'!$C$19),"n/a") -> n/a | D20: =IF('Optimal Structure'!$D$16>0,Inputs!$C$8/('Optimal Structure'!$D$16*'Optimal Structure'!$D$19),"n/a") -> 14.012225 | E20: =IF('Optimal Structure'!$E$16>0,Inputs!$C$8/('Optimal Structure'!$E$16*'Optimal Structure'!$E$19),"n/a") -> 5.8851345 | F20: =IF('Optimal Structure'!$F$16>0,Inputs!$C$8/('Optimal Structure'!$F$16*'Optimal Structure'!$F$19),"n/a") -> 3.4159155 | G20: =IF('Optimal Structure'!$G$16>0,Inputs!$C$8/('Optimal Structure'!$G$16*'Optimal Structure'!$G$19),"n/a") -> 2.5619367 | H20: =IF('Optimal Structure'!$H$16>0,Inputs!$C$8/('Optimal Structure'!$H$16*'Optimal Structure'!$H$19),"n/a") -> 1.7093752
B21: Re-levered beta | C21: ='Optimal Structure'!$C$7*(1+(1-Inputs!$C$39)*'Optimal Structure'!$C$15) -> 0.94584647 | D21: ='Optimal Structure'!$C$7*(1+(1-Inputs!$C$39)*'Optimal Structure'!$D$15) -> 1.0244884 | E21: ='Optimal Structure'!$C$7*(1+(1-Inputs!$C$39)*'Optimal Structure'!$E$15) -> 1.1227907 | F21: ='Optimal Structure'!$C$7*(1+(1-Inputs!$C$39)*'Optimal Structure'!$F$15) -> 1.2491794 | G21: ='Optimal Structure'!$C$7*(1+(1-Inputs!$C$39)*'Optimal Structure'!$G$15) -> 1.4176978 | H21: ='Optimal Structure'!$C$7*(1+(1-Inputs!$C$39)*'Optimal Structure'!$H$15) -> 1.6536234
B22: Cost of equity | C22: =Inputs!$C$36+'Optimal Structure'!$C$21*Inputs!$C$37 -> 0.13170925 | D22: =Inputs!$C$36+'Optimal Structure'!$D$21*Inputs!$C$37 -> 0.13721418 | E22: =Inputs!$C$36+'Optimal Structure'!$E$21*Inputs!$C$37 -> 0.14409535 | F22: =Inputs!$C$36+'Optimal Structure'!$F$21*Inputs!$C$37 -> 0.15294256 | G22: =Inputs!$C$36+'Optimal Structure'!$G$21*Inputs!$C$37 -> 0.16473884 | H22: =Inputs!$C$36+'Optimal Structure'!$H$21*Inputs!$C$37 -> 0.18125364
B23: WACC | C23: =(1-'Optimal Structure'!$C$14)*'Optimal Structure'!$C$22+'Optimal Structure'!$C$14*'Optimal Structure'!$C$19*(1-Inputs!$C$39) -> 0.13170925 | D23: =(1-'Optimal Structure'!$D$14)*'Optimal Structure'!$D$22+'Optimal Structure'!$D$14*'Optimal Structure'!$D$19*(1-Inputs!$C$39) -> 0.12899277 | E23: =(1-'Optimal Structure'!$E$14)*'Optimal Structure'!$E$22+'Optimal Structure'!$E$14*'Optimal Structure'!$E$19*(1-Inputs!$C$39) -> 0.12837153 | F23: =(1-'Optimal Structure'!$F$14)*'Optimal Structure'!$F$22+'Optimal Structure'!$F$14*'Optimal Structure'!$F$19*(1-Inputs!$C$39) -> 0.12962104 | G23: =(1-'Optimal Structure'!$G$14)*'Optimal Structure'!$G$22+'Optimal Structure'!$G$14*'Optimal Structure'!$G$19*(1-Inputs!$C$39) -> 0.12892497 | H23: =(1-'Optimal Structure'!$H$14)*'Optimal Structure'!$H$22+'Optimal Structure'!$H$14*'Optimal Structure'!$H$19*(1-Inputs!$C$39) -> 0.13571189
B25: Minimum WACC in the grid | C25: =MIN($C$23:$H$23) -> 0.12837153
B26: Debt weight at the minimum | C26: =INDEX($C$14:$H$14,MATCH('Optimal Structure'!$C$25,$C$23:$H$23,0)) -> 0.2
B27: WACC saving versus today (basis points) | C27: =('Optimal Structure'!$C$10-'Optimal Structure'!$C$25)*10000 -> 4.2899779
B28: Illustrative firm-value gain: FY2026 FCF grown at 4%, capitalised at old and new WACC | C28: =IF('Credit Profile'!$C$22>0,'Credit Profile'!$C$22*1.04*(1/('Optimal Structure'!$C$25-0.04)-1/('Optimal Structure'!$C$10-0.04)),0) -> 2720.0056 | H28: A perpetuity on one year's free cash flow. Indicative of order of magnitude only
B29: The curve is flat between roughly 10% and 30% debt: the tax shield and the rising cost of equity nearly offset, and the drop to BBB at 20% costs 140 basis points of spread that the shield mostly absorbs. The optimum is therefore a range, not a point, and the company already sits inside it at about 13%. Beyond 30% the grid implies BB, the spread jumps again, and WACC rises faster than the shield can compensate.

Sheet Liquidity
B1: Reliance Industries — Debt Capacity and Capital Structure | F1: RELIANCE INDUSTRIES
B2: Twelve-month sources and uses — can the company fund itself without the market?
B4: SOURCES OVER THE NEXT TWELVE MONTHS
B5: Cash and cash equivalents at 31 March 2026 | C5: =Inputs!$C$22 -> 249704
B6: Assumed growth in operating cash flow | C6: 0.06 | F6: Below FY2026 EBITDA growth of 13%, which was flattered by cracks and the disposal gain
B7: Operating cash flow, FY2027E | C7: =Inputs!$C$16*(1+Liquidity!$C$6) -> 203639.78
B8: Total sources | C8: =Liquidity!$C$5+Liquidity!$C$7 -> 453343.78
B10: USES OVER THE NEXT TWELVE MONTHS
B11: Borrowings due within twelve months | C11: =Inputs!$C$27 -> 103670 | F11: Includes commercial paper and working-capital lines that are rolled in the ordinary course
B12: Assumed capex, FY2027E, as % of FY2026 | C12: 1 | F12: New Energy giga-factories and O2C projects keep the programme flat
B13: Capital expenditure, FY2027E | C13: =Inputs!$C$17*Liquidity!$C$12 -> 144271
B14: Cash interest | C14: =Inputs!$C$12 -> 39981
B15: Dividend at ₹6 per share | C15: =Inputs!$C$33*Inputs!$C$31 -> 8119.5
B16: Spectrum instalment (assumed at FY2026 level) | C16: 4736 | F16: FY2026 payment of deferred liabilities from the cash flow statement
B17: Total uses | C17: =Liquidity!$C$11+Liquidity!$C$13+Liquidity!$C$14+Liquidity!$C$15+Liquidity!$C$16 -> 300777.5
B19: Sources / uses | C19: =Liquidity!$C$8/Liquidity!$C$17 -> 1.5072397
B20: Sources / uses excluding rollover of short-term borrowings | C20: =Liquidity!$C$8/(Liquidity!$C$17-Liquidity!$C$11) -> 2.2999824
B21: Surplus / (shortfall) after all uses | C21: =Liquidity!$C$8-Liquidity!$C$17 -> 152566.28
B22: Minimum operating cash assumed | C22: 40000
B23: Cash room after minimum balance | C23: =Liquidity!$C$21-Liquidity!$C$22 -> 112566.28
B24: The company can meet every use for the year from cash on hand and one year's operating cash flow without raising a rupee, and can do so even if every short-term line is repaid rather than rolled. That is what an A-category liquidity profile looks like, and it is the qualitative factor that lets the rating sit above the sovereign.

Sheet Sensitivity
B1: Reliance Industries — Debt Capacity and Capital Structure | H1: RELIANCE INDUSTRIES
B2: Incremental capacity at the A category (₹ crore) — every cell rebuilds all three constraints
B4: HEADROOM — EBITDA CHANGE versus LEVERAGE THRESHOLD AT A (cover and FFO thresholds held)
B5: Max ND/EBITDA at A \ Change in EBITDA | C5: -0.2 | D5: -0.1 | E5: 0 | F5: 0.1 | G5: 0.2
B6: 1.25 | C6: =MIN((Inputs!$C$8*(1+C$5))*$B6,(Inputs!$C$8*(1+C$5))/(Inputs!$D$45*Inputs!$D$48),((Inputs!$C$8*(1+C$5))-Inputs!$C$12-Inputs!$C$14)/Inputs!$D$46)-'Credit Profile'!$C$8 -> -48861 | D6: =MIN((Inputs!$C$8*(1+D$5))*$B6,(Inputs!$C$8*(1+D$5))/(Inputs!$D$45*Inputs!$D$48),((Inputs!$C$8*(1+D$5))-Inputs!$C$12-Inputs!$C$14)/Inputs!$D$46)-'Credit Profile'!$C$8 -> -23987.625 | E6: =MIN((Inputs!$C$8*(1+E$5))*$B6,(Inputs!$C$8*(1+E$5))/(Inputs!$D$45*Inputs!$D$48),((Inputs!$C$8*(1+E$5))-Inputs!$C$12-Inputs!$C$14)/Inputs!$D$46)-'Credit Profile'!$C$8 -> 885.75 | F6: =MIN((Inputs!$C$8*(1+F$5))*$B6,(Inputs!$C$8*(1+F$5))/(Inputs!$D$45*Inputs!$D$48),((Inputs!$C$8*(1+F$5))-Inputs!$C$12-Inputs!$C$14)/Inputs!$D$46)-'Credit Profile'!$C$8 -> 25759.125 | G6: =MIN((Inputs!$C$8*(1+G$5))*$B6,(Inputs!$C$8*(1+G$5))/(Inputs!$D$45*Inputs!$D$48),((Inputs!$C$8*(1+G$5))-Inputs!$C$12-Inputs!$C$14)/Inputs!$D$46)-'Credit Profile'!$C$8 -> 50632.5
B7: 1.5 | C7: =MIN((Inputs!$C$8*(1+C$5))*$B7,(Inputs!$C$8*(1+C$5))/(Inputs!$D$45*Inputs!$D$48),((Inputs!$C$8*(1+C$5))-Inputs!$C$12-Inputs!$C$14)/Inputs!$D$46)-'Credit Profile'!$C$8 -> -44166.667 | D7: =MIN((Inputs!$C$8*(1+D$5))*$B7,(Inputs!$C$8*(1+D$5))/(Inputs!$D$45*Inputs!$D$48),((Inputs!$C$8*(1+D$5))-Inputs!$C$12-Inputs!$C$14)/Inputs!$D$46)-'Credit Profile'!$C$8 -> 52.666667 | E7: =MIN((Inputs!$C$8*(1+E$5))*$B7,(Inputs!$C$8*(1+E$5))/(Inputs!$D$45*Inputs!$D$48),((Inputs!$C$8*(1+E$5))-Inputs!$C$12-Inputs!$C$14)/Inputs!$D$46)-'Credit Profile'!$C$8 -> 44272 | F7: =MIN((Inputs!$C$8*(1+F$5))*$B7,(Inputs!$C$8*(1+F$5))/(Inputs!$D$45*Inputs!$D$48),((Inputs!$C$8*(1+F$5))-Inputs!$C$12-Inputs!$C$14)/Inputs!$D$46)-'Credit Profile'!$C$8 -> 80480.55 | G7: =MIN((Inputs!$C$8*(1+G$5))*$B7,(Inputs!$C$8*(1+G$5))/(Inputs!$D$45*Inputs!$D$48),((Inputs!$C$8*(1+G$5))-Inputs!$C$12-Inputs!$C$14)/Inputs!$D$46)-'Credit Profile'!$C$8 -> 110328.6
B8: 1.75 | C8: =MIN((Inputs!$C$8*(1+C$5))*$B8,(Inputs!$C$8*(1+C$5))/(Inputs!$D$45*Inputs!$D$48),((Inputs!$C$8*(1+C$5))-Inputs!$C$12-Inputs!$C$14)/Inputs!$D$46)-'Credit Profile'!$C$8 -> -44166.667 | D8: =MIN((Inputs!$C$8*(1+D$5))*$B8,(Inputs!$C$8*(1+D$5))/(Inputs!$D$45*Inputs!$D$48),((Inputs!$C$8*(1+D$5))-Inputs!$C$12-Inputs!$C$14)/Inputs!$D$46)-'Credit Profile'!$C$8 -> 52.666667 | E8: =MIN((Inputs!$C$8*(1+E$5))*$B8,(Inputs!$C$8*(1+E$5))/(Inputs!$D$45*Inputs!$D$48),((Inputs!$C$8*(1+E$5))-Inputs!$C$12-Inputs!$C$14)/Inputs!$D$46)-'Credit Profile'!$C$8 -> 44272 | F8: =MIN((Inputs!$C$8*(1+F$5))*$B8,(Inputs!$C$8*(1+F$5))/(Inputs!$D$45*Inputs!$D$48),((Inputs!$C$8*(1+F$5))-Inputs!$C$12-Inputs!$C$14)/Inputs!$D$46)-'Credit Profile'!$C$8 -> 88491.333 | G8: =MIN((Inputs!$C$8*(1+G$5))*$B8,(Inputs!$C$8*(1+G$5))/(Inputs!$D$45*Inputs!$D$48),((Inputs!$C$8*(1+G$5))-Inputs!$C$12-Inputs!$C$14)/Inputs!$D$46)-'Credit Profile'!$C$8 -> 127599.17
B9: 2 | C9: =MIN((Inputs!$C$8*(1+C$5))*$B9,(Inputs!$C$8*(1+C$5))/(Inputs!$D$45*Inputs!$D$48),((Inputs!$C$8*(1+C$5))-Inputs!$C$12-Inputs!$C$14)/Inputs!$D$46)-'Credit Profile'!$C$8 -> -44166.667 | D9: =MIN((Inputs!$C$8*(1+D$5))*$B9,(Inputs!$C$8*(1+D$5))/(Inputs!$D$45*Inputs!$D$48),((Inputs!$C$8*(1+D$5))-Inputs!$C$12-Inputs!$C$14)/Inputs!$D$46)-'Credit Profile'!$C$8 -> 52.666667 | E9: =MIN((Inputs!$C$8*(1+E$5))*$B9,(Inputs!$C$8*(1+E$5))/(Inputs!$D$45*Inputs!$D$48),((Inputs!$C$8*(1+E$5))-Inputs!$C$12-Inputs!$C$14)/Inputs!$D$46)-'Credit Profile'!$C$8 -> 44272 | F9: =MIN((Inputs!$C$8*(1+F$5))*$B9,(Inputs!$C$8*(1+F$5))/(Inputs!$D$45*Inputs!$D$48),((Inputs!$C$8*(1+F$5))-Inputs!$C$12-Inputs!$C$14)/Inputs!$D$46)-'Credit Profile'!$C$8 -> 88491.333 | G9: =MIN((Inputs!$C$8*(1+G$5))*$B9,(Inputs!$C$8*(1+G$5))/(Inputs!$D$45*Inputs!$D$48),((Inputs!$C$8*(1+G$5))-Inputs!$C$12-Inputs!$C$14)/Inputs!$D$46)-'Credit Profile'!$C$8 -> 127599.17
B10: 2.25 | C10: =MIN((Inputs!$C$8*(1+C$5))*$B10,(Inputs!$C$8*(1+C$5))/(Inputs!$D$45*Inputs!$D$48),((Inputs!$C$8*(1+C$5))-Inputs!$C$12-Inputs!$C$14)/Inputs!$D$46)-'Credit Profile'!$C$8 -> -44166.667 | D10: =MIN((Inputs!$C$8*(1+D$5))*$B10,(Inputs!$C$8*(1+D$5))/(Inputs!$D$45*Inputs!$D$48),((Inputs!$C$8*(1+D$5))-Inputs!$C$12-Inputs!$C$14)/Inputs!$D$46)-'Credit Profile'!$C$8 -> 52.666667 | E10: =MIN((Inputs!$C$8*(1+E$5))*$B10,(Inputs!$C$8*(1+E$5))/(Inputs!$D$45*Inputs!$D$48),((Inputs!$C$8*(1+E$5))-Inputs!$C$12-Inputs!$C$14)/Inputs!$D$46)-'Credit Profile'!$C$8 -> 44272 | F10: =MIN((Inputs!$C$8*(1+F$5))*$B10,(Inputs!$C$8*(1+F$5))/(Inputs!$D$45*Inputs!$D$48),((Inputs!$C$8*(1+F$5))-Inputs!$C$12-Inputs!$C$14)/Inputs!$D$46)-'Credit Profile'!$C$8 -> 88491.333 | G10: =MIN((Inputs!$C$8*(1+G$5))*$B10,(Inputs!$C$8*(1+G$5))/(Inputs!$D$45*Inputs!$D$48),((Inputs!$C$8*(1+G$5))-Inputs!$C$12-Inputs!$C$14)/Inputs!$D$46)-'Credit Profile'!$C$8 -> 127599.17
B12: WACC — EQUITY RISK PREMIUM versus DEBT WEIGHT (rating and cost of debt from the grid)
B13: Debt weight \ Equity risk premium | C13: 0.06 | D13: 0.065 | E13: 0.07 | F13: 0.075 | G13: 0.08
B14: 0.1 | C14: =(1-$B14)*(Inputs!$C$36+('Optimal Structure'!$C$7*(1+(1-Inputs!$C$39)*($B14/(1-$B14))))*C$13)+$B14*IF(($B14*(Inputs!$C$32+'Credit Profile'!$C$8)/Inputs!$C$8)<=Inputs!$C$44,Inputs!$C$48,IF(($B14*(Inputs!$C$32+'Credit Profile'!$C$8)/Inputs!$C$8)<=Inputs!$D$44,Inputs!$D$48,IF(($B14*(Inputs!$C$32+'Credit Profile'!$C$8)/Inputs!$C$8)<=Inputs!$E$44,Inputs!$E$48,IF(($B14*(Inputs!$C$32+'Credit Profile'!$C$8)/Inputs!$C$8)<=Inputs!$F$44,Inputs!$F$48,Inputs!$G$48))))*(1-Inputs!$C$39) -> 0.11977238 | D14: =(1-$B14)*(Inputs!$C$36+('Optimal Structure'!$C$7*(1+(1-Inputs!$C$39)*($B14/(1-$B14))))*D$13)+$B14*IF(($B14*(Inputs!$C$32+'Credit Profile'!$C$8)/Inputs!$C$8)<=Inputs!$C$44,Inputs!$C$48,IF(($B14*(Inputs!$C$32+'Credit Profile'!$C$8)/Inputs!$C$8)<=Inputs!$D$44,Inputs!$D$48,IF(($B14*(Inputs!$C$32+'Credit Profile'!$C$8)/Inputs!$C$8)<=Inputs!$E$44,Inputs!$E$48,IF(($B14*(Inputs!$C$32+'Credit Profile'!$C$8)/Inputs!$C$8)<=Inputs!$F$44,Inputs!$F$48,Inputs!$G$48))))*(1-Inputs!$C$39) -> 0.12438257 | E14: =(1-$B14)*(Inputs!$C$36+('Optimal Structure'!$C$7*(1+(1-Inputs!$C$39)*($B14/(1-$B14))))*E$13)+$B14*IF(($B14*(Inputs!$C$32+'Credit Profile'!$C$8)/Inputs!$C$8)<=Inputs!$C$44,Inputs!$C$48,IF(($B14*(Inputs!$C$32+'Credit Profile'!$C$8)/Inputs!$C$8)<=Inputs!$D$44,Inputs!$D$48,IF(($B14*(Inputs!$C$32+'Credit Profile'!$C$8)/Inputs!$C$8)<=Inputs!$E$44,Inputs!$E$48,IF(($B14*(Inputs!$C$32+'Credit Profile'!$C$8)/Inputs!$C$8)<=Inputs!$F$44,Inputs!$F$48,Inputs!$G$48))))*(1-Inputs!$C$39) -> 0.12899277 | F14: =(1-$B14)*(Inputs!$C$36+('Optimal Structure'!$C$7*(1+(1-Inputs!$C$39)*($B14/(1-$B14))))*F$13)+$B14*IF(($B14*(Inputs!$C$32+'Credit Profile'!$C$8)/Inputs!$C$8)<=Inputs!$C$44,Inputs!$C$48,IF(($B14*(Inputs!$C$32+'Credit Profile'!$C$8)/Inputs!$C$8)<=Inputs!$D$44,Inputs!$D$48,IF(($B14*(Inputs!$C$32+'Credit Profile'!$C$8)/Inputs!$C$8)<=Inputs!$E$44,Inputs!$E$48,IF(($B14*(Inputs!$C$32+'Credit Profile'!$C$8)/Inputs!$C$8)<=Inputs!$F$44,Inputs!$F$48,Inputs!$G$48))))*(1-Inputs!$C$39) -> 0.13360297 | G14: =(1-$B14)*(Inputs!$C$36+('Optimal Structure'!$C$7*(1+(1-Inputs!$C$39)*($B14/(1-$B14))))*G$13)+$B14*IF(($B14*(Inputs!$C$32+'Credit Profile'!$C$8)/Inputs!$C$8)<=Inputs!$C$44,Inputs!$C$48,IF(($B14*(Inputs!$C$32+'Credit Profile'!$C$8)/Inputs!$C$8)<=Inputs!$D$44,Inputs!$D$48,IF(($B14*(Inputs!$C$32+'Credit Profile'!$C$8)/Inputs!$C$8)<=Inputs!$E$44,Inputs!$E$48,IF(($B14*(Inputs!$C$32+'Credit Profile'!$C$8)/Inputs!$C$8)<=Inputs!$F$44,Inputs!$F$48,Inputs!$G$48))))*(1-Inputs!$C$39) -> 0.13821317
B15: 0.2 | C15: =(1-$B15)*(Inputs!$C$36+('Optimal Structure'!$C$7*(1+(1-Inputs!$C$39)*($B15/(1-$B15))))*C$13)+$B15*IF(($B15*(Inputs!$C$32+'Credit Profile'!$C$8)/Inputs!$C$8)<=Inputs!$C$44,Inputs!$C$48,IF(($B15*(Inputs!$C$32+'Credit Profile'!$C$8)/Inputs!$C$8)<=Inputs!$D$44,Inputs!$D$48,IF(($B15*(Inputs!$C$32+'Credit Profile'!$C$8)/Inputs!$C$8)<=Inputs!$E$44,Inputs!$E$48,IF(($B15*(Inputs!$C$32+'Credit Profile'!$C$8)/Inputs!$C$8)<=Inputs!$F$44,Inputs!$F$48,Inputs!$G$48))))*(1-Inputs!$C$39) -> 0.1193892 | D15: =(1-$B15)*(Inputs!$C$36+('Optimal Structure'!$C$7*(1+(1-Inputs!$C$39)*($B15/(1-$B15))))*D$13)+$B15*IF(($B15*(Inputs!$C$32+'Credit Profile'!$C$8)/Inputs!$C$8)<=Inputs!$C$44,Inputs!$C$48,IF(($B15*(Inputs!$C$32+'Credit Profile'!$C$8)/Inputs!$C$8)<=Inputs!$D$44,Inputs!$D$48,IF(($B15*(Inputs!$C$32+'Credit Profile'!$C$8)/Inputs!$C$8)<=Inputs!$E$44,Inputs!$E$48,IF(($B15*(Inputs!$C$32+'Credit Profile'!$C$8)/Inputs!$C$8)<=Inputs!$F$44,Inputs!$F$48,Inputs!$G$48))))*(1-Inputs!$C$39) -> 0.12388037 | E15: =(1-$B15)*(Inputs!$C$36+('Optimal Structure'!$C$7*(1+(1-Inputs!$C$39)*($B15/(1-$B15))))*E$13)+$B15*IF(($B15*(Inputs!$C$32+'Credit Profile'!$C$8)/Inputs!$C$8)<=Inputs!$C$44,Inputs!$C$48,IF(($B15*(Inputs!$C$32+'Credit Profile'!$C$8)/Inputs!$C$8)<=Inputs!$D$44,Inputs!$D$48,IF(($B15*(Inputs!$C$32+'Credit Profile'!$C$8)/Inputs!$C$8)<=Inputs!$E$44,Inputs!$E$48,IF(($B15*(Inputs!$C$32+'Credit Profile'!$C$8)/Inputs!$C$8)<=Inputs!$F$44,Inputs!$F$48,Inputs!$G$48))))*(1-Inputs!$C$39) -> 0.12837153 | F15: =(1-$B15)*(Inputs!$C$36+('Optimal Structure'!$C$7*(1+(1-Inputs!$C$39)*($B15/(1-$B15))))*F$13)+$B15*IF(($B15*(Inputs!$C$32+'Credit Profile'!$C$8)/Inputs!$C$8)<=Inputs!$C$44,Inputs!$C$48,IF(($B15*(Inputs!$C$32+'Credit Profile'!$C$8)/Inputs!$C$8)<=Inputs!$D$44,Inputs!$D$48,IF(($B15*(Inputs!$C$32+'Credit Profile'!$C$8)/Inputs!$C$8)<=Inputs!$E$44,Inputs!$E$48,IF(($B15*(Inputs!$C$32+'Credit Profile'!$C$8)/Inputs!$C$8)<=Inputs!$F$44,Inputs!$F$48,Inputs!$G$48))))*(1-Inputs!$C$39) -> 0.13286269 | G15: =(1-$B15)*(Inputs!$C$36+('Optimal Structure'!$C$7*(1+(1-Inputs!$C$39)*($B15/(1-$B15))))*G$13)+$B15*IF(($B15*(Inputs!$C$32+'Credit Profile'!$C$8)/Inputs!$C$8)<=Inputs!$C$44,Inputs!$C$48,IF(($B15*(Inputs!$C$32+'Credit Profile'!$C$8)/Inputs!$C$8)<=Inputs!$D$44,Inputs!$D$48,IF(($B15*(Inputs!$C$32+'Credit Profile'!$C$8)/Inputs!$C$8)<=Inputs!$E$44,Inputs!$E$48,IF(($B15*(Inputs!$C$32+'Credit Profile'!$C$8)/Inputs!$C$8)<=Inputs!$F$44,Inputs!$F$48,Inputs!$G$48))))*(1-Inputs!$C$39) -> 0.13735385
B16: 0.3 | C16: =(1-$B16)*(Inputs!$C$36+('Optimal Structure'!$C$7*(1+(1-Inputs!$C$39)*($B16/(1-$B16))))*C$13)+$B16*IF(($B16*(Inputs!$C$32+'Credit Profile'!$C$8)/Inputs!$C$8)<=Inputs!$C$44,Inputs!$C$48,IF(($B16*(Inputs!$C$32+'Credit Profile'!$C$8)/Inputs!$C$8)<=Inputs!$D$44,Inputs!$D$48,IF(($B16*(Inputs!$C$32+'Credit Profile'!$C$8)/Inputs!$C$8)<=Inputs!$E$44,Inputs!$E$48,IF(($B16*(Inputs!$C$32+'Credit Profile'!$C$8)/Inputs!$C$8)<=Inputs!$F$44,Inputs!$F$48,Inputs!$G$48))))*(1-Inputs!$C$39) -> 0.12087678 | D16: =(1-$B16)*(Inputs!$C$36+('Optimal Structure'!$C$7*(1+(1-Inputs!$C$39)*($B16/(1-$B16))))*D$13)+$B16*IF(($B16*(Inputs!$C$32+'Credit Profile'!$C$8)/Inputs!$C$8)<=Inputs!$C$44,Inputs!$C$48,IF(($B16*(Inputs!$C$32+'Credit Profile'!$C$8)/Inputs!$C$8)<=Inputs!$D$44,Inputs!$D$48,IF(($B16*(Inputs!$C$32+'Credit Profile'!$C$8)/Inputs!$C$8)<=Inputs!$E$44,Inputs!$E$48,IF(($B16*(Inputs!$C$32+'Credit Profile'!$C$8)/Inputs!$C$8)<=Inputs!$F$44,Inputs!$F$48,Inputs!$G$48))))*(1-Inputs!$C$39) -> 0.12524891 | E16: =(1-$B16)*(Inputs!$C$36+('Optimal Structure'!$C$7*(1+(1-Inputs!$C$39)*($B16/(1-$B16))))*E$13)+$B16*IF(($B16*(Inputs!$C$32+'Credit Profile'!$C$8)/Inputs!$C$8)<=Inputs!$C$44,Inputs!$C$48,IF(($B16*(Inputs!$C$32+'Credit Profile'!$C$8)/Inputs!$C$8)<=Inputs!$D$44,Inputs!$D$48,IF(($B16*(Inputs!$C$32+'Credit Profile'!$C$8)/Inputs!$C$8)<=Inputs!$E$44,Inputs!$E$48,IF(($B16*(Inputs!$C$32+'Credit Profile'!$C$8)/Inputs!$C$8)<=Inputs!$F$44,Inputs!$F$48,Inputs!$G$48))))*(1-Inputs!$C$39) -> 0.12962104 | F16: =(1-$B16)*(Inputs!$C$36+('Optimal Structure'!$C$7*(1+(1-Inputs!$C$39)*($B16/(1-$B16))))*F$13)+$B16*IF(($B16*(Inputs!$C$32+'Credit Profile'!$C$8)/Inputs!$C$8)<=Inputs!$C$44,Inputs!$C$48,IF(($B16*(Inputs!$C$32+'Credit Profile'!$C$8)/Inputs!$C$8)<=Inputs!$D$44,Inputs!$D$48,IF(($B16*(Inputs!$C$32+'Credit Profile'!$C$8)/Inputs!$C$8)<=Inputs!$E$44,Inputs!$E$48,IF(($B16*(Inputs!$C$32+'Credit Profile'!$C$8)/Inputs!$C$8)<=Inputs!$F$44,Inputs!$F$48,Inputs!$G$48))))*(1-Inputs!$C$39) -> 0.13399317 | G16: =(1-$B16)*(Inputs!$C$36+('Optimal Structure'!$C$7*(1+(1-Inputs!$C$39)*($B16/(1-$B16))))*G$13)+$B16*IF(($B16*(Inputs!$C$32+'Credit Profile'!$C$8)/Inputs!$C$8)<=Inputs!$C$44,Inputs!$C$48,IF(($B16*(Inputs!$C$32+'Credit Profile'!$C$8)/Inputs!$C$8)<=Inputs!$D$44,Inputs!$D$48,IF(($B16*(Inputs!$C$32+'Credit Profile'!$C$8)/Inputs!$C$8)<=Inputs!$E$44,Inputs!$E$48,IF(($B16*(Inputs!$C$32+'Credit Profile'!$C$8)/Inputs!$C$8)<=Inputs!$F$44,Inputs!$F$48,Inputs!$G$48))))*(1-Inputs!$C$39) -> 0.13836529
B17: 0.4 | C17: =(1-$B17)*(Inputs!$C$36+('Optimal Structure'!$C$7*(1+(1-Inputs!$C$39)*($B17/(1-$B17))))*C$13)+$B17*IF(($B17*(Inputs!$C$32+'Credit Profile'!$C$8)/Inputs!$C$8)<=Inputs!$C$44,Inputs!$C$48,IF(($B17*(Inputs!$C$32+'Credit Profile'!$C$8)/Inputs!$C$8)<=Inputs!$D$44,Inputs!$D$48,IF(($B17*(Inputs!$C$32+'Credit Profile'!$C$8)/Inputs!$C$8)<=Inputs!$E$44,Inputs!$E$48,IF(($B17*(Inputs!$C$32+'Credit Profile'!$C$8)/Inputs!$C$8)<=Inputs!$F$44,Inputs!$F$48,Inputs!$G$48))))*(1-Inputs!$C$39) -> 0.12041878 | D17: =(1-$B17)*(Inputs!$C$36+('Optimal Structure'!$C$7*(1+(1-Inputs!$C$39)*($B17/(1-$B17))))*D$13)+$B17*IF(($B17*(Inputs!$C$32+'Credit Profile'!$C$8)/Inputs!$C$8)<=Inputs!$C$44,Inputs!$C$48,IF(($B17*(Inputs!$C$32+'Credit Profile'!$C$8)/Inputs!$C$8)<=Inputs!$D$44,Inputs!$D$48,IF(($B17*(Inputs!$C$32+'Credit Profile'!$C$8)/Inputs!$C$8)<=Inputs!$E$44,Inputs!$E$48,IF(($B17*(Inputs!$C$32+'Credit Profile'!$C$8)/Inputs!$C$8)<=Inputs!$F$44,Inputs!$F$48,Inputs!$G$48))))*(1-Inputs!$C$39) -> 0.12467187 | E17: =(1-$B17)*(Inputs!$C$36+('Optimal Structure'!$C$7*(1+(1-Inputs!$C$39)*($B17/(1-$B17))))*E$13)+$B17*IF(($B17*(Inputs!$C$32+'Credit Profile'!$C$8)/Inputs!$C$8)<=Inputs!$C$44,Inputs!$C$48,IF(($B17*(Inputs!$C$32+'Credit Profile'!$C$8)/Inputs!$C$8)<=Inputs!$D$44,Inputs!$D$48,IF(($B17*(Inputs!$C$32+'Credit Profile'!$C$8)/Inputs!$C$8)<=Inputs!$E$44,Inputs!$E$48,IF(($B17*(Inputs!$C$32+'Credit Profile'!$C$8)/Inputs!$C$8)<=Inputs!$F$44,Inputs!$F$48,Inputs!$G$48))))*(1-Inputs!$C$39) -> 0.12892497 | F17: =(1-$B17)*(Inputs!$C$36+('Optimal Structure'!$C$7*(1+(1-Inputs!$C$39)*($B17/(1-$B17))))*F$13)+$B17*IF(($B17*(Inputs!$C$32+'Credit Profile'!$C$8)/Inputs!$C$8)<=Inputs!$C$44,Inputs!$C$48,IF(($B17*(Inputs!$C$32+'Credit Profile'!$C$8)/Inputs!$C$8)<=Inputs!$D$44,Inputs!$D$48,IF(($B17*(Inputs!$C$32+'Credit Profile'!$C$8)/Inputs!$C$8)<=Inputs!$E$44,Inputs!$E$48,IF(($B17*(Inputs!$C$32+'Credit Profile'!$C$8)/Inputs!$C$8)<=Inputs!$F$44,Inputs!$F$48,Inputs!$G$48))))*(1-Inputs!$C$39) -> 0.13317806 | G17: =(1-$B17)*(Inputs!$C$36+('Optimal Structure'!$C$7*(1+(1-Inputs!$C$39)*($B17/(1-$B17))))*G$13)+$B17*IF(($B17*(Inputs!$C$32+'Credit Profile'!$C$8)/Inputs!$C$8)<=Inputs!$C$44,Inputs!$C$48,IF(($B17*(Inputs!$C$32+'Credit Profile'!$C$8)/Inputs!$C$8)<=Inputs!$D$44,Inputs!$D$48,IF(($B17*(Inputs!$C$32+'Credit Profile'!$C$8)/Inputs!$C$8)<=Inputs!$E$44,Inputs!$E$48,IF(($B17*(Inputs!$C$32+'Credit Profile'!$C$8)/Inputs!$C$8)<=Inputs!$F$44,Inputs!$F$48,Inputs!$G$48))))*(1-Inputs!$C$39) -> 0.13743115
B18: 0.5 | C18: =(1-$B18)*(Inputs!$C$36+('Optimal Structure'!$C$7*(1+(1-Inputs!$C$39)*($B18/(1-$B18))))*C$13)+$B18*IF(($B18*(Inputs!$C$32+'Credit Profile'!$C$8)/Inputs!$C$8)<=Inputs!$C$44,Inputs!$C$48,IF(($B18*(Inputs!$C$32+'Credit Profile'!$C$8)/Inputs!$C$8)<=Inputs!$D$44,Inputs!$D$48,IF(($B18*(Inputs!$C$32+'Credit Profile'!$C$8)/Inputs!$C$8)<=Inputs!$E$44,Inputs!$E$48,IF(($B18*(Inputs!$C$32+'Credit Profile'!$C$8)/Inputs!$C$8)<=Inputs!$F$44,Inputs!$F$48,Inputs!$G$48))))*(1-Inputs!$C$39) -> 0.12744378 | D18: =(1-$B18)*(Inputs!$C$36+('Optimal Structure'!$C$7*(1+(1-Inputs!$C$39)*($B18/(1-$B18))))*D$13)+$B18*IF(($B18*(Inputs!$C$32+'Credit Profile'!$C$8)/Inputs!$C$8)<=Inputs!$C$44,Inputs!$C$48,IF(($B18*(Inputs!$C$32+'Credit Profile'!$C$8)/Inputs!$C$8)<=Inputs!$D$44,Inputs!$D$48,IF(($B18*(Inputs!$C$32+'Credit Profile'!$C$8)/Inputs!$C$8)<=Inputs!$E$44,Inputs!$E$48,IF(($B18*(Inputs!$C$32+'Credit Profile'!$C$8)/Inputs!$C$8)<=Inputs!$F$44,Inputs!$F$48,Inputs!$G$48))))*(1-Inputs!$C$39) -> 0.13157784 | E18: =(1-$B18)*(Inputs!$C$36+('Optimal Structure'!$C$7*(1+(1-Inputs!$C$39)*($B18/(1-$B18))))*E$13)+$B18*IF(($B18*(Inputs!$C$32+'Credit Profile'!$C$8)/Inputs!$C$8)<=Inputs!$C$44,Inputs!$C$48,IF(($B18*(Inputs!$C$32+'Credit Profile'!$C$8)/Inputs!$C$8)<=Inputs!$D$44,Inputs!$D$48,IF(($B18*(Inputs!$C$32+'Credit Profile'!$C$8)/Inputs!$C$8)<=Inputs!$E$44,Inputs!$E$48,IF(($B18*(Inputs!$C$32+'Credit Profile'!$C$8)/Inputs!$C$8)<=Inputs!$F$44,Inputs!$F$48,Inputs!$G$48))))*(1-Inputs!$C$39) -> 0.13571189 | F18: =(1-$B18)*(Inputs!$C$36+('Optimal Structure'!$C$7*(1+(1-Inputs!$C$39)*($B18/(1-$B18))))*F$13)+$B18*IF(($B18*(Inputs!$C$32+'Credit Profile'!$C$8)/Inputs!$C$8)<=Inputs!$C$44,Inputs!$C$48,IF(($B18*(Inputs!$C$32+'Credit Profile'!$C$8)/Inputs!$C$8)<=Inputs!$D$44,Inputs!$D$48,IF(($B18*(Inputs!$C$32+'Credit Profile'!$C$8)/Inputs!$C$8)<=Inputs!$E$44,Inputs!$E$48,IF(($B18*(Inputs!$C$32+'Credit Profile'!$C$8)/Inputs!$C$8)<=Inputs!$F$44,Inputs!$F$48,Inputs!$G$48))))*(1-Inputs!$C$39) -> 0.13984595 | G18: =(1-$B18)*(Inputs!$C$36+('Optimal Structure'!$C$7*(1+(1-Inputs!$C$39)*($B18/(1-$B18))))*G$13)+$B18*IF(($B18*(Inputs!$C$32+'Credit Profile'!$C$8)/Inputs!$C$8)<=Inputs!$C$44,Inputs!$C$48,IF(($B18*(Inputs!$C$32+'Credit Profile'!$C$8)/Inputs!$C$8)<=Inputs!$D$44,Inputs!$D$48,IF(($B18*(Inputs!$C$32+'Credit Profile'!$C$8)/Inputs!$C$8)<=Inputs!$E$44,Inputs!$E$48,IF(($B18*(Inputs!$C$32+'Credit Profile'!$C$8)/Inputs!$C$8)<=Inputs!$F$44,Inputs!$F$48,Inputs!$G$48))))*(1-Inputs!$C$39) -> 0.14398001

Sheet Summary
B1: Reliance Industries — Debt Capacity and Capital Structure | F1: RELIANCE INDUSTRIES
B2: Debt capacity on one page
B4: WHERE THE BALANCE SHEET STANDS
B5: Net debt / EBITDA — headline | C5: ='Credit Profile'!$C$12 -> 0.59985763
B6: Adjusted net debt / adjusted EBITDA — agency basis | C6: ='Credit Profile'!$C$13 -> 1.2455487
B7: EBITDA / cash interest paid | C7: ='Credit Profile'!$C$16 -> 4.9770391
B8: FFO / adjusted net debt | C8: ='Credit Profile'!$C$21 -> 0.53038152
B9: Free cash flow after dividends (₹ crore) | C9: ='Credit Profile'!$C$23 -> 40399
B10: Published ratings | C10: A- (S&P) · Baa1 (Moody's) · two notches above the sovereign
B12: HOW MUCH MORE IT COULD BORROW
B13: Incremental capacity holding an A-category profile (₹ crore) | C13: ='Debt Capacity'!$D$14 -> 44272
B14: in US$ billion | C14: ='Debt Capacity'!$D$15 -> 5.3020359
B15: binding constraint at A | C15: ='Debt Capacity'!$D$10 -> FFO
B16: Incremental capacity if the company accepted BBB (₹ crore) | C16: ='Debt Capacity'!$E$14 -> 190332
B18: WHERE THE COST OF CAPITAL BOTTOMS OUT
B19: WACC today | C19: ='Optimal Structure'!$C$10 -> 0.12880053
B20: Minimum WACC across the leverage grid | C20: ='Optimal Structure'!$C$25 -> 0.12837153
B21: Debt weight at the minimum | C21: ='Optimal Structure'!$C$26 -> 0.2
B22: Twelve-month sources / uses | C22: =Liquidity!$C$19 -> 1.5072397
B24: • The headline 0.6x understates leverage by about half. Add the leases and the spectrum instalments owed to the government and the ratio is close to 1.25x, which is still comfortably A-category but is the honest starting point.
B25: • Capacity is real but committed. At an A profile the company could add over ₹1.5 lakh crore of net debt, yet FY2026 capex was ₹1.44 lakh crore and free cash flow after dividends was thin. The capacity exists to protect the investment programme through a downturn, not to fund a recapitalisation.
B26: • There is no WACC case for more debt. The curve is flat from 10% to 30% debt and the company is already at the cheap end of it. Leverage beyond the A category costs more in spread than the tax shield returns.
B27: • Liquidity is the story. Cash on hand plus one year's operating cash flow covers every use for the next twelve months with room to spare. That, more than any ratio, is why the rating sits above India's sovereign.

Sheet Checks
B1: Reliance Industries — Debt Capacity and Capital Structure | E1: RELIANCE INDUSTRIES
B2: Every check must read TRUE
B4: INTEGRITY CHECKS
B5: Company net debt reconciles to the published figure of ₹124,717 crore | C5: =ABS('Credit Profile'!$C$5-124717)<1 -> TRUE
B6: Adjusted EBITDA equals reported less the disposal gain | C6: =ABS(Inputs!$C$8-(Inputs!$C$6-Inputs!$C$7))<0.01 -> TRUE
B7: Adjusted net debt exceeds company net debt | C7: ='Credit Profile'!$C$8>'Credit Profile'!$C$5 -> TRUE
B8: Headline leverage reconciles to the published 0.6x within rounding | C8: =ABS('Credit Profile'!$C$12-0.6)<0.02 -> TRUE
B9: Capacity at each rating is the minimum of its three constraints | C9: =AND('Debt Capacity'!$C$9<='Debt Capacity'!$C$6+0.01,'Debt Capacity'!$D$9<='Debt Capacity'!$D$6+0.01,'Debt Capacity'!$E$9<='Debt Capacity'!$E$6+0.01,'Debt Capacity'!$F$9<='Debt Capacity'!$F$6+0.01,'Debt Capacity'!$G$9<='Debt Capacity'!$G$6+0.01) -> TRUE
B10: Capacity rises monotonically as the rating weakens | C10: =AND('Debt Capacity'!$D$9>='Debt Capacity'!$C$9,'Debt Capacity'!$E$9>='Debt Capacity'!$D$9,'Debt Capacity'!$F$9>='Debt Capacity'!$E$9,'Debt Capacity'!$G$9>='Debt Capacity'!$F$9) -> TRUE
B11: Cost of debt rises monotonically as the rating weakens | C11: =AND(Inputs!$D$48>Inputs!$C$48,Inputs!$E$48>Inputs!$D$48,Inputs!$F$48>Inputs!$E$48,Inputs!$G$48>Inputs!$F$48) -> TRUE
B12: Headroom at A is positive | C12: ='Debt Capacity'!$D$14>0 -> TRUE
B13: Unlevered beta is below the observed levered beta | C13: ='Optimal Structure'!$C$7<Inputs!$C$38 -> TRUE
B14: WACC at zero debt equals the unlevered cost of equity | C14: =ABS('Optimal Structure'!$C$23-(Inputs!$C$36+'Optimal Structure'!$C$7*Inputs!$C$37))<0.0001 -> TRUE
B15: Minimum WACC is not above today's WACC | C15: ='Optimal Structure'!$C$25<='Optimal Structure'!$C$10+0.0001 -> TRUE
B16: Base-case sensitivity cell reconciles to the Debt Capacity sheet | C16: =ABS(Sensitivity!E8-'Debt Capacity'!$D$14)<1 -> TRUE
B17: Sources cover uses over twelve months | C17: =Liquidity!$C$19>1 -> TRUE
B18: Effective tax rate is between 15% and 35% | C18: =AND(Inputs!$C$15>0.15,Inputs!$C$15<0.35) -> TRUE
B19: Market capitalisation reconciles to price times shares | C19: =ABS(Inputs!$C$32-Inputs!$C$30*Inputs!$C$31)<1 -> TRUE
B21: MODEL STATUS | C21: =IF(COUNTIF(C5:C19,FALSE())=0,"MODEL OK","CHECK FAILED") -> MODEL OK
B23: The reconciliation to the published net debt and leverage figures is the check that matters most: it proves the model starts from the company's own numbers before it restates them.
